package com.gtladd.gtladditions.common.data.multiblockMachine

import com.gregtechceu.gtceu.api.data.chemical.ChemicalHelper
import com.gregtechceu.gtceu.api.data.tag.TagPrefix
import com.gregtechceu.gtceu.api.machine.MultiblockMachineDefinition
import com.gregtechceu.gtceu.api.machine.multiblock.PartAbility
import com.gregtechceu.gtceu.api.pattern.FactoryBlockPattern
import com.gregtechceu.gtceu.api.pattern.Predicates
import com.gregtechceu.gtceu.common.data.GCyMBlocks
import com.gregtechceu.gtceu.common.data.GTBlocks
import com.gregtechceu.gtceu.common.data.GTMaterials
import com.gtladd.gtladditions.api.machine.GTLAddPartAbility
import net.minecraft.world.level.material.Fluids
import org.gtlcore.gtlcore.common.data.GTLBlocks
import org.gtlcore.gtlcore.utils.Registries
import java.util.function.Function

@SuppressWarnings("DuplicatedCode")
object ElectricMultiRecipeMultiBlocks {

    val COOLING_TOWER = Function { definition: MultiblockMachineDefinition ->
        FactoryBlockPattern.start()
            .aisle("                                                                ", "                                                                ", "                                                                ", "                                                                ", "                                                                ", "                                                                ", "                                                                ", "                                                                ", "                                                                ", "                                                                ", "                                                                ", "                                                                ", "                                                                ", "                                                                ", "                                                                ", "                                                                ", "                                                                ", "                                                                ", "                                                                ", "                                                                ", "                                                                ", "                                                                ", "                                                                ", "                                                                ", "                                                                ", "                                                                ", "                                                                ", "                                                                ", "                                                                ", "                                                                ", "                                                                ", "                                                                ", "                                                                ", "                                                                ", "                                                                ", "                                                                ", "                                                                ", "                                                                ", "                                                                ", "                                                                ", "                                                                ", "                                                                ", "                                                                ", "                                                                ", "                                                                ", "                                                                ", "                                                                ", "                                                                ", "                                                                ", "                                                                ", "                                                                ", "                                                                ", "                                                                ", "                                                                ", "                                                                ", "                                                                ", "                                                                ", "                                                                ", "                                                                ", "                                                                ", "                                                                ", "                                                                ", "                                                                ", "                                                                ", "                                                                ", "                                                                ", "                                                                ", "                                                                ", "                                                                ")
            .aisle("                                                                ", "                                                                ", "                                                                ", "                                                                ", "                                                                ", "                                                                ", "                                                                ", "                                                                ", "                                                                ", "                                                                ", "                                                                ", "                                                                ", "                                                                ", "                                                                ", "                                                                ", "                                                                ", "                                                                ", "                                                                ", "                                                                ", "                                                                ", "                                                                ", "                                                                ", "                                                                ", "                                                                ", "                                                                ", "                                                                ", "                                                                ", "                                                                ", "                                                                ", "                                                                ", "                                                                ", "                                                                ", "                                                                ", "                                                                ", "                                                                ", "                                                                ", "                                                                ", "                                                                ", "                                                                ", "                                                                ", "                                                                ", "                                                                ", "                                                                ", "                                                                ", "                                                                ", "                                                                ", "                                                                ", "                                                                ", "                                                                ", "                                                                ", "                                                                ", "                                                                ", "                                                                ", "                                                                ", "                                                                ", "                                                                ", "                                                                ", "                                                                ", "                                                                ", "                                                                ", "                                                                ", "                                                                ", "                                                                ", "                                                                ", "                                                                ", "                                                                ", "                                                                ", "                                                                ", "                                                                ")
            .aisle("                         CWWWWWWWWWWWC                          ", "                         CCCCCCCCCCCCC                          ", "                         CD  DDCD  DDC                          ", "                         CDD D CDD D C                          ", "                         C  E  C  E  C                          ", "                         C D DDC D DDC                          ", "                         CDD  DCDD  DC                          ", "                         CCCCCCCCCCCCC                          ", "                         FFFFFFFFFFFFF                          ", "                         CCCGG   GGCCC                          ", "                         CCCGG   GGCCC                          ", "                         CCCGG   GGCCC                          ", "                                                                ", "                                                                ", "                                                                ", "                                                                ", "                                                                ", "                                                                ", "                                                                ", "                                                                ", "                                                                ", "                                                                ", "                                                                ", "                                                                ", "                                                                ", "                                                                ", "                                                                ", "                                                                ", "                                                                ", "                                                                ", "                                                                ", "                                                                ", "                                                                ", "                                                                ", "                                                                ", "                                                                ", "                                                                ", "                                                                ", "                                                                ", "                                                                ", "                                                                ", "                                                                ", "                                                                ", "                                                                ", "                                                                ", "                                                                ", "                                                                ", "                                                                ", "                                                                ", "                                                                ", "                                                                ", "                                                                ", "                                                                ", "                                                                ", "                                                                ", "                                                                ", "                                                                ", "                                                                ", "                                                                ", "                                                                ", "                                                                ", "                                                                ", "                                                                ", "                                                                ", "                                                                ", "                                                                ", "                                                                ", "                                                                ", "                                                                ")
            .aisle("                      CCCHHHHHHHHHHHHHCCC                       ", "                      CCCIIIIIIJIIIIIICCC                       ", "                      KLK             KLK                       ", "                      KLK             KLK                       ", "                      KLK             KLK                       ", "                      KLK             KLK                       ", "                      KLK             KLK                       ", "                      CCC             CCC                       ", "                      FFFLLLLLLLLLLLLLFFF                       ", "                      CCC             CCC                       ", "                      CCC             CCC                       ", "                      CCC             CCC                       ", "                         CCCCCCCCCCCCC                          ", "                         CCCCCCCCCCCCC                          ", "                                                                ", "                                                                ", "                                                                ", "                                                                ", "                                                                ", "                                                                ", "                                                                ", "                                                                ", "                                                                ", "                                                                ", "                                                                ", "                                                                ", "                                                                ", "                                                                ", "                                                                ", "                                                                ", "                                                                ", "                                                                ", "                                                                ", "                                                                ", "                                                                ", "                                                                ", "                                                                ", "                                                                ", "                                                                ", "                                                                ", "                                                                ", "                                                                ", "                                                                ", "                                                                ", "                                                                ", "                                                                ", "                                                                ", "                                                                ", "                                                                ", "                                                                ", "                                                                ", "                                                                ", "                                                                ", "                                                                ", "                                                                ", "                                                                ", "                                                                ", "                                                                ", "                                                                ", "                                                                ", "                                                                ", "                                                                ", "                                                                ", "                                                                ", "                                                                ", "                                                                ", "                                                                ", "                                                                ", "                                                                ")
            .aisle("                   CCCHHHHHHHHHHHHHHHHHHHCCC                    ", "                   CCCIIIIIIIIIJIIIIIIIIICCC                    ", "                   KLK                   KLK                    ", "                   KLK                   KLK                    ", "                   KLK                   KLK                    ", "                   KLK                   KLK                    ", "                   KLK                   KLK                    ", "                   CCC                   CCC                    ", "                   FFFLLLLLLLLLLLLLLLLLLLFFF                    ", "                   CCC                   CCC                    ", "                   CCC                   CCC                    ", "                   CCC                   CCC                    ", "                      CCC             CCC                       ", "                      CCC             CCC                       ", "                         CCCCCCCCCCCCC                          ", "                         CCCCCCCCCCCCC                          ", "                                                                ", "                                                                ", "                                                                ", "                                                                ", "                                                                ", "                                                                ", "                                                                ", "                                                                ", "                                                                ", "                                                                ", "                                                                ", "                                                                ", "                                                                ", "                                                                ", "                                                                ", "                                                                ", "                                                                ", "                                                                ", "                                                                ", "                                                                ", "                                                                ", "                                                                ", "                                                                ", "                                                                ", "                                                                ", "                                                                ", "                                                                ", "                                                                ", "                                                                ", "                                                                ", "                                                                ", "                                                                ", "                                                                ", "                                                                ", "                                                                ", "                                                                ", "                                                                ", "                                                                ", "                                                                ", "                                                                ", "                                                                ", "                                                                ", "                                                                ", "                                                                ", "                                                                ", "                                                                ", "                                                                ", "                                                                ", "                                                                ", "                                                                ", "                                                                ", "                                                                ", "                                                                ")
            .aisle("                 CCHHHHHHHHHHHHHHHHHHHHHHHHHCC                  ", "                 CCIIIIIIIIIIIIJIIIIIIIIIIIICC                  ", "                 CC                         CC                  ", "                 CC                         CC                  ", "                 CC                         CC                  ", "                 CC                         CC                  ", "                 CC                         CC                  ", "                 CC                         CC                  ", "                 FFLLLLLLLLLLLLLLLLLLLLLLLLLFF                  ", "                 CC                         CC                  ", "                 CC                         CC                  ", "                 CC                         CC                  ", "                   CCC                   CCC                    ", "                   CCC                   CCC                    ", "                      CCC             CCC                       ", "                      CCC             CCC                       ", "                         CCCCCCCCCCCCC                          ", "                         CCCCCCCCCCCCC                          ", "                         CCCCCCCCCCCCC                          ", "                                                                ", "                                                                ", "                                                                ", "                                                                ", "                                                                ", "                                                                ", "                                                                ", "                                                                ", "                                                                ", "                                                                ", "                                                                ", "                                                                ", "                                                                ", "                                                                ", "                                                                ", "                                                                ", "                                                                ", "                                                                ", "                                                                ", "                                                                ", "                                                                ", "                                                                ", "                                                                ", "                                                                ", "                                                                ", "                                                                ", "                                                                ", "                                                                ", "                                                                ", "                                                                ", "                                                                ", "                                                                ", "                                                                ", "                                                                ", "                                                                ", "                                                                ", "                                                                ", "                                                                ", "                                                                ", "                                                                ", "                                                                ", "                                                                ", "                                                                ", "                                                                ", "                                                                ", "                                                                ", "                                                                ", "                                                                ", "                                                                ", "                                                                ")
            .aisle("               CCHHHHHHHHHHHHHHHHHHHHHHHHHHHHHCC                ", "               CCIIIIIIIIIIIIIIJIIIIIIIIIIIIIICC                ", "               CC                             CC                ", "               CC                             CC                ", "               CC                             CC                ", "               CC                             CC                ", "               CC                             CC                ", "               CC                             CC                ", "               FFLLLLLLLLLLLLLLLLLLLLLLLLLLLLLFF                ", "               CC                             CC                ", "               CC                             CC                ", "               CC                             CC                ", "                 CC                         CC                  ", "                 CC                         CC                  ", "                   CCC                   CCC                    ", "                   CCC                   CCC                    ", "                      CCC             CCC                       ", "                      CCC             CCC                       ", "                      CCC             CCC                       ", "                         CCCCCCCCCCCCC                          ", "                         CCCCCCCCCCCCC                          ", "                         CCCCCCCCCCCCC                          ", "                         CCCCCCCCCCCCC                          ", "                                                                ", "                                                                ", "                                                                ", "                                                                ", "                                                                ", "                                                                ", "                                                                ", "                                                                ", "                                                                ", "                                                                ", "                                                                ", "                                                                ", "                                                                ", "                                                                ", "                                                                ", "                                                                ", "                                                                ", "                                                                ", "                                                                ", "                                                                ", "                                                                ", "                                                                ", "                                                                ", "                                                                ", "                                                                ", "                                                                ", "                                                                ", "                                                                ", "                                                                ", "                                                                ", "                                                                ", "                                                                ", "                                                                ", "                                                                ", "                                                                ", "                                                                ", "                                                                ", "                                                                ", "                                                                ", "                                                                ", "                                                                ", "                                                                ", "                                                                ", "                                                                ", "                                                                ", "                                                                ")
            .aisle("              CHHHHHHHHHHHHHHHHHHHHHHHHHHHHHHHHHC               ", "              CIIIIIIIIIIIIIIIIJIIIIIIIIIIIIIIIIC               ", "              C                                 C               ", "              C                                 C               ", "              C                                 C               ", "              C                                 C               ", "              C                                 C               ", "              C                                 C               ", "              FLLLLLLLLLLLLLLLLLLLLLLLLLLLLLLLLLF               ", "              C                                 C               ", "              C                                 C               ", "              C                                 C               ", "               CC                             CC                ", "               CC                             CC                ", "                 CC                         CC                  ", "                 CC                         CC                  ", "                   CCC                   CCC                    ", "                   CCC                   CCC                    ", "                   CCC                   CCC                    ", "                      CCC             CCC                       ", "                      CCC             CCC                       ", "                      CCC             CCC                       ", "                      CCC             CCC                       ", "                         CCCCCCCCCCCCC                          ", "                         CCCCCM MCCCCC                          ", "                         CCCCC N CCCCC                          ", "                         CCCCCM MCCCCC                          ", "                         CCCCCCCCCCCCC                          ", "                                                                ", "                                                                ", "                                                                ", "                                                                ", "                                                                ", "                                                                ", "                                                                ", "                                                                ", "                                                                ", "                                                                ", "                                                                ", "                                                                ", "                                                                ", "                                                                ", "                                                                ", "                                                                ", "                                                                ", "                                                                ", "                                                                ", "                                                                ", "                                                                ", "                                                                ", "                                                                ", "                                                                ", "                                                                ", "                                                                ", "                                                                ", "                                                                ", "                                                                ", "                                                                ", "                                                                ", "                                                                ", "                                                                ", "                                                                ", "                                                                ", "                                                                ", "                                                                ", "                                                                ", "                                                                ", "                         FFFFFFFFFFFFF                          ", "                                                                ")
            .aisle("            CCHHHHHHHHHHHHHHHHHHHHHHHHHHHHHHHHHHHCC             ", "            CCIIIIIIIIIIIIIIIIIJIIIIIIIIIIIIIIIIICC             ", "            CC                                   CC             ", "            CC                                   CC             ", "            CC                                   CC             ", "            CC                                   CC             ", "            CC                                   CC             ", "            CC                                   CC             ", "            FFLLLLLLLLLLLLLLLLLLLLLLLLLLLLLLLLLLLFF             ", "            CC                                   CC             ", "            CC                                   CC             ", "            CC                                   CC             ", "              C                                 C               ", "              C                                 C               ", "               CC                             CC                ", "               CC                             CC                ", "                 CC                         CC                  ", "                 CC                         CC                  ", "                 CC                         CC                  ", "                   CCC                   CCC                    ", "                   CCC                   CCC                    ", "                   CCC                   CCC                    ", "                   CCC                   CCC                    ", "                      CCC             CCC                       ", "                      CCC             CCC                       ", "                      CCC             CCC                       ", "                      CCC             CCC                       ", "                      CCC             CCC                       ", "                         CCCCCCCCCCCCC                          ", "                         CCCCCCCCCCCCC                          ", "                         CCCCCCCCCCCCC                          ", "                         CCCCCCCCCCCCC                          ", "                         CCCCCCCCCCCCC                          ", "                         CCCCCCCCCCCCC                          ", "                                                                ", "                                                                ", "                                                                ", "                                                                ", "                                                                ", "                                                                ", "                                                                ", "                                                                ", "                                                                ", "                                                                ", "                                                                ", "                                                                ", "                                                                ", "                                                                ", "                                                                ", "                                                                ", "                                                                ", "                                                                ", "                                                                ", "                                                                ", "                                                                ", "                                                                ", "                                                                ", "                                                                ", "                                                                ", "                                                                ", "                                                                ", "                                                                ", "                                                                ", "                                                                ", "                                                                ", "                         CCCCCCCCCCCCC                          ", "                         CCCCCCCCCCCCC                          ", "                      FFF             FFF                       ", "                                                                ")
            .aisle("           CHHHHHHHHHHHHHHHHHHHHHHHHHHHHHHHHHHHHHHHC            ", "           CIIIIIIIIIIIIIIIIIIIJIIIIIIIIIIIIIIIIIIIC            ", "           C                                       C            ", "           C                                       C            ", "           C                                       C            ", "           C                                       C            ", "           C                                       C            ", "           C                                       C            ", "           FLLLLLLLLLLLLLLLLLLLLLLLLLLLLLLLLLLLLLLLF            ", "           C                                       C            ", "           C                                       C            ", "           C                                       C            ", "            CC                                   CC             ", "            CC                                   CC             ", "              C                                 C               ", "              C                                 C               ", "               CC                             CC                ", "               CC                             CC                ", "               CC                             CC                ", "                 CC                         CC                  ", "                 CC                         CC                  ", "                 CC                         CC                  ", "                 CC                         CC                  ", "                   CCC                   CCC                    ", "                   CCC                   CCC                    ", "                   CCC                   CCC                    ", "                   CCC                   CCC                    ", "                   CCC                   CCC                    ", "                      CCC             CCC                       ", "                      CCC             CCC                       ", "                      CCC             CCC                       ", "                      CCC             CCC                       ", "                      CCC             CCC                       ", "                      CCC             CCC                       ", "                         CCCCCCCCCCCCC                          ", "                         CCCC O   CCCC                          ", "                         CCCC O OOCCCC                          ", "                         CCCC  P  CCCC                          ", "                         CCCCOO O CCCC                          ", "                         CCCC   O CCCC                          ", "                         CCCCCCCCCCCCC                          ", "                                                                ", "                                                                ", "                                                                ", "                                                                ", "                                                                ", "                                                                ", "                                                                ", "                                                                ", "                                                                ", "                                                                ", "                                                                ", "                                                                ", "                                                                ", "                                                                ", "                                                                ", "                                                                ", "                                                                ", "                                                                ", "                                                                ", "                                                                ", "                                                                ", "                                                                ", "                                                                ", "                         CCCCCCCCCCCCC                          ", "                      CCC             CCC                       ", "                      CCC             CCC                       ", "                   FFF                   FFF                    ", "                                                                ")
            .aisle("          CHHHHHHHHHHHHHHHHHHHHHHHHHHHHHHHHHHHHHHHHHC           ", "          CIIIIIIIIIIIIIIIIIIIIJIIIIIIIIIIIIIIIIIIIIC           ", "          C                                         C           ", "          C                                         C           ", "          C                                         C           ", "          C                                         C           ", "          C                                         C           ", "          C                                         C           ", "          FLLLLLLLLLLLLLLLLLLLLLLLLLLLLLLLLLLLLLLLLLF           ", "          C                                         C           ", "          C                                         C           ", "          C                                         C           ", "           C                                       C            ", "           C                                       C            ", "            CC                                   CC             ", "            CC                                   CC             ", "              C                                 C               ", "              C                                 C               ", "              C                                 C               ", "               CC                             CC                ", "               CC                             CC                ", "               CC                             CC                ", "               CC                             CC                ", "                 CC                         CC                  ", "                 CC                         CC                  ", "                 CC                         CC                  ", "                 CC                         CC                  ", "                 CC                         CC                  ", "                   CCC                   CCC                    ", "                   CCC                   CCC                    ", "                   CCC                   CCC                    ", "                   CCC                   CCC                    ", "                   CCC                   CCC                    ", "                   CCC                   CCC                    ", "                      CCC             CCC                       ", "                      CCC             CCC                       ", "                      CCC             CCC                       ", "                      CCC             CCC                       ", "                      CCC             CCC                       ", "                      CCC             CCC                       ", "                      CCC             CCC                       ", "                         CCCCCCCCCCCCC                          ", "                         CCCCCCCCCCCCC                          ", "                         CCCCCCCCCCCCC                          ", "                         CCCCCCCCCCCCC                          ", "                         CCCCCCCCCCCCC                          ", "                         CCCCCCCCCCCCC                          ", "                         CCCCCCCCCCCCC                          ", "                         CCCCCCCCCCCCC                          ", "                                                                ", "                                                                ", "                                                                ", "                                                                ", "                                                                ", "                                                                ", "                                                                ", "                                                                ", "                                                                ", "                                                                ", "                                                                ", "                                                                ", "                                                                ", "                         CCCCCCCCCCCCC                          ", "                         CCCCCCCCCCCCC                          ", "                      CCC             CCC                       ", "                   CCC                   CCC                    ", "                   CCC                   CCC                    ", "                 FF                         FF                  ", "                                                                ")
            .aisle("         CHHHHHHHHHHHHHHHHHHHHHHHHHHHHHHHHHHHHHHHHHHHC          ", "         CIIIIIIIIIIIIIIIIIIIIIJIIIIIIIIIIIIIIIIIIIIIC          ", "         C                                           C          ", "         C                                           C          ", "         C                                           C          ", "         C                                           C          ", "         C                                           C          ", "         C                                           C          ", "         FLLLLLLLLLLLLLLLLLLLLLLLLLLLLLLLLLLLLLLLLLLLF          ", "         C                                           C          ", "         C                                           C          ", "         C                                           C          ", "          C                                         C           ", "          C                                         C           ", "           C                                       C            ", "           C                                       C            ", "            CC                                   CC             ", "            CC                                   CC             ", "            CC                                   CC             ", "              C                                 C               ", "              C                                 C               ", "              C                                 C               ", "              C                                 C               ", "               CC                             CC                ", "               CC                             CC                ", "               CC                             CC                ", "               CC                             CC                ", "               CC                             CC                ", "                 CC                         CC                  ", "                 CC                         CC                  ", "                 CC                         CC                  ", "                 CC                         CC                  ", "                 CC                         CC                  ", "                 CC                         CC                  ", "                   CCC                   CCC                    ", "                   CCC                   CCC                    ", "                   CCC                   CCC                    ", "                   CCC                   CCC                    ", "                   CCC                   CCC                    ", "                   CCC                   CCC                    ", "                   CCC                   CCC                    ", "                      CCC             CCC                       ", "                      CCC             CCC                       ", "                      CCC             CCC                       ", "                      CCC             CCC                       ", "                      CCC             CCC                       ", "                      CCC             CCC                       ", "                      CCC             CCC                       ", "                      CCC             CCC                       ", "                         CCCCCCCCCCCCC                          ", "                         CCCCCCCCCCCCC                          ", "                         CCCCCCCCCCCCC                          ", "                         CCCCCCCCCCCCC                          ", "                         CCCCCCCCCCCCC                          ", "                         CCCCCCCCCCCCC                          ", "                                                                ", "                                                                ", "                                                                ", "                                                                ", "                                                                ", "                                                                ", "                         CCCCCCCCCCCCC                          ", "                      CCC             CCC                       ", "                      CCC             CCC                       ", "                   CCC                   CCC                    ", "                 CC                         CC                  ", "                 CC                         CC                  ", "               FF                             FF                ", "                                                                ")
            .aisle("        CHHHHHHHHHHHHHHHHHHHHHHHHHHHHHHHHHHHHHHHHHHHHHC         ", "        CIIIIIIIIIIIIIIIIIIIIIIJIIIIIIIIIIIIIIIIIIIIIIC         ", "        C                                             C         ", "        C                                             C         ", "        C                                             C         ", "        C                                             C         ", "        C                                             C         ", "        C                                             C         ", "        FLLLLLLLLLLLLLLLLLLLLLLLLLLLLLLLLLLLLLLLLLLLLLF         ", "        C                                             C         ", "        C                                             C         ", "        C                                             C         ", "         C                                           C          ", "         C                                           C          ", "          C                                         C           ", "          C                                         C           ", "           C                                       C            ", "           C                                       C            ", "           C                                       C            ", "            CC                                   CC             ", "            CC                                   CC             ", "            CC                                   CC             ", "            CC                                   CC             ", "              C                                 C               ", "              C                                 C               ", "              C                                 C               ", "              C                                 C               ", "              C                                 C               ", "               CC                             CC                ", "               CC                             CC                ", "               CC                             CC                ", "               CC                             CC                ", "               CC                             CC                ", "               CC                             CC                ", "                 CC                         CC                  ", "                 CC                         CC                  ", "                 CC                         CC                  ", "                 CC                         CC                  ", "                 CC                         CC                  ", "                 CC                         CC                  ", "                 CC                         CC                  ", "                   CCC                   CCC                    ", "                   CCC                   CCC                    ", "                   CCC                   CCC                    ", "                   CCC                   CCC                    ", "                   CCC                   CCC                    ", "                   CCC                   CCC                    ", "                   CCC                   CCC                    ", "                   CCC                   CCC                    ", "                      CCC             CCC                       ", "                      CCC             CCC                       ", "                      CCC             CCC                       ", "                      CCC             CCC                       ", "                      CCC             CCC                       ", "                      CCC             CCC                       ", "                         CCCCCCCCCCCCC                          ", "                         CCCCCCCCCCCCC                          ", "                         CCCCCCCCCCCCC                          ", "                         CCCCCCCCCCCCC                          ", "                         CCCCCCCCCCCCC                          ", "                         CCCCCCCCCCCCC                          ", "                      CCC             CCC                       ", "                   CCC                   CCC                    ", "                   CCC                   CCC                    ", "                 CC                         CC                  ", "               CC                             CC                ", "               CC                             CC                ", "              F                                 F               ", "                                                                ")
            .aisle("        CHHHHHHHHHHHHHHHHHHHHHHHHHHHHHHHHHHHHHHHHHHHHHC         ", "        CIIIIIIIIIIIIIIIIIIIIIIJIIIIIIIIIIIIIIIIIIIIIIC         ", "        C                                             C         ", "        C                                             C         ", "        C                                             C         ", "        C                                             C         ", "        C                                             C         ", "        C                                             C         ", "        FLLLLLLLLLLLLLLLLLLLLLLLLLLLLLLLLLLLLLLLLLLLLLF         ", "        C                                             C         ", "        C                                             C         ", "        C                                             C         ", "         C                                           C          ", "         C                                           C          ", "          C                                         C           ", "          C                                         C           ", "           C                                       C            ", "           C                                       C            ", "           C                                       C            ", "            C                                     C             ", "            C                                     C             ", "            C                                     C             ", "            C                                     C             ", "             C                                   C              ", "             C                                   C              ", "             C                                   C              ", "             C                                   C              ", "             C                                   C              ", "              C                                 C               ", "              C                                 C               ", "              C                                 C               ", "              C                                 C               ", "              C                                 C               ", "              C                                 C               ", "               CC                             CC                ", "               CC                             CC                ", "               CC                             CC                ", "               CC                             CC                ", "               CC                             CC                ", "               CC                             CC                ", "               CC                             CC                ", "                 CC                         CC                  ", "                 CC                         CC                  ", "                 CC                         CC                  ", "                 CC                         CC                  ", "                 CC                         CC                  ", "                 CC                         CC                  ", "                 CC                         CC                  ", "                 CC                         CC                  ", "                   CCC                   CCC                    ", "                   CCC                   CCC                    ", "                   CCC                   CCC                    ", "                   CCC                   CCC                    ", "                   CCC                   CCC                    ", "                   CCC                   CCC                    ", "                      CCC             CCC                       ", "                      CCC             CCC                       ", "                      CCC             CCC                       ", "                      CCC             CCC                       ", "                      CCC             CCC                       ", "                      CCC             CCC                       ", "                   CCC                   CCC                    ", "                 CC                         CC                  ", "                 CC                         CC                  ", "               CC                             CC                ", "              C                                 C               ", "              C                                 C               ", "             F                                   F              ", "                                                                ")
            .aisle("       CHHHHHHHHHHHHHHHHHHHHHHHHHHHHHHHHHHHHHHHHHHHHHHHC        ", "       CIIIIIIIIIIIIIIIIIIIIIIIJIIIIIIIIIIIIIIIIIIIIIIIC        ", "       C                                               C        ", "       C                                               C        ", "       C                                               C        ", "       C                                               C        ", "       C                                               C        ", "       C                                               C        ", "       FLLLLLLLLLLLLLLLLLLLLLLLLLLLLLLLLLLLLLLLLLLLLLLLF        ", "       C                                               C        ", "       C                                               C        ", "       C                                               C        ", "        C                                             C         ", "        C                                             C         ", "         C                                           C          ", "         C                                           C          ", "          C                                         C           ", "          C                                         C           ", "          C                                         C           ", "           C                                       C            ", "           C                                       C            ", "           C                                       C            ", "           C                                       C            ", "            C                                     C             ", "            C                                     C             ", "            C                                     C             ", "            C                                     C             ", "            C                                     C             ", "             C                                   C              ", "             C                                   C              ", "             C                                   C              ", "             C                                   C              ", "             C                                   C              ", "             C                                   C              ", "              C                                 C               ", "              C                                 C               ", "              C                                 C               ", "              C                                 C               ", "              C                                 C               ", "              C                                 C               ", "              C                                 C               ", "               CC                             CC                ", "               CC                             CC                ", "               CC                             CC                ", "               CC                             CC                ", "               CC                             CC                ", "               CC                             CC                ", "               CC                             CC                ", "               CC                             CC                ", "                 CC                         CC                  ", "                 CC                         CC                  ", "                 CC                         CC                  ", "                 CC                         CC                  ", "                 CC                         CC                  ", "                 CC                         CC                  ", "                   CCC                   CCC                    ", "                   CCC                   CCC                    ", "                   CCC                   CCC                    ", "                   CCC                   CCC                    ", "                   CCC                   CCC                    ", "                   CCC                   CCC                    ", "                 CC                         CC                  ", "               CC                             CC                ", "               CC                             CC                ", "              C                                 C               ", "             C                                   C              ", "             C                                   C              ", "            F                                     F             ", "                                                                ")
            .aisle("      CHHHHHHHHHHHHHHHHHHHHHHHHHHHHHHHHHHHHHHHHHHHHHHHHHC       ", "      CIIIIIIIIIIIIIIIIIIIIIIIIJIIIIIIIIIIIIIIIIIIIIIIIIC       ", "      C                                                 C       ", "      C                                                 C       ", "      C                                                 C       ", "      C                                                 C       ", "      C                                                 C       ", "      C                                                 C       ", "      FLLLLLLLLLLLLLLLLLLLLLLLLLLLLLLLLLLLLLLLLLLLLLLLLLF       ", "      C                                                 C       ", "      C                                                 C       ", "      C                                                 C       ", "       C                                               C        ", "       C                                               C        ", "        C                                             C         ", "        C                                             C         ", "         C                                           C          ", "         C                                           C          ", "         C                                           C          ", "          C                                         C           ", "          C                                         C           ", "          C                                         C           ", "          C                                         C           ", "           C                                       C            ", "           C                                       C            ", "           C                                       C            ", "           C                                       C            ", "           C                                       C            ", "            C                                     C             ", "            C                                     C             ", "            C                                     C             ", "            C                                     C             ", "            C                                     C             ", "            C                                     C             ", "             C                                   C              ", "             C                                   C              ", "             C                                   C              ", "             C                                   C              ", "             C                                   C              ", "             C                                   C              ", "             C                                   C              ", "              C                                 C               ", "              C                                 C               ", "              C                                 C               ", "              C                                 C               ", "              C                                 C               ", "              C                                 C               ", "              C                                 C               ", "              C                                 C               ", "               CC                             CC                ", "               CC                             CC                ", "               CC                             CC                ", "               CC                             CC                ", "               CC                             CC                ", "               CC                             CC                ", "                 CC                         CC                  ", "                 CC                         CC                  ", "                 CC                         CC                  ", "                 CC                         CC                  ", "                 CC                         CC                  ", "                 CC                         CC                  ", "               CC                             CC                ", "              C                                 C               ", "              C                                 C               ", "             C                                   C              ", "            C                                     C             ", "            C                                     C             ", "           F                                       F            ", "                                                                ")
            .aisle("      CHHHHHHHHHHHHHHHHHHHHHHHHHHHHHHHHHHHHHHHHHHHHHHHHHC       ", "      CIIIIIIIIIIIIIIIIIIIIIIIIJIIIIIIIIIIIIIIIIIIIIIIIIC       ", "      C                                                 C       ", "      C                                                 C       ", "      C                                                 C       ", "      C                                                 C       ", "      C                                                 C       ", "      C                                                 C       ", "      FLLLLLLLLLLLLLLLLLLLLLLLLLLLLLLLLLLLLLLLLLLLLLLLLLF       ", "      C                                                 C       ", "      C                                                 C       ", "      C                                                 C       ", "       C                                               C        ", "       C                                               C        ", "        C                                             C         ", "        C                                             C         ", "         C                                           C          ", "         C                                           C          ", "         C                                           C          ", "          C                                         C           ", "          C                                         C           ", "          C                                         C           ", "          C                                         C           ", "           C                                       C            ", "           C                                       C            ", "           C                                       C            ", "           C                                       C            ", "           C                                       C            ", "            C                                     C             ", "            C                                     C             ", "            C                                     C             ", "            C                                     C             ", "            C                                     C             ", "            C                                     C             ", "             C                                   C              ", "             C                                   C              ", "             C                                   C              ", "             C                                   C              ", "             C                                   C              ", "             C                                   C              ", "             C                                   C              ", "              C                                 C               ", "              C                                 C               ", "              C                                 C               ", "              C                                 C               ", "              C                                 C               ", "              C                                 C               ", "              C                                 C               ", "              C                                 C               ", "               C                               C                ", "               C                               C                ", "               C                               C                ", "               C                               C                ", "               C                               C                ", "               C                               C                ", "                C                             C                 ", "                C                             C                 ", "                C                             C                 ", "                C                             C                 ", "                C                             C                 ", "                C                             C                 ", "               C                               C                ", "              C                                 C               ", "              C                                 C               ", "             C                                   C              ", "            C                                     C             ", "            C                                     C             ", "           F                                       F            ", "                                                                ")
            .aisle("     CHHHHHHHHHHHHHHHHHHHHHHHHHHHHHHHHHHHHHHHHHHHHHHHHHHHC      ", "     CIIIIIIIIIIIIIIIIIIIIIIIIIJIIIIIIIIIIIIIIIIIIIIIIIIIC      ", "     C                                                   C      ", "     C                                                   C      ", "     C                                                   C      ", "     C                                                   C      ", "     C                                                   C      ", "     C                                                   C      ", "     FLLLLLLLLLLLLLLLLLLLLLLLLLLLLLLLLLLLLLLLLLLLLLLLLLLLF      ", "     C                                                   C      ", "     C                                                   C      ", "     C                                                   C      ", "      C                                                 C       ", "      C                                                 C       ", "       C                                               C        ", "       C                                               C        ", "        C                                             C         ", "        C                                             C         ", "        C                                             C         ", "         C                                           C          ", "         C                                           C          ", "         C                                           C          ", "         C                                           C          ", "          C                                         C           ", "          C                                         C           ", "          C                                         C           ", "          C                                         C           ", "          C                                         C           ", "           C                                       C            ", "           C                                       C            ", "           C                                       C            ", "           C                                       C            ", "           C                                       C            ", "           C                                       C            ", "            C                                     C             ", "            C                                     C             ", "            C                                     C             ", "            C                                     C             ", "            C                                     C             ", "            C                                     C             ", "            C                                     C             ", "             C                                   C              ", "             C                                   C              ", "             C                                   C              ", "             C                                   C              ", "             C                                   C              ", "             C                                   C              ", "             C                                   C              ", "             C                                   C              ", "              C                                 C               ", "              C                                 C               ", "              C                                 C               ", "              C                                 C               ", "              C                                 C               ", "              C                                 C               ", "               C                               C                ", "               C                               C                ", "               C                               C                ", "               C                               C                ", "               C                               C                ", "               C                               C                ", "              C                                 C               ", "             C                                   C              ", "             C                                   C              ", "            C                                     C             ", "           C                                       C            ", "           C                                       C            ", "          F                                         F           ", "                                                                ")
            .aisle("     CHHHHHHHHHHHHHHHHHHHHHHHHHHHHHHHHHHHHHHHHHHHHHHHHHHHC      ", "     CIIIIIIIIIIIIIIIIIIIIIIIIIJIIIIIIIIIIIIIIIIIIIIIIIIIC      ", "     C                                                   C      ", "     C                                                   C      ", "     C                                                   C      ", "     C                                                   C      ", "     C                                                   C      ", "     C                                                   C      ", "     FLLLLLLLLLLLLQQQQQQQQQQQSSQSSQQQQQQQQQQQLLLLLLLLLLLLF      ", "     C                                                   C      ", "     C                                                   C      ", "     C                                                   C      ", "      C                                                 C       ", "      C                                                 C       ", "       C                                               C        ", "       C                                               C        ", "        C                                             C         ", "        C                                             C         ", "        C                                             C         ", "         C                                           C          ", "         C                                           C          ", "         C                                           C          ", "         C                                           C          ", "          C                                         C           ", "          C                                         C           ", "          C                                         C           ", "          C                                         C           ", "          C                                         C           ", "           C                                       C            ", "           C                                       C            ", "           C                                       C            ", "           C                                       C            ", "           C                                       C            ", "           C                                       C            ", "            C                                     C             ", "            C                                     C             ", "            C                                     C             ", "            C                                     C             ", "            C                                     C             ", "            C                                     C             ", "            C                                     C             ", "             C                                   C              ", "             C                                   C              ", "             C                                   C              ", "             C                                   C              ", "             C                                   C              ", "             C                                   C              ", "             C                                   C              ", "             C                                   C              ", "              C                                 C               ", "              C                                 C               ", "              C                                 C               ", "              C                                 C               ", "              C                                 C               ", "              C                                 C               ", "               C                               C                ", "               C                               C                ", "               C                               C                ", "               C                               C                ", "               C                               C                ", "               C                               C                ", "              C                                 C               ", "             C                                   C              ", "             C                                   C              ", "            C                                     C             ", "           C                                       C            ", "           C                                       C            ", "          F                                         F           ", "                                                                ")
            .aisle("    CHHHHHHHHHHHHHHHHHHHHHHHHHHHHHHHHHHHHHHHHHHHHHHHHHHHHHC     ", "    CIIIIIIIIIIIIIIIIIIIIIIIIIIJIIIIIIIIIIIIIIIIIIIIIIIIIIC     ", "    K                                                     K     ", "    K                                                     K     ", "    K                                                     K     ", "    K                                                     K     ", "    K                                                     K     ", "    C                                                     C     ", "    FLLLLLLLLLLLLLQ      RR SSSQSSS      RR QLLLLLLLLLLLLLF     ", "    C                                                     C     ", "    C                                                     C     ", "    C                                                     C     ", "     C                                                   C      ", "     C                                                   C      ", "      C                                                 C       ", "      C                                                 C       ", "       C                                               C        ", "       C                                               C        ", "       C                                               C        ", "        C                                             C         ", "        C                                             C         ", "        C                                             C         ", "        C                                             C         ", "         C                                           C          ", "         C                                           C          ", "         C                                           C          ", "         C                                           C          ", "         C                                           C          ", "          C                                         C           ", "          C                                         C           ", "          C                                         C           ", "          C                                         C           ", "          C                                         C           ", "          C                                         C           ", "           C                                       C            ", "           C                                       C            ", "           C                                       C            ", "           C                                       C            ", "           C                                       C            ", "           C                                       C            ", "           C                                       C            ", "            C                                     C             ", "            C                                     C             ", "            C                                     C             ", "            C                                     C             ", "            C                                     C             ", "            C                                     C             ", "            C                                     C             ", "            C                                     C             ", "             C                                   C              ", "             C                                   C              ", "             C                                   C              ", "             C                                   C              ", "             C                                   C              ", "             C                                   C              ", "              C                                 C               ", "              C                                 C               ", "              C                                 C               ", "              C                                 C               ", "              C                                 C               ", "              C                                 C               ", "             C                                   C              ", "            C                                     C             ", "            C                                     C             ", "           C                                       C            ", "          C                                         C           ", "          C                                         C           ", "         F                                           F          ", "                                                                ")
            .aisle("    CHHHHHHHHHHHHHHHHHHHHHHHHHHHHHHHHHHHHHHHHHHHHHHHHHHHHHC     ", "    CIIIIIIIIIIIIIIIIIIIIIIIIIIJIIIIIIIIIIIIIIIIIIIIIIIIIIC     ", "    L                                                     L     ", "    L                                                     L     ", "    L                                                     L     ", "    L                                                     L     ", "    L                                                     L     ", "    C                                                     C     ", "    FLLLLLLLLLLLLLQRR    RR SSSQSSSRR    RR QLLLLLLLLLLLLLF     ", "    C                                                     C     ", "    C                                                     C     ", "    C                                                     C     ", "     C                                                   C      ", "     C                                                   C      ", "      C                                                 C       ", "      C                                                 C       ", "       C                                               C        ", "       C                                               C        ", "       C                                               C        ", "        C                                             C         ", "        C                                             C         ", "        C                                             C         ", "        C                                             C         ", "         C                                           C          ", "         C                                           C          ", "         C                                           C          ", "         C                                           C          ", "         C                                           C          ", "          C                                         C           ", "          C                                         C           ", "          C                                         C           ", "          C                                         C           ", "          C                                         C           ", "          C                                         C           ", "           C                                       C            ", "           C                                       C            ", "           C                                       C            ", "           C                                       C            ", "           C                                       C            ", "           C                                       C            ", "           C                                       C            ", "            C                                     C             ", "            C                                     C             ", "            C                                     C             ", "            C                                     C             ", "            C                                     C             ", "            C                                     C             ", "            C                                     C             ", "            C                                     C             ", "             C                                   C              ", "             C                                   C              ", "             C                                   C              ", "             C                                   C              ", "             C                                   C              ", "             C                                   C              ", "              C                                 C               ", "              C                                 C               ", "              C                                 C               ", "              C                                 C               ", "              C                                 C               ", "              C                                 C               ", "             C                                   C              ", "            C                                     C             ", "            C                                     C             ", "           C                                       C            ", "          C                                         C           ", "          C                                         C           ", "         F                                           F          ", "                                                                ")
