package com.gtladd.gtladditions.common.machine.muiltblock.structure

import com.gregtechceu.gtceu.api.pattern.FactoryBlockPattern
import com.gregtechceu.gtceu.api.pattern.util.RelativeDirection

object MultiBlockStructureE {
    val SUBSPACE_CORRIDOR_HUB_INDUSTRIAL_ARRAY: FactoryBlockPattern? = FactoryBlockPattern.start(
        RelativeDirection.LEFT, RelativeDirection.UP, RelativeDirection.BACK)
        .aisle(*LargeStructureA.A_2)
        .aisle(*LargeStructureA.A_3)
        .aisle(*LargeStructureA.A_4)
        .aisle(*LargeStructureA.A_5)
        .aisle(*LargeStructureA.A_6)
        .aisle(*LargeStructureA.A_7)
        .aisle(*LargeStructureA.A_8)
        .aisle(*LargeStructureA.A_9)
        .aisle(*LargeStructureA.A_10)
        .aisle(*LargeStructureA.A_11)
        .aisle(*LargeStructureA.A_12)
        .aisle(*LargeStructureA.A_13)
        .aisle(*LargeStructureA.A_14)
        .aisle(*LargeStructureA.A_15)
        .aisle(*LargeStructureA.A_16)
        .aisle(*LargeStructureA.A_17)
        .aisle(*LargeStructureA.A_18)
        .aisle(*LargeStructureA.A_19)
        .aisle(*LargeStructureA.A_20)
        .aisle(*LargeStructureA.A_21)
        .aisle(*LargeStructureA.A_22)
        .aisle(*LargeStructureA.A_23)
        .aisle(*LargeStructureA.A_24)
        .aisle(*LargeStructureA.A_25)
        .aisle(*LargeStructureA.A_26)
        .aisle(*LargeStructureA.A_27)
        .aisle(*LargeStructureA.A_28)
        .aisle(*LargeStructureA.A_29)
        .aisle(*LargeStructureA.A_30)
        .aisle(*LargeStructureA.A_31)
        .aisle(*LargeStructureB.A_32)
        .aisle(*LargeStructureB.A_33)
        .aisle(*LargeStructureB.A_34)
        .aisle(*LargeStructureB.A_35)
        .aisle(*LargeStructureB.A_36)
        .aisle(*LargeStructureB.A_37)
        .aisle(*LargeStructureB.A_38)
        .aisle(*LargeStructureB.A_39)
        .aisle(*LargeStructureB.A_40)
        .aisle(*LargeStructureB.A_41)
        .aisle(*LargeStructureB.A_42)
        .aisle(*LargeStructureB.A_43)
        .aisle(*LargeStructureB.A_44)
        .aisle(*LargeStructureB.A_45)
        .aisle(*LargeStructureB.A_46)
        .aisle(*LargeStructureB.A_47)
        .aisle(*LargeStructureB.A_48)
        .aisle(*LargeStructureB.A_49)
        .aisle(*LargeStructureB.A_50)
        .aisle(*LargeStructureB.A_51)
        .aisle(*LargeStructureB.A_52)
        .aisle(*LargeStructureB.A_53)
        .aisle(*LargeStructureB.A_54)
        .aisle(*LargeStructureB.A_55)
        .aisle(*LargeStructureB.A_56)
        .aisle(*LargeStructureB.A_57)
        .aisle(*LargeStructureB.A_58)
        .aisle(*LargeStructureB.A_59)
        .aisle(*LargeStructureB.A_60)
        .aisle(*LargeStructureB.A_61)
        .aisle(*LargeStructureC.A_62)
        .aisle(*LargeStructureC.A_63)
        .aisle(*LargeStructureC.A_64)
        .aisle(*LargeStructureC.A_65)
        .aisle(*LargeStructureC.A_66)
        .aisle(*LargeStructureC.A_67)
        .aisle(*LargeStructureC.A_68)
        .aisle(*LargeStructureC.A_69)
        .aisle(*LargeStructureC.A_70)
        .aisle(*LargeStructureC.A_71)
        .aisle(*LargeStructureC.A_72)
        .aisle(*LargeStructureC.A_73)
        .aisle(*LargeStructureC.A_74)
        .aisle(*LargeStructureC.A_75)
        .aisle(*LargeStructureC.A_76)
        .aisle(*LargeStructureC.A_77)
        .aisle(*LargeStructureC.A_78)
        .aisle(*LargeStructureC.A_79)
        .aisle(*LargeStructureC.A_80)
        .aisle(*LargeStructureC.A_81)
        .aisle(*LargeStructureC.A_82)
        .aisle(*LargeStructureC.A_83)
        .aisle(*LargeStructureC.A_84)
        .aisle(*LargeStructureC.A_85)
        .aisle(*LargeStructureC.A_86)
        .aisle(*LargeStructureC.A_87)
        .aisle(*LargeStructureC.A_88)
        .aisle(*LargeStructureC.A_89)
        .aisle(*LargeStructureC.A_90)
        .aisle(*LargeStructureC.A_91)
        .aisle(*LargeStructureD.A_92)
        .aisle(*LargeStructureD.A_93)
        .aisle(*LargeStructureD.A_94)
        .aisle(*LargeStructureD.A_95)
        .aisle(*LargeStructureD.A_96)
        .aisle(*LargeStructureD.A_97)
        .aisle(*LargeStructureD.A_98)
        .aisle(*LargeStructureD.A_99)
        .aisle(*LargeStructureD.A_100)
        .aisle(*LargeStructureD.A_101)
        .aisle(*LargeStructureD.A_102)
        .aisle(*LargeStructureD.A_103)
        .aisle(*LargeStructureD.A_104)
        .aisle(*LargeStructureD.A_105)
        .aisle(*LargeStructureD.A_106)
        .aisle(*LargeStructureD.A_107)
        .aisle(*LargeStructureD.A_108)
        .aisle(*LargeStructureD.A_109)
        .aisle(*LargeStructureD.A_110)
        .aisle(*LargeStructureD.A_111)
        .aisle(*LargeStructureD.A_112)
        .aisle(*LargeStructureD.A_113)
        .aisle(*LargeStructureD.A_114)
        .aisle(*LargeStructureD.A_115)
        .aisle(*LargeStructureD.A_116)
        .aisle(*LargeStructureD.A_117)
        .aisle(*LargeStructureD.A_118)
        .aisle(*LargeStructureD.A_119)
        .aisle(*LargeStructureD.A_120)
        .aisle(*LargeStructureD.A_121)
        .aisle(*LargeStructureE.A_122)
        .aisle(*LargeStructureE.A_123)
        .aisle(*LargeStructureE.A_124)
        .aisle(*LargeStructureE.A_125)
        .aisle(*LargeStructureE.A_126)
        .aisle(*LargeStructureE.A_127)
        .aisle(*LargeStructureE.A_128)
        .aisle(*LargeStructureE.A_129)
        .aisle(*LargeStructureE.A_130)
        .aisle(*LargeStructureE.A_131)
        .aisle(*LargeStructureE.A_132)
        .aisle(*LargeStructureE.A_133)
        .aisle(*LargeStructureE.A_134)
        .aisle(*LargeStructureE.A_135)
        .aisle(*LargeStructureE.A_136)
        .aisle(*LargeStructureE.A_137)
        .aisle(*LargeStructureE.A_138)
        .aisle(*LargeStructureE.A_139)
        .aisle(*LargeStructureE.A_140)
        .aisle(*LargeStructureE.A_141)
        .aisle(*LargeStructureE.A_142)
        .aisle(*LargeStructureE.A_143)
        .aisle(*LargeStructureE.A_144)
        .aisle(*LargeStructureE.A_145)
        .aisle(*LargeStructureE.A_146)
        .aisle(*LargeStructureE.A_147)
        .aisle(*LargeStructureE.A_148)
        .aisle(*LargeStructureE.A_149)
        .aisle(*LargeStructureE.A_150)
        .aisle(*LargeStructureE.A_151)
        .aisle(*LargeStructureF.A_152)
        .aisle(*LargeStructureF.A_153)
        .aisle(*LargeStructureF.A_154)
        .aisle(*LargeStructureF.A_155)
        .aisle(*LargeStructureF.A_156)
        .aisle(*LargeStructureF.A_157)
        .aisle(*LargeStructureF.A_158)
        .aisle(*LargeStructureF.A_159)
        .aisle(*LargeStructureF.A_160)
        .aisle(*LargeStructureF.A_161)
        .aisle(*LargeStructureF.A_162)
        .aisle(*LargeStructureF.A_163)
        .aisle(*LargeStructureF.A_164)
        .aisle(*LargeStructureF.A_165)
        .aisle(*LargeStructureF.A_166)
        .aisle(*LargeStructureF.A_167)
        .aisle(*LargeStructureF.A_168)
        .aisle(*LargeStructureF.A_169)
        .aisle(*LargeStructureF.A_170)
        .aisle(*LargeStructureF.A_171)
        .aisle(*LargeStructureF.A_172)
        .aisle(*LargeStructureF.A_173)
        .aisle(*LargeStructureF.A_174)
        .aisle(*LargeStructureF.A_175)
        .aisle(*LargeStructureF.A_176)
        .aisle(*LargeStructureF.A_177)
        .aisle(*LargeStructureF.A_178)
        .aisle(*LargeStructureF.A_179)
        .aisle(*LargeStructureF.A_180)
        .aisle(*LargeStructureF.A_181)
        .aisle(*LargeStructureG.A_182)
        .aisle(*LargeStructureG.A_183)
        .aisle(*LargeStructureG.A_184)
        .aisle(*LargeStructureG.A_185)
        .aisle(*LargeStructureG.A_186)
        .aisle(*LargeStructureG.A_187)
        .aisle(*LargeStructureG.A_188)
        .aisle(*LargeStructureG.A_189)
        .aisle(*LargeStructureG.A_190)
        .aisle(*LargeStructureG.A_191)
        .aisle(*LargeStructureG.A_192)
        .aisle(*LargeStructureG.A_193)
        .aisle(*LargeStructureG.A_194)
        .aisle(*LargeStructureG.A_195)
        .aisle(*LargeStructureG.A_196)
        .aisle(*LargeStructureG.A_197)
        .aisle(*LargeStructureG.A_198)
        .aisle(*LargeStructureG.A_199)
        .aisle(*LargeStructureG.A_200)
        .aisle(*LargeStructureG.A_201)
        .aisle(*LargeStructureG.A_202)
        .aisle(*LargeStructureG.A_203)
        .aisle(*LargeStructureG.A_204)
        .aisle(*LargeStructureG.A_205)
        .aisle(*LargeStructureG.A_206)
        .aisle(*LargeStructureG.A_207)
        .aisle(*LargeStructureG.A_208)
        .aisle(*LargeStructureG.A_209)
        .aisle(*LargeStructureG.A_210)
        .aisle(*LargeStructureG.A_211)
        .aisle(*LargeStructureH.A_212)
        .aisle(*LargeStructureH.A_213)
        .aisle(*LargeStructureH.A_214)
        .aisle(*LargeStructureH.A_215)
        .aisle(*LargeStructureH.A_216)
        .aisle(*LargeStructureH.A_217)
        .aisle(*LargeStructureH.A_218)
        .aisle(*LargeStructureH.A_219)
        .aisle(*LargeStructureH.A_220)
        .aisle(*LargeStructureH.A_221)
        .aisle(*LargeStructureH.A_222)
        .aisle(*LargeStructureH.A_223)
        .aisle(*LargeStructureH.A_224)
        .aisle(*LargeStructureH.A_225)
        .aisle(*LargeStructureH.A_226)
        .aisle(*LargeStructureH.A_227)
        .aisle(*LargeStructureH.A_228)
        .aisle(*LargeStructureH.A_229)
        .aisle(*LargeStructureH.A_230)
        .aisle(*LargeStructureH.A_231)
        .aisle(*LargeStructureH.A_232)
        .aisle(*LargeStructureH.A_233)
        .aisle(*LargeStructureH.A_234)
        .aisle(*LargeStructureH.A_235)
        .aisle(*LargeStructureH.A_236)
        .aisle(*LargeStructureH.A_237)
        .aisle(*LargeStructureH.A_238)
        .aisle(*LargeStructureH.A_239)
        .aisle(*LargeStructureH.A_240)
        .aisle(*LargeStructureH.A_241)
        .aisle(*LargeStructureI.A_242)
        .aisle(*LargeStructureI.A_243)
        .aisle(*LargeStructureI.A_244)
        .aisle(*LargeStructureI.A_245)
        .aisle(*LargeStructureI.A_246)
        .aisle(*LargeStructureI.A_247)
        .aisle(*LargeStructureI.A_248)
        .aisle(*LargeStructureI.A_249)
        .aisle(*LargeStructureI.A_250)
        .aisle(*LargeStructureI.A_251)
        .aisle(*LargeStructureI.A_252)
        .aisle(*LargeStructureI.A_253)
        .aisle(*LargeStructureI.A_254)
        .aisle(*LargeStructureI.A_255)
        .aisle(*LargeStructureI.A_256)
        .aisle(*LargeStructureI.A_257)
        .aisle(*LargeStructureI.A_258)
        .aisle(*LargeStructureI.A_259)
        .aisle(*LargeStructureI.A_260)
        .aisle(*LargeStructureI.A_261)
        .aisle(*LargeStructureI.A_262)
        .aisle(*LargeStructureI.A_263)
        .aisle(*LargeStructureI.A_264)
        .aisle(*LargeStructureI.A_265)
        .aisle(*LargeStructureI.A_266)
        .aisle(*LargeStructureI.A_267)
        .aisle(*LargeStructureI.A_268)
        .aisle(*LargeStructureI.A_269)
        .aisle(*LargeStructureI.A_270)
        .aisle(*LargeStructureI.A_271)
        .aisle(*LargeStructureJ.A_272)
        .aisle(*LargeStructureJ.A_273)
        .aisle(*LargeStructureJ.A_274)

    val SUBSPACE_CORRIDOR_HUB_INDUSTRIAL_ARRAY_MODULE: FactoryBlockPattern? = FactoryBlockPattern.start(
        RelativeDirection.LEFT, RelativeDirection.UP, RelativeDirection.BACK)
        .aisle("C", "B", "B", "B", "~", "B", "B")
        .aisle("C", "B", "B", "B", "B", "B", "B")
        .aisle("A", "B", "B", "B", "B", "B", "B")

    val MACRO_ATOMIC_RESONANT_FRAGMENT_STRIPPER: FactoryBlockPattern? =
        FactoryBlockPattern.start(
            RelativeDirection.LEFT, RelativeDirection.BACK, RelativeDirection.DOWN)
            .aisle("                                                                             ","                                                                             ","                                                                             ","                                                                             ","                                                                             ","                                                                             ","                                                                             ","                                                                             ","                                                                             ","                                                                             ","                                                                             ","                                GGGGGGGGGGGGG                                ","                                ZZZZZZZZZZZZZ                                ","                                GGGGGGGGGGGGG                                ","                                                                             ","                                                                             ","                                                                             ","                                                                             ","                                                                             ","                                                                             ","                                                                             ","                                                                             ","                                                                             ","                                                                             ","                                                                             ")
            .aisle("                                                                             ","                                                                             ","                                                                             ","                                                                             ","                                                                             ","                                                                             ","                                                                             ","                                                                             ","                                                                             ","                                                                             ","                                GGGGGGGGGGGGG                                ","                            GGGGBBBBBBBBBBBBBGGGG                            ","                            ZZZZBBBBBBBBBBBBBZZZZ                            ","                            GGGGBBBBBBBBBBBBBGGGG                            ","                                GGGGGGGGGGGGG                                ","                                                                             ","                                                                             ","                                                                             ","                                                                             ","                                                                             ","                                                                             ","                                                                             ","                                                                             ","                                                                             ","                                                                             ")
            .aisle("                                                                             ","                                                                             ","                                                                             ","                                                                             ","                                                                             ","                                                                             ","                                                                             ","                                                                             ","                                                                             ","                                GGGGGGGGGGGGG                                ","                            GGGGBBBBBBBBBBBBBGGGG                            ","                         GGGBBBBBBBBBBBBBBBBBBBBBGGG                         ","                         ZZZBBBBBBBBBBBBBBBBBBBBBZZZ                         ","                         GGGBBBBBBBBBBBBBBBBBBBBBGGG                         ","                            GGGGBBBBBBBBBBBBBGGGG                            ","                                GGGGGGGGGGGGG                                ","                                                                             ","                                                                             ","                                                                             ","                                                                             ","                                                                             ","                                                                             ","                                                                             ","                                                                             ","                                                                             ")
            .aisle("                                                                             ","                                                                             ","                                                                             ","                                                                             ","                                                                             ","                                                                             ","                                                                             ","                                                                             ","                                                                             ","                            GGGGIIIIIIIIIIIIIGGGG                            ","                         GGGBBBBBBBBBBBBBBBBBBBBBGGG                         ","                      GGGBBBBBBBBBBBBBBBBBBBBBBBBBBBGGG                      ","                      ZZZBBBBBBBBBBBBBBBBBBBBBBBBBBBZZZ                      ","                      GGGBBBBBBBBBBBBBBBBBBBBBBBBBBBGGG                      ","                         GGGBBBBBBBBBBBBBBBBBBBBBGGG                         ","                            GGGGIIIIIIIIIIIIIGGGG                            ","                                                                             ","                                                                             ","                                                                             ","                                                                             ","                                                                             ","                                                                             ","                                                                             ","                                                                             ","                                                                             ")
            .aisle("                                                                             ","                                                                             ","                                                                             ","                                                                             ","                                                                             ","                                                                             ","                                                                             ","                                                                             ","                                                                             ","                         GGGIIIIIIIIIIIIIIIIIIIIIGGG                         ","                      GGGBBBBBBBBBBBBBBBBBBBBBBBBBBBGGG                      ","                    GGBBBBBBBBBBBBBBBBBBBBBBBBBBBBBBBBBGG                    ","                    ZZBBBBBBBBBBBBBBBBBBBBBBBBBBBBBBBBBZZ                    ","                    GGBBBBBBBBBBBBBBBBBBBBBBBBBBBBBBBBBGG                    ","                      GGGBBBBBBBBBBBBBBBBBBBBBBBBBBBGGG                      ","                         GGGIIIIIIIIIIIIIIIIIIIIIGGG                         ","                                                                             ","                                                                             ","                                                                             ","                                                                             ","                                                                             ","                                                                             ","                                                                             ","                                                                             ","                                                                             ")
            .aisle("                                                                             ","                                                                             ","                                                                             ","                                                                             ","                                                                             ","                                                                             ","                                                                             ","                                                                             ","                                                                             ","                       GGIIIIIIIIIIIIIIIIIIIIIIIIIIIGG                       ","                    GGGBBBBBBBBBBIIIJLLLJIIIBBBBBBBBBBGGG                    ","                   GBBBBBBBBBBBBBIIJLMMMLJIIBBBBBBBBBBBBBG                   ","                   ZBBBBBBBBBBBBBIIJLMMMLJIIBBBBBBBBBBBBBZ                   ","                   GBBBBBBBBBBBBBIIJLMMMLJIIBBBBBBBBBBBBBG                   ","                    GGGBBBBBBBBBBIIIJLLLJIIIBBBBBBBBBBGGG                    ","                       GGIIIIIIIIIIIIIIIIIIIIIIIIIIIGG                       ","                                                                             ","                                                                             ","                                                                             ","                                                                             ","                                                                             ","                                                                             ","                                                                             ","                                                                             ","                                                                             ")
            .aisle("                                                                             ","                                                                             ","                                                                             ","                                                                             ","                                                                             ","                                                                             ","                                                                             ","                                                                             ","                                                                             ","                     GGIIIIIIIIIIGGGGGGGGGGGIIIIIIIIIIGG                     ","                   GGBBBBBBB     GGJIMMMIJGG     BBBBBBBGG                   ","                 GGBBBBBBBBB     GJIMMMMMIJG     BBBBBBBBBGG                 ","                 ZZBBBBBBBBB     GJIMMMMMIJG     BBBBBBBBBZZ                 ","                 GGBBBBBBBBB     GJIMMMMMIJG     BBBBBBBBBGG                 ","                   GGBBBBBBB     GGJIMMMIJGG     BBBBBBBGG                   ","                     GGIIIIIIIIIIGGGGGGGGGGGIIIIIIIIIIGG                     ","                                                                             ","                                                                             ","                                                                             ","                                                                             ","                                                                             ","                                                                             ","                                                                             ","                                                                             ","                                                                             ")
            .aisle("                                                                             ","                                                                             ","                                                                             ","                                                                             ","                                                                             ","                                                                             ","                                                                             ","                                                                             ","                                                                             ","                   GGIIIIIIIIGGGG   OOOOO   GGGGIIIIIIIIGG                   ","                 GGBBBBBBB   AAAG  OGGGGGO  GAAA   BBBBBBBGG                 ","                GBBBBBBBBB   AAAG OGGMMMGGO GAAA   BBBBBBBBBG                ","                ZBBBBBBBBB   AAAG OGIMMMIGO GAAA   BBBBBBBBBZ                ","                GBBBBBBBBB   AAAG OGGMMMGGO GAAA   BBBBBBBBBG                ","                 GGBBBBBBB   AAAG  OGGGGGO  GAAA   BBBBBBBGG                 ","                   GGIIIIIIIIGGGG   OOOOO   GGGGIIIIIIIIGG                   ","                                                                             ","                                                                             ","                                                                             ","                                                                             ","                                                                             ","                                                                             ","                                                                             ","                                                                             ","                                                                             ")
            .aisle("                                                                             ","                                                                             ","                                                                             ","                                                                             ","                                                                             ","                                                                             ","                                                                             ","                                                                             ","                                                                             ","                  GIIIIIIIGGG        GGG        GGGIIIIIIIG                  ","                GGBBBBB   AAAGGG    GIIIG    GGGAAA   BBBBBGG                ","              GGBBBBBBB   AAA      GIOOOIG      AAA   BBBBBBBGG              ","              ZZBBBBBBB   AAA      GIOOOIG      AAA   BBBBBBBZZ              ","              GGBBBBBBB   AAA      GIOOOIG      AAA   BBBBBBBGG              ","                GGBBBBB   AAAGGG    GIIIG    GGGAAA   BBBBBGG                ","                  GIIIIIIIGGG        GGG        GGGIIIIIIIG                  ","                                                                             ","                                                                             ","                                                                             ","                                                                             ","                                                                             ","                                                                             ","                                                                             ","                                                                             ","                                                                             ")
            .aisle("                                                                             ","                                                                             ","                                                                             ","                                                                             ","                                                                             ","                                                                             ","                                                                             ","                                                                             ","                                                                             ","                GGIIIIIIGG                         GGIIIIIIGG                ","              GGBBBBB   AAGGG                   GGGAA   BBBBBGG              ","             GBBBBBBB   AA                         AA   BBBBBBBG             ","             ZBBBBBBB   AA                         AA   BBBBBBBZ             ","             GBBBBBBB   AA                         AA   BBBBBBBG             ","              GGBBBBB   AAGGG                   GGGAA   BBBBBGG              ","                GGIIIIIIGG                         GGIIIIIIGG                ","                                                                             ","                                                                             ","                                                                             ","                                                                             ","                                                                             ","                                                                             ","                                                                             ","                                                                             ","                                                                             ")
            .aisle("                                                                             ","                                                                             ","                                                                             ","                                                                             ","                                                                             ","                                                                             ","                                                                             ","                                                                             ","                                                                             ","               GIIIIIIGG                             GGIIIIIIG               ","             GGBBBBB  AAGG                         GGAA  BBBBBGG             ","            GBBBBBBB  AA                             AA  BBBBBBBG            ","            ZBBBBBBB  AA                             AA  BBBBBBBZ            ","            GBBBBBBB  AA                             AA  BBBBBBBG            ","             GGBBBBB  AAGG                         GGAA  BBBBBGG             ","               GIIIIIIGG                             GGIIIIIIG               ","                                                                             ","                                                                             ","                                                                             ","                                                                             ","                                                                             ","                                                                             ","                                                                             ","                                                                             ","                                                                             ")
            .aisle("                                                                             ","                                                                             ","                                                                             ","                                                                             ","                                                                             ","                                                                             ","                                                                             ","                                                                             ","                                                                             ","              GIIIIIGG                                 GGIIIIIG              ","            GGBBBB  AAGG                             GGAA  BBBBGG            ","           GBBBBBB  AA                                 AA  BBBBBBG           ","           ZBBBBBB  AA                                 AA  BBBBBBZ           ","           GBBBBBB  AA                                 AA  BBBBBBG           ","            GGBBBB  AAGG                             GGAA  BBBBGG            ","              GIIIIIGG                                 GGIIIIIG              ","                                                                             ","                                                                             ","                                                                             ","                                                                             ","                                                                             ","                                                                             ","                                                                             ","                                                                             ","                                                                             ")
            .aisle("                                                                             ","                                                                             ","                                                                             ","                                                                             ","                                                                             ","                                                                             ","                                      O                                      ","                                    OOOOO                                    ","                                  OOGGGGGOO                                  ","             GIIIIIG              OGGGGGGGO              GIIIIIG             ","           GGBBBB  AGG           OGGGJJJGGGO           GGA  BBBBGG           ","          GBBBBBB  A             OGGJOOOJGGO             A  BBBBBBG          ","          ZBBBBBB  A            OOGGJOOOJGGOO            A  BBBBBBZ          ","          GBBBBBB  A             OGGJOOOJGGO             A  BBBBBBG          ","           GGBBBB  AGG           OGGGJJJGGGO           GGA  BBBBGG           ","             GIIIIIG              OGGGGGGGO              GIIIIIG             ","                                  OOGGGGGOO                                  ","                                    OOOOO                                    ","                                      O                                      ","                                                                             ","                                                                             ","                                                                             ","                                                                             ","                                                                             ","                                                                             ")
            .aisle("                                                                             ","                                                                             ","                                                                             ","                                                                             ","                                                                             ","                                    GEOEG                                    ","                                  GGEEEEEGG                                  ","                                 GEEGGGGGEEG                                 ","                                GEGGBBBBBGGEG                                ","            GIIIIIG             GEGBNNNNNBGEG             GIIIIIG            ","          GGBBBB  AG           GEGBNGKKKGNBGEG           GA  BBBBGG          ","         GBBBBBB  A            GEGBNKMMMKNBGEG            A  BBBBBBG         ","         ZBBBBBB  A            OEGBNKMMMKNBGEO            A  BBBBBBZ         ","         GBBBBBB  A            GEGBNKMMMKNBGEG            A  BBBBBBG         ","          GGBBBB  AG           GEGBNGKKKGNBGEG           GA  BBBBGG          ","            GIIIIIG             GEGBNNNNNBGEG             GIIIIIG            ","                                GEGGBBBBBGGEG                                ","                                 GEEGGGGGEEG                                 ","                                  GGEEEEEGG                                  ","                                    GEOEG                                    ","                                                                             ","                                                                             ","                                                                             ","                                                                             ","                                                                             ")
            .aisle("                                                                             ","                                                                             ","                                                                             ","                                                                             ","                                   GGEGEGG                                   ","                                 GGGBBGBBGGG                                 ","                                GGBBBBBBBBBGG                                ","                               GGBBBNNNNNBBBGG                               ","                               GBBBNBBBBBNBBBG                               ","           GIIIIIG            GGBBNBNNNNNBNBBGG            GIIIIIG           ","         GGBBBB  AG           GBBNBNGKKKGNBNBBG           GA  BBBBGG         ","        GBBBBBB  A            GBBNBNKKKKKNBNBBG            A  BBBBBBG        ","        ZBBBBBB  A            EEBNBNKKKKKNBNBEE            A  BBBBBBZ        ","        GBBBBBB  A            GBBNBNKKKKKNBNBBG            A  BBBBBBG        ","         GGBBBB  AG           GBBNBNGKKKGNBNBBG           GA  BBBBGG         ","           GIIIIIG            GGBBNBNNNNNBNBBGG            GIIIIIG           ","                               GBBBNBBBBBNBBBG                               ","                               GGBBBNNNNNBBBGG                               ","                                GGBBBBBBBBBGG                                ","                                 GGGBBGBBGGG                                 ","                                   GGEGEGG                                   ","                                                                             ","                                                                             ","                                                                             ","                                                                             ")
            .aisle("                                                                             ","                                                                             ","                                                                             ","                                   GGEGEGG                                   ","                                 GGNNNNNNNGG                                 ","                                GNNNBBBBBNNNG                                ","                               GNNBBBBBBBBBNNG                               ","                              GNNBBBNNNNNBBBNNG                              ","                              GNBBBNBBBBBNBBBNG                              ","          GIIIIIG            GNNBBNBNNNNNBNBBNNG            GIIIIIG          ","         GBBBB  AG           GNBBNBNGKKKGNBNBBNG           GA  BBBBG         ","        GBBBBB  A            GNBBNBNKKKKKNBNBBNG            A  BBBBBG        ","        ZBBBBB  A            ENBBNBNKKKKKNBNBBNE            A  BBBBBZ        ","        GBBBBB  A            GNBBNBNKKKKKNBNBBNG            A  BBBBBG        ","         GBBBB  AG           GNBBNBNGKKKGNBNBBNG           GA  BBBBG         ","          GIIIIIG            GNNBBNBNNNNNBNBBNNG            GIIIIIG          ","                              GNBBBNBBBBBNBBBNG                              ","                              GNNBBBNNNNNBBBNNG                              ","                               GNNBBBBBBBBBNNG                               ","                                GNNNBBBBBNNNG                                ","                                 GGNNNNNNNGG                                 ","                                   GGEGEGG                                   ","                                                                             ","                                                                             ","                                                                             ")
            .aisle("                                                                             ","                                                                             ","                                                                             ","                                   EEEEEEE                                   ","                                 EEGGGGGGGEE                                 ","                                EGGGIIIIIGGGE                                ","                               EGGIIIIIIIIIGGE                               ","                              EGGIIIGGGGGIIIGGE                              ","                              EGIIIGGGGGGGIIIGE                              ","         GIIIIIG             EGGIIGGGGGGGGGIIGGE             GIIIIIG         ","        GBBBB  AG            EGIIGGGGGGGGGGGIIGE            GA  BBBBG        ","       GBBBBB  A             EGIIGGGGGGGGGGGIIGE             A  BBBBBG       ","       ZBBBBB  A             EGIIGGGGGGGGGGGIIGE             A  BBBBBZ       ","       GBBBBB  A             EGIIGGGGGGGGGGGIIGE             A  BBBBBG       ","        GBBBB  AG            EGIIGGGGGGGGGGGIIGE            GA  BBBBG        ","         GIIIIIG             EGGIIGGGGGGGGGIIGGE             GIIIIIG         ","                              EGIIIGGGGGGGIIIGE                              ","                              EGGIIIGGGGGIIIGGE                              ","                               EGGIIIIIIIIIGGE                               ","                                EGGGIIIIIGGGE                                ","                                 EEGGGGGGGEE                                 ","                                   EEEEEEE                                   ","                                                                             ","                                                                             ","                                                                             ")
            .aisle("                                                                             ","                                                                             ","                                                                             ","                                   GGGGGGG                                   ","                                 GGOOOOOOOGG                                 ","                                GOOO     OOOG                                ","                               GOO         OOG                               ","                              GOO   GGGGG   OOG                              ","                              GO   GJJJJJG   OG                              ","         GIIIIG              GOO  GJGGGGGJG  OOG              GIIIIG         ","       GGBBB  AG             GO  GJGGJJJGGJG  OG             GA  BBBGG       ","      GBBBBB  A              GO  GJGJGGGJGJG  OG              A  BBBBBG      ","      ZBBBBB  A              GO  GJGJGGGJGJG  OG              A  BBBBBZ      ","      GBBBBB  A              GO  GJGJGGGJGJG  OG              A  BBBBBG      ","       GGBBB  AG             GO  GJGGJJJGGJG  OG             GA  BBBGG       ","         GIIIIG              GOO  GJGGGGGJG  OOG              GIIIIG         ","                              GO   GJJJJJG   OG                              ","                              GOO   GGGGG   OOG                              ","                               GOO         OOG                               ","                                GOOO     OOOG                                ","                                 GGOOOOOOOGG                                 ","                                   GGGGGGG                                   ","                                                                             ","                                                                             ","                                                                             ")
            .aisle("                                                                             ","                                                                             ","                                                                             ","                                                                             ","                                                                             ","                                                                             ","                                                                             ","                                                                             ","                                                                             ","        GIIIIG                                                 GIIIIG        ","       GBBB  AG                                               GA  BBBG       ","      GBBBB  A                                                 A  BBBBG      ","      ZBBBB  A                                                 A  BBBBZ      ","      GBBBB  A                                                 A  BBBBG      ","       GBBB  AG                                               GA  BBBG       ","        GIIIIG                                                 GIIIIG        ","                                                                             ","                                                                             ","                                                                             ","                                                                             ","                                                                             ","                                                                             ","                                                                             ","                                                                             ","                                                                             ")
            .aisle("                                                                             ","                                                                             ","                                                                             ","                                                                             ","                                                                             ","                                                                             ","                                                                             ","                                                                             ","                                                                             ","       GIIIIG                                                   GIIIIG       ","      GBBBB AG                                                 GA BBBBG      ","     GBBBBB A                                                   A BBBBBG     ","     ZBBBBB A                                                   A BBBBBZ     ","     GBBBBB A                                                   A BBBBBG     ","      GBBBB AG                                                 GA BBBBG      ","       GIIIIG                                                   GIIIIG       ","                                                                             ","                                                                             ","                                                                             ","                                                                             ","                                                                             ","                                                                             ","                                                                             ","                                                                             ","                                                                             ")
            .aisle("                                                                             ","                                                                             ","                                                                             ","                                   GGGGGGG                                   ","                                 GGOOOOOOOGG                                 ","                                GOOO     OOOG                                ","                               GOO         OOG                               ","                              GOO   GGGGG   OOG                              ","                              GO   GIIIIIG   OG                              ","       GIIIG                 GOO  GIGGGGGIG  OOG                 GIIIG       ","     GGBBB AG                GO  GIGGIIIGGIG  OG                GA BBBGG     ","    GBBBBB A                 GO  GIGIGGGIGIG  OG                 A BBBBBG    ","    ZBBBBB A                 GO  GIGIGGGIGIG  OG                 A BBBBBZ    ","    GBBBBB A                 GO  GIGIGGGIGIG  OG                 A BBBBBG    ","     GGBBB AG                GO  GIGGIIIGGIG  OG                GA BBBGG     ","       GIIIG                 GOO  GIGGGGGIG  OOG                 GIIIG       ","                              GO   GIIIIIG   OG                              ","                              GOO   GGGGG   OOG                              ","                               GOO         OOG                               ","                                GOOO     OOOG                                ","                                 GGOOOOOOOGG                                 ","                                   GGGGGGG                                   ","                                                                             ","                                                                             ","                                                                             ")
            .aisle("                                                                             ","                                   GGGGGGG                                   ","                                 GGEEEEEEEGG                                 ","                               GGEEGGGGGGGEEGG                               ","                              GGEGGGGGGGGGGGEGG                              ","                             GGEGGGGJJJJJGGGGEGG                             ","                             GEGGGJJJJJJJJJGGGEG                             ","                            GEGGGJJJGGGGGJJJGGGEG                            ","                            GEGGJJJGGGGGGGJJJGGEG                            ","      GIIIIG               GEGGGJJGGGGGGGGGJJGGGEG               GIIIIG      ","     GBBB  AG              GEGGJJGGGGGGGGGGGJJGGEG              GA  BBBG     ","    GBBBB  A               GEGGJJGGGGGGGGGGGJJGGEG               A  BBBBG    ","    ZBBBB  A               GEGGJJGGGGGGGGGGGJJGGEG               A  BBBBZ    ","    GBBBB  A               GEGGJJGGGGGGGGGGGJJGGEG               A  BBBBG    ","     GBBB  AG              GEGGJJGGGGGGGGGGGJJGGEG              GA  BBBG     ","      GIIIIG               GEGGGJJGGGGGGGGGJJGGGEG               GIIIIG      ","                            GEGGJJJGGGGGGGJJJGGEG                            ","                            GEGGGJJJGGGGGJJJGGGEG                            ","                             GEGGGJJJJJJJJJGGGEG                             ","                             GGEGGGGJJJJJGGGGEGG                             ","                              GGEGGGGGGGGGGGEGG                              ","                               GGEEGGGGGGGEEGG                               ","                                 GGEEEEEEEGG                                 ","                                   GGGGGGG                                   ","                                                                             ")
            .aisle("                                   GGGGGGG                                   ","                                 GGEEEEEEEGG                                 ","                               GGEEEEEEEEEEEGG                               ","                              GEEEEEEEEEEEEEEEG                              ","                             GEEEEEEEEEEEEEEEEEG                             ","                            GEEEEEEEEEEEEEEEEEEEG                            ","                            GEEEEEEEEEEEEEEEEEEEG                            ","                           GEEEEEEEEEEEEEEEEEEEEEG                           ","                           GEEEEEEEEEEEEEEEEEEEEEG                           ","      GIIIG               GEEEEEEEEEEEEEEEEEEEEEEEG               GIIIG      ","    GGBBB AG              GEEEEEEEEEEEEEEEEEEEEEEEG              GA BBBGG    ","   GBBBBB A               GEEEEEEEEEEEEEEEEEEEEEEEG               A BBBBBG   ","   ZBBBBB A               GEEEEEEEEEEEEEEEEEEEEEEEG               A BBBBBZ   ","   GBBBBB A               GEEEEEEEEEEEEEEEEEEEEEEEG               A BBBBBG   ","    GGBBB AG              GEEEEEEEEEEEEEEEEEEEEEEEG              GA BBBGG    ","      GIIIG               GEEEEEEEEEEEEEEEEEEEEEEEG               GIIIG      ","                           GEEEEEEEEEEEEEEEEEEEEEG                           ","                           GEEEEEEEEEEEEEEEEEEEEEG                           ","                            GEEEEEEEEEEEEEEEEEEEG                            ","                            GEEEEEEEEEEEEEEEEEEEG                            ","                             GEEEEEEEEEEEEEEEEEG                             ","                              GEEEEEEEEEEEEEEEG                              ","                               GGEEEEEEEEEEEGG                               ","                                 GGEEEEEEEGG                                 ","                                   GGGGGGG                                   ")
            .aisle("                                                                             ","                                   GGGGGGG                                   ","                                 GGEEEEEEEGG                                 ","                               GGEEGGGGGGGEEGG                               ","                              GGEGGGGGGGGGGGEGG                              ","                             GGEGGGGJJJJJGGGGEGG                             ","                             GEGGGJJJJJJJJJGGGEG                             ","                            GEGGGJJJGGGGGJJJGGGEG                            ","                            GEGGJJJGGGGGGGJJJGGEG                            ","     GIIIIG                GEGGGJJGGGGGGGGGJJGGGEG                GIIIIG     ","    GBBB  AG               GEGGJJGGGGGGGGGGGJJGGEG               GA  BBBG    ","   GBBBB  A                GEGGJJGGGGGGGGGGGJJGGEG                A  BBBBG   ","   ZBBBB  A                GEGGJJGGGGGGGGGGGJJGGEG                A  BBBBZ   ","   GBBBB  A                GEGGJJGGGGGGGGGGGJJGGEG                A  BBBBG   ","    GBBB  AG               GEGGJJGGGGGGGGGGGJJGGEG               GA  BBBG    ","     GIIIIG                GEGGGJJGGGGGGGGGJJGGGEG                GIIIIG     ","                            GEGGJJJGGGGGGGJJJGGEG                            ","                            GEGGGJJJGGGGGJJJGGGEG                            ","                             GEGGGJJJJJJJJJGGGEG                             ","                             GGEGGGGJJJJJGGGGEGG                             ","                              GGEGGGGGGGGGGGEGG                              ","                               GGEEGGGGGGGEEGG                               ","                                 GGEEEEEEEGG                                 ","                                   GGGGGGG                                   ","                                                                             ")
            .aisle("                                                                             ","                                                                             ","                                                                             ","                                   GGGGGGG                                   ","                                 GGOOOOOOOGG                                 ","                                GOOO     OOOG                                ","                               GOO         OOG                               ","                              GOO   GGGGG   OOG                              ","                              GO   GHHHHHG   OG                              ","     GIIIG                   GOO  GHHHHHHHG  OOG                   GIIIG     ","    GBBB AG                  GO  GHHHHHHHHHG  OG                  GA BBBG    ","   GBBBB A                   GO  GHHHHHHHHHG  OG                   A BBBBG   ","   ZBBBB A                   GO  GHHHHHHHHHG  OG                   A BBBBZ   ","   GBBBB A                   GO  GHHHHHHHHHG  OG                   A BBBBG   ","    GBBB AG                  GO  GHHHHHHHHHG  OG                  GA BBBG    ","     GIIIG                   GOO  GHHHHHHHG  OOG                   GIIIG     ","                              GO   GHHHHHG   OG                              ","                              GOO   GGGGG   OOG                              ","                               GOO         OOG                               ","                                GOOO     OOOG                                ","                                 GGOOOOOOOGG                                 ","                                   GGGGGGG                                   ","                                                                             ","                                                                             ","                                                                             ")
            .aisle("                                                                             ","                                                                             ","                                                                             ","                                                                             ","                                                                             ","                                                                             ","                                                                             ","                                                                             ","                                    GGGGG                                    ","    GIIIIG                         GHHGHHG                         GIIIIG    ","   GBBBB AG                       GH  G  HG                       GA BBBBG   ","  GBBBBB A                        GH JGJ HG                        A BBBBBG  ","  ZBBBBB A                        GGGGBGGGG                        A BBBBBZ  ","  GBBBBB A                        GH JGJ HG                        A BBBBBG  ","   GBBBB AG                       GH  G  HG                       GA BBBBG   ","    GIIIIG                         GHHGHHG                         GIIIIG    ","                                    GGGGG                                    ","                                                                             ","                                                                             ","                                                                             ","                                                                             ","                                                                             ","                                                                             ","                                                                             ","                                                                             ")
            .aisle("                                                                             ","                                                                             ","                                                                             ","                                                                             ","                                                                             ","                                                                             ","                                                                             ","                                                                             ","                                     O O                                     ","    GIIIG                          O     O                          GIIIG    ","   GBBB AG                                                         GA BBBG   ","  GBBBB A                         O  JOJ  O                         A BBBBG  ","  ZBBBB A                            OBO                            A BBBBZ  ","  GBBBB A                         O  JOJ  O                         A BBBBG  ","   GBBB AG                                                         GA BBBG   ","    GIIIG                          O     O                          GIIIG    ","                                     O O                                     ","                                                                             ","                                                                             ","                                                                             ","                                                                             ","                                                                             ","                                                                             ","                                                                             ","                                                                             ")
            .aisle("                                                                             ","                                                                             ","                                                                             ","                                                                             ","                                                                             ","                                                                             ","                                                                             ","                                                                             ","                                    EEEEE                                    ","    GIIIG                          E  O  E                          GIIIG    ","   GBBB AG                        E   O   E                        GA BBBG   ","  GBBBB A                         E  JOJ  E                         A BBBBG  ","  ZBBBB A                         EOOOBOOOE                         A BBBBZ  ","  GBBBB A                         E  JOJ  E                         A BBBBG  ","   GBBB AG                        E   O   E                        GA BBBG   ","    GIIIG                          E  O  E                          GIIIG    ","                                    EEEEE                                    ","                                                                             ","                                                                             ","                                                                             ","                                                                             ","                                                                             ","                                                                             ","                                                                             ","                                                                             ")
            .aisle("                                                                             ","                                                                             ","                                                                             ","                                                                             ","                                                                             ","                                                                             ","                                                                             ","                                                                             ","                                                                             ","   GIIIIG                                                           GIIIIG   ","  GBBB  AG                                                         GA  BBBG  "," GBBBB  A                            JOJ                            A  BBBBG "," ZBBBB  A                            OBO                            A  BBBBZ "," GBBBB  A                            JOJ                            A  BBBBG ","  GBBB  AG                                                         GA  BBBG  ","   GIIIIG                                                           GIIIIG   ","                                                                             ","                                                                             ","                                                                             ","                                                                             ","                                                                             ","                                                                             ","                                                                             ","                                                                             ","                                                                             ")
            .aisle("                                                                             ","                                                                             ","                                                                             ","                                                                             ","                                                                             ","                                                                             ","                                                                             ","                                                                             ","                                                                             ","   GIIIG                             EEE                             GIIIG   ","  GBBB AG                           E O E                           GA BBBG  "," GBBBB A                           E JOJ E                           A BBBBG "," ZBBBB A                           EOOBOOE                           A BBBBZ "," GBBBB A                           E JOJ E                           A BBBBG ","  GBBB AG                           E O E                           GA BBBG  ","   GIIIG                             EEE                             GIIIG   ","                                                                             ","                                                                             ","                                                                             ","                                                                             ","                                                                             ","                                                                             ","                                                                             ","                                                                             ","                                                                             ")
            .aisle("                                                                             ","                                                                             ","                                                                             ","                                                                             ","                                                                             ","                                                                             ","                                                                             ","                                                                             ","                                                                             ","   GIIIG                                                             GIIIG   ","  GBBB AG                                                           GA BBBG  "," GBBBB A                             JOJ                             A BBBBG "," ZBBBB A                             OBO                             A BBBBZ "," GBBBB A                             JOJ                             A BBBBG ","  GBBB AG                                                           GA BBBG  ","   GIIIG                                                             GIIIG   ","                                                                             ","                                                                             ","                                                                             ","                                                                             ","                                                                             ","                                                                             ","                                                                             ","                                                                             ","                                                                             ")
            .aisle("                                                                             ","                                                                             ","                                                                             ","                                                                             ","                                                                             ","                                                                             ","                                                                             ","                                                                             ","                                                                             ","   GIIIG                                                             GIIIG   ","  GBBB AG                     GI     III     IG                     GA BBBG  "," GBBBB A                      GI    IJJJI    IG                      A BBBBG "," ZBBBB A                      GI    IJJJI    IG                      A BBBBZ "," GBBBB A                      GI    IJJJI    IG                      A BBBBG ","  GBBB AG                     GI     III     IG                     GA BBBG  ","   GIIIG                                                             GIIIG   ","                                                                             ","                                                                             ","                                                                             ","                                                                             ","                                                                             ","                                                                             ","                                                                             ","                                                                             ","                                                                             ")
            .aisle("                                                                             ","                                                                             ","                                                                             ","                                                                             ","                                                                             ","                                                                             ","                                                                             ","                                                                             ","                              GI             IG                              ","  GIIIIG                     GGI             IGG                     GIIIIG  "," GBBBB AG                    GDJ             JDG                    GA BBBBG ","GBBBBB A                     GDJ             JDG                     A BBBBBG","ZBBBBB A                    GGDJ             JDGG                    A BBBBBZ","GBBBBB A                     GDJ             JDG                     A BBBBBG"," GBBBB AG                    GDJ             JDG                    GA BBBBG ","  GIIIIG                     GGI             IGG                     GIIIIG  ","                              GI             IG                              ","                                                                             ","                                                                             ","                                                                             ","                                                                             ","                                                                             ","                                                                             ","                                                                             ","                                                                             ")
            .aisle("                                                                             ","                                                                             ","                                                                             ","                                                                             ","                                                                             ","                                                                             ","                                                                             ","                              GI             IG                              ","                             GDJ             JDG                             ","  GIIIG                     G DJ             JD G                     GIIIG  "," GBBB AG                    GDBD     AAA     DBDG                    GA BBBG ","GBBBB A                     GDBD    AAAAA    DBDG                     A BBBBG","ZBBBB A                     GDBD    AAAAA    DBDG                     A BBBBZ","GBBBB A                     GDBD    AAAAA    DBDG                     A BBBBG"," GBBB AG                    GDBD     AAA     DBDG                    GA BBBG ","  GIIIG                     G DJ             JD G                     GIIIG  ","                             GDJ             JDG                             ","                              GI             IG                              ","                                                                             ","                                                                             ","                                                                             ","                                                                             ","                                                                             ","                                                                             ","                                                                             ")
            .aisle("                                                                             ","                                                                             ","                                                                             ","                                                                             ","                                                                             ","                                                                             ","                              GI             IG                              ","                             GDJ             JDG                             ","                            GDBD             DBDG                            ","  GIIIG                     GDBD    AAAAA    DBDG                     GIIIG  "," GGGGGGG                   GO D    AA   AA    D OG                   GGGGGGG ","GGGAAGGG                   GO D    A     A    D OG                   GGGAAGGG","ZGGAAGGG                   GO D    A     A    D OG                   GGGAAGGZ","GGGAAGGG                   GO D    A     A    D OG                   GGGAAGGG"," GGGGGGG                   GO D    AA   AA    D OG                   GGGGGGG ","  GIIIG                     GDBD    AAAAA    DBDG                     GIIIG  ","                            GDBD             DBDG                            ","                             GDJ             JDG                             ","                              GI             IG                              ","                                                                             ","                                                                             ","                                                                             ","                                                                             ","                                                                             ","                                                                             ")
            .aisle("                                                                             ","                                                                             ","                                                                             ","                                                                             ","                                                                             ","                                                                             ","                             GGI             IGG                             ","                            G DJ             JD G                            ","                            GDBD    AAAAA    DBDG                            ","  GGGGGG                   GO D    A     A    D OG                   GGGGGG  "," GHHHJA                    G      A       A      G                    AJHHHG ","GGJ  JA                    G      A       A      G                    AJ  JGG","ZGJ  JA                    G      A       A      G                    AJ  JGZ","GGJ  JA                    G      A       A      G                    AJ  JGG"," GHHHJA                    G      A       A      G                    AJHHHG ","  GGGGGG                   GO D    A     A    D OG                   GGGGGG  ","                            GDBD    AAAAA    DBDG                            ","                            G DJ             JD G                            ","                             GGI             IGG                             ","                                                                             ","                                                                             ","                                                                             ","                                                                             ","                                                                             ","                                                                             ")
            .aisle("                                                                             ","                                                                             ","                                                                             ","                                                                             ","                                                                             ","                              GI             IG                              ","                             GDJ             JDG                             ","                            GDBD     AAA     DBDG                            ","  GGGGGG                   GO D    AA   AA    D OG                   GGGGGG  "," GHHHJA                    G      A       A      G                    AJHHHG "," GLLLJA                    G      A       A      G                    AJLLLG ","GKKMMGA                   GGD D DADO     ODAD D DGG                   AGMMKKG","GKKMMGA                   GGD D DADO     ODAD D DGG                   AGMMKKG","GKKMMGA                   GGD D DADO     ODAD D DGG                   AGMMKKG"," GLLLJA                    G      A       A      G                    AJLLLG "," GHHHJA                    G      A       A      G                    AJHHHG ","  GGGGGG                   GO D    AA   AA    D OG                   GGGGGG  ","                            GDBD     AAA     DBDG                            ","                             GDJ             JDG                             ","                              GI             IG                              ","                                                                             ","                                                                             ","                                                                             ","                                                                             ","                                                                             ")
            .aisle("                                                                             ","                                                                             ","                                                                             ","                                                                             ","                                                                             ","                              GI             IG                              ","                             GDJ             JDG                             ","                            GDBD    AAAAA    DBDG                            ","  GAAGGG                   GO D    A     A    D OG                   GGGAAG  "," GJ  JA                    G      A       A      G                    AJ  JG ","GKKMMGA                   GGD D DADO     ODAD D DGG                   AGMMKKG","GLBMO A                   GG     A C  C  C A     GG                   A OMBLG","GLBMO A                   IOOOOOOOOC CFC COOOOOOOOI                   A OMBLG","GLBMO A                   GG     A C  C  C A     GG                   A OMBLG","GKKMMGA                   GGD D DADO     ODAD D DGG                   AGMMKKG"," GJ  JA                    G      A       A      G                    AJ  JG ","  GAAGGG                   GO D    A     A    D OG                   GGGAAG  ","                            GDBD    AAAAA    DBDG                            ","                             GDJ             JDG                             ","                              GI             IG                              ","                                                                             ","                                                                             ","                                                                             ","                                                                             ","                                                                             ")
            .aisle("                                                                             ","                                                                             ","                                                                             ","                                                                             ","                                                                             ","                              GI             IG                              ","                            GGDJ             JDGG                            ","                            GDBD    AAAAA    DBDG                            ","  GAAGGG                   GO D    A     A    D OG                   GGGAAG  "," GJ  JA                    G      A       A      G                    AJ  JG ","GKKMMGA                   GGD D DADO     ODAD D DGG                   AGMMKKG","GLBMO A                   IOOOOOOOO  CFC  OOOOOOOOI                   A OMBLG","GLBMO A                   IBBBBBBBBF F F FBBBBBBBBI                   A OMBLG","GLBMO A                   IOOOOOOOO  CFC  OOOOOOOOI                   A OMBLG","GKKMMGA                   GGD D DADO     ODAD D DGG                   AGMMKKG"," GJ  JA                    G      A       A      G                    AJ  JG ","  GAAGGG                   GO D    A     A    D OG                   GGGAAG  ","                            GDBD    AAAAA    DBDG                            ","                            GGDJ             JDGG                            ","                              GI             IG                              ","                                                                             ","                                                                             ","                                                                             ","                                                                             ","                                                                             ")
            .aisle("                                                                             ","                                                                             ","                                                                             ","                                                                             ","                                                                             ","                              GI             IG                              ","                             GDJ             JDG                             ","                            GDBD    AAAAA    DBDG                            ","  GAAGGG                   GO D    A     A    D OG                   GGGAAG  "," GJ  JA                    G      A       A      G                    AJ  JG ","GKKMMGA                   GGD D DADO     ODAD D DGG                   AGMMKKG","GLBMO A                   GG     A C  C  C A     GG                   A OMBLG","GLBMO A                   IOOOOOOOOC CFC COOOOOOOOI                   A OMBLG","GLBMO A                   GG     A C  C  C A     GG                   A OMBLG","GKKMMGA                   GGD D DADO     ODAD D DGG                   AGMMKKG"," GJ  JA                    G      A       A      G                    AJ  JG ","  GAAGGG                   GO D    A     A    D OG                   GGGAAG  ","                            GDBD    AAAAA    DBDG                            ","                             GDJ             JDG                             ","                              GI             IG                              ","                                                                             ","                                                                             ","                                                                             ","                                                                             ","                                                                             ")
            .aisle("                                                                             ","                                                                             ","                                                                             ","                                                                             ","                                                                             ","                              GI             IG                              ","                             GDJ             JDG                             ","                            GDBD     AAA     DBDG                            ","  GGGGGG                   GO D    AA   AA    D OG                   GGGGGG  "," GHHHJA                    G      A       A      G                    AJHHHG "," GLLLJA                    G      A       A      G                    AJLLLG ","GKKMMGA                   GGD D DADO     ODAD D DGG                   AGMMKKG","GKKMMGA                   GGD D DADO     ODAD D DGG                   AGMMKKG","GKKMMGA                   GGD D DADO     ODAD D DGG                   AGMMKKG"," GLLLJA                    G      A       A      G                    AJLLLG "," GHHHJA                    G      A       A      G                    AJHHHG ","  GGGGGG                   GO D    AA   AA    D OG                   GGGGGG  ","                            GDBD     AAA     DBDG                            ","                             GDJ             JDG                             ","                              GI             IG                              ","                                                                             ","                                                                             ","                                                                             ","                                                                             ","                                                                             ")
            .aisle("                                                                             ","                                                                             ","                                                                             ","                                                                             ","                                                                             ","                                                                             ","                             GGI             IGG                             ","                            G DJ             JD G                            ","                            GDBD    AAAAA    DBDG                            ","  GGGGGG                   GO D    A     A    D OG                   GGGGGG  "," GHHHJA                    G      A       A      G                    AJHHHG ","GGJ  JA                    G      A       A      G                    AJ  JGG","ZGJ  JA                    G      A       A      G                    AJ  JGZ","GGJ  JA                    G      A       A      G                    AJ  JGG"," GHHHJA                    G      A       A      G                    AJHHHG ","  GGGGGG                   GO D    A     A    D OG                   GGGGGG  ","                            GDBD    AAAAA    DBDG                            ","                            G DJ             JD G                            ","                             GGI             IGG                             ","                                                                             ","                                                                             ","                                                                             ","                                                                             ","                                                                             ","                                                                             ")
            .aisle("                                                                             ","                                                                             ","                                                                             ","                                                                             ","                                                                             ","                                                                             ","                              GI             IG                              ","                             GDJ             JDG                             ","                            GDBD             DBDG                            ","  GIIIG                     GDBD    AAAAA    DBDG                     GIIIG  "," GGGGGGG                   GO D    AA   AA    D OG                   GGGGGGG ","GGGAAGGG                   GO D    A     A    D OG                   GGGAAGGG","ZGGAAGGG                   GO D    A     A    D OG                   GGGAAGGZ","GGGAAGGG                   GO D    A     A    D OG                   GGGAAGGG"," GGGGGGG                   GO D    AA   AA    D OG                   GGGGGGG ","  GIIIG                     GDBD    AAAAA    DBDG                     GIIIG  ","                            GDBD             DBDG                            ","                             GDJ             JDG                             ","                              GI             IG                              ","                                                                             ","                                                                             ","                                                                             ","                                                                             ","                                                                             ","                                                                             ")
