package com.gtladd.gtladditions.common.machine.muiltblock.structure

import com.gregtechceu.gtceu.api.pattern.FactoryBlockPattern
import com.gregtechceu.gtceu.api.pattern.util.RelativeDirection
import com.gtladd.gtladditions.common.machine.muiltblock.structure.lighthunterstructure.LightHunterStructureA
import com.gtladd.gtladditions.common.machine.muiltblock.structure.lighthunterstructure.LightHunterStructureB
import com.gtladd.gtladditions.common.machine.muiltblock.structure.lighthunterstructure.LightHunterStructureC
import com.gtladd.gtladditions.common.machine.muiltblock.structure.lighthunterstructure.LightHunterStructureD

object MultiBlockStructureE {
    val LIGHT_HUNTER_SPACE_STATION: FactoryBlockPattern? = FactoryBlockPattern.start(
        RelativeDirection.LEFT, RelativeDirection.UP, RelativeDirection.FRONT)
        .aisle(*LightHunterStructureA.A_1)
        .aisle(*LightHunterStructureA.A_2)
        .aisle(*LightHunterStructureA.A_3)
        .aisle(*LightHunterStructureA.A_4)
        .aisle(*LightHunterStructureA.A_5)
        .aisle(*LightHunterStructureA.A_6)
        .aisle(*LightHunterStructureA.A_7)
        .aisle(*LightHunterStructureA.A_8)
        .aisle(*LightHunterStructureA.A_9)
        .aisle(*LightHunterStructureA.A_10)
        .aisle(*LightHunterStructureA.A_11)
        .aisle(*LightHunterStructureA.A_12)
        .aisle(*LightHunterStructureA.A_13)
        .aisle(*LightHunterStructureA.A_14)
        .aisle(*LightHunterStructureA.A_15)
        .aisle(*LightHunterStructureA.A_16)
        .aisle(*LightHunterStructureA.A_17)
        .aisle(*LightHunterStructureA.A_18)
        .aisle(*LightHunterStructureA.A_19)
        .aisle(*LightHunterStructureA.A_20)
        .aisle(*LightHunterStructureA.A_21)
        .aisle(*LightHunterStructureA.A_22)
        .aisle(*LightHunterStructureA.A_23)
        .aisle(*LightHunterStructureA.A_24)
        .aisle(*LightHunterStructureA.A_25)
        .aisle(*LightHunterStructureA.A_26)
        .aisle(*LightHunterStructureA.A_27)
        .aisle(*LightHunterStructureA.A_28)
        .aisle(*LightHunterStructureA.A_29)
        .aisle(*LightHunterStructureA.A_30)
        .aisle(*LightHunterStructureA.A_31)
        .aisle(*LightHunterStructureA.A_32)
        .aisle(*LightHunterStructureA.A_33)
        .aisle(*LightHunterStructureA.A_34)
        .aisle(*LightHunterStructureA.A_35)
        .aisle(*LightHunterStructureA.A_36)
        .aisle(*LightHunterStructureA.A_37)
        .aisle(*LightHunterStructureA.A_38)
        .aisle(*LightHunterStructureA.A_39)
        .aisle(*LightHunterStructureA.A_40)
        .aisle(*LightHunterStructureA.A_41)
        .aisle(*LightHunterStructureA.A_42)
        .aisle(*LightHunterStructureA.A_43)
        .aisle(*LightHunterStructureA.A_44)
        .aisle(*LightHunterStructureA.A_45)
        .aisle(*LightHunterStructureA.A_46)
        .aisle(*LightHunterStructureA.A_47)
        .aisle(*LightHunterStructureA.A_48)
        .aisle(*LightHunterStructureA.A_49)
        .aisle(*LightHunterStructureA.A_50)
        .aisle(*LightHunterStructureA.A_51)
        .aisle(*LightHunterStructureA.A_52)
        .aisle(*LightHunterStructureA.A_53)
        .aisle(*LightHunterStructureA.A_54)
        .aisle(*LightHunterStructureA.A_55)
        .aisle(*LightHunterStructureA.A_56)
        .aisle(*LightHunterStructureA.A_57)
        .aisle(*LightHunterStructureA.A_58)
        .aisle(*LightHunterStructureA.A_59)
        .aisle(*LightHunterStructureA.A_60)
        .aisle(*LightHunterStructureB.A_61)
        .aisle(*LightHunterStructureB.A_62)
        .aisle(*LightHunterStructureB.A_63)
        .aisle(*LightHunterStructureB.A_64)
        .aisle(*LightHunterStructureB.A_65)
        .aisle(*LightHunterStructureB.A_66)
        .aisle(*LightHunterStructureB.A_67)
        .aisle(*LightHunterStructureB.A_68)
        .aisle(*LightHunterStructureB.A_69)
        .aisle(*LightHunterStructureB.A_70)
        .aisle(*LightHunterStructureB.A_71)
        .aisle(*LightHunterStructureB.A_72)
        .aisle(*LightHunterStructureB.A_73)
        .aisle(*LightHunterStructureB.A_74)
        .aisle(*LightHunterStructureB.A_75)
        .aisle(*LightHunterStructureB.A_76)
        .aisle(*LightHunterStructureB.A_77)
        .aisle(*LightHunterStructureB.A_78)
        .aisle(*LightHunterStructureB.A_79)
        .aisle(*LightHunterStructureB.A_80)
        .aisle(*LightHunterStructureB.A_81)
        .aisle(*LightHunterStructureB.A_82)
        .aisle(*LightHunterStructureB.A_83)
        .aisle(*LightHunterStructureB.A_84)
        .aisle(*LightHunterStructureB.A_85)
        .aisle(*LightHunterStructureB.A_86)
        .aisle(*LightHunterStructureB.A_87)
        .aisle(*LightHunterStructureB.A_88)
        .aisle(*LightHunterStructureB.A_89)
        .aisle(*LightHunterStructureB.A_90)
        .aisle(*LightHunterStructureB.A_91)
        .aisle(*LightHunterStructureB.A_92)
        .aisle(*LightHunterStructureB.A_93)
        .aisle(*LightHunterStructureB.A_94)
        .aisle(*LightHunterStructureB.A_95)
        .aisle(*LightHunterStructureB.A_96)
        .aisle(*LightHunterStructureB.A_97)
        .aisle(*LightHunterStructureB.A_98)
        .aisle(*LightHunterStructureB.A_99)
        .aisle(*LightHunterStructureB.A_100)
        .aisle(*LightHunterStructureB.A_101)
        .aisle(*LightHunterStructureB.A_102)
        .aisle(*LightHunterStructureB.A_103)
        .aisle(*LightHunterStructureB.A_104)
        .aisle(*LightHunterStructureB.A_105)
        .aisle(*LightHunterStructureB.A_106)
        .aisle(*LightHunterStructureB.A_107)
        .aisle(*LightHunterStructureB.A_108)
        .aisle(*LightHunterStructureB.A_109)
        .aisle(*LightHunterStructureB.A_110)
        .aisle(*LightHunterStructureB.A_111)
        .aisle(*LightHunterStructureB.A_112)
        .aisle(*LightHunterStructureB.A_113)
        .aisle(*LightHunterStructureB.A_114)
        .aisle(*LightHunterStructureB.A_115)
        .aisle(*LightHunterStructureB.A_116)
        .aisle(*LightHunterStructureB.A_117)
        .aisle(*LightHunterStructureB.A_118)
        .aisle(*LightHunterStructureB.A_119)
        .aisle(*LightHunterStructureB.A_120)
        .aisle(*LightHunterStructureC.A_121)
        .aisle(*LightHunterStructureC.A_122)
        .aisle(*LightHunterStructureC.A_123)
        .aisle(*LightHunterStructureC.A_124)
        .aisle(*LightHunterStructureC.A_125)
        .aisle(*LightHunterStructureC.A_126)
        .aisle(*LightHunterStructureC.A_127)
        .aisle(*LightHunterStructureC.A_128)
        .aisle(*LightHunterStructureC.A_129)
        .aisle(*LightHunterStructureC.A_130)
        .aisle(*LightHunterStructureC.A_131)
        .aisle(*LightHunterStructureC.A_132)
        .aisle(*LightHunterStructureC.A_133)
        .aisle(*LightHunterStructureC.A_134)
        .aisle(*LightHunterStructureC.A_135)
        .aisle(*LightHunterStructureC.A_136)
        .aisle(*LightHunterStructureC.A_137)
        .aisle(*LightHunterStructureC.A_138)
        .aisle(*LightHunterStructureC.A_139)
        .aisle(*LightHunterStructureC.A_140)
        .aisle(*LightHunterStructureC.A_141)
        .aisle(*LightHunterStructureC.A_142)
        .aisle(*LightHunterStructureC.A_143)
        .aisle(*LightHunterStructureC.A_144)
        .aisle(*LightHunterStructureC.A_145)
        .aisle(*LightHunterStructureC.A_146)
        .aisle(*LightHunterStructureC.A_147)
        .aisle(*LightHunterStructureC.A_148)
        .aisle(*LightHunterStructureC.A_149)
        .aisle(*LightHunterStructureC.A_150)
        .aisle(*LightHunterStructureC.A_151)
        .aisle(*LightHunterStructureC.A_152)
        .aisle(*LightHunterStructureC.A_153)
        .aisle(*LightHunterStructureC.A_154)
        .aisle(*LightHunterStructureC.A_155)
        .aisle(*LightHunterStructureC.A_156)
        .aisle(*LightHunterStructureC.A_157)
        .aisle(*LightHunterStructureC.A_158)
        .aisle(*LightHunterStructureC.A_159)
        .aisle(*LightHunterStructureC.A_160)
        .aisle(*LightHunterStructureC.A_161)
        .aisle(*LightHunterStructureC.A_162)
        .aisle(*LightHunterStructureC.A_163)
        .aisle(*LightHunterStructureC.A_164)
        .aisle(*LightHunterStructureC.A_165)
        .aisle(*LightHunterStructureC.A_166)
        .aisle(*LightHunterStructureC.A_167)
        .aisle(*LightHunterStructureC.A_168)
        .aisle(*LightHunterStructureC.A_169)
        .aisle(*LightHunterStructureC.A_170)
        .aisle(*LightHunterStructureC.A_171)
        .aisle(*LightHunterStructureC.A_172)
        .aisle(*LightHunterStructureC.A_173)
        .aisle(*LightHunterStructureC.A_174)
        .aisle(*LightHunterStructureC.A_175)
        .aisle(*LightHunterStructureC.A_176)
        .aisle(*LightHunterStructureC.A_177)
        .aisle(*LightHunterStructureC.A_178)
        .aisle(*LightHunterStructureC.A_179)
        .aisle(*LightHunterStructureC.A_180)
        .aisle(*LightHunterStructureD.A_181)
        .aisle(*LightHunterStructureD.A_182)
        .aisle(*LightHunterStructureD.A_183)
        .aisle(*LightHunterStructureD.A_184)
        .aisle(*LightHunterStructureD.A_185)
        .aisle(*LightHunterStructureD.A_186)
        .aisle(*LightHunterStructureD.A_187)
        .aisle(*LightHunterStructureD.A_188)
        .aisle(*LightHunterStructureD.A_189)

    val LIGHT_HUNTER_SPACE_STATION_MODULE: FactoryBlockPattern? = FactoryBlockPattern.start(
        RelativeDirection.RIGHT, RelativeDirection.UP, RelativeDirection.FRONT)
        .aisle("     ", "     ", "     ", "     ", "     ", "     ", "     ", "A B A", "A C A", "ACDCA", "CDEDC", "ACDCA", "A C A", "A B A", "     ", "     ", "     ", "     ", "     ", "     ", "     ")
        .aisle("     ", "     ", "     ", "     ", "     ", "A B A", "A B A", "FGGGF", "FGGGF", "FGGGF", "FGGGF", "FGGGF", "FGGGF", "FGGGF", "A B A", "A B A", "     ", "     ", "     ", "     ", "     ")
        .aisle("     ", "     ", "     ", "     ", "FGBGF", "FGGGF", "FGGGF", "HIJIH", "HIJIH", "HIJIH", "HIJIH", "HIJIH", "HIJIH", "HIJIH", "FGGGF", "FGGGF", "FGBGF", "     ", "     ", "     ", "     ")
        .aisle("     ", "     ", "     ", "FGBGF", "HIJIH", "HIJIH", "HIJIH", "HIJIH", "KLLLK", "KLLLK", "KLLLK", "KLLLK", "KLLLK", "HIJIH", "HIJIH", "HIJIH", "HIJIH", "FGBGF", "     ", "     ", "     ")
        .aisle("     ", "     ", "FGGGF", "HIJIH", "HIJIH", "KLLLK", "KLLLK", "KLLLK", "KLLLK", "HIJIH", "HIJIH", "HIJIH", "KLLLK", "KLLLK", "KLLLK", "KLLLK", "HIJIH", "HIJIH", "FGGGF", "     ", "     ")
        .aisle("     ", "FGGGF", "HIJIH", "HIJIH", "KLLLK", "KLLLK", "HIJIH", "HIJIH", "HIJIH", "HIJIH", "MMMMM", "HIJIH", "HIJIH", "HIJIH", "HIJIH", "KLLLK", "KLLLK", "HIJIH", "HIJIH", "FGGGF", "     ")
        .aisle("FHHHF", "HIJIH", "HIJIH", "KLLLK", "KLLLK", "HIJIH", "HIJIH", "FGGGF", "FGGGF", "FGGGF", "FGGGF", "FGGGF", "FGGGF", "FGGGF", "HIJIH", "HIJIH", "KLLLK", "KLLLK", "HIJIH", "HIJIH", "FHHHF")
        .aisle("FMMMF", "HIJIH", "KLLLK", "KLLLK", "HIJIH", "HIJIH", "FGBGF", "     ", " CBC ", "CFFFC", "BFFFB", "CFFFC", " CBC ", "     ", "FGBGF", "HIJIH", "HIJIH", "KLLLK", "KLLLK", "HIJIH", "FMMMF")
        .aisle("FHHHF", "HIJIH", "HIJIH", "HIJIH", "HIJIH", "FGBGF", "     ", "     ", "     ", " KJK ", " JMJ ", " KJK ", "     ", "     ", "     ", "FGBGF", "HIJIH", "HIJIH", "HIJIH", "HIJIH", "FHHHF")
        .aisle("     ", "FGGGF", "HIJIH", "HIJIH", "FGBGF", "     ", "     ", "     ", "     ", " KJK ", " JMJ ", " KJK ", "     ", "     ", "     ", "     ", "FGBGF", "HIJIH", "HIJIH", "FGGGF", "     ")
        .aisle("     ", "     ", "FGGGF", "FGBGF", "     ", "     ", "     ", "     ", " K K ", " KJK ", " JMJ ", " KJK ", " K K ", "     ", "     ", "     ", "     ", "FGBGF", "FGGGF", "     ", "     ")
        .aisle("     ", "     ", "     ", "     ", "     ", "     ", "     ", " K K ", "FFFFF", "FFMFF", "FFNFF", "FFMFF", "FFFFF", " K K ", "     ", "     ", "     ", "     ", "     ", "     ", "     ")
        .aisle("     ", "     ", "     ", "     ", "     ", "     ", "     ", "     ", "OOOOO", "OOOOO", "OO~OO", "OOOOO", "OOOOO", "     ", "     ", "     ", "     ", "     ", "     ", "     ", "     ")

    val MACRO_ATOMIC_RESONANT_FRAGMENT_STRIPPER: FactoryBlockPattern? =
        FactoryBlockPattern.start(
            RelativeDirection.LEFT, RelativeDirection.BACK, RelativeDirection.DOWN)
            .aisle("                                                                             ","                                                                             ","                                                                             ","                                                                             ","                                                                             ","                                                                             ","                                                                             ","                                                                             ","                                                                             ","                                                                             ","                                                                             ","                                GGGGGGGGGGGGG                                ","                                ZZZZZZZZZZZZZ                                ","                                GGGGGGGGGGGGG                                ","                                                                             ","                                                                             ","                                                                             ","                                                                             ","                                                                             ","                                                                             ","                                                                             ","                                                                             ","                                                                             ","                                                                             ","                                                                             ")
            .aisle("                                                                             ","                                                                             ","                                                                             ","                                                                             ","                                                                             ","                                                                             ","                                                                             ","                                                                             ","                                                                             ","                                                                             ","                                GGGGGGGGGGGGG                                ","                            GGGGBBBBBBBBBBBBBGGGG                            ","                            ZZZZBBBBBBBBBBBBBZZZZ                            ","                            GGGGBBBBBBBBBBBBBGGGG                            ","                                GGGGGGGGGGGGG                                ","                                                                             ","                                                                             ","                                                                             ","                                                                             ","                                                                             ","                                                                             ","                                                                             ","                                                                             ","                                                                             ","                                                                             ")
            .aisle("                                                                             ","                                                                             ","                                                                             ","                                                                             ","                                                                             ","                                                                             ","                                                                             ","                                                                             ","                                                                             ","                                GGGGGGGGGGGGG                                ","                            GGGGBBBBBBBBBBBBBGGGG                            ","                         GGGBBBBBBBBBBBBBBBBBBBBBGGG                         ","                         ZZZBBBBBBBBBBBBBBBBBBBBBZZZ                         ","                         GGGBBBBBBBBBBBBBBBBBBBBBGGG                         ","                            GGGGBBBBBBBBBBBBBGGGG                            ","                                GGGGGGGGGGGGG                                ","                                                                             ","                                                                             ","                                                                             ","                                                                             ","                                                                             ","                                                                             ","                                                                             ","                                                                             ","                                                                             ")
            .aisle("                                                                             ","                                                                             ","                                                                             ","                                                                             ","                                                                             ","                                                                             ","                                                                             ","                                                                             ","                                                                             ","                            GGGGIIIIIIIIIIIIIGGGG                            ","                         GGGBBBBBBBBBBBBBBBBBBBBBGGG                         ","                      GGGBBBBBBBBBBBBBBBBBBBBBBBBBBBGGG                      ","                      ZZZBBBBBBBBBBBBBBBBBBBBBBBBBBBZZZ                      ","                      GGGBBBBBBBBBBBBBBBBBBBBBBBBBBBGGG                      ","                         GGGBBBBBBBBBBBBBBBBBBBBBGGG                         ","                            GGGGIIIIIIIIIIIIIGGGG                            ","                                                                             ","                                                                             ","                                                                             ","                                                                             ","                                                                             ","                                                                             ","                                                                             ","                                                                             ","                                                                             ")
            .aisle("                                                                             ","                                                                             ","                                                                             ","                                                                             ","                                                                             ","                                                                             ","                                                                             ","                                                                             ","                                                                             ","                         GGGIIIIIIIIIIIIIIIIIIIIIGGG                         ","                      GGGBBBBBBBBBBBBBBBBBBBBBBBBBBBGGG                      ","                    GGBBBBBBBBBBBBBBBBBBBBBBBBBBBBBBBBBGG                    ","                    ZZBBBBBBBBBBBBBBBBBBBBBBBBBBBBBBBBBZZ                    ","                    GGBBBBBBBBBBBBBBBBBBBBBBBBBBBBBBBBBGG                    ","                      GGGBBBBBBBBBBBBBBBBBBBBBBBBBBBGGG                      ","                         GGGIIIIIIIIIIIIIIIIIIIIIGGG                         ","                                                                             ","                                                                             ","                                                                             ","                                                                             ","                                                                             ","                                                                             ","                                                                             ","                                                                             ","                                                                             ")
            .aisle("                                                                             ","                                                                             ","                                                                             ","                                                                             ","                                                                             ","                                                                             ","                                                                             ","                                                                             ","                                                                             ","                       GGIIIIIIIIIIIIIIIIIIIIIIIIIIIGG                       ","                    GGGBBBBBBBBBBIIIJLLLJIIIBBBBBBBBBBGGG                    ","                   GBBBBBBBBBBBBBIIJLMMMLJIIBBBBBBBBBBBBBG                   ","                   ZBBBBBBBBBBBBBIIJLMMMLJIIBBBBBBBBBBBBBZ                   ","                   GBBBBBBBBBBBBBIIJLMMMLJIIBBBBBBBBBBBBBG                   ","                    GGGBBBBBBBBBBIIIJLLLJIIIBBBBBBBBBBGGG                    ","                       GGIIIIIIIIIIIIIIIIIIIIIIIIIIIGG                       ","                                                                             ","                                                                             ","                                                                             ","                                                                             ","                                                                             ","                                                                             ","                                                                             ","                                                                             ","                                                                             ")
            .aisle("                                                                             ","                                                                             ","                                                                             ","                                                                             ","                                                                             ","                                                                             ","                                                                             ","                                                                             ","                                                                             ","                     GGIIIIIIIIIIGGGGGGGGGGGIIIIIIIIIIGG                     ","                   GGBBBBBBB     GGJIMMMIJGG     BBBBBBBGG                   ","                 GGBBBBBBBBB     GJIMMMMMIJG     BBBBBBBBBGG                 ","                 ZZBBBBBBBBB     GJIMMMMMIJG     BBBBBBBBBZZ                 ","                 GGBBBBBBBBB     GJIMMMMMIJG     BBBBBBBBBGG                 ","                   GGBBBBBBB     GGJIMMMIJGG     BBBBBBBGG                   ","                     GGIIIIIIIIIIGGGGGGGGGGGIIIIIIIIIIGG                     ","                                                                             ","                                                                             ","                                                                             ","                                                                             ","                                                                             ","                                                                             ","                                                                             ","                                                                             ","                                                                             ")
            .aisle("                                                                             ","                                                                             ","                                                                             ","                                                                             ","                                                                             ","                                                                             ","                                                                             ","                                                                             ","                                                                             ","                   GGIIIIIIIIGGGG   OOOOO   GGGGIIIIIIIIGG                   ","                 GGBBBBBBB   AAAG  OGGGGGO  GAAA   BBBBBBBGG                 ","                GBBBBBBBBB   AAAG OGGMMMGGO GAAA   BBBBBBBBBG                ","                ZBBBBBBBBB   AAAG OGIMMMIGO GAAA   BBBBBBBBBZ                ","                GBBBBBBBBB   AAAG OGGMMMGGO GAAA   BBBBBBBBBG                ","                 GGBBBBBBB   AAAG  OGGGGGO  GAAA   BBBBBBBGG                 ","                   GGIIIIIIIIGGGG   OOOOO   GGGGIIIIIIIIGG                   ","                                                                             ","                                                                             ","                                                                             ","                                                                             ","                                                                             ","                                                                             ","                                                                             ","                                                                             ","                                                                             ")
            .aisle("                                                                             ","                                                                             ","                                                                             ","                                                                             ","                                                                             ","                                                                             ","                                                                             ","                                                                             ","                                                                             ","                  GIIIIIIIGGG        GGG        GGGIIIIIIIG                  ","                GGBBBBB   AAAGGG    GIIIG    GGGAAA   BBBBBGG                ","              GGBBBBBBB   AAA      GIOOOIG      AAA   BBBBBBBGG              ","              ZZBBBBBBB   AAA      GIOOOIG      AAA   BBBBBBBZZ              ","              GGBBBBBBB   AAA      GIOOOIG      AAA   BBBBBBBGG              ","                GGBBBBB   AAAGGG    GIIIG    GGGAAA   BBBBBGG                ","                  GIIIIIIIGGG        GGG        GGGIIIIIIIG                  ","                                                                             ","                                                                             ","                                                                             ","                                                                             ","                                                                             ","                                                                             ","                                                                             ","                                                                             ","                                                                             ")
            .aisle("                                                                             ","                                                                             ","                                                                             ","                                                                             ","                                                                             ","                                                                             ","                                                                             ","                                                                             ","                                                                             ","                GGIIIIIIGG                         GGIIIIIIGG                ","              GGBBBBB   AAGGG                   GGGAA   BBBBBGG              ","             GBBBBBBB   AA                         AA   BBBBBBBG             ","             ZBBBBBBB   AA                         AA   BBBBBBBZ             ","             GBBBBBBB   AA                         AA   BBBBBBBG             ","              GGBBBBB   AAGGG                   GGGAA   BBBBBGG              ","                GGIIIIIIGG                         GGIIIIIIGG                ","                                                                             ","                                                                             ","                                                                             ","                                                                             ","                                                                             ","                                                                             ","                                                                             ","                                                                             ","                                                                             ")
            .aisle("                                                                             ","                                                                             ","                                                                             ","                                                                             ","                                                                             ","                                                                             ","                                                                             ","                                                                             ","                                                                             ","               GIIIIIIGG                             GGIIIIIIG               ","             GGBBBBB  AAGG                         GGAA  BBBBBGG             ","            GBBBBBBB  AA                             AA  BBBBBBBG            ","            ZBBBBBBB  AA                             AA  BBBBBBBZ            ","            GBBBBBBB  AA                             AA  BBBBBBBG            ","             GGBBBBB  AAGG                         GGAA  BBBBBGG             ","               GIIIIIIGG                             GGIIIIIIG               ","                                                                             ","                                                                             ","                                                                             ","                                                                             ","                                                                             ","                                                                             ","                                                                             ","                                                                             ","                                                                             ")
            .aisle("                                                                             ","                                                                             ","                                                                             ","                                                                             ","                                                                             ","                                                                             ","                                                                             ","                                                                             ","                                                                             ","              GIIIIIGG                                 GGIIIIIG              ","            GGBBBB  AAGG                             GGAA  BBBBGG            ","           GBBBBBB  AA                                 AA  BBBBBBG           ","           ZBBBBBB  AA                                 AA  BBBBBBZ           ","           GBBBBBB  AA                                 AA  BBBBBBG           ","            GGBBBB  AAGG                             GGAA  BBBBGG            ","              GIIIIIGG                                 GGIIIIIG              ","                                                                             ","                                                                             ","                                                                             ","                                                                             ","                                                                             ","                                                                             ","                                                                             ","                                                                             ","                                                                             ")
            .aisle("                                                                             ","                                                                             ","                                                                             ","                                                                             ","                                                                             ","                                                                             ","                                      O                                      ","                                    OOOOO                                    ","                                  OOGGGGGOO                                  ","             GIIIIIG              OGGGGGGGO              GIIIIIG             ","           GGBBBB  AGG           OGGGJJJGGGO           GGA  BBBBGG           ","          GBBBBBB  A             OGGJOOOJGGO             A  BBBBBBG          ","          ZBBBBBB  A            OOGGJOOOJGGOO            A  BBBBBBZ          ","          GBBBBBB  A             OGGJOOOJGGO             A  BBBBBBG          ","           GGBBBB  AGG           OGGGJJJGGGO           GGA  BBBBGG           ","             GIIIIIG              OGGGGGGGO              GIIIIIG             ","                                  OOGGGGGOO                                  ","                                    OOOOO                                    ","                                      O                                      ","                                                                             ","                                                                             ","                                                                             ","                                                                             ","                                                                             ","                                                                             ")
            .aisle("                                                                             ","                                                                             ","                                                                             ","                                                                             ","                                                                             ","                                    GEOEG                                    ","                                  GGEEEEEGG                                  ","                                 GEEGGGGGEEG                                 ","                                GEGGBBBBBGGEG                                ","            GIIIIIG             GEGBNNNNNBGEG             GIIIIIG            ","          GGBBBB  AG           GEGBNGKKKGNBGEG           GA  BBBBGG          ","         GBBBBBB  A            GEGBNKMMMKNBGEG            A  BBBBBBG         ","         ZBBBBBB  A            OEGBNKMMMKNBGEO            A  BBBBBBZ         ","         GBBBBBB  A            GEGBNKMMMKNBGEG            A  BBBBBBG         ","          GGBBBB  AG           GEGBNGKKKGNBGEG           GA  BBBBGG          ","            GIIIIIG             GEGBNNNNNBGEG             GIIIIIG            ","                                GEGGBBBBBGGEG                                ","                                 GEEGGGGGEEG                                 ","                                  GGEEEEEGG                                  ","                                    GEOEG                                    ","                                                                             ","                                                                             ","                                                                             ","                                                                             ","                                                                             ")
            .aisle("                                                                             ","                                                                             ","                                                                             ","                                                                             ","                                   GGEGEGG                                   ","                                 GGGBBGBBGGG                                 ","                                GGBBBBBBBBBGG                                ","                               GGBBBNNNNNBBBGG                               ","                               GBBBNBBBBBNBBBG                               ","           GIIIIIG            GGBBNBNNNNNBNBBGG            GIIIIIG           ","         GGBBBB  AG           GBBNBNGKKKGNBNBBG           GA  BBBBGG         ","        GBBBBBB  A            GBBNBNKKKKKNBNBBG            A  BBBBBBG        ","        ZBBBBBB  A            EEBNBNKKKKKNBNBEE            A  BBBBBBZ        ","        GBBBBBB  A            GBBNBNKKKKKNBNBBG            A  BBBBBBG        ","         GGBBBB  AG           GBBNBNGKKKGNBNBBG           GA  BBBBGG         ","           GIIIIIG            GGBBNBNNNNNBNBBGG            GIIIIIG           ","                               GBBBNBBBBBNBBBG                               ","                               GGBBBNNNNNBBBGG                               ","                                GGBBBBBBBBBGG                                ","                                 GGGBBGBBGGG                                 ","                                   GGEGEGG                                   ","                                                                             ","                                                                             ","                                                                             ","                                                                             ")
            .aisle("                                                                             ","                                                                             ","                                                                             ","                                   GGEGEGG                                   ","                                 GGNNNNNNNGG                                 ","                                GNNNBBBBBNNNG                                ","                               GNNBBBBBBBBBNNG                               ","                              GNNBBBNNNNNBBBNNG                              ","                              GNBBBNBBBBBNBBBNG                              ","          GIIIIIG            GNNBBNBNNNNNBNBBNNG            GIIIIIG          ","         GBBBB  AG           GNBBNBNGKKKGNBNBBNG           GA  BBBBG         ","        GBBBBB  A            GNBBNBNKKKKKNBNBBNG            A  BBBBBG        ","        ZBBBBB  A            ENBBNBNKKKKKNBNBBNE            A  BBBBBZ        ","        GBBBBB  A            GNBBNBNKKKKKNBNBBNG            A  BBBBBG        ","         GBBBB  AG           GNBBNBNGKKKGNBNBBNG           GA  BBBBG         ","          GIIIIIG            GNNBBNBNNNNNBNBBNNG            GIIIIIG          ","                              GNBBBNBBBBBNBBBNG                              ","                              GNNBBBNNNNNBBBNNG                              ","                               GNNBBBBBBBBBNNG                               ","                                GNNNBBBBBNNNG                                ","                                 GGNNNNNNNGG                                 ","                                   GGEGEGG                                   ","                                                                             ","                                                                             ","                                                                             ")
            .aisle("                                                                             ","                                                                             ","                                                                             ","                                   EEEEEEE                                   ","                                 EEGGGGGGGEE                                 ","                                EGGGIIIIIGGGE                                ","                               EGGIIIIIIIIIGGE                               ","                              EGGIIIGGGGGIIIGGE                              ","                              EGIIIGGGGGGGIIIGE                              ","         GIIIIIG             EGGIIGGGGGGGGGIIGGE             GIIIIIG         ","        GBBBB  AG            EGIIGGGGGGGGGGGIIGE            GA  BBBBG        ","       GBBBBB  A             EGIIGGGGGGGGGGGIIGE             A  BBBBBG       ","       ZBBBBB  A             EGIIGGGGGGGGGGGIIGE             A  BBBBBZ       ","       GBBBBB  A             EGIIGGGGGGGGGGGIIGE             A  BBBBBG       ","        GBBBB  AG            EGIIGGGGGGGGGGGIIGE            GA  BBBBG        ","         GIIIIIG             EGGIIGGGGGGGGGIIGGE             GIIIIIG         ","                              EGIIIGGGGGGGIIIGE                              ","                              EGGIIIGGGGGIIIGGE                              ","                               EGGIIIIIIIIIGGE                               ","                                EGGGIIIIIGGGE                                ","                                 EEGGGGGGGEE                                 ","                                   EEEEEEE                                   ","                                                                             ","                                                                             ","                                                                             ")
            .aisle("                                                                             ","                                                                             ","                                                                             ","                                   GGGGGGG                                   ","                                 GGOOOOOOOGG                                 ","                                GOOO     OOOG                                ","                               GOO         OOG                               ","                              GOO   GGGGG   OOG                              ","                              GO   GJJJJJG   OG                              ","         GIIIIG              GOO  GJGGGGGJG  OOG              GIIIIG         ","       GGBBB  AG             GO  GJGGJJJGGJG  OG             GA  BBBGG       ","      GBBBBB  A              GO  GJGJGGGJGJG  OG              A  BBBBBG      ","      ZBBBBB  A              GO  GJGJGGGJGJG  OG              A  BBBBBZ      ","      GBBBBB  A              GO  GJGJGGGJGJG  OG              A  BBBBBG      ","       GGBBB  AG             GO  GJGGJJJGGJG  OG             GA  BBBGG       ","         GIIIIG              GOO  GJGGGGGJG  OOG              GIIIIG         ","                              GO   GJJJJJG   OG                              ","                              GOO   GGGGG   OOG                              ","                               GOO         OOG                               ","                                GOOO     OOOG                                ","                                 GGOOOOOOOGG                                 ","                                   GGGGGGG                                   ","                                                                             ","                                                                             ","                                                                             ")
            .aisle("                                                                             ","                                                                             ","                                                                             ","                                                                             ","                                                                             ","                                                                             ","                                                                             ","                                                                             ","                                                                             ","        GIIIIG                                                 GIIIIG        ","       GBBB  AG                                               GA  BBBG       ","      GBBBB  A                                                 A  BBBBG      ","      ZBBBB  A                                                 A  BBBBZ      ","      GBBBB  A                                                 A  BBBBG      ","       GBBB  AG                                               GA  BBBG       ","        GIIIIG                                                 GIIIIG        ","                                                                             ","                                                                             ","                                                                             ","                                                                             ","                                                                             ","                                                                             ","                                                                             ","                                                                             ","                                                                             ")
            .aisle("                                                                             ","                                                                             ","                                                                             ","                                                                             ","                                                                             ","                                                                             ","                                                                             ","                                                                             ","                                                                             ","       GIIIIG                                                   GIIIIG       ","      GBBBB AG                                                 GA BBBBG      ","     GBBBBB A                                                   A BBBBBG     ","     ZBBBBB A                                                   A BBBBBZ     ","     GBBBBB A                                                   A BBBBBG     ","      GBBBB AG                                                 GA BBBBG      ","       GIIIIG                                                   GIIIIG       ","                                                                             ","                                                                             ","                                                                             ","                                                                             ","                                                                             ","                                                                             ","                                                                             ","                                                                             ","                                                                             ")
            .aisle("                                                                             ","                                                                             ","                                                                             ","                                   GGGGGGG                                   ","                                 GGOOOOOOOGG                                 ","                                GOOO     OOOG                                ","                               GOO         OOG                               ","                              GOO   GGGGG   OOG                              ","                              GO   GIIIIIG   OG                              ","       GIIIG                 GOO  GIGGGGGIG  OOG                 GIIIG       ","     GGBBB AG                GO  GIGGIIIGGIG  OG                GA BBBGG     ","    GBBBBB A                 GO  GIGIGGGIGIG  OG                 A BBBBBG    ","    ZBBBBB A                 GO  GIGIGGGIGIG  OG                 A BBBBBZ    ","    GBBBBB A                 GO  GIGIGGGIGIG  OG                 A BBBBBG    ","     GGBBB AG                GO  GIGGIIIGGIG  OG                GA BBBGG     ","       GIIIG                 GOO  GIGGGGGIG  OOG                 GIIIG       ","                              GO   GIIIIIG   OG                              ","                              GOO   GGGGG   OOG                              ","                               GOO         OOG                               ","                                GOOO     OOOG                                ","                                 GGOOOOOOOGG                                 ","                                   GGGGGGG                                   ","                                                                             ","                                                                             ","                                                                             ")
            .aisle("                                                                             ","                                   GGGGGGG                                   ","                                 GGEEEEEEEGG                                 ","                               GGEEGGGGGGGEEGG                               ","                              GGEGGGGGGGGGGGEGG                              ","                             GGEGGGGJJJJJGGGGEGG                             ","                             GEGGGJJJJJJJJJGGGEG                             ","                            GEGGGJJJGGGGGJJJGGGEG                            ","                            GEGGJJJGGGGGGGJJJGGEG                            ","      GIIIIG               GEGGGJJGGGGGGGGGJJGGGEG               GIIIIG      ","     GBBB  AG              GEGGJJGGGGGGGGGGGJJGGEG              GA  BBBG     ","    GBBBB  A               GEGGJJGGGGGGGGGGGJJGGEG               A  BBBBG    ","    ZBBBB  A               GEGGJJGGGGGGGGGGGJJGGEG               A  BBBBZ    ","    GBBBB  A               GEGGJJGGGGGGGGGGGJJGGEG               A  BBBBG    ","     GBBB  AG              GEGGJJGGGGGGGGGGGJJGGEG              GA  BBBG     ","      GIIIIG               GEGGGJJGGGGGGGGGJJGGGEG               GIIIIG      ","                            GEGGJJJGGGGGGGJJJGGEG                            ","                            GEGGGJJJGGGGGJJJGGGEG                            ","                             GEGGGJJJJJJJJJGGGEG                             ","                             GGEGGGGJJJJJGGGGEGG                             ","                              GGEGGGGGGGGGGGEGG                              ","                               GGEEGGGGGGGEEGG                               ","                                 GGEEEEEEEGG                                 ","                                   GGGGGGG                                   ","                                                                             ")
            .aisle("                                   GGGGGGG                                   ","                                 GGEEEEEEEGG                                 ","                               GGEEEEEEEEEEEGG                               ","                              GEEEEEEEEEEEEEEEG                              ","                             GEEEEEEEEEEEEEEEEEG                             ","                            GEEEEEEEEEEEEEEEEEEEG                            ","                            GEEEEEEEEEEEEEEEEEEEG                            ","                           GEEEEEEEEEEEEEEEEEEEEEG                           ","                           GEEEEEEEEEEEEEEEEEEEEEG                           ","      GIIIG               GEEEEEEEEEEEEEEEEEEEEEEEG               GIIIG      ","    GGBBB AG              GEEEEEEEEEEEEEEEEEEEEEEEG              GA BBBGG    ","   GBBBBB A               GEEEEEEEEEEEEEEEEEEEEEEEG               A BBBBBG   ","   ZBBBBB A               GEEEEEEEEEEEEEEEEEEEEEEEG               A BBBBBZ   ","   GBBBBB A               GEEEEEEEEEEEEEEEEEEEEEEEG               A BBBBBG   ","    GGBBB AG              GEEEEEEEEEEEEEEEEEEEEEEEG              GA BBBGG    ","      GIIIG               GEEEEEEEEEEEEEEEEEEEEEEEG               GIIIG      ","                           GEEEEEEEEEEEEEEEEEEEEEG                           ","                           GEEEEEEEEEEEEEEEEEEEEEG                           ","                            GEEEEEEEEEEEEEEEEEEEG                            ","                            GEEEEEEEEEEEEEEEEEEEG                            ","                             GEEEEEEEEEEEEEEEEEG                             ","                              GEEEEEEEEEEEEEEEG                              ","                               GGEEEEEEEEEEEGG                               ","                                 GGEEEEEEEGG                                 ","                                   GGGGGGG                                   ")
            .aisle("                                                                             ","                                   GGGGGGG                                   ","                                 GGEEEEEEEGG                                 ","                               GGEEGGGGGGGEEGG                               ","                              GGEGGGGGGGGGGGEGG                              ","                             GGEGGGGJJJJJGGGGEGG                             ","                             GEGGGJJJJJJJJJGGGEG                             ","                            GEGGGJJJGGGGGJJJGGGEG                            ","                            GEGGJJJGGGGGGGJJJGGEG                            ","     GIIIIG                GEGGGJJGGGGGGGGGJJGGGEG                GIIIIG     ","    GBBB  AG               GEGGJJGGGGGGGGGGGJJGGEG               GA  BBBG    ","   GBBBB  A                GEGGJJGGGGGGGGGGGJJGGEG                A  BBBBG   ","   ZBBBB  A                GEGGJJGGGGGGGGGGGJJGGEG                A  BBBBZ   ","   GBBBB  A                GEGGJJGGGGGGGGGGGJJGGEG                A  BBBBG   ","    GBBB  AG               GEGGJJGGGGGGGGGGGJJGGEG               GA  BBBG    ","     GIIIIG                GEGGGJJGGGGGGGGGJJGGGEG                GIIIIG     ","                            GEGGJJJGGGGGGGJJJGGEG                            ","                            GEGGGJJJGGGGGJJJGGGEG                            ","                             GEGGGJJJJJJJJJGGGEG                             ","                             GGEGGGGJJJJJGGGGEGG                             ","                              GGEGGGGGGGGGGGEGG                              ","                               GGEEGGGGGGGEEGG                               ","                                 GGEEEEEEEGG                                 ","                                   GGGGGGG                                   ","                                                                             ")
            .aisle("                                                                             ","                                                                             ","                                                                             ","                                   GGGGGGG                                   ","                                 GGOOOOOOOGG                                 ","                                GOOO     OOOG                                ","                               GOO         OOG                               ","                              GOO   GGGGG   OOG                              ","                              GO   GHHHHHG   OG                              ","     GIIIG                   GOO  GHHHHHHHG  OOG                   GIIIG     ","    GBBB AG                  GO  GHHHHHHHHHG  OG                  GA BBBG    ","   GBBBB A                   GO  GHHHHHHHHHG  OG                   A BBBBG   ","   ZBBBB A                   GO  GHHHHHHHHHG  OG                   A BBBBZ   ","   GBBBB A                   GO  GHHHHHHHHHG  OG                   A BBBBG   ","    GBBB AG                  GO  GHHHHHHHHHG  OG                  GA BBBG    ","     GIIIG                   GOO  GHHHHHHHG  OOG                   GIIIG     ","                              GO   GHHHHHG   OG                              ","                              GOO   GGGGG   OOG                              ","                               GOO         OOG                               ","                                GOOO     OOOG                                ","                                 GGOOOOOOOGG                                 ","                                   GGGGGGG                                   ","                                                                             ","                                                                             ","                                                                             ")
            .aisle("                                                                             ","                                                                             ","                                                                             ","                                                                             ","                                                                             ","                                                                             ","                                                                             ","                                                                             ","                                    GGGGG                                    ","    GIIIIG                         GHHGHHG                         GIIIIG    ","   GBBBB AG                       GH  G  HG                       GA BBBBG   ","  GBBBBB A                        GH JGJ HG                        A BBBBBG  ","  ZBBBBB A                        GGGGBGGGG                        A BBBBBZ  ","  GBBBBB A                        GH JGJ HG                        A BBBBBG  ","   GBBBB AG                       GH  G  HG                       GA BBBBG   ","    GIIIIG                         GHHGHHG                         GIIIIG    ","                                    GGGGG                                    ","                                                                             ","                                                                             ","                                                                             ","                                                                             ","                                                                             ","                                                                             ","                                                                             ","                                                                             ")
            .aisle("                                                                             ","                                                                             ","                                                                             ","                                                                             ","                                                                             ","                                                                             ","                                                                             ","                                                                             ","                                     O O                                     ","    GIIIG                          O     O                          GIIIG    ","   GBBB AG                                                         GA BBBG   ","  GBBBB A                         O  JOJ  O                         A BBBBG  ","  ZBBBB A                            OBO                            A BBBBZ  ","  GBBBB A                         O  JOJ  O                         A BBBBG  ","   GBBB AG                                                         GA BBBG   ","    GIIIG                          O     O                          GIIIG    ","                                     O O                                     ","                                                                             ","                                                                             ","                                                                             ","                                                                             ","                                                                             ","                                                                             ","                                                                             ","                                                                             ")
            .aisle("                                                                             ","                                                                             ","                                                                             ","                                                                             ","                                                                             ","                                                                             ","                                                                             ","                                                                             ","                                    EEEEE                                    ","    GIIIG                          E  O  E                          GIIIG    ","   GBBB AG                        E   O   E                        GA BBBG   ","  GBBBB A                         E  JOJ  E                         A BBBBG  ","  ZBBBB A                         EOOOBOOOE                         A BBBBZ  ","  GBBBB A                         E  JOJ  E                         A BBBBG  ","   GBBB AG                        E   O   E                        GA BBBG   ","    GIIIG                          E  O  E                          GIIIG    ","                                    EEEEE                                    ","                                                                             ","                                                                             ","                                                                             ","                                                                             ","                                                                             ","                                                                             ","                                                                             ","                                                                             ")
            .aisle("                                                                             ","                                                                             ","                                                                             ","                                                                             ","                                                                             ","                                                                             ","                                                                             ","                                                                             ","                                                                             ","   GIIIIG                                                           GIIIIG   ","  GBBB  AG                                                         GA  BBBG  "," GBBBB  A                            JOJ                            A  BBBBG "," ZBBBB  A                            OBO                            A  BBBBZ "," GBBBB  A                            JOJ                            A  BBBBG ","  GBBB  AG                                                         GA  BBBG  ","   GIIIIG                                                           GIIIIG   ","                                                                             ","                                                                             ","                                                                             ","                                                                             ","                                                                             ","                                                                             ","                                                                             ","                                                                             ","                                                                             ")
            .aisle("                                                                             ","                                                                             ","                                                                             ","                                                                             ","                                                                             ","                                                                             ","                                                                             ","                                                                             ","                                                                             ","   GIIIG                             EEE                             GIIIG   ","  GBBB AG                           E O E                           GA BBBG  "," GBBBB A                           E JOJ E                           A BBBBG "," ZBBBB A                           EOOBOOE                           A BBBBZ "," GBBBB A                           E JOJ E                           A BBBBG ","  GBBB AG                           E O E                           GA BBBG  ","   GIIIG                             EEE                             GIIIG   ","                                                                             ","                                                                             ","                                                                             ","                                                                             ","                                                                             ","                                                                             ","                                                                             ","                                                                             ","                                                                             ")
            .aisle("                                                                             ","                                                                             ","                                                                             ","                                                                             ","                                                                             ","                                                                             ","                                                                             ","                                                                             ","                                                                             ","   GIIIG                                                             GIIIG   ","  GBBB AG                                                           GA BBBG  "," GBBBB A                             JOJ                             A BBBBG "," ZBBBB A                             OBO                             A BBBBZ "," GBBBB A                             JOJ                             A BBBBG ","  GBBB AG                                                           GA BBBG  ","   GIIIG                                                             GIIIG   ","                                                                             ","                                                                             ","                                                                             ","                                                                             ","                                                                             ","                                                                             ","                                                                             ","                                                                             ","                                                                             ")
            .aisle("                                                                             ","                                                                             ","                                                                             ","                                                                             ","                                                                             ","                                                                             ","                                                                             ","                                                                             ","                                                                             ","   GIIIG                                                             GIIIG   ","  GBBB AG                     GI     III     IG                     GA BBBG  "," GBBBB A                      GI    IJJJI    IG                      A BBBBG "," ZBBBB A                      GI    IJJJI    IG                      A BBBBZ "," GBBBB A                      GI    IJJJI    IG                      A BBBBG ","  GBBB AG                     GI     III     IG                     GA BBBG  ","   GIIIG                                                             GIIIG   ","                                                                             ","                                                                             ","                                                                             ","                                                                             ","                                                                             ","                                                                             ","                                                                             ","                                                                             ","                                                                             ")
            .aisle("                                                                             ","                                                                             ","                                                                             ","                                                                             ","                                                                             ","                                                                             ","                                                                             ","                                                                             ","                              GI             IG                              ","  GIIIIG                     GGI             IGG                     GIIIIG  "," GBBBB AG                    GDJ             JDG                    GA BBBBG ","GBBBBB A                     GDJ             JDG                     A BBBBBG","ZBBBBB A                    GGDJ             JDGG                    A BBBBBZ","GBBBBB A                     GDJ             JDG                     A BBBBBG"," GBBBB AG                    GDJ             JDG                    GA BBBBG ","  GIIIIG                     GGI             IGG                     GIIIIG  ","                              GI             IG                              ","                                                                             ","                                                                             ","                                                                             ","                                                                             ","                                                                             ","                                                                             ","                                                                             ","                                                                             ")
            .aisle("                                                                             ","                                                                             ","                                                                             ","                                                                             ","                                                                             ","                                                                             ","                                                                             ","                              GI             IG                              ","                             GDJ             JDG                             ","  GIIIG                     G DJ             JD G                     GIIIG  "," GBBB AG                    GDBD     AAA     DBDG                    GA BBBG ","GBBBB A                     GDBD    AAAAA    DBDG                     A BBBBG","ZBBBB A                     GDBD    AAAAA    DBDG                     A BBBBZ","GBBBB A                     GDBD    AAAAA    DBDG                     A BBBBG"," GBBB AG                    GDBD     AAA     DBDG                    GA BBBG ","  GIIIG                     G DJ             JD G                     GIIIG  ","                             GDJ             JDG                             ","                              GI             IG                              ","                                                                             ","                                                                             ","                                                                             ","                                                                             ","                                                                             ","                                                                             ","                                                                             ")
            .aisle("                                                                             ","                                                                             ","                                                                             ","                                                                             ","                                                                             ","                                                                             ","                              GI             IG                              ","                             GDJ             JDG                             ","                            GDBD             DBDG                            ","  GIIIG                     GDBD    AAAAA    DBDG                     GIIIG  "," GGGGGGG                   GO D    AA   AA    D OG                   GGGGGGG ","GGGAAGGG                   GO D    A     A    D OG                   GGGAAGGG","ZGGAAGGG                   GO D    A     A    D OG                   GGGAAGGZ","GGGAAGGG                   GO D    A     A    D OG                   GGGAAGGG"," GGGGGGG                   GO D    AA   AA    D OG                   GGGGGGG ","  GIIIG                     GDBD    AAAAA    DBDG                     GIIIG  ","                            GDBD             DBDG                            ","                             GDJ             JDG                             ","                              GI             IG                              ","                                                                             ","                                                                             ","                                                                             ","                                                                             ","                                                                             ","                                                                             ")
            .aisle("                                                                             ","                                                                             ","                                                                             ","                                                                             ","                                                                             ","                                                                             ","                             GGI             IGG                             ","                            G DJ             JD G                            ","                            GDBD    AAAAA    DBDG                            ","  GGGGGG                   GO D    A     A    D OG                   GGGGGG  "," GHHHJA                    G      A       A      G                    AJHHHG ","GGJ  JA                    G      A       A      G                    AJ  JGG","ZGJ  JA                    G      A       A      G                    AJ  JGZ","GGJ  JA                    G      A       A      G                    AJ  JGG"," GHHHJA                    G      A       A      G                    AJHHHG ","  GGGGGG                   GO D    A     A    D OG                   GGGGGG  ","                            GDBD    AAAAA    DBDG                            ","                            G DJ             JD G                            ","                             GGI             IGG                             ","                                                                             ","                                                                             ","                                                                             ","                                                                             ","                                                                             ","                                                                             ")
            .aisle("                                                                             ","                                                                             ","                                                                             ","                                                                             ","                                                                             ","                              GI             IG                              ","                             GDJ             JDG                             ","                            GDBD     AAA     DBDG                            ","  GGGGGG                   GO D    AA   AA    D OG                   GGGGGG  "," GHHHJA                    G      A       A      G                    AJHHHG "," GLLLJA                    G      A       A      G                    AJLLLG ","GKKMMGA                   GGD D DADO     ODAD D DGG                   AGMMKKG","GKKMMGA                   GGD D DADO     ODAD D DGG                   AGMMKKG","GKKMMGA                   GGD D DADO     ODAD D DGG                   AGMMKKG"," GLLLJA                    G      A       A      G                    AJLLLG "," GHHHJA                    G      A       A      G                    AJHHHG ","  GGGGGG                   GO D    AA   AA    D OG                   GGGGGG  ","                            GDBD     AAA     DBDG                            ","                             GDJ             JDG                             ","                              GI             IG                              ","                                                                             ","                                                                             ","                                                                             ","                                                                             ","                                                                             ")
            .aisle("                                                                             ","                                                                             ","                                                                             ","                                                                             ","                                                                             ","                              GI             IG                              ","                             GDJ             JDG                             ","                            GDBD    AAAAA    DBDG                            ","  GAAGGG                   GO D    A     A    D OG                   GGGAAG  "," GJ  JA                    G      A       A      G                    AJ  JG ","GKKMMGA                   GGD D DADO     ODAD D DGG                   AGMMKKG","GLBMO A                   GG     A C  C  C A     GG                   A OMBLG","GLBMO A                   IOOOOOOOOC CFC COOOOOOOOI                   A OMBLG","GLBMO A                   GG     A C  C  C A     GG                   A OMBLG","GKKMMGA                   GGD D DADO     ODAD D DGG                   AGMMKKG"," GJ  JA                    G      A       A      G                    AJ  JG ","  GAAGGG                   GO D    A     A    D OG                   GGGAAG  ","                            GDBD    AAAAA    DBDG                            ","                             GDJ             JDG                             ","                              GI             IG                              ","                                                                             ","                                                                             ","                                                                             ","                                                                             ","                                                                             ")
            .aisle("                                                                             ","                                                                             ","                                                                             ","                                                                             ","                                                                             ","                              GI             IG                              ","                            GGDJ             JDGG                            ","                            GDBD    AAAAA    DBDG                            ","  GAAGGG                   GO D    A     A    D OG                   GGGAAG  "," GJ  JA                    G      A       A      G                    AJ  JG ","GKKMMGA                   GGD D DADO     ODAD D DGG                   AGMMKKG","GLBMO A                   IOOOOOOOO  CFC  OOOOOOOOI                   A OMBLG","GLBMO A                   IBBBBBBBBF F F FBBBBBBBBI                   A OMBLG","GLBMO A                   IOOOOOOOO  CFC  OOOOOOOOI                   A OMBLG","GKKMMGA                   GGD D DADO     ODAD D DGG                   AGMMKKG"," GJ  JA                    G      A       A      G                    AJ  JG ","  GAAGGG                   GO D    A     A    D OG                   GGGAAG  ","                            GDBD    AAAAA    DBDG                            ","                            GGDJ             JDGG                            ","                              GI             IG                              ","                                                                             ","                                                                             ","                                                                             ","                                                                             ","                                                                             ")
            .aisle("                                                                             ","                                                                             ","                                                                             ","                                                                             ","                                                                             ","                              GI             IG                              ","                             GDJ             JDG                             ","                            GDBD    AAAAA    DBDG                            ","  GAAGGG                   GO D    A     A    D OG                   GGGAAG  "," GJ  JA                    G      A       A      G                    AJ  JG ","GKKMMGA                   GGD D DADO     ODAD D DGG                   AGMMKKG","GLBMO A                   GG     A C  C  C A     GG                   A OMBLG","GLBMO A                   IOOOOOOOOC CFC COOOOOOOOI                   A OMBLG","GLBMO A                   GG     A C  C  C A     GG                   A OMBLG","GKKMMGA                   GGD D DADO     ODAD D DGG                   AGMMKKG"," GJ  JA                    G      A       A      G                    AJ  JG ","  GAAGGG                   GO D    A     A    D OG                   GGGAAG  ","                            GDBD    AAAAA    DBDG                            ","                             GDJ             JDG                             ","                              GI             IG                              ","                                                                             ","                                                                             ","                                                                             ","                                                                             ","                                                                             ")
            .aisle("                                                                             ","                                                                             ","                                                                             ","                                                                             ","                                                                             ","                              GI             IG                              ","                             GDJ             JDG                             ","                            GDBD     AAA     DBDG                            ","  GGGGGG                   GO D    AA   AA    D OG                   GGGGGG  "," GHHHJA                    G      A       A      G                    AJHHHG "," GLLLJA                    G      A       A      G                    AJLLLG ","GKKMMGA                   GGD D DADO     ODAD D DGG                   AGMMKKG","GKKMMGA                   GGD D DADO     ODAD D DGG                   AGMMKKG","GKKMMGA                   GGD D DADO     ODAD D DGG                   AGMMKKG"," GLLLJA                    G      A       A      G                    AJLLLG "," GHHHJA                    G      A       A      G                    AJHHHG ","  GGGGGG                   GO D    AA   AA    D OG                   GGGGGG  ","                            GDBD     AAA     DBDG                            ","                             GDJ             JDG                             ","                              GI             IG                              ","                                                                             ","                                                                             ","                                                                             ","                                                                             ","                                                                             ")
            .aisle("                                                                             ","                                                                             ","                                                                             ","                                                                             ","                                                                             ","                                                                             ","                             GGI             IGG                             ","                            G DJ             JD G                            ","                            GDBD    AAAAA    DBDG                            ","  GGGGGG                   GO D    A     A    D OG                   GGGGGG  "," GHHHJA                    G      A       A      G                    AJHHHG ","GGJ  JA                    G      A       A      G                    AJ  JGG","ZGJ  JA                    G      A       A      G                    AJ  JGZ","GGJ  JA                    G      A       A      G                    AJ  JGG"," GHHHJA                    G      A       A      G                    AJHHHG ","  GGGGGG                   GO D    A     A    D OG                   GGGGGG  ","                            GDBD    AAAAA    DBDG                            ","                            G DJ             JD G                            ","                             GGI             IGG                             ","                                                                             ","                                                                             ","                                                                             ","                                                                             ","                                                                             ","                                                                             ")
            .aisle("                                                                             ","                                                                             ","                                                                             ","                                                                             ","                                                                             ","                                                                             ","                              GI             IG                              ","                             GDJ             JDG                             ","                            GDBD             DBDG                            ","  GIIIG                     GDBD    AAAAA    DBDG                     GIIIG  "," GGGGGGG                   GO D    AA   AA    D OG                   GGGGGGG ","GGGAAGGG                   GO D    A     A    D OG                   GGGAAGGG","ZGGAAGGG                   GO D    A     A    D OG                   GGGAAGGZ","GGGAAGGG                   GO D    A     A    D OG                   GGGAAGGG"," GGGGGGG                   GO D    AA   AA    D OG                   GGGGGGG ","  GIIIG                     GDBD    AAAAA    DBDG                     GIIIG  ","                            GDBD             DBDG                            ","                             GDJ             JDG                             ","                              GI             IG                              ","                                                                             ","                                                                             ","                                                                             ","                                                                             ","                                                                             ","                                                                             ")
