package com.gtladd.gtladditions.common.machine.muiltblock.structure

import com.gregtechceu.gtceu.api.pattern.FactoryBlockPattern
import com.gregtechceu.gtceu.api.pattern.util.RelativeDirection

object MultiBlockStructureB {
    val APOCALYPTIC_TORSION_QUANTUM_MATRIX: FactoryBlockPattern? =
        FactoryBlockPattern.start(
            RelativeDirection.LEFT, RelativeDirection.BACK, RelativeDirection.DOWN)
            .aisle("   D D                         D D                         D D   ", "  DCDCD                       DCDCD                       DCDCD  ", " DBBBBBD    D     D     D    DBBBBBD    D     D     D    DBBBBBD ", "DCBBBBBCDDDDCDDDDDCDDDDDCDDDDCBBBBBCDDDDCDDDDDCDDDDDCDDDDCBBBBBCD", " DBBBBBDBBBBDBBBBBDBBBBBDBBBBDBBBBBDBBBBDBBBBBDBBBBBDBBBBDBBBBBD ", "DCBBBBBCDDDDCDDDDDCDDDDDCDDDDCBBBBBCDDDDCDDDDDCDDDDDCDDDDCBBBBBCD", " DBBBBBD    D     D     D    DBBBBBD    D     D     D    DBBBBBD ", "  DCDCD     D     D     D     DCDCD     D     D     D     DCDCD  ", "   DBD      D     D     D      DBD      D     D     D      DBD   ", "   DBD      D     D     D      DBD      D     D     D      DBD   ", "   DBD     DDD   DDD   DDD     DBD     DDD   DDD   DDD     DBD   ", "   DBD    DBBBD DBBBD DBBBD    DBD    DBBBD DBBBD DBBBD    DBD   ", "  DCDCDDDDDBBBD DBBBD DBBBDDDDDCDCDDDDDBBBD DBBBD DBBBDDDDDCDCD  ", "   DBD    DBBBDDDBBBDDDBBBD    DBD    DBBBDDDBBBDDDBBBD    DBD   ", "   DBD     DDD   DDD   DDD     DBD     DDD   DDD   DDD     DBD   ", "   DBD       D   D D   D       DBD       D   D D   D       DBD   ", "   DBD     DDD   DDD   DDD     DBD     DDD   DDD   DDD     DBD   ", "   DBD    DBBBDDDBBBDDDBBBD    DBD    DBBBDDDBBBDDDBBBD    DBD   ", "  DCDCDDDDDBBBD DBBBD DBBBDDDDDCDCDDDDDBBBD DBBBD DBBBDDDDDCDCD  ", "   DBD    DBBBDDDBBBDDDBBBD    DBD    DBBBDDDBBBDDDBBBD    DBD   ", "   DBD     DDD   DDD   DDD     DBD     DDD   DDD   DDD     DBD   ", "   DBD       D   D D   D       DBD       D   D D   D       DBD   ", "   DBD     DDD   DDD   DDD     DBD     DDD   DDD   DDD     DBD   ", "   DBD    DBBBDDDBBBDDDBBBD    DBD    DBBBDDDBBBDDDBBBD    DBD   ", "  DCDCDDDDDBBBD DBBBD DBBBDDDDDCDCDDDDDBBBD DBBBD DBBBDDDDDCDCD  ", "   DBD    DBBBD DBBBD DBBBD    DBD    DBBBD DBBBD DBBBD    DBD   ", "   DBD     DDD   DDD   DDD     DBD     DDD   DDD   DDD     DBD   ", "   DBD      D     D     D      DBD      D     D     D      DBD   ", "   DBD      D     D     D      DBD      D     D     D      DBD   ", "  DCDCD     D     D     D     DCDCD     D     D     D     DCDCD  ", " DBBBBBD    D     D     D    DBBBBBD    D     D     D    DBBBBBD ", "DCBBBBBCDDDDCDDDDDCDDDDDCDDDDCBBBBBCDDDDCDDDDDCDDDDDCDDDDCBBBBBCD", " DBBBBBDBBBBDBBBBBDBBBBBDBBBBDBBBBBDBBBBDBBBBBDBBBBBDBBBBDBBBBBD ", "DCBBBBBCDDDDCDDDDDCDDDDDCDDDDCBBBBBCDDDDCDDDDDCDDDDDCDDDDCBBBBBCD", " DBBBBBD    D     D     D    DBBBBBD    D     D     D    DBBBBBD ", "  DCDCD     D     D     D     DCDCD     D     D     D     DCDCD  ", "   DBD      D     D     D      DBD      D     D     D      DBD   ", "   DBD      D     D     D      DBD      D     D     D      DBD   ", "   DBD     DDD   DDD   DDD     DBD     DDD   DDD   DDD     DBD   ", "   DBD    DBBBD DBBBD DBBBD    DBD    DBBBD DBBBD DBBBD    DBD   ", "  DCDCDDDDDBBBD DBBBD DBBBDDDDDCDCDDDDDBBBD DBBBD DBBBDDDDDCDCD  ", "   DBD    DBBBDDDBBBDDDBBBD    DBD    DBBBDDDBBBDDDBBBD    DBD   ", "   DBD     DDD   DDD   DDD     DBD     DDD   DDD   DDD     DBD   ", "   DBD       D   D D   D       DBD       D   D D   D       DBD   ", "   DBD     DDD   DDD   DDD     DBD     DDD   DDD   DDD     DBD   ", "   DBD    DBBBDDDBBBDDDBBBD    DBD    DBBBDDDBBBDDDBBBD    DBD   ", "  DCDCDDDDDBBBD DBBBD DBBBDDDDDCDCDDDDDBBBD DBBBD DBBBDDDDDCDCD  ", "   DBD    DBBBDDDBBBDDDBBBD    DBD    DBBBDDDBBBDDDBBBD    DBD   ", "   DBD     DDD   DDD   DDD     DBD     DDD   DDD   DDD     DBD   ", "   DBD       D   D D   D       DBD       D   D D   D       DBD   ", "   DBD     DDD   DDD   DDD     DBD     DDD   DDD   DDD     DBD   ", "   DBD    DBBBDDDBBBDDDBBBD    DBD    DBBBDDDBBBDDDBBBD    DBD   ", "  DCDCDDDDDBBBD DBBBD DBBBDDDDDCDCDDDDDBBBD DBBBD DBBBDDDDDCDCD  ", "   DBD    DBBBD DBBBD DBBBD    DBD    DBBBD DBBBD DBBBD    DBD   ", "   DBD     DDD   DDD   DDD     DBD     DDD   DDD   DDD     DBD   ", "   DBD      D     D     D      DBD      D     D     D      DBD   ", "   DBD      D     D     D      DBD      D     D     D      DBD   ", "  DCDCD     D     D     D     DCDCD     D     D     D     DCDCD  ", " DBBBBBD    D     D     D    DBBBBBD    D     D     D    DBBBBBD ", "DCBBBBBCDDDDCDDDDDCDDDDDCDDDDCBBBBBCDDDDCDDDDDCDDDDDCDDDDCBBBBBCD", " DBBBBBDBBBBDBBBBBDBBBBBDBBBBDBBBBBDBBBBDBBBBBDBBBBBDBBBBDBBBBBD ", "DCBBBBBCDDDDCDDDDDCDDDDDCDDDDCBBBBBCDDDDCDDDDDCDDDDDCDDDDCBBBBBCD", " DBBBBBD    D     D     D    DBBBBBD    D     D     D    DBBBBBD ", "  DCDCD                       DCDCD                       DCDCD  ", "   D D                         D D                         D D   ")
            .aisle("                                                                 ", "                                                                 ", "                                                                 ", "    D                           D                           D    ", "   DDD                         DDD                         DDD   ", "    D                           D                           D    ", "                                                                 ", "                                                                 ", "                                                                 ", "                                                                 ", "                                                                 ", "           AAA   AAA   AAA             AAA   AAA   AAA           ", "           ABA   ABA   ABA             ABA   ABA   ABA           ", "           AAAAAAAAAAAAAAA             AAAAAAAAAAAAAAA           ", "             A   A A   A                 A   A A   A             ", "             A   A A   A                 A   A A   A             ", "             A   A A   A                 A   A A   A             ", "           AAAAAAAAAAAAAAA             AAAAAAAAAAAAAAA           ", "           ABA   ABA   ABA             ABA   ABA   ABA           ", "           AAAAAAAAAAAAAAA             AAAAAAAAAAAAAAA           ", "             A   A A   A                 A   A A   A             ", "             A   A A   A                 A   A A   A             ", "             A   A A   A                 A   A A   A             ", "           AAAAAAAAAAAAAAA             AAAAAAAAAAAAAAA           ", "           ABA   ABA   ABA             ABA   ABA   ABA           ", "           AAA   AAA   AAA             AAA   AAA   AAA           ", "                                                                 ", "                                                                 ", "                                                                 ", "                                                                 ", "                                                                 ", "    D                           D                           D    ", "   DDD                         DDD                         DDD   ", "    D                           D                           D    ", "                                                                 ", "                                                                 ", "                                                                 ", "                                                                 ", "                                                                 ", "           AAA   AAA   AAA             AAA   AAA   AAA           ", "           ABA   ABA   ABA             ABA   ABA   ABA           ", "           AAAAAAAAAAAAAAA             AAAAAAAAAAAAAAA           ", "             A   A A   A                 A   A A   A             ", "             A   A A   A                 A   A A   A             ", "             A   A A   A                 A   A A   A             ", "           AAAAAAAAAAAAAAA             AAAAAAAAAAAAAAA           ", "           ABA   ABA   ABA             ABA   ABA   ABA           ", "           AAAAAAAAAAAAAAA             AAAAAAAAAAAAAAA           ", "             A   A A   A                 A   A A   A             ", "             A   A A   A                 A   A A   A             ", "             A   A A   A                 A   A A   A             ", "           AAAAAAAAAAAAAAA             AAAAAAAAAAAAAAA           ", "           ABA   ABA   ABA             ABA   ABA   ABA           ", "           AAA   AAA   AAA             AAA   AAA   AAA           ", "                                                                 ", "                                                                 ", "                                                                 ", "                                                                 ", "                                                                 ", "    D                           D                           D    ", "   DDD                         DDD                         DDD   ", "    D                           D                           D    ", "                                                                 ", "                                                                 ", "                                                                 ")
            .aisle("                                                                 ", "                                                                 ", "                                                                 ", "    E                           E                           E    ", "   EGE                         EGE                         EGE   ", "    E                           E                           E    ", "                                                                 ", "                                                                 ", "                                                                 ", "                                                                 ", "                                                                 ", "           AAA   AAA   AAA             AAA   AAA   AAA           ", "           ABA   ABA   ABA             ABA   ABA   ABA           ", "           AAAAAAAAAAAAAAA             AAAAAAAAAAAAAAA           ", "             A   A A   A                 A   A A   A             ", "             A   A A   A                 A   A A   A             ", "             A   A A   A                 A   A A   A             ", "           AAAAAAAAAAAAAAA             AAAAAAAAAAAAAAA           ", "           ABA   ABA   ABA             ABA   ABA   ABA           ", "           AAAAAAAAAAAAAAA             AAAAAAAAAAAAAAA           ", "             A   A A   A                 A   A A   A             ", "             A   A A   A                 A   A A   A             ", "             A   A A   A                 A   A A   A             ", "           AAAAAAAAAAAAAAA             AAAAAAAAAAAAAAA           ", "           ABA   ABA   ABA             ABA   ABA   ABA           ", "           AAA   AAA   AAA             AAA   AAA   AAA           ", "                                                                 ", "                                                                 ", "                                                                 ", "                                                                 ", "                                                                 ", "    E                           E                           E    ", "   EGE                         EGE                         EGE   ", "    E                           E                           E    ", "                                                                 ", "                                                                 ", "                                                                 ", "                                                                 ", "                                                                 ", "           AAA   AAA   AAA             AAA   AAA   AAA           ", "           ABA   ABA   ABA             ABA   ABA   ABA           ", "           AAAAAAAAAAAAAAA             AAAAAAAAAAAAAAA           ", "             A   A A   A                 A   A A   A             ", "             A   A A   A                 A   A A   A             ", "             A   A A   A                 A   A A   A             ", "           AAAAAAAAAAAAAAA             AAAAAAAAAAAAAAA           ", "           ABA   ABA   ABA             ABA   ABA   ABA           ", "           AAAAAAAAAAAAAAA             AAAAAAAAAAAAAAA           ", "             A   A A   A                 A   A A   A             ", "             A   A A   A                 A   A A   A             ", "             A   A A   A                 A   A A   A             ", "           AAAAAAAAAAAAAAA             AAAAAAAAAAAAAAA           ", "           ABA   ABA   ABA             ABA   ABA   ABA           ", "           AAA   AAA   AAA             AAA   AAA   AAA           ", "                                                                 ", "                                                                 ", "                                                                 ", "                                                                 ", "                                                                 ", "    E                           E                           E    ", "   EGE                         EGE                         EGE   ", "    E                           E                           E    ", "                                                                 ", "                                                                 ", "                                                                 ")
            .aisle("                                                                 ", "                                                                 ", "                                                                 ", "    E                           E                           E    ", "   EGE                         EGE                         EGE   ", "    E                           E                           E    ", "                                                                 ", "                                                                 ", "                                                                 ", "                                                                 ", "                                                                 ", "           AAA   AAA   AAA             AAA   AAA   AAA           ", "           ABA   ABA   ABA             ABA   ABA   ABA           ", "           AAAAAAAAAAAAAAA             AAAAAAAAAAAAAAA           ", "             A   A A   A                 A   A A   A             ", "             A   A A   A                 A   A A   A             ", "             A   A A   A                 A   A A   A             ", "           AAAAAAAAAAAAAAA             AAAAAAAAAAAAAAA           ", "           ABA   ABA   ABA             ABA   ABA   ABA           ", "           AAAAAAAAAAAAAAA             AAAAAAAAAAAAAAA           ", "             A   A A   A                 A   A A   A             ", "             A   A A   A                 A   A A   A             ", "             A   A A   A                 A   A A   A             ", "           AAAAAAAAAAAAAAA             AAAAAAAAAAAAAAA           ", "           ABA   ABA   ABA             ABA   ABA   ABA           ", "           AAA   AAA   AAA             AAA   AAA   AAA           ", "                                                                 ", "                                                                 ", "                                                                 ", "                                                                 ", "                                                                 ", "    E                           E                           E    ", "   EGE                         EGE                         EGE   ", "    E                           E                           E    ", "                                                                 ", "                                                                 ", "                                                                 ", "                                                                 ", "                                                                 ", "           AAA   AAA   AAA             AAA   AAA   AAA           ", "           ABA   ABA   ABA             ABA   ABA   ABA           ", "           AAAAAAAAAAAAAAA             AAAAAAAAAAAAAAA           ", "             A   A A   A                 A   A A   A             ", "             A   A A   A                 A   A A   A             ", "             A   A A   A                 A   A A   A             ", "           AAAAAAAAAAAAAAA             AAAAAAAAAAAAAAA           ", "           ABA   ABA   ABA             ABA   ABA   ABA           ", "           AAAAAAAAAAAAAAA             AAAAAAAAAAAAAAA           ", "             A   A A   A                 A   A A   A             ", "             A   A A   A                 A   A A   A             ", "             A   A A   A                 A   A A   A             ", "           AAAAAAAAAAAAAAA             AAAAAAAAAAAAAAA           ", "           ABA   ABA   ABA             ABA   ABA   ABA           ", "           AAA   AAA   AAA             AAA   AAA   AAA           ", "                                                                 ", "                                                                 ", "                                                                 ", "                                                                 ", "                                                                 ", "    E                           E                           E    ", "   EGE                         EGE                         EGE   ", "    E                           E                           E    ", "                                                                 ", "                                                                 ", "                                                                 ")
            .aisle("                                                                 ", "                                                                 ", "                                                                 ", "    E                           E                           E    ", "   EGE                         EGE                         EGE   ", "    E                           E                           E    ", "                                                                 ", "                                                                 ", "                                                                 ", "                                                                 ", "           DDD   DDD   DDD             DDD   DDD   DDD           ", "          DBBBD DBBBD DBBBD           DBBBD DBBBD DBBBD          ", "          DBBBD DBBBD DBBBD           DBBBD DBBBD DBBBD          ", "          DBBBDDDBBBDDDBBBD           DBBBDDDBBBDDDBBBD          ", "           DDD   DDD   DDD             DDD   DDD   DDD           ", "             D   D D   D                 D   D D   D             ", "           DDD   DDD   DDD             DDD   DDD   DDD           ", "          DBBBDDDBBBDDDBBBD           DBBBDDDBBBDDDBBBD          ", "          DBBBD DBBBD DBBBD           DBBBD DBBBD DBBBD          ", "          DBBBDDDBBBDDDBBBD           DBBBDDDBBBDDDBBBD          ", "           DDD   DDD   DDD             DDD   DDD   DDD           ", "             D   D D   D                 D   D D   D             ", "           DDD   DDD   DDD             DDD   DDD   DDD           ", "          DBBBDDDBBBDDDBBBD           DBBBDDDBBBDDDBBBD          ", "          DBBBD DBBBD DBBBD           DBBBD DBBBD DBBBD          ", "          DBBBD DBBBD DBBBD           DBBBD DBBBD DBBBD          ", "           DDD   DDD   DDD             DDD   DDD   DDD           ", "                                                                 ", "                                                                 ", "                                                                 ", "                                                                 ", "    E                           E                           E    ", "   EGE                         EGE                         EGE   ", "    E                           E                           E    ", "                                                                 ", "                                                                 ", "                                                                 ", "                                                                 ", "           DDD   DDD   DDD             DDD   DDD   DDD           ", "          DBBBD DBBBD DBBBD           DBBBD DBBBD DBBBD          ", "          DBBBD DBBBD DBBBD           DBBBD DBBBD DBBBD          ", "          DBBBDDDBBBDDDBBBD           DBBBDDDBBBDDDBBBD          ", "           DDD   DDD   DDD             DDD   DDD   DDD           ", "             D   D D   D                 D   D D   D             ", "           DDD   DDD   DDD             DDD   DDD   DDD           ", "          DBBBDDDBBBDDDBBBD           DBBBDDDBBBDDDBBBD          ", "          DBBBD DBBBD DBBBD           DBBBD DBBBD DBBBD          ", "          DBBBDDDBBBDDDBBBD           DBBBDDDBBBDDDBBBD          ", "           DDD   DDD   DDD             DDD   DDD   DDD           ", "             D   D D   D                 D   D D   D             ", "           DDD   DDD   DDD             DDD   DDD   DDD           ", "          DBBBDDDBBBDDDBBBD           DBBBDDDBBBDDDBBBD          ", "          DBBBD DBBBD DBBBD           DBBBD DBBBD DBBBD          ", "          DBBBD DBBBD DBBBD           DBBBD DBBBD DBBBD          ", "           DDD   DDD   DDD             DDD   DDD   DDD           ", "                                                                 ", "                                                                 ", "                                                                 ", "                                                                 ", "    E                           E                           E    ", "   EGE                         EGE                         EGE   ", "    E                           E                           E    ", "                                                                 ", "                                                                 ", "                                                                 ")
            .aisle("                                                                 ", "                                                                 ", "                                                                 ", "    E                           E                           E    ", "   EGE                         EGE                         EGE   ", "    E                           E                           E    ", "                                                                 ", "                                                                 ", "                                                                 ", "                                                                 ", "                                                                 ", "            D     D     D               D     D     D            ", "           DDD   DDD   DDD             DDD   DDD   DDD           ", "            D     D     D               D     D     D            ", "                                                                 ", "                                                                 ", "                                                                 ", "            D     D     D               D     D     D            ", "           DDD   DDD   DDD             DDD   DDD   DDD           ", "            D     D     D               D     D     D            ", "                                                                 ", "                                                                 ", "                                                                 ", "            D     D     D               D     D     D            ", "           DDD   DDD   DDD             DDD   DDD   DDD           ", "            D     D     D               D     D     D            ", "                                                                 ", "                                                                 ", "                                                                 ", "                                                                 ", "                                                                 ", "    E                           E                           E    ", "   EGE                         EGE                         EGE   ", "    E                           E                           E    ", "                                                                 ", "                                                                 ", "                                                                 ", "                                                                 ", "                                                                 ", "            D     D     D               D     D     D            ", "           DDD   DDD   DDD             DDD   DDD   DDD           ", "            D     D     D               D     D     D            ", "                                                                 ", "                                                                 ", "                                                                 ", "            D     D     D               D     D     D            ", "           DDD   DDD   DDD             DDD   DDD   DDD           ", "            D     D     D               D     D     D            ", "                                                                 ", "                                                                 ", "                                                                 ", "            D     D     D               D     D     D            ", "           DDD   DDD   DDD             DDD   DDD   DDD           ", "            D     D     D               D     D     D            ", "                                                                 ", "                                                                 ", "                                                                 ", "                                                                 ", "                                                                 ", "    E                           E                           E    ", "   EGE                         EGE                         EGE   ", "    E                           E                           E    ", "                                                                 ", "                                                                 ", "                                                                 ")
            .aisle("                                                                 ", "                                                                 ", "                                                                 ", "    D                           D                           D    ", "   DDD                         DDD                         DDD   ", "    D                           D                           D    ", "                                                                 ", "                                                                 ", "                                                                 ", "                                                                 ", "                                                                 ", "            D     D     D               D     D     D            ", "           DDD   DDD   DDD             DDD   DDD   DDD           ", "            D     D     D               D     D     D            ", "                                                                 ", "                                                                 ", "                                                                 ", "            D     D     D               D     D     D            ", "           DDD   DDD   DDD             DDD   DDD   DDD           ", "            D     D     D               D     D     D            ", "                                                                 ", "                                                                 ", "                                                                 ", "            D     D     D               D     D     D            ", "           DDD   DDD   DDD             DDD   DDD   DDD           ", "            D     D     D               D     D     D            ", "                                                                 ", "                                                                 ", "                                                                 ", "                                                                 ", "                                                                 ", "    D                           D                           D    ", "   DDD                         DDD                         DDD   ", "    D                           D                           D    ", "                                                                 ", "                                                                 ", "                                                                 ", "                                                                 ", "                                                                 ", "            D     D     D               D     D     D            ", "           DDD   DDD   DDD             DDD   DDD   DDD           ", "            D     D     D               D     D     D            ", "                                                                 ", "                                                                 ", "                                                                 ", "            D     D     D               D     D     D            ", "           DDD   DDD   DDD             DDD   DDD   DDD           ", "            D     D     D               D     D     D            ", "                                                                 ", "                                                                 ", "                                                                 ", "            D     D     D               D     D     D            ", "           DDD   DDD   DDD             DDD   DDD   DDD           ", "            D     D     D               D     D     D            ", "                                                                 ", "                                                                 ", "                                                                 ", "                                                                 ", "                                                                 ", "    D                           D                           D    ", "   DDD                         DDD                         DDD   ", "    D                           D                           D    ", "                                                                 ", "                                                                 ", "                                                                 ")
            .aisle("                                                                 ", "                                                                 ", "                                                                 ", "                                                                 ", "    C                           C                           C    ", "                                                                 ", "                                                                 ", "                                                                 ", "                                                                 ", "                                                                 ", "                                                                 ", "                                                                 ", "            C     C     C               C     C     C            ", "                                                                 ", "                                                                 ", "                                                                 ", "                                                                 ", "                                                                 ", "            C     C     C               C     C     C            ", "                                                                 ", "                                                                 ", "                                                                 ", "                                                                 ", "                                                                 ", "            C     C     C               C     C     C            ", "                                                                 ", "                                                                 ", "                                                                 ", "                                                                 ", "                                                                 ", "                                                                 ", "                                                                 ", "    C                           C                           C    ", "                                                                 ", "                                                                 ", "                                                                 ", "                                                                 ", "                                                                 ", "                                                                 ", "                                                                 ", "            C     C     C               C     C     C            ", "                                                                 ", "                                                                 ", "                                                                 ", "                                                                 ", "                                                                 ", "            C     C     C               C     C     C            ", "                                                                 ", "                                                                 ", "                                                                 ", "                                                                 ", "                                                                 ", "            C     C     C               C     C     C            ", "                                                                 ", "                                                                 ", "                                                                 ", "                                                                 ", "                                                                 ", "                                                                 ", "                                                                 ", "    C                           C                           C    ", "                                                                 ", "                                                                 ", "                                                                 ", "                                                                 ")
            .aisle("                                                                 ", "                                                                 ", "                                                                 ", "    D                           D                           D    ", "   DDD                         DDD                         DDD   ", "    D                           D                           D    ", "                                                                 ", "                                                                 ", "                                                                 ", "                                                                 ", "                                                                 ", "            D     D     D               D     D     D            ", "           DDD   DDD   DDD             DDD   DDD   DDD           ", "            D     D     D               D     D     D            ", "                                                                 ", "                                                                 ", "                                                                 ", "            D     D     D               D     D     D            ", "           DDD   DDD   DDD             DDD   DDD   DDD           ", "            D     D     D               D     D     D            ", "                                                                 ", "                                                                 ", "                                                                 ", "            D     D     D               D     D     D            ", "           DDD   DDD   DDD             DDD   DDD   DDD           ", "            D     D     D               D     D     D            ", "                                                                 ", "                                                                 ", "                                                                 ", "                                                                 ", "                                                                 ", "    D                           D                           D    ", "   DDD                         DDD                         DDD   ", "    D                           D                           D    ", "                                                                 ", "                                                                 ", "                                                                 ", "                                                                 ", "                                                                 ", "            D     D     D               D     D     D            ", "           DDD   DDD   DDD             DDD   DDD   DDD           ", "            D     D     D               D     D     D            ", "                                                                 ", "                                                                 ", "                                                                 ", "            D     D     D               D     D     D            ", "           DDD   DDD   DDD             DDD   DDD   DDD           ", "            D     D     D               D     D     D            ", "                                                                 ", "                                                                 ", "                                                                 ", "            D     D     D               D     D     D            ", "           DDD   DDD   DDD             DDD   DDD   DDD           ", "            D     D     D               D     D     D            ", "                                                                 ", "                                                                 ", "                                                                 ", "                                                                 ", "                                                                 ", "    D                           D                           D    ", "   DDD                         DDD                         DDD   ", "    D                           D                           D    ", "                                                                 ", "                                                                 ", "                                                                 ")
            .aisle("                                                                 ", "                                                                 ", "                                                                 ", "    E                           E                           E    ", "   EGE                         EGE                         EGE   ", "    E                           E                           E    ", "                                                                 ", "                                                                 ", "                                                                 ", "                                                                 ", "                                                                 ", "            D     D     D               D     D     D            ", "           DDD   DDD   DDD             DDD   DDD   DDD           ", "            D     D     D               D     D     D            ", "                                                                 ", "                                                                 ", "                                                                 ", "            D     D     D               D     D     D            ", "           DDD   DDD   DDD             DDD   DDD   DDD           ", "            D     D     D               D     D     D            ", "                                                                 ", "                                                                 ", "                                                                 ", "            D     D     D               D     D     D            ", "           DDD   DDD   DDD             DDD   DDD   DDD           ", "            D     D     D               D     D     D            ", "                                                                 ", "                                                                 ", "                                                                 ", "                                                                 ", "                                                                 ", "    E                           E                           E    ", "   EGE                         EGE                         EGE   ", "    E                           E                           E    ", "                                                                 ", "                                                                 ", "                                                                 ", "                                                                 ", "                                                                 ", "            D     D     D               D     D     D            ", "           DDD   DDD   DDD             DDD   DDD   DDD           ", "            D     D     D               D     D     D            ", "                                                                 ", "                                                                 ", "                                                                 ", "            D     D     D               D     D     D            ", "           DDD   DDD   DDD             DDD   DDD   DDD           ", "            D     D     D               D     D     D            ", "                                                                 ", "                                                                 ", "                                                                 ", "            D     D     D               D     D     D            ", "           DDD   DDD   DDD             DDD   DDD   DDD           ", "            D     D     D               D     D     D            ", "                                                                 ", "                                                                 ", "                                                                 ", "                                                                 ", "                                                                 ", "    E                           E                           E    ", "   EGE                         EGE                         EGE   ", "    E                           E                           E    ", "                                                                 ", "                                                                 ", "                                                                 ")
            .aisle("                                                                 ", "                                                                 ", "                                                                 ", "    E                           E                           E    ", "   EGE                         EGE                         EGE   ", "    E                           E                           E    ", "                                                                 ", "                                                                 ", "                                                                 ", "                                                                 ", "           DDD   DDD   DDD             DDD   DDD   DDD           ", "          DBBBD DBBBD DBBBD           DBBBD DBBBD DBBBD          ", "          DBBBD DBBBD DBBBD           DBBBD DBBBD DBBBD          ", "          DBBBDDDBBBDDDBBBD           DBBBDDDBBBDDDBBBD          ", "           DDD   DDD   DDD             DDD   DDD   DDD           ", "             D   D D   D                 D   D D   D             ", "           DDD   DDD   DDD             DDD   DDD   DDD           ", "          DBBBDDDBBBDDDBBBD           DBBBDDDBBBDDDBBBD          ", "          DBBBD DBBBD DBBBD           DBBBD DBBBD DBBBD          ", "          DBBBDDDBBBDDDBBBD           DBBBDDDBBBDDDBBBD          ", "           DDD   DDD   DDD             DDD   DDD   DDD           ", "             D   D D   D                 D   D D   D             ", "           DDD   DDD   DDD             DDD   DDD   DDD           ", "          DBBBDDDBBBDDDBBBD           DBBBDDDBBBDDDBBBD          ", "          DBBBD DBBBD DBBBD           DBBBD DBBBD DBBBD          ", "          DBBBD DBBBD DBBBD           DBBBD DBBBD DBBBD          ", "           DDD   DDD   DDD             DDD   DDD   DDD           ", "                                                                 ", "                                                                 ", "                                                                 ", "                                                                 ", "    E                           E                           E    ", "   EGE                         EGE                         EGE   ", "    E                           E                           E    ", "                                                                 ", "                                                                 ", "                                                                 ", "                                                                 ", "           DDD   DDD   DDD             DDD   DDD   DDD           ", "          DBBBD DBBBD DBBBD           DBBBD DBBBD DBBBD          ", "          DBBBD DBBBD DBBBD           DBBBD DBBBD DBBBD          ", "          DBBBDDDBBBDDDBBBD           DBBBDDDBBBDDDBBBD          ", "           DDD   DDD   DDD             DDD   DDD   DDD           ", "             D   D D   D                 D   D D   D             ", "           DDD   DDD   DDD             DDD   DDD   DDD           ", "          DBBBDDDBBBDDDBBBD           DBBBDDDBBBDDDBBBD          ", "          DBBBD DBBBD DBBBD           DBBBD DBBBD DBBBD          ", "          DBBBDDDBBBDDDBBBD           DBBBDDDBBBDDDBBBD          ", "           DDD   DDD   DDD             DDD   DDD   DDD           ", "             D   D D   D                 D   D D   D             ", "           DDD   DDD   DDD             DDD   DDD   DDD           ", "          DBBBDDDBBBDDDBBBD           DBBBDDDBBBDDDBBBD          ", "          DBBBD DBBBD DBBBD           DBBBD DBBBD DBBBD          ", "          DBBBD DBBBD DBBBD           DBBBD DBBBD DBBBD          ", "           DDD   DDD   DDD             DDD   DDD   DDD           ", "                                                                 ", "                                                                 ", "                                                                 ", "                                                                 ", "    E                           E                           E    ", "   EGE                         EGE                         EGE   ", "    E                           E                           E    ", "                                                                 ", "                                                                 ", "                                                                 ")
            .aisle("                                                                 ", "                                                                 ", "                                                                 ", "    E                           E                           E    ", "   EGE                         EGE                         EGE   ", "    E                           E                           E    ", "                                                                 ", "                                                                 ", "                                                                 ", "                                                                 ", "                                                                 ", "           AAA   AAA   AAA             AAA   AAA   AAA           ", "           ABA   ABA   ABA             ABA   ABA   ABA           ", "           AAAAAAAAAAAAAAA             AAAAAAAAAAAAAAA           ", "             A   A A   A                 A   A A   A             ", "             A   A A   A                 A   A A   A             ", "             A   A A   A                 A   A A   A             ", "           AAAAAAAAAAAAAAA             AAAAAAAAAAAAAAA           ", "           ABA   ABA   ABA             ABA   ABA   ABA           ", "           AAAAAAAAAAAAAAA             AAAAAAAAAAAAAAA           ", "             A   A A   A                 A   A A   A             ", "             A   A A   A                 A   A A   A             ", "             A   A A   A                 A   A A   A             ", "           AAAAAAAAAAAAAAA             AAAAAAAAAAAAAAA           ", "           ABA   ABA   ABA             ABA   ABA   ABA           ", "           AAA   AAA   AAA             AAA   AAA   AAA           ", "                                                                 ", "                                                                 ", "                                                                 ", "                                                                 ", "                                                                 ", "    E                           E                           E    ", "   EGE                         EGE                         EGE   ", "    E                           E                           E    ", "                                                                 ", "                                                                 ", "                                                                 ", "                                                                 ", "                                                                 ", "           AAA   AAA   AAA             AAA   AAA   AAA           ", "           ABA   ABA   ABA             ABA   ABA   ABA           ", "           AAAAAAAAAAAAAAA             AAAAAAAAAAAAAAA           ", "             A   A A   A                 A   A A   A             ", "             A   A A   A                 A   A A   A             ", "             A   A A   A                 A   A A   A             ", "           AAAAAAAAAAAAAAA             AAAAAAAAAAAAAAA           ", "           ABA   ABA   ABA             ABA   ABA   ABA           ", "           AAAAAAAAAAAAAAA             AAAAAAAAAAAAAAA           ", "             A   A A   A                 A   A A   A             ", "             A   A A   A                 A   A A   A             ", "             A   A A   A                 A   A A   A             ", "           AAAAAAAAAAAAAAA             AAAAAAAAAAAAAAA           ", "           ABA   ABA   ABA             ABA   ABA   ABA           ", "           AAA   AAA   AAA             AAA   AAA   AAA           ", "                                                                 ", "                                                                 ", "                                                                 ", "                                                                 ", "                                                                 ", "    E                           E                           E    ", "   EGE                         EGE                         EGE   ", "    E                           E                           E    ", "                                                                 ", "                                                                 ", "                                                                 ")
            .aisle("                                                                 ", "                                                                 ", "                                                                 ", "    E                           E                           E    ", "   EGE                         EGE                         EGE   ", "    E                           E                           E    ", "                                                                 ", "                                                                 ", "                                                                 ", "                                                                 ", "                                                                 ", "           AAA   AAA   AAA             AAA   AAA   AAA           ", "           ABA   ABA   ABA             ABA   ABA   ABA           ", "           AAAAAAAAAAAAAAA             AAAAAAAAAAAAAAA           ", "             A   A A   A                 A   A A   A             ", "             A   A A   A                 A   A A   A             ", "             A   A A   A                 A   A A   A             ", "           AAAAAAAAAAAAAAA             AAAAAAAAAAAAAAA           ", "           ABA   ABA   ABA             ABA   ABA   ABA           ", "           AAAAAAAAAAAAAAA             AAAAAAAAAAAAAAA           ", "             A   A A   A                 A   A A   A             ", "             A   A A   A                 A   A A   A             ", "             A   A A   A                 A   A A   A             ", "           AAAAAAAAAAAAAAA             AAAAAAAAAAAAAAA           ", "           ABA   ABA   ABA             ABA   ABA   ABA           ", "           AAA   AAA   AAA             AAA   AAA   AAA           ", "                                                                 ", "                                                                 ", "                                                                 ", "                                                                 ", "                                                                 ", "    E                           E                           E    ", "   EGE                         EGE                         EGE   ", "    E                           E                           E    ", "                                                                 ", "                                                                 ", "                                                                 ", "                                                                 ", "                                                                 ", "           AAA   AAA   AAA             AAA   AAA   AAA           ", "           ABA   ABA   ABA             ABA   ABA   ABA           ", "           AAAAAAAAAAAAAAA             AAAAAAAAAAAAAAA           ", "             A   A A   A                 A   A A   A             ", "             A   A A   A                 A   A A   A             ", "             A   A A   A                 A   A A   A             ", "           AAAAAAAAAAAAAAA             AAAAAAAAAAAAAAA           ", "           ABA   ABA   ABA             ABA   ABA   ABA           ", "           AAAAAAAAAAAAAAA             AAAAAAAAAAAAAAA           ", "             A   A A   A                 A   A A   A             ", "             A   A A   A                 A   A A   A             ", "             A   A A   A                 A   A A   A             ", "           AAAAAAAAAAAAAAA             AAAAAAAAAAAAAAA           ", "           ABA   ABA   ABA             ABA   ABA   ABA           ", "           AAA   AAA   AAA             AAA   AAA   AAA           ", "                                                                 ", "                                                                 ", "                                                                 ", "                                                                 ", "                                                                 ", "    E                           E                           E    ", "   EGE                         EGE                         EGE   ", "    E                           E                           E    ", "                                                                 ", "                                                                 ", "                                                                 ")
            .aisle("                                                                 ", "                                                                 ", "                                                                 ", "    E                           E                           E    ", "   EGE                         EGE                         EGE   ", "    E                           E                           E    ", "                                                                 ", "           DDD   DDD   DDD             DDD   DDD   DDD           ", "                                                                 ", "                                                                 ", "                                                                 ", "       D   AAA   AAA   AAA   D     D   AAA   AAA   AAA   D       ", "       D   ABA   ABA   ABA   D     D   ABA   ABA   ABA   D       ", "       D   AAAAAAAAAAAAAAA   D     D   AAAAAAAAAAAAAAA   D       ", "             A   A A   A                 A   A A   A             ", "             A   A A   A                 A   A A   A             ", "             A   A A   A                 A   A A   A             ", "       D   AAAAAAAAAAAAAAA   D     D   AAAAAAAAAAAAAAA   D       ", "       D   ABA   ABA   ABA   D     D   ABA   ABA   ABA   D       ", "       D   AAAAAAAAAAAAAAA   D     D   AAAAAAAAAAAAAAA   D       ", "             A   A A   A                 A   A A   A             ", "             A   A A   A                 A   A A   A             ", "             A   A A   A                 A   A A   A             ", "       D   AAAAAAAAAAAAAAA   D     D   AAAAAAAAAAAAAAA   D       ", "       D   ABA   ABA   ABA   D     D   ABA   ABA   ABA   D       ", "       D   AAA   AAA   AAA   D     D   AAA   AAA   AAA   D       ", "                                                                 ", "                                                                 ", "                                                                 ", "           DDD   DDD   DDD             DDD   DDD   DDD           ", "                                                                 ", "    E                           E                           E    ", "   EGE                         EGE                         EGE   ", "    E                           E                           E    ", "                                                                 ", "           DDD   DDD   DDD             DDD   DDD   DDD           ", "                                                                 ", "                                                                 ", "                                                                 ", "       D   AAA   AAA   AAA   D     D   AAA   AAA   AAA   D       ", "       D   ABA   ABA   ABA   D     D   ABA   ABA   ABA   D       ", "       D   AAAAAAAAAAAAAAA   D     D   AAAAAAAAAAAAAAA   D       ", "             A   A A   A                 A   A A   A             ", "             A   A A   A                 A   A A   A             ", "             A   A A   A                 A   A A   A             ", "       D   AAAAAAAAAAAAAAA   D     D   AAAAAAAAAAAAAAA   D       ", "       D   ABA   ABA   ABA   D     D   ABA   ABA   ABA   D       ", "       D   AAAAAAAAAAAAAAA   D     D   AAAAAAAAAAAAAAA   D       ", "             A   A A   A                 A   A A   A             ", "             A   A A   A                 A   A A   A             ", "             A   A A   A                 A   A A   A             ", "       D   AAAAAAAAAAAAAAA   D     D   AAAAAAAAAAAAAAA   D       ", "       D   ABA   ABA   ABA   D     D   ABA   ABA   ABA   D       ", "       D   AAA   AAA   AAA   D     D   AAA   AAA   AAA   D       ", "                                                                 ", "                                                                 ", "                                                                 ", "           DDD   DDD   DDD             DDD   DDD   DDD           ", "                                                                 ", "    E                           E                           E    ", "   EGE                         EGE                         EGE   ", "    E                           E                           E    ", "                                                                 ", "                                                                 ", "                                                                 ")
            .aisle("                                                                 ", "                                                                 ", "                                                                 ", "    D                           D                           D    ", "   DDD                         DDD                         DDD   ", "    D                           D                           D    ", "                                                                 ", "          DBBBD DBBBD DBBBD           DBBBD DBBBD DBBBD          ", "           AAA   AAA   AAA             AAA   AAA   AAA           ", "           AAA   AAA   AAA             AAA   AAA   AAA           ", "       D   AAA   AAA   AAA   D     D   AAA   AAA   AAA   D       ", "       BAAADDD  DDDDD  DDDAAAB     BAAADDD  DDDDD  DDDAAAB       ", "       BAAADBBD DBBBD DBBDAAAB     BAAADBBD DBBBD DBBDAAAB       ", "       BAAADBBDDDBBBDDDBBDAAAB     BAAADBBDDDBBBDDDBBDAAAB       ", "       D    DD   DDD   DD    D     D    DD   DDD   DD    D       ", "             D   D D   D                 D   D D   D             ", "       D   DDD   DDD   DDD   D     D   DDD   DDD   DDD   D       ", "       BAAADBBDDDBBBDDDBBDAAAB     BAAADBBDDDBBBDDDBBDAAAB       ", "       BAAADBBD DBBBD DBBDAAAB     BAAADBBD DBBBD DBBDAAAB       ", "       BAAADBBDDDBBBDDDBBDAAAB     BAAADBBDDDBBBDDDBBDAAAB       ", "       D   DDD   DDD   DDD   D     D   DDD   DDD   DDD   D       ", "             D   D D   D                 D   D D   D             ", "       D    DD   DDD   DD    D     D    DD   DDD   DD    D       ", "       BAAADBBDDDBBBDDDBBDAAAB     BAAADBBDDDBBBDDDBBDAAAB       ", "       BAAADBBD DBBBD DBBDAAAB     BAAADBBD DBBBD DBBDAAAB       ", "       BAAADDD  DDDDD  DDDAAAB     BAAADDD  DDDDD  DDDAAAB       ", "       D   AAA   AAA   AAA   D     D   AAA   AAA   AAA   D       ", "           AAA   AAA   AAA             AAA   AAA   AAA           ", "           AAA   AAA   AAA             AAA   AAA   AAA           ", "          DBBBD DBBBD DBBBD           DBBBD DBBBD DBBBD          ", "                                                                 ", "    D                           D                           D    ", "   DDD                         DDD                         DDD   ", "    D                           D                           D    ", "                                                                 ", "          DBBBD DBBBD DBBBD           DBBBD DBBBD DBBBD          ", "           AAA   AAA   AAA             AAA   AAA   AAA           ", "           AAA   AAA   AAA             AAA   AAA   AAA           ", "       D   AAA   AAA   AAA   D     D   AAA   AAA   AAA   D       ", "       BAAADDD  DDDDD  DDDAAAB     BAAADDD  DDDDD  DDDAAAB       ", "       BAAADBBD DBBBD DBBDAAAB     BAAADBBD DBBBD DBBDAAAB       ", "       BAAADBBDDDBBBDDDBBDAAAB     BAAADBBDDDBBBDDDBBDAAAB       ", "       D    DD   DDD   DD    D     D    DD   DDD   DD    D       ", "             D   D D   D                 D   D D   D             ", "       D   DDD   DDD   DDD   D     D   DDD   DDD   DDD   D       ", "       BAAADBBDDDBBBDDDBBDAAAB     BAAADBBDDDBBBDDDBBDAAAB       ", "       BAAADBBD DBBBD DBBDAAAB     BAAADBBD DBBBD DBBDAAAB       ", "       BAAADBBDDDBBBDDDBBDAAAB     BAAADBBDDDBBBDDDBBDAAAB       ", "       D   DDD   DDD   DDD   D     D   DDD   DDD   DDD   D       ", "             D   D D   D                 D   D D   D             ", "       D    DD   DDD   DD    D     D    DD   DDD   DD    D       ", "       BAAADBBDDDBBBDDDBBDAAAB     BAAADBBDDDBBBDDDBBDAAAB       ", "       BAAADBBD DBBBD DBBDAAAB     BAAADBBD DBBBD DBBDAAAB       ", "       BAAADDD  DDDDD  DDDAAAB     BAAADDD  DDDDD  DDDAAAB       ", "       D   AAA   AAA   AAA   D     D   AAA   AAA   AAA   D       ", "           AAA   AAA   AAA             AAA   AAA   AAA           ", "           AAA   AAA   AAA             AAA   AAA   AAA           ", "          DBBBD DBBBD DBBBD           DBBBD DBBBD DBBBD          ", "                                                                 ", "    D                           D                           D    ", "   DDD                         DDD                         DDD   ", "    D                           D                           D    ", "                                                                 ", "                                                                 ", "                                                                 ")
            .aisle("                                                                 ", "                                                                 ", "                                                                 ", "                                                                 ", "    C                           C                           C    ", "                                                                 ", "            C     C     C               C     C     C            ", "          DBBBD DBBBD DBBBD           DBBBD DBBBD DBBBD          ", "           ABA   ABA   ABA             ABA   ABA   ABA           ", "           ABA   ABA   ABA             ABA   ABA   ABA           ", "       D   ABA   ABA   ABA   D     D   ABA   ABA   ABA   D       ", "       BAAADBBD DBBBD DBBDAAAB     BAAADBBD DBBBD DBBDAAAB       ", "      CBBBBBC     C     CBBBBBC   CBBBBBC     C     CBBBBBC      ", "       BAAAB             BAAAB     BAAAB             BAAAB       ", "       D   D             D   D     D   D             D   D       ", "                                                                 ", "       D   D             D   D     D   D             D   D       ", "       BAAAB             BAAAB     BAAAB             BAAAB       ", "      CBBBBBC     D     CBBBBBC   CBBBBBC     D     CBBBBBC      ", "       BAAAB             BAAAB     BAAAB             BAAAB       ", "       D   D             D   D     D   D             D   D       ", "                                                                 ", "       D   D             D   D     D   D             D   D       ", "       BAAAB             BAAAB     BAAAB             BAAAB       ", "      CBBBBBC     C     CBBBBBC   CBBBBBC     C     CBBBBBC      ", "       BAAADBBD DBBBD DBBDAAAB     BAAADBBD DBBBD DBBDAAAB       ", "       D   ABA   ABA   ABA   D     D   ABA   ABA   ABA   D       ", "           ABA   ABA   ABA             ABA   ABA   ABA           ", "           ABA   ABA   ABA             ABA   ABA   ABA           ", "          DBBBD DBBBD DBBBD           DBBBD DBBBD DBBBD          ", "            C     C     C               C     C     C            ", "                                                                 ", "    C                           C                           C    ", "                                                                 ", "            C     C     C               C     C     C            ", "          DBBBD DBBBD DBBBD           DBBBD DBBBD DBBBD          ", "           ABA   ABA   ABA             ABA   ABA   ABA           ", "           ABA   ABA   ABA             ABA   ABA   ABA           ", "       D   ABA   ABA   ABA   D     D   ABA   ABA   ABA   D       ", "       BAAADBBD DBBBD DBBDAAAB     BAAADBBD DBBBD DBBDAAAB       ", "      CBBBBBC     C     CBBBBBC   CBBBBBC     C     CBBBBBC      ", "       BAAAB             BAAAB     BAAAB             BAAAB       ", "       D   D             D   D     D   D             D   D       ", "                                                                 ", "       D   D             D   D     D   D             D   D       ", "       BAAAB             BAAAB     BAAAB             BAAAB       ", "      CBBBBBC     D     CBBBBBC   CBBBBBC     D     CBBBBBC      ", "       BAAAB             BAAAB     BAAAB             BAAAB       ", "       D   D             D   D     D   D             D   D       ", "                                                                 ", "       D   D             D   D     D   D             D   D       ", "       BAAAB             BAAAB     BAAAB             BAAAB       ", "      CBBBBBC     C     CBBBBBC   CBBBBBC     C     CBBBBBC      ", "       BAAADBBD DBBBD DBBDAAAB     BAAADBBD DBBBD DBBDAAAB       ", "       D   ABA   ABA   ABA   D     D   ABA   ABA   ABA   D       ", "           ABA   ABA   ABA             ABA   ABA   ABA           ", "           ABA   ABA   ABA             ABA   ABA   ABA           ", "          DBBBD DBBBD DBBBD           DBBBD DBBBD DBBBD          ", "            C     C     C               C     C     C            ", "                                                                 ", "    C                           C                           C    ", "                                                                 ", "                                                                 ", "                                                                 ", "                                                                 ")
            .aisle("                                                                 ", "                                                                 ", "                                                                 ", "    D                           D                           D    ", "   DDD                         DDD                         DDD   ", "    D                           D                           D    ", "                                                                 ", "          DBBBDDDBBBDDDBBBD           DBBBDDDBBBDDDBBBD          ", "           AAAAAAAAAAAAAAA             AAAAAAAAAAAAAAA           ", "           AAAAAAAAAAAAAAA             AAAAAAAAAAAAAAA           ", "       D   AAAAAAAAAAAAAAA   D     D   AAAAAAAAAAAAAAA   D       ", "       BAAADBBDDDBBBDDDBBDAAAB     BAAADBBDDDBBBDDDBBDAAAB       ", "       BAAAB             BAAAB     BAAAB             BAAAB       ", "       BAAAB             BAAAB     BAAAB             BAAAB       ", "       DAAAD             DAAAD     DAAAD             DAAAD       ", "       DAAAD             DAAAD     DAAAD             DAAAD       ", "       DAAAD             DAAAD     DAAAD             DAAAD       ", "       BAAAB             BAAAB     BAAAB             BAAAB       ", "       BAAAB      D      BAAAB     BAAAB      D      BAAAB       ", "       BAAAB             BAAAB     BAAAB             BAAAB       ", "       DAAAD             DAAAD     DAAAD             DAAAD       ", "       DAAAD             DAAAD     DAAAD             DAAAD       ", "       DAAAD             DAAAD     DAAAD             DAAAD       ", "       BAAAB             BAAAB     BAAAB             BAAAB       ", "       BAAAB             BAAAB     BAAAB             BAAAB       ", "       BAAADBBDDDBBBDDDBBDAAAB     BAAADBBDDDBBBDDDBBDAAAB       ", "       D   AAAAAAAAAAAAAAA   D     D   AAAAAAAAAAAAAAA   D       ", "           AAAAAAAAAAAAAAA             AAAAAAAAAAAAAAA           ", "           AAAAAAAAAAAAAAA             AAAAAAAAAAAAAAA           ", "          DBBBDDDBBBDDDBBBD           DBBBDDDBBBDDDBBBD          ", "                                                                 ", "    D                           D                           D    ", "   DDD                         DDD                         DDD   ", "    D                           D                           D    ", "                                                                 ", "          DBBBDDDBBBDDDBBBD           DBBBDDDBBBDDDBBBD          ", "           AAAAAAAAAAAAAAA             AAAAAAAAAAAAAAA           ", "           AAAAAAAAAAAAAAA             AAAAAAAAAAAAAAA           ", "       D   AAAAAAAAAAAAAAA   D     D   AAAAAAAAAAAAAAA   D       ", "       BAAADBBDDDBBBDDDBBDAAAB     BAAADBBDDDBBBDDDBBDAAAB       ", "       BAAAB             BAAAB     BAAAB             BAAAB       ", "       BAAAB             BAAAB     BAAAB             BAAAB       ", "       DAAAD             DAAAD     DAAAD             DAAAD       ", "       DAAAD             DAAAD     DAAAD             DAAAD       ", "       DAAAD             DAAAD     DAAAD             DAAAD       ", "       BAAAB             BAAAB     BAAAB             BAAAB       ", "       BAAAB      D      BAAAB     BAAAB      D      BAAAB       ", "       BAAAB             BAAAB     BAAAB             BAAAB       ", "       DAAAD             DAAAD     DAAAD             DAAAD       ", "       DAAAD             DAAAD     DAAAD             DAAAD       ", "       DAAAD             DAAAD     DAAAD             DAAAD       ", "       BAAAB             BAAAB     BAAAB             BAAAB       ", "       BAAAB             BAAAB     BAAAB             BAAAB       ", "       BAAADBBDDDBBBDDDBBDAAAB     BAAADBBDDDBBBDDDBBDAAAB       ", "       D   AAAAAAAAAAAAAAA   D     D   AAAAAAAAAAAAAAA   D       ", "           AAAAAAAAAAAAAAA             AAAAAAAAAAAAAAA           ", "           AAAAAAAAAAAAAAA             AAAAAAAAAAAAAAA           ", "          DBBBDDDBBBDDDBBBD           DBBBDDDBBBDDDBBBD          ", "                                                                 ", "    D                           D                           D    ", "   DDD                         DDD                         DDD   ", "    D                           D                           D    ", "                                                                 ", "                                                                 ", "                                                                 ")
            .aisle("                                                                 ", "                                                                 ", "                                                                 ", "    E                           E                           E    ", "   EGE                         EGE                         EGE   ", "    E                           E                           E    ", "                                                                 ", "           DDD   DDD   DDD             DDD   DDD   DDD           ", "             A   A A   A                 A   A A   A             ", "             A   A A   A                 A   A A   A             ", "             A   A A   A                 A   A A   A             ", "       D   DDD   DDD   DDD   D     D   DDD   DDD   DDD   D       ", "       D   D             D   D     D   D             D   D       ", "       DAAAD             DAAAD     DAAAD             DAAAD       ", "                                                                 ", "                                                                 ", "                                                                 ", "       DAAAD             DAAAD     DAAAD             DAAAD       ", "       D   D      D      D   D     D   D      D      D   D       ", "       DAAAD             DAAAD     DAAAD             DAAAD       ", "                                                                 ", "                                                                 ", "                                                                 ", "       DAAAD             DAAAD     DAAAD             DAAAD       ", "       D   D             D   D     D   D             D   D       ", "       D   DDD   DDD   DDD   D     D   DDD   DDD   DDD   D       ", "             A   A A   A                 A   A A   A             ", "             A   A A   A                 A   A A   A             ", "             A   A A   A                 A   A A   A             ", "           DDD   DDD   DDD             DDD   DDD   DDD           ", "                                                                 ", "    E                           E                           E    ", "   EGE                         EGE                         EGE   ", "    E                           E                           E    ", "                                                                 ", "           DDD   DDD   DDD             DDD   DDD   DDD           ", "             A   A A   A                 A   A A   A             ", "             A   A A   A                 A   A A   A             ", "             A   A A   A                 A   A A   A             ", "       D   DDD   DDD   DDD   D     D   DDD   DDD   DDD   D       ", "       D   D             D   D     D   D             D   D       ", "       DAAAD             DAAAD     DAAAD             DAAAD       ", "                                                                 ", "                                                                 ", "                                                                 ", "       DAAAD             DAAAD     DAAAD             DAAAD       ", "       D   D      D      D   D     D   D      D      D   D       ", "       DAAAD             DAAAD     DAAAD             DAAAD       ", "                                                                 ", "                                                                 ", "                                                                 ", "       DAAAD             DAAAD     DAAAD             DAAAD       ", "       D   D             D   D     D   D             D   D       ", "       D   DDD   DDD   DDD   D     D   DDD   DDD   DDD   D       ", "             A   A A   A                 A   A A   A             ", "             A   A A   A                 A   A A   A             ", "             A   A A   A                 A   A A   A             ", "           DDD   DDD   DDD             DDD   DDD   DDD           ", "                                                                 ", "    E                           E                           E    ", "   EGE                         EGE                         EGE   ", "    E                           E                           E    ", "                                                                 ", "                                                                 ", "                                                                 ")
            .aisle("                                                                 ", "                                                                 ", "                                                                 ", "    E                           E                           E    ", "   EGE                         EGE                         EGE   ", "    E                           E                           E    ", "                                                                 ", "             D   D D   D                 D   D D   D             ", "             A   A A   A                 A   A A   A             ", "             A   A A   A                 A   A A   A             ", "             A   A A   A                 A   A A   A             ", "             D   D D   D                 D   D D   D             ", "                                                                 ", "       DAAAD             DAAAD     DAAAD             DAAAD       ", "                                                                 ", "                                                                 ", "                                                                 ", "       DAAAD      C      DAAAD     DAAAD      C      DAAAD       ", "                 C C                         C C                 ", "       DAAAD      C      DAAAD     DAAAD      C      DAAAD       ", "                                                                 ", "                                                                 ", "                                                                 ", "       DAAAD             DAAAD     DAAAD             DAAAD       ", "                                                                 ", "             D   D D   D                 D   D D   D             ", "             A   A A   A                 A   A A   A             ", "             A   A A   A                 A   A A   A             ", "             A   A A   A                 A   A A   A             ", "             D   D D   D                 D   D D   D             ", "                                                                 ", "    E                           E                           E    ", "   EGE                         EGE                         EGE   ", "    E                           E                           E    ", "                                                                 ", "             D   D D   D                 D   D D   D             ", "             A   A A   A                 A   A A   A             ", "             A   A A   A                 A   A A   A             ", "             A   A A   A                 A   A A   A             ", "             D   D D   D                 D   D D   D             ", "                                                                 ", "       DAAAD             DAAAD     DAAAD             DAAAD       ", "                                                                 ", "                                                                 ", "                                                                 ", "       DAAAD      C      DAAAD     DAAAD      C      DAAAD       ", "                 C C                         C C                 ", "       DAAAD      C      DAAAD     DAAAD      C      DAAAD       ", "                                                                 ", "                                                                 ", "                                                                 ", "       DAAAD             DAAAD     DAAAD             DAAAD       ", "                                                                 ", "             D   D D   D                 D   D D   D             ", "             A   A A   A                 A   A A   A             ", "             A   A A   A                 A   A A   A             ", "             A   A A   A                 A   A A   A             ", "             D   D D   D                 D   D D   D             ", "                                                                 ", "    E                           E                           E    ", "   EGE                         EGE                         EGE   ", "    E                           E                           E    ", "                                                                 ", "                                                                 ", "                                                                 ")
            .aisle("                                                                 ", "                                                                 ", "                                                                 ", "    E                           E                           E    ", "   EGE                         EGE                         EGE   ", "    E                           E                           E    ", "                                                                 ", "           DDD   DDD   DDD             DDD   DDD   DDD           ", "             A   A A   A                 A   A A   A             ", "             A   A A   A                 A   A A   A             ", "             A   A A   A                 A   A A   A             ", "       D   DDD   DDD   DDD   D     D   DDD   DDD   DDD   D       ", "       D   D             D   D     D   D             D   D       ", "       DAAAD             DAAAD     DAAAD             DAAAD       ", "                                                                 ", "                                                                 ", "                                                                 ", "       DAAAD      C      DAAAD     DAAAD      C      DAAAD       ", "       D   D     C C     D   D     D   D     C C     D   D       ", "       DAAAD      C      DAAAD     DAAAD      C      DAAAD       ", "                                                                 ", "                                                                 ", "                                                                 ", "       DAAAD             DAAAD     DAAAD             DAAAD       ", "       D   D             D   D     D   D             D   D       ", "       D   DDD   DDD   DDD   D     D   DDD   DDD   DDD   D       ", "             A   A A   A                 A   A A   A             ", "             A   A A   A                 A   A A   A             ", "             A   A A   A                 A   A A   A             ", "           DDD   DDD   DDD             DDD   DDD   DDD           ", "                                                                 ", "    E                           E                           E    ", "   EGE                         EGE                         EGE   ", "    E                           E                           E    ", "                                                                 ", "           DDD   DDD   DDD             DDD   DDD   DDD           ", "             A   A A   A                 A   A A   A             ", "             A   A A   A                 A   A A   A             ", "             A   A A   A                 A   A A   A             ", "       D   DDD   DDD   DDD   D     D   DDD   DDD   DDD   D       ", "       D   D             D   D     D   D             D   D       ", "       DAAAD             DAAAD     DAAAD             DAAAD       ", "                                                                 ", "                                                                 ", "                                                                 ", "       DAAAD      C      DAAAD     DAAAD      C      DAAAD       ", "       D   D     C C     D   D     D   D     C C     D   D       ", "       DAAAD      C      DAAAD     DAAAD      C      DAAAD       ", "                                                                 ", "                                                                 ", "                                                                 ", "       DAAAD             DAAAD     DAAAD             DAAAD       ", "       D   D             D   D     D   D             D   D       ", "       D   DDD   DDD   DDD   D     D   DDD   DDD   DDD   D       ", "             A   A A   A                 A   A A   A             ", "             A   A A   A                 A   A A   A             ", "             A   A A   A                 A   A A   A             ", "           DDD   DDD   DDD             DDD   DDD   DDD           ", "                                                                 ", "    E                           E                           E    ", "   EGE                         EGE                         EGE   ", "    E                           E                           E    ", "                                                                 ", "                                                                 ", "                                                                 ")
            .aisle("                                                                 ", "                                                                 ", "                                                                 ", "    D                           D                           D    ", "   DDD                         DDD                         DDD   ", "    D                           D                           D    ", "                                                                 ", "          DBBBDDDBBBDDDBBBD           DBBBDDDBBBDDDBBBD          ", "           AAAAAAAAAAAAAAA             AAAAAAAAAAAAAAA           ", "           AAAAAAAAAAAAAAA             AAAAAAAAAAAAAAA           ", "       D   AAAAAAAAAAAAAAA   D     D   AAAAAAAAAAAAAAA   D       ", "       BAAADBBDDDBBBDDDBBDAAAB     BAAADBBDDDBBBDDDBBDAAAB       ", "       BAAAB             BAAAB     BAAAB             BAAAB       ", "       BAAAB             BAAAB     BAAAB             BAAAB       ", "       DAAAD             DAAAD     DAAAD             DAAAD       ", "       DAAAD      C      DAAAD     DAAAD      C      DAAAD       ", "       DAAAD      C      DAAAD     DAAAD      C      DAAAD       ", "       BAAAB             BAAAB     BAAAB             BAAAB       ", "       BAAAB   CC   CC   BAAAB     BAAAB   CC   CC   BAAAB       ", "       BAAAB             BAAAB     BAAAB             BAAAB       ", "       DAAAD      C      DAAAD     DAAAD      C      DAAAD       ", "       DAAAD      C      DAAAD     DAAAD      C      DAAAD       ", "       DAAAD             DAAAD     DAAAD             DAAAD       ", "       BAAAB             BAAAB     BAAAB             BAAAB       ", "       BAAAB             BAAAB     BAAAB             BAAAB       ", "       BAAADBBDDDBBBDDDBBDAAAB     BAAADBBDDDBBBDDDBBDAAAB       ", "       D   AAAAAAAAAAAAAAA   D     D   AAAAAAAAAAAAAAA   D       ", "           AAAAAAAAAAAAAAA             AAAAAAAAAAAAAAA           ", "           AAAAAAAAAAAAAAA             AAAAAAAAAAAAAAA           ", "          DBBBDDDBBBDDDBBBD           DBBBDDDBBBDDDBBBD          ", "                                                                 ", "    D                           D                           D    ", "   DDD                         DDD                         DDD   ", "    D                           D                           D    ", "                                                                 ", "          DBBBDDDBBBDDDBBBD           DBBBDDDBBBDDDBBBD          ", "           AAAAAAAAAAAAAAA             AAAAAAAAAAAAAAA           ", "           AAAAAAAAAAAAAAA             AAAAAAAAAAAAAAA           ", "       D   AAAAAAAAAAAAAAA   D     D   AAAAAAAAAAAAAAA   D       ", "       BAAADBBDDDBBBDDDBBDAAAB     BAAADBBDDDBBBDDDBBDAAAB       ", "       BAAAB             BAAAB     BAAAB             BAAAB       ", "       BAAAB             BAAAB     BAAAB             BAAAB       ", "       DAAAD             DAAAD     DAAAD             DAAAD       ", "       DAAAD      C      DAAAD     DAAAD      C      DAAAD       ", "       DAAAD      C      DAAAD     DAAAD      C      DAAAD       ", "       BAAAB             BAAAB     BAAAB             BAAAB       ", "       BAAAB   CC   CC   BAAAB     BAAAB   CC   CC   BAAAB       ", "       BAAAB             BAAAB     BAAAB             BAAAB       ", "       DAAAD      C      DAAAD     DAAAD      C      DAAAD       ", "       DAAAD      C      DAAAD     DAAAD      C      DAAAD       ", "       DAAAD             DAAAD     DAAAD             DAAAD       ", "       BAAAB             BAAAB     BAAAB             BAAAB       ", "       BAAAB             BAAAB     BAAAB             BAAAB       ", "       BAAADBBDDDBBBDDDBBDAAAB     BAAADBBDDDBBBDDDBBDAAAB       ", "       D   AAAAAAAAAAAAAAA   D     D   AAAAAAAAAAAAAAA   D       ", "           AAAAAAAAAAAAAAA             AAAAAAAAAAAAAAA           ", "           AAAAAAAAAAAAAAA             AAAAAAAAAAAAAAA           ", "          DBBBDDDBBBDDDBBBD           DBBBDDDBBBDDDBBBD          ", "                                                                 ", "    D                           D                           D    ", "   DDD                         DDD                         DDD   ", "    D                           D                           D    ", "                                                                 ", "                                                                 ", "                                                                 ")
            .aisle("                                                                 ", "                                                                 ", "                                                                 ", "                                                                 ", "    C                           C                           C    ", "                                                                 ", "            C     C     C               C     C     C            ", "          DBBBD DBBBD DBBBD           DBBBD DBBBD DBBBD          ", "           ABA   ABA   ABA             ABA   ABA   ABA           ", "           ABA   ABA   ABA             ABA   ABA   ABA           ", "       D   ABA   ABA   ABA   D     D   ABA   ABA   ABA   D       ", "       BAAADBBD DBBBD DBBDAAAB     BAAADBBD DBBBD DBBDAAAB       ", "      CBBBBBC     D     CBBBBBC   CBBBBBC     D     CBBBBBC      ", "       BAAAB      D      BAAAB     BAAAB      D      BAAAB       ", "       D   D      D      D   D     D   D      D      D   D       ", "                 C C                         C C                 ", "       D   D     C C     D   D     D   D     C C     D   D       ", "       BAAAB   CC   CC   BAAAB     BAAAB   CC   CC   BAAAB       ", "      CBBBBBDDD       DDDBBBBBC   CBBBBBDDD       DDDBBBBBC      ", "       BAAAB   CC   CC   BAAAB     BAAAB   CC   CC   BAAAB       ", "       D   D     C C     D   D     D   D     C C     D   D       ", "                 C C                         C C                 ", "       D   D      D      D   D     D   D      D      D   D       ", "       BAAAB      D      BAAAB     BAAAB      D      BAAAB       ", "      CBBBBBC     D     CBBBBBC   CBBBBBC     D     CBBBBBC      ", "       BAAADBBD DBBBD DBBDAAAB     BAAADBBD DBBBD DBBDAAAB       ", "       D   ABA   ABA   ABA   D     D   ABA   ABA   ABA   D       ", "           ABA   ABA   ABA             ABA   ABA   ABA           ", "           ABA   ABA   ABA             ABA   ABA   ABA           ", "          DBBBD DBBBD DBBBD           DBBBD DBBBD DBBBD          ", "            C     C     C               C     C     C            ", "                                                                 ", "    C                           C                           C    ", "                                                                 ", "            C     C     C               C     C     C            ", "          DBBBD DBBBD DBBBD           DBBBD DBBBD DBBBD          ", "           ABA   ABA   ABA             ABA   ABA   ABA           ", "           ABA   ABA   ABA             ABA   ABA   ABA           ", "       D   ABA   ABA   ABA   D     D   ABA   ABA   ABA   D       ", "       BAAADBBD DBBBD DBBDAAAB     BAAADBBD DBBBD DBBDAAAB       ", "      CBBBBBC     D     CBBBBBC   CBBBBBC     D     CBBBBBC      ", "       BAAAB      D      BAAAB     BAAAB      D      BAAAB       ", "       D   D      D      D   D     D   D      D      D   D       ", "                 C C                         C C                 ", "       D   D     C C     D   D     D   D     C C     D   D       ", "       BAAAB   CC   CC   BAAAB     BAAAB   CC   CC   BAAAB       ", "      CBBBBBDDD       DDDBBBBBC   CBBBBBDDD       DDDBBBBBC      ", "       BAAAB   CC   CC   BAAAB     BAAAB   CC   CC   BAAAB       ", "       D   D     C C     D   D     D   D     C C     D   D       ", "                 C C                         C C                 ", "       D   D      D      D   D     D   D      D      D   D       ", "       BAAAB      D      BAAAB     BAAAB      D      BAAAB       ", "      CBBBBBC     D     CBBBBBC   CBBBBBC     D     CBBBBBC      ", "       BAAADBBD DBBBD DBBDAAAB     BAAADBBD DBBBD DBBDAAAB       ", "       D   ABA   ABA   ABA   D     D   ABA   ABA   ABA   D       ", "           ABA   ABA   ABA             ABA   ABA   ABA           ", "           ABA   ABA   ABA             ABA   ABA   ABA           ", "          DBBBD DBBBD DBBBD           DBBBD DBBBD DBBBD          ", "            C     C     C               C     C     C            ", "                                                                 ", "    C                           C                           C    ", "                                                                 ", "                                                                 ", "                                                                 ", "                                                                 ")
