package com.gtladd.gtladditions.common.machine.muiltblock.structure

import com.gregtechceu.gtceu.api.pattern.FactoryBlockPattern
import com.gregtechceu.gtceu.api.pattern.util.RelativeDirection
import org.gtlcore.gtlcore.common.data.machines.AnnihilateGeneratorA
import org.gtlcore.gtlcore.common.data.machines.AnnihilateGeneratorB

@Suppress("DuplicatedCode")
object MultiBlockStructureD {
    val ANNIHILATE_GENERATOR_STRUCTURE: FactoryBlockPattern? = FactoryBlockPattern.start()
        .aisle(*AnnihilateGeneratorB.A_1)
        .aisle(*AnnihilateGeneratorB.A_2)
        .aisle(*AnnihilateGeneratorB.A_3)
        .aisle(*AnnihilateGeneratorB.A_4)
        .aisle(*AnnihilateGeneratorB.A_5)
        .aisle(*AnnihilateGeneratorB.A_6)
        .aisle(*AnnihilateGeneratorB.A_7)
        .aisle(*AnnihilateGeneratorB.A_8)
        .aisle(*AnnihilateGeneratorB.A_9)
        .aisle(*AnnihilateGeneratorB.A_10)
        .aisle(*AnnihilateGeneratorB.A_11)
        .aisle(*AnnihilateGeneratorB.A_12)
        .aisle(*AnnihilateGeneratorB.A_13)
        .aisle(*AnnihilateGeneratorB.A_14)
        .aisle(*AnnihilateGeneratorB.A_15)
        .aisle(*AnnihilateGeneratorB.A_16)
        .aisle(*AnnihilateGeneratorB.A_17)
        .aisle(*AnnihilateGeneratorB.A_18)
        .aisle(*AnnihilateGeneratorB.A_19)
        .aisle(*AnnihilateGeneratorB.A_20)
        .aisle(*AnnihilateGeneratorB.A_21)
        .aisle(*AnnihilateGeneratorB.A_22)
        .aisle(*AnnihilateGeneratorB.A_23)
        .aisle(*AnnihilateGeneratorB.A_24)
        .aisle(*AnnihilateGeneratorB.A_25)
        .aisle(*AnnihilateGeneratorB.A_26)
        .aisle(*AnnihilateGeneratorB.A_27)
        .aisle(*AnnihilateGeneratorB.A_28)
        .aisle(*AnnihilateGeneratorB.A_29)
        .aisle(*AnnihilateGeneratorB.A_30)
        .aisle(*AnnihilateGeneratorB.A_31)
        .aisle(*AnnihilateGeneratorB.A_32)
        .aisle(*AnnihilateGeneratorB.A_33)
        .aisle(*AnnihilateGeneratorB.A_34)
        .aisle(*AnnihilateGeneratorB.A_35)
        .aisle(*AnnihilateGeneratorB.A_36)
        .aisle(*AnnihilateGeneratorB.A_37)
        .aisle(*AnnihilateGeneratorB.A_38)
        .aisle(*AnnihilateGeneratorB.A_39)
        .aisle(*AnnihilateGeneratorB.A_40)
        .aisle(*AnnihilateGeneratorB.A_41)
        .aisle(*AnnihilateGeneratorB.A_42)
        .aisle(*AnnihilateGeneratorB.A_43)
        .aisle(*AnnihilateGeneratorB.A_44)
        .aisle(*AnnihilateGeneratorB.A_45)
        .aisle(*AnnihilateGeneratorB.A_46)
        .aisle(*AnnihilateGeneratorB.A_47)
        .aisle(*AnnihilateGeneratorB.A_48)
        .aisle(*AnnihilateGeneratorB.A_49)
        .aisle(*AnnihilateGeneratorB.A_50)
        .aisle(*AnnihilateGeneratorB.A_51)
        .aisle(*AnnihilateGeneratorB.A_52)
        .aisle(*AnnihilateGeneratorB.A_53)
        .aisle(*AnnihilateGeneratorA.A_54)
        .aisle(*AnnihilateGeneratorA.A_55)
        .aisle(*AnnihilateGeneratorA.A_56)
        .aisle(*AnnihilateGeneratorA.A_57)
        .aisle(*AnnihilateGeneratorA.A_58)
        .aisle(*AnnihilateGeneratorA.A_59)
        .aisle(*AnnihilateGeneratorA.A_60)
        .aisle(*AnnihilateGeneratorA.A_61)
        .aisle(*AnnihilateGeneratorA.A_62)
        .aisle(*AnnihilateGeneratorA.A_63)
        .aisle(*AnnihilateGeneratorA.A_64)
        .aisle(*AnnihilateGeneratorA.A_65)
        .aisle(*AnnihilateGeneratorA.A_66)
        .aisle(*AnnihilateGeneratorA.A_67)
        .aisle(*AnnihilateGeneratorA.A_68)
        .aisle(*AnnihilateGeneratorA.A_69)
        .aisle(*AnnihilateGeneratorA.A_70)
        .aisle(*AnnihilateGeneratorA.A_71)
        .aisle(*AnnihilateGeneratorA.A_72)
        .aisle(*AnnihilateGeneratorA.A_73)
        .aisle(*AnnihilateGeneratorA.A_74)
        .aisle(*AnnihilateGeneratorA.A_75)
        .aisle(*AnnihilateGeneratorA.A_76)
        .aisle(*AnnihilateGeneratorA.A_77)
        .aisle(*AnnihilateGeneratorA.A_78)
        .aisle(*AnnihilateGeneratorA.A_79)
        .aisle(*AnnihilateGeneratorA.A_80)
        .aisle(*AnnihilateGeneratorA.A_81)
        .aisle(*AnnihilateGeneratorA.A_82)
        .aisle(*AnnihilateGeneratorA.A_83)
        .aisle(*AnnihilateGeneratorA.A_84)
        .aisle(*AnnihilateGeneratorA.A_85)
        .aisle(*AnnihilateGeneratorA.A_86)
        .aisle(*AnnihilateGeneratorA.A_87)
        .aisle(*AnnihilateGeneratorA.A_88)
        .aisle(*AnnihilateGeneratorA.A_89)
        .aisle(*AnnihilateGeneratorA.A_90)
        .aisle(*AnnihilateGeneratorA.A_91)
        .aisle(*AnnihilateGeneratorA.A_92)
        .aisle(*AnnihilateGeneratorA.A_93)
        .aisle(*AnnihilateGeneratorA.A_94)
        .aisle(*AnnihilateGeneratorA.A_95)
        .aisle(*AnnihilateGeneratorA.A_96)
        .aisle(*AnnihilateGeneratorA.A_97)
        .aisle(*AnnihilateGeneratorA.A_98)
        .aisle(*AnnihilateGeneratorA.A_99)
        .aisle(*AnnihilateGeneratorA.A_100)
        .aisle(*AnnihilateGeneratorA.A_101)
        .aisle(*AnnihilateGeneratorA.A_102)
        .aisle(*AnnihilateGeneratorA.A_103)
        .aisle(*AnnihilateGeneratorA.A_104)
        .aisle(*AnnihilateGeneratorA.A_105)
        .aisle(*AnnihilateGeneratorA.A_106)
        .aisle(*AnnihilateGeneratorA.A_107)
        .aisle(*AnnihilateGeneratorA.A_108)
        .aisle(*AnnihilateGeneratorA.A_109)

    val FORGE_OF_THE_ANTICHRIST_MODULE: FactoryBlockPattern? = FactoryBlockPattern.start()
        .aisle("       ", "       ", "       ", "   G   ", "       ", "       ", "       ")
        .aisle("       ", "       ", "       ", "   E   ", "       ", "       ", "       ")
        .aisle("       ", "       ", "       ", "   E   ", "       ", "       ", "       ")
        .aisle("       ", "       ", "       ", "   E   ", "       ", "       ", "       ")
        .aisle("       ", "       ", "       ", "   E   ", "       ", "       ", "       ")
        .aisle("       ", "       ", "       ", "   E   ", "       ", "       ", "       ")
        .aisle("       ", "       ", "   E   ", "  EFE  ", "   E   ", "       ", "       ")
        .aisle("       ", "       ", "   E   ", "  EFE  ", "   E   ", "       ", "       ")
        .aisle("       ", "       ", "   E   ", "  EFE  ", "   E   ", "       ", "       ")
        .aisle("       ", "       ", "   E   ", "  EFE  ", "   E   ", "       ", "       ")
        .aisle("       ", "       ", "   E   ", "  EFE  ", "   E   ", "       ", "       ")
        .aisle("  BBB  ", " BDDDB ", "BDDDDDB", "BDDDDDB", "BDDDDDB", " BDDDB ", "  BBB  ")
        .aisle("       ", "  BBB  ", " BBBBB ", " BB~BB ", " BBBBB ", "  BBB  ", "       ")

    val DIMENSION_FOCUS_INFINITY_CRAFTING_ARRAY: FactoryBlockPattern? = FactoryBlockPattern.start(RelativeDirection.LEFT, RelativeDirection.UP, RelativeDirection.BACK)
        .aisle("                                         ", "                                         ", "                                         ", "                                         ", "                                         ", "                                         ", "                                         ", "                                         ", "                                         ", "               A         A               ", "             AA           AA             ", "            AAA           AAA            ", "           AAA             AAA           ", "          AAA               AAA          ", "          AA                 AA          ", "         A                     A         ", "                                         ", "                                         ", "                                         ", "                                         ", "                                         ", "                                         ", "                                         ", "                                         ", "                                         ", "         A                     A         ", "          AA                 AA          ", "          AAA               AAA          ", "           AAA             AAA           ", "            AAA           AAA            ", "             AA           AA             ", "               A         A               ", "                                         ", "                                         ", "                                         ", "                                         ", "                                         ", "                                         ", "                                         ", "                                         ", "                                         ")
        .aisle("                                         ", "                                         ", "                                         ", "                                         ", "                                         ", "                                         ", "                                         ", "                A       A                ", "              AA         AA              ", "            AAA           AAA            ", "           AA               AA           ", "          AA                 AA          ", "         AA                   AA         ", "         A                     A         ", "        AA                     AA        ", "        A                       A        ", "       A                         A       ", "                                         ", "                                         ", "                                         ", "                                         ", "                                         ", "                                         ", "                                         ", "       A                         A       ", "        A                       A        ", "        AA                     AA        ", "         A                     A         ", "         AA                   AA         ", "          AA                 AA          ", "           AA               AA           ", "            AAA           AAA            ", "              AA         AA              ", "                A       A                ", "                                         ", "                                         ", "                                         ", "                                         ", "                                         ", "                                         ", "                                         ")
        .aisle("                                         ", "                                         ", "                                         ", "                                         ", "                                         ", "                                         ", "               AA       AA               ", "             AAA         AAA             ", "           AAA             AAA           ", "          AA                 AA          ", "         AA                   AA         ", "        AA                     AA        ", "        A                       A        ", "       AA                       AA       ", "       A                         A       ", "      AA                         AA      ", "      A                           A      ", "                                         ", "                    B                    ", "                    C                    ", "                    C                    ", "                    C                    ", "                    B                    ", "                                         ", "      A                           A      ", "      AA                         AA      ", "       A                         A       ", "       AA                       AA       ", "        A                       A        ", "        AA                     AA        ", "         AA                   AA         ", "          AA                 AA          ", "           AAA             AAA           ", "             AAA         AAA             ", "               AA       AA               ", "                                         ", "                                         ", "                                         ", "                                         ", "                                         ", "                                         ")
        .aisle("                                         ", "                                         ", "                                         ", "                                         ", "                                         ", "              AAAA     AAAA              ", "            AAA           AAA            ", "           AA               AA           ", "          D                   D          ", "         D                     D         ", "        D                       D        ", "       A                         A       ", "      AA                         AA      ", "      A                           A      ", "     AA                           AA     ", "     A                             A     ", "     A              B              A     ", "     A              B              A     ", "                   BEB                   ", "                   FGF                   ", "                FFFFGFFFF                ", "                   FGF                   ", "                   BEB                   ", "     A              B              A     ", "     A              B              A     ", "     A                             A     ", "     AA                           AA     ", "      A                           A      ", "      AA                         AA      ", "       A                         A       ", "        D                       D        ", "         D                     D         ", "          D                   D          ", "           AA               AA           ", "            AAA           AAA            ", "              AAAA     AAAA              ", "                                         ", "                                         ", "                                         ", "                                         ", "                                         ")
        .aisle("                                         ", "                                         ", "                                         ", "                                         ", "              AAAA     AAAA              ", "            AA             AA            ", "          DD                 DD          ", "         DD                   DD         ", "        DD                     DD        ", "       DD                       DD       ", "      DD                         DD      ", "      D                           D      ", "     A                             A     ", "     A                             A     ", "    A                               A    ", "    A                               A    ", "    A                               A    ", "    A                               A    ", "                    B                    ", "                BBBBBBBBB                ", "             FFFHHHHHHHHHFFF             ", "                BBBBBBBBB                ", "                    B                    ", "    A                               A    ", "    A                               A    ", "    A                               A    ", "    A                               A    ", "     A                             A     ", "     A                             A     ", "      D                           D      ", "      DD                         DD      ", "       DD                       DD       ", "        DD                     DD        ", "         DD                   DD         ", "          DD                 DD          ", "            AA             AA            ", "              AAAA     AAAA              ", "                                         ", "                                         ", "                                         ", "                                         ")
        .aisle("                                         ", "                                         ", "                                         ", "              AAAA     AAAA              ", "            AA             AA            ", "          DD                 DD          ", "         D                     D         ", "        D                       D        ", "       D                         D       ", "      D                           D      ", "     D                             D     ", "     D                             D     ", "    A                               A    ", "    A                               A    ", "   A                                 A   ", "   A                                 A   ", "   A                                 A   ", "   A                                 A   ", "                                         ", "             BBBB       BBBB             ", "           FFHHHIJJJJJJJIHHHFF           ", "             BBBB       BBBB             ", "                                         ", "   A                                 A   ", "   A                                 A   ", "   A                                 A   ", "   A                                 A   ", "    A                               A    ", "    A                               A    ", "     D                             D     ", "     D                             D     ", "      D                           D      ", "       D                         D       ", "        D                       D        ", "         D                     D         ", "          DD                 DD          ", "            AA             AA            ", "              AAAA     AAAA              ", "                                         ", "                                         ", "                                         ")
        .aisle("                                         ", "                                         ", "               AA       AA               ", "            AAA           AAA            ", "          DD                 DD          ", "         D                     D         ", "        D                       D        ", "       KL                       LK       ", "      DL                         LD      ", "     D                             D     ", "    D                               D    ", "    D                               D    ", "   A                                 A   ", "   A                                 A   ", "   A                                 A   ", "  A                                   A  ", "  A                                   A  ", "                                         ", "                                         ", "           BBB             BBB           ", "          FHHIJJJ       JJJIHHF          ", "           BBB             BBB           ", "                                         ", "                                         ", "  A                                   A  ", "  A                                   A  ", "   A                                 A   ", "   A                                 A   ", "   A                                 A   ", "    D                               D    ", "    D                               D    ", "     D                             D     ", "      DL                         LD      ", "       KL                       LK       ", "        D                       D        ", "         D                     D         ", "          DD                 DD          ", "            AAA           AAA            ", "               AA       AA               ", "                                         ", "                                         ")
        .aisle("                                         ", "                A       A                ", "             AAA         AAA             ", "           AA               AA           ", "         DD                   DD         ", "        D                       D        ", "       KL                       LK       ", "      KML                       LMK      ", "     DLLL                       LLLD     ", "    D                               D    ", "    D                               D    ", "   A                                 A   ", "   A                                 A   ", "  A                                   A  ", "  A                                   A  ", "  A                                   A  ", " A                                     A ", "                                         ", "        N                       N        ", "        CBBB                 BBBC        ", "        CFHIJJ             JJIHFC        ", "        CBBB                 BBBC        ", "        N                       N        ", "                                         ", " A                                     A ", "  A                                   A  ", "  A                                   A  ", "  A                                   A  ", "   A                                 A   ", "   A                                 A   ", "    D                               D    ", "    D                               D    ", "     DLLL                       LLLD     ", "      KML                       LMK      ", "       KL                       LK       ", "        D                       D        ", "         DD                   DD         ", "           AA               AA           ", "             AAA         AAA             ", "                A       A                ", "                                         ")
        .aisle("                                         ", "              AA         AA              ", "           AAA             AAA           ", "          D                   D          ", "        DD                     DD        ", "       D                         D       ", "      DL                         LD      ", "     DLLL                       LLLD     ", "    D  LML                     LML  D    ", "    D   LL                     LL   D    ", "   D                                 D   ", "  A                                   A  ", "  A                                   A  ", "  A                                   A  ", " A                                     A ", " A      I                       I      A ", "        O                       O        ", "        O                       O        ", "       NEN                     NEN       ", "       CGBB                   BBGC       ", "       CGHIJ                 JIHGC       ", "       CGBB                   BBGC       ", "       NEN                     NEN       ", "        O                       O        ", "        O                       O        ", " A      I                       I      A ", " A                                     A ", "  A                                   A  ", "  A                                   A  ", "  A                                   A  ", "   D                                 D   ", "    D   LL                     LL   D    ", "    D  LML                     LML  D    ", "     DLLL                       LLLD     ", "      DL                         LD      ", "       D                         D       ", "        DD                     DD        ", "          D                   D          ", "           AAA             AAA           ", "              AA         AA              ", "                                         ")
        .aisle("               A         A               ", "            AAA           AAA            ", "          AA                 AA          ", "         D                     D         ", "       DD                       DD       ", "      D                           D      ", "     D                             D     ", "    D                               D    ", "    D   LL                     LL   D    ", "   D    LML                   LML    D   ", "  A      LL                   LL      A  ", "  A                                   A  ", " A                                     A ", " A                                     A ", " A                                     A ", "A                                       A", "                                         ", "                                         ", "        N       PQQSSSQQP       N        ", "       BBB        SRRRS        BBB       ", "       FHIJ       SRRRS       JIHF       ", "       BBB        SRRRS        BBB       ", "        N       PQQS~SQQP       N        ", "                                         ", "                                         ", "A                                       A", " A                                     A ", " A                                     A ", " A                                     A ", "  A                                   A  ", "  A      LL                   LL      A  ", "   D    LML                   LML    D   ", "    D   LL                     LL   D    ", "    D                               D    ", "     D                             D     ", "      D                           D      ", "       DD                       DD       ", "         D                     D         ", "          AA                 AA          ", "            AAA           AAA            ", "               A         A               ")
        .aisle("             AA           AA             ", "           AA               AA           ", "         AA                   AA         ", "        D                       D        ", "      DD                         DD      ", "     D                             D     ", "    D                               D    ", "    D                               D    ", "   D                                 D   ", "  A      LL                   LL      A  ", "  A      LML                 LML      A  ", " A        L                   L        A ", " A                                     A ", "A                                       A", "A                                       A", "                                         ", "                                         ", "                                         ", "                 P     P                 ", "       BB      QQ       QQ      BB       ", "      FHIJ    P           P    JIHF      ", "       BB      QQ       QQ      BB       ", "                 P     P                 ", "                                         ", "                                         ", "                                         ", "A                                       A", "A                                       A", " A                                     A ", " A        L                   L        A ", "  A      LML                 LML      A  ", "  A      LL                   LL      A  ", "   D                                 D   ", "    D                               D    ", "    D                               D    ", "     D                             D     ", "      DD                         DD      ", "        D                       D        ", "         AA                   AA         ", "           AA               AA           ", "             AA           AA             ")
        .aisle("            AAA           AAA            ", "          AA                 AA          ", "        AA                     AA        ", "       A                         A       ", "      D                           D      ", "     D                             D     ", "    D                               D    ", "   A                                 A   ", "  A                                   A  ", "  A                                   A  ", " A        L                   L        A ", " A         L                 L         A ", "A                                       A", "A                                       A", "A                                       A", "                                         ", "                                         ", "                                         ", "                                         ", "      BB    F               F    BB      ", "     FHIJ   PQQP         PQQP   JIHF     ", "      BB    F               F    BB      ", "                                         ", "                                         ", "                                         ", "                                         ", "A                                       A", "A                                       A", "A                                       A", " A         L                 L         A ", " A        L                   L        A ", "  A                                   A  ", "  A                                   A  ", "   A                                 A   ", "    D                               D    ", "     D                             D     ", "      D                           D      ", "       A                         A       ", "        AA                     AA        ", "          AA                 AA          ", "            AAA           AAA            ")
        .aisle("           AAA             AAA           ", "         AA                   AA         ", "        A                       A        ", "      AA                         AA      ", "     A                             A     ", "    A                               A    ", "   A                                 A   ", "   A                                 A   ", "  A                                   A  ", " A                                     A ", " A                                     A ", "A                                       A", "A                                       A", "A                                       A", "                                         ", "                                         ", "                                         ", "            F               F            ", "            F               F            ", "      B    FHF             FHF    B      ", "     FHJ   PHI             IHP   JHF     ", "      B    FHF             FHF    B      ", "            F               F            ", "            F               F            ", "                                         ", "                                         ", "                                         ", "A                                       A", "A                                       A", "A                                       A", " A                                     A ", " A                                     A ", "  A                                   A  ", "   A                                 A   ", "   A                                 A   ", "    A                               A    ", "     A                             A     ", "      AA                         AA      ", "        A                       A        ", "         AA                   AA         ", "           AAA             AAA           ")
        .aisle("          AAA               AAA          ", "         A                     A         ", "       AA                       AA       ", "      A                           A      ", "     A                             A     ", "    A                               A    ", "   A                                 A   ", "  A                                   A  ", "  A                                   A  ", " A                                     A ", "A                                       A", "A                                       A", "A                                       A", "                                         ", "                                         ", "                                         ", "                                         ", "                                         ", "                                         ", "     BB     F               F     BB     ", "    FHIJ   QI               IQ   JIHF    ", "     BB     F               F     BB     ", "                                         ", "                                         ", "                                         ", "                                         ", "                                         ", "                                         ", "A                                       A", "A                                       A", "A                                       A", " A                                     A ", "  A                                   A  ", "  A                                   A  ", "   A                                 A   ", "    A                               A    ", "     A                             A     ", "      A                           A      ", "       AA                       AA       ", "         A                     A         ", "          AAA               AAA          ")
        .aisle("          AA                 AA          ", "        AA                     AA        ", "       A                         A       ", "     AA                           AA     ", "    A                               A    ", "   A                                 A   ", "   A                                 A   ", "  A                                   A  ", " A                                     A ", " A                                     A ", "A                                       A", "A                                       A", "                                         ", "                                         ", "                                         ", "                                         ", "                                         ", "                                         ", "                                         ", "     B                             B     ", "    FHJ   PQ                 QP   JHF    ", "     B                             B     ", "                                         ", "                                         ", "                                         ", "                                         ", "                                         ", "                                         ", "                                         ", "A                                       A", "A                                       A", " A                                     A ", " A                                     A ", "  A                                   A  ", "   A                                 A   ", "   A                                 A   ", "    A                               A    ", "     AA                           AA     ", "       A                         A       ", "        AA                     AA        ", "          AA                 AA          ")
        .aisle("         A                     A         ", "        A                       A        ", "      AA                         AA      ", "     A                             A     ", "    A                               A    ", "   A                                 A   ", "  A                                   A  ", "  A                                   A  ", " A                                     A ", "A                                       A", "                                         ", "                                         ", "                                         ", "                                         ", "                                         ", "                                         ", "                                         ", "                                         ", "                                         ", "     B    Q                   Q    B     ", "    FHJ    P                 P    JHF    ", "     B    Q                   Q    B     ", "                                         ", "                                         ", "                                         ", "                                         ", "                                         ", "                                         ", "                                         ", "                                         ", "                                         ", "A                                       A", " A                                     A ", "  A                                   A  ", "  A                                   A  ", "   A                                 A   ", "    A                               A    ", "     A                             A     ", "      AA                         AA      ", "        A                       A        ", "         A                     A         ")
        .aisle("                                         ", "       A                         A       ", "      A                           A      ", "     A                             A     ", "    A                               A    ", "   A                                 A   ", "  A                                   A  ", " A                                     A ", "                                         ", "                                         ", "                                         ", "                                         ", "                                         ", "                                         ", "                                         ", "                                         ", "                                         ", "                                         ", "         P                     P         ", "    BB    Q                   Q    BB    ", "   FHIJ                           JIHF   ", "    BB    Q                   Q    BB    ", "         P                     P         ", "                                         ", "                                         ", "                                         ", "                                         ", "                                         ", "                                         ", "                                         ", "                                         ", "                                         ", "                                         ", " A                                     A ", "  A                                   A  ", "   A                                 A   ", "    A                               A    ", "     A                             A     ", "      A                           A      ", "       A                         A       ", "                                         ")
        .aisle("                                         ", "                                         ", "                                         ", "     A                             A     ", "    A                               A    ", "   A                                 A   ", "                                         ", "                                         ", "                                         ", "                                         ", "                                         ", "                                         ", "                                         ", "                                         ", "                                         ", "                                         ", "                                         ", "                                         ", "         QP                   PQ         ", "    B                               B    ", "   FHJ                             JHF   ", "    B                               B    ", "         QP                   PQ         ", "                                         ", "                                         ", "                                         ", "                                         ", "                                         ", "                                         ", "                                         ", "                                         ", "                                         ", "                                         ", "                                         ", "                                         ", "   A                                 A   ", "    A                               A    ", "     A                             A     ", "                                         ", "                                         ", "                                         ")
        .aisle("                                         ", "                                         ", "                                         ", "                                         ", "                                         ", "                                         ", "                                         ", "                                         ", "                                         ", "                                         ", "                                         ", "                                         ", "                                         ", "                                         ", "                                         ", "                                         ", "                                         ", "                                         ", "         Q                     Q         ", "    B    D                     D    B    ", "   FHJ   D                     D   JHF   ", "    B    D                     D    B    ", "         Q                     Q         ", "                                         ", "                                         ", "                                         ", "                                         ", "                                         ", "                                         ", "                                         ", "                                         ", "                                         ", "                                         ", "                                         ", "                                         ", "                                         ", "                                         ", "                                         ", "                                         ", "                                         ", "                                         ")
        .aisle("                                         ", "                                         ", "                                         ", "                                         ", "                                         ", "                                         ", "                                         ", "                                         ", "                                         ", "                                         ", "                                         ", "                                         ", "                                         ", "                                         ", "                                         ", "                                         ", "                                         ", "                                         ", "   B     D                     D     B   ", "   FB    R                     R    BF   ", "   FHJ   R                     R   JHF   ", "   FB    R                     R    BF   ", "   B     D                     D     B   ", "                                         ", "                                         ", "                                         ", "                                         ", "                                         ", "                                         ", "                                         ", "                                         ", "                                         ", "                                         ", "                                         ", "                                         ", "                                         ", "                                         ", "                                         ", "                                         ", "                                         ", "                                         ")
        .aisle("                                         ", "                                         ", "                                         ", "                                         ", "                                         ", "                                         ", "                                         ", "                                         ", "                                         ", "                                         ", "                                         ", "                                         ", "                                         ", "                                         ", "                                         ", "                                         ", "   B                                 B   ", "   B                                 B   ", "  BEB    D                     D    BEB  ", "  CGB    R                     R    BGC  ", "  CGHJ   R                     R   JHGC  ", "  CGB    R                     R    BGC  ", "  BEB    D                     D    BEB  ", "   B                                 B   ", "   B                                 B   ", "                                         ", "                                         ", "                                         ", "                                         ", "                                         ", "                                         ", "                                         ", "                                         ", "                                         ", "                                         ", "                                         ", "                                         ", "                                         ", "                                         ", "                                         ", "                                         ")
        .aisle("                                         ", "                                         ", "                                         ", "                                         ", "                                         ", "                                         ", "                                         ", "                                         ", "                                         ", "                                         ", "                                         ", "                                         ", "                                         ", "                                         ", "                                         ", "                                         ", "                                         ", "                                         ", "   B     D                     D     B   ", "   FB    R                     R    BF   ", "   FHJ   R                     R   JHF   ", "   FB    R                     R    BF   ", "   B     D                     D     B   ", "                                         ", "                                         ", "                                         ", "                                         ", "                                         ", "                                         ", "                                         ", "                                         ", "                                         ", "                                         ", "                                         ", "                                         ", "                                         ", "                                         ", "                                         ", "                                         ", "                                         ", "                                         ")
        .aisle("                                         ", "                                         ", "                                         ", "                                         ", "                                         ", "                                         ", "                                         ", "                                         ", "                                         ", "                                         ", "                                         ", "                                         ", "                                         ", "                                         ", "                                         ", "                                         ", "                                         ", "                                         ", "         Q                     Q         ", "    B    D                     D    B    ", "   FHJ   D                     D   JHF   ", "    B    D                     D    B    ", "         Q                     Q         ", "                                         ", "                                         ", "                                         ", "                                         ", "                                         ", "                                         ", "                                         ", "                                         ", "                                         ", "                                         ", "                                         ", "                                         ", "                                         ", "                                         ", "                                         ", "                                         ", "                                         ", "                                         ")
        .aisle("                                         ", "                                         ", "                                         ", "     A                             A     ", "    A                               A    ", "   A                                 A   ", "                                         ", "                                         ", "                                         ", "                                         ", "                                         ", "                                         ", "                                         ", "                                         ", "                                         ", "                                         ", "                                         ", "                                         ", "         QP                   PQ         ", "    B                               B    ", "   FHJ                             JHF   ", "    B                               B    ", "         QP                   PQ         ", "                                         ", "                                         ", "                                         ", "                                         ", "                                         ", "                                         ", "                                         ", "                                         ", "                                         ", "                                         ", "                                         ", "                                         ", "   A                                 A   ", "    A                               A    ", "     A                             A     ", "                                         ", "                                         ", "                                         ")
        .aisle("                                         ", "       A                         A       ", "      A                           A      ", "     A                             A     ", "    A                               A    ", "   A                                 A   ", "  A                                   A  ", " A                                     A ", "                                         ", "                                         ", "                                         ", "                                         ", "                                         ", "                                         ", "                                         ", "                                         ", "                                         ", "                                         ", "         P                     P         ", "    BB    Q                   Q    BB    ", "   FHIJ                           JIHF   ", "    BB    Q                   Q    BB    ", "         P                     P         ", "                                         ", "                                         ", "                                         ", "                                         ", "                                         ", "                                         ", "                                         ", "                                         ", "                                         ", "                                         ", " A                                     A ", "  A                                   A  ", "   A                                 A   ", "    A                               A    ", "     A                             A     ", "      A                           A      ", "       A                         A       ", "                                         ")
        .aisle("         A                     A         ", "        A                       A        ", "      AA                         AA      ", "     A                             A     ", "    A                               A    ", "   A                                 A   ", "  A                                   A  ", "  A                                   A  ", " A                                     A ", "A                                       A", "                                         ", "                                         ", "                                         ", "                                         ", "                                         ", "                                         ", "                                         ", "                                         ", "                                         ", "     B    Q                   Q    B     ", "    FHJ    P                 P    JHF    ", "     B    Q                   Q    B     ", "                                         ", "                                         ", "                                         ", "                                         ", "                                         ", "                                         ", "                                         ", "                                         ", "                                         ", "A                                       A", " A                                     A ", "  A                                   A  ", "  A                                   A  ", "   A                                 A   ", "    A                               A    ", "     A                             A     ", "      AA                         AA      ", "        A                       A        ", "         A                     A         ")
        .aisle("          AA                 AA          ", "        AA                     AA        ", "       A                         A       ", "     AA                           AA     ", "    A                               A    ", "   A                                 A   ", "   A                                 A   ", "  A                                   A  ", " A                                     A ", " A                                     A ", "A                                       A", "A                                       A", "                                         ", "                                         ", "                                         ", "                                         ", "                                         ", "                                         ", "                                         ", "     B                             B     ", "    FHJ   PQ                 QP   JHF    ", "     B                             B     ", "                                         ", "                                         ", "                                         ", "                                         ", "                                         ", "                                         ", "                                         ", "A                                       A", "A                                       A", " A                                     A ", " A                                     A ", "  A                                   A  ", "   A                                 A   ", "   A                                 A   ", "    A                               A    ", "     AA                           AA     ", "       A                         A       ", "        AA                     AA        ", "          AA                 AA          ")
        .aisle("          AAA               AAA          ", "         A                     A         ", "       AA                       AA       ", "      A                           A      ", "     A                             A     ", "    A                               A    ", "   A                                 A   ", "  A                                   A  ", "  A                                   A  ", " A                                     A ", "A                                       A", "A                                       A", "A                                       A", "                                         ", "                                         ", "                                         ", "                                         ", "                                         ", "                                         ", "     BB     F               F     BB     ", "    FHIJ   QI               IQ   JIHF    ", "     BB     F               F     BB     ", "                                         ", "                                         ", "                                         ", "                                         ", "                                         ", "                                         ", "A                                       A", "A                                       A", "A                                       A", " A                                     A ", "  A                                   A  ", "  A                                   A  ", "   A                                 A   ", "    A                               A    ", "     A                             A     ", "      A                           A      ", "       AA                       AA       ", "         A                     A         ", "          AAA               AAA          ")
        .aisle("           AAA             AAA           ", "         AA                   AA         ", "        A                       A        ", "      AA                         AA      ", "     A                             A     ", "    A                               A    ", "   A                                 A   ", "   A                                 A   ", "  A                                   A  ", " A                                     A ", " A                                     A ", "A                                       A", "A                                       A", "A                                       A", "                                         ", "                                         ", "                                         ", "            F               F            ", "            F               F            ", "      B    FHF             FHF    B      ", "     FHJ   PHI             IHP   JHF     ", "      B    FHF             FHF    B      ", "            F               F            ", "            F               F            ", "                                         ", "                                         ", "                                         ", "A                                       A", "A                                       A", "A                                       A", " A                                     A ", " A                                     A ", "  A                                   A  ", "   A                                 A   ", "   A                                 A   ", "    A                               A    ", "     A                             A     ", "      AA                         AA      ", "        A                       A        ", "         AA                   AA         ", "           AAA             AAA           ")
        .aisle("            AAA           AAA            ", "          AA                 AA          ", "        AA                     AA        ", "       A                         A       ", "      D                           D      ", "     D                             D     ", "    D                               D    ", "   A                                 A   ", "  A                                   A  ", "  A                                   A  ", " A        L                   L        A ", " A         L                 L         A ", "A                                       A", "A                                       A", "A                                       A", "                                         ", "                                         ", "                                         ", "                                         ", "      BB    F               F    BB      ", "     FHIJ   PQQP         PQQP   JIHF     ", "      BB    F               F    BB      ", "                                         ", "                                         ", "                                         ", "                                         ", "A                                       A", "A                                       A", "A                                       A", " A         L                 L         A ", " A        L                   L        A ", "  A                                   A  ", "  A                                   A  ", "   A                                 A   ", "    D                               D    ", "     D                             D     ", "      D                           D      ", "       A                         A       ", "        AA                     AA        ", "          AA                 AA          ", "            AAA           AAA            ")
        .aisle("             AA           AA             ", "           AA               AA           ", "         AA                   AA         ", "        D                       D        ", "      DD                         DD      ", "     D                             D     ", "    D                               D    ", "    D                               D    ", "   D                                 D   ", "  A      LL                   LL      A  ", "  A      LML                 LML      A  ", " A        L                   L        A ", " A                                     A ", "A                                       A", "A                                       A", "                                         ", "                                         ", "                                         ", "                 P     P                 ", "       BB      QQ       QQ      BB       ", "      FHIJ    P           P    JIHF      ", "       BB      QQ       QQ      BB       ", "                 P     P                 ", "                                         ", "                                         ", "                                         ", "A                                       A", "A                                       A", " A                                     A ", " A        L                   L        A ", "  A      LML                 LML      A  ", "  A      LL                   LL      A  ", "   D                                 D   ", "    D                               D    ", "    D                               D    ", "     D                             D     ", "      DD                         DD      ", "        D                       D        ", "         AA                   AA         ", "           AA               AA           ", "             AA           AA             ")
        .aisle("               A         A               ", "            AAA           AAA            ", "          AA                 AA          ", "         D                     D         ", "       DD                       DD       ", "      D                           D      ", "     D                             D     ", "    D                               D    ", "    D   LL                     LL   D    ", "   D    LML                   LML    D   ", "  A      LL                   LL      A  ", "  A                                   A  ", " A                                     A ", " A                                     A ", " A                                     A ", "A                                       A", "                                         ", "                                         ", "        N       PQQDDDQQP       N        ", "       BBB        DRRRD        BBB       ", "       FHIJ       DRRRD       JIHF       ", "       BBB        DRRRD        BBB       ", "        N       PQQDDDQQP       N        ", "                                         ", "                                         ", "A                                       A", " A                                     A ", " A                                     A ", " A                                     A ", "  A                                   A  ", "  A      LL                   LL      A  ", "   D    LML                   LML    D   ", "    D   LL                     LL   D    ", "    D                               D    ", "     D                             D     ", "      D                           D      ", "       DD                       DD       ", "         D                     D         ", "          AA                 AA          ", "            AAA           AAA            ", "               A         A               ")
        .aisle("                                         ", "              AA         AA              ", "           AAA             AAA           ", "          D                   D          ", "        DD                     DD        ", "       D                         D       ", "      DL                         LD      ", "     DLLL                       LLLD     ", "    D  LML                     LML  D    ", "    D   LL                     LL   D    ", "   D                                 D   ", "  A                                   A  ", "  A                                   A  ", "  A                                   A  ", " A                                     A ", " A      I                       I      A ", "        O                       O        ", "        O                       O        ", "       NEN                     NEN       ", "       CGBB                   BBGC       ", "       CGHIJ                 JIHGC       ", "       CGBB                   BBGC       ", "       NEN                     NEN       ", "        O                       O        ", "        O                       O        ", " A      I                       I      A ", " A                                     A ", "  A                                   A  ", "  A                                   A  ", "  A                                   A  ", "   D                                 D   ", "    D   LL                     LL   D    ", "    D  LML                     LML  D    ", "     DLLL                       LLLD     ", "      DL                         LD      ", "       D                         D       ", "        DD                     DD        ", "          D                   D          ", "           AAA             AAA           ", "              AA         AA              ", "                                         ")
        .aisle("                                         ", "                A       A                ", "             AAA         AAA             ", "           AA               AA           ", "         DD                   DD         ", "        D                       D        ", "       KL                       LK       ", "      KML                       LMK      ", "     DLLL                       LLLD     ", "    D                               D    ", "    D                               D    ", "   A                                 A   ", "   A                                 A   ", "  A                                   A  ", "  A                                   A  ", "  A                                   A  ", " A                                     A ", "                                         ", "        N                       N        ", "        CBBB                 BBBC        ", "        CFHIJJ             JJIHFC        ", "        CBBB                 BBBC        ", "        N                       N        ", "                                         ", " A                                     A ", "  A                                   A  ", "  A                                   A  ", "  A                                   A  ", "   A                                 A   ", "   A                                 A   ", "    D                               D    ", "    D                               D    ", "     DLLL                       LLLD     ", "      KML                       LMK      ", "       KL                       LK       ", "        D                       D        ", "         DD                   DD         ", "           AA               AA           ", "             AAA         AAA             ", "                A       A                ", "                                         ")
        .aisle("                                         ", "                                         ", "               AA       AA               ", "            AAA           AAA            ", "          DD                 DD          ", "         D                     D         ", "        D                       D        ", "       KL                       LK       ", "      DL                         LD      ", "     D                             D     ", "    D                               D    ", "    D                               D    ", "   A                                 A   ", "   A                                 A   ", "   A                                 A   ", "  A                                   A  ", "  A                                   A  ", "                                         ", "                                         ", "           BBB             BBB           ", "          FHHIJJJ       JJJIHHF          ", "           BBB             BBB           ", "                                         ", "                                         ", "  A                                   A  ", "  A                                   A  ", "   A                                 A   ", "   A                                 A   ", "   A                                 A   ", "    D                               D    ", "    D                               D    ", "     D                             D     ", "      DL                         LD      ", "       KL                       LK       ", "        D                       D        ", "         D                     D         ", "          DD                 DD          ", "            AAA           AAA            ", "               AA       AA               ", "                                         ", "                                         ")
        .aisle("                                         ", "                                         ", "                                         ", "              AAAA     AAAA              ", "            AA             AA            ", "          DD                 DD          ", "         D                     D         ", "        D                       D        ", "       D                         D       ", "      D                           D      ", "     D                             D     ", "     D                             D     ", "    A                               A    ", "    A                               A    ", "   A                                 A   ", "   A                                 A   ", "   A                                 A   ", "   A                                 A   ", "                                         ", "             BBBB       BBBB             ", "           FFHHHIJJJJJJJIHHHFF           ", "             BBBB       BBBB             ", "                                         ", "   A                                 A   ", "   A                                 A   ", "   A                                 A   ", "   A                                 A   ", "    A                               A    ", "    A                               A    ", "     D                             D     ", "     D                             D     ", "      D                           D      ", "       D                         D       ", "        D                       D        ", "         D                     D         ", "          DD                 DD          ", "            AA             AA            ", "              AAAA     AAAA              ", "                                         ", "                                         ", "                                         ")
        .aisle("                                         ", "                                         ", "                                         ", "                                         ", "              AAAA     AAAA              ", "            AA             AA            ", "          DD                 DD          ", "         DD                   DD         ", "        DD                     DD        ", "       DD                       DD       ", "      DD                         DD      ", "      D                           D      ", "     A                             A     ", "     A                             A     ", "    A                               A    ", "    A                               A    ", "    A                               A    ", "    A                               A    ", "                    B                    ", "                BBBBBBBBB                ", "             FFFHHHHHHHHHFFF             ", "                BBBBBBBBB                ", "                    B                    ", "    A                               A    ", "    A                               A    ", "    A                               A    ", "    A                               A    ", "     A                             A     ", "     A                             A     ", "      D                           D      ", "      DD                         DD      ", "       DD                       DD       ", "        DD                     DD        ", "         DD                   DD         ", "          DD                 DD          ", "            AA             AA            ", "              AAAA     AAAA              ", "                                         ", "                                         ", "                                         ", "                                         ")
        .aisle("                                         ", "                                         ", "                                         ", "                                         ", "                                         ", "              AAAA     AAAA              ", "            AAA           AAA            ", "           AA               AA           ", "          D                   D          ", "         D                     D         ", "        D                       D        ", "       A                         A       ", "      AA                         AA      ", "      A                           A      ", "     AA                           AA     ", "     A                             A     ", "     A              B              A     ", "     A              B              A     ", "                   BEB                   ", "                   FGF                   ", "                FFFFGFFFF                ", "                   FGF                   ", "                   BEB                   ", "     A              B              A     ", "     A              B              A     ", "     A                             A     ", "     AA                           AA     ", "      A                           A      ", "      AA                         AA      ", "       A                         A       ", "        D                       D        ", "         D                     D         ", "          D                   D          ", "           AA               AA           ", "            AAA           AAA            ", "              AAAA     AAAA              ", "                                         ", "                                         ", "                                         ", "                                         ", "                                         ")
        .aisle("                                         ", "                                         ", "                                         ", "                                         ", "                                         ", "                                         ", "               AA       AA               ", "             AAA         AAA             ", "           AAA             AAA           ", "          AA                 AA          ", "         AA                   AA         ", "        AA                     AA        ", "        A                       A        ", "       AA                       AA       ", "       A                         A       ", "      AA                         AA      ", "      A                           A      ", "                                         ", "                    B                    ", "                    C                    ", "                    C                    ", "                    C                    ", "                    B                    ", "                                         ", "      A                           A      ", "      AA                         AA      ", "       A                         A       ", "       AA                       AA       ", "        A                       A        ", "        AA                     AA        ", "         AA                   AA         ", "          AA                 AA          ", "           AAA             AAA           ", "             AAA         AAA             ", "               AA       AA               ", "                                         ", "                                         ", "                                         ", "                                         ", "                                         ", "                                         ")
        .aisle("                                         ", "                                         ", "                                         ", "                                         ", "                                         ", "                                         ", "                                         ", "                A       A                ", "              AA         AA              ", "            AAA           AAA            ", "           AA               AA           ", "          AA                 AA          ", "         AA                   AA         ", "         A                     A         ", "        AA                     AA        ", "        A                       A        ", "       A                         A       ", "                                         ", "                                         ", "                                         ", "                                         ", "                                         ", "                                         ", "                                         ", "       A                         A       ", "        A                       A        ", "        AA                     AA        ", "         A                     A         ", "         AA                   AA         ", "          AA                 AA          ", "           AA               AA           ", "            AAA           AAA            ", "              AA         AA              ", "                A       A                ", "                                         ", "                                         ", "                                         ", "                                         ", "                                         ", "                                         ", "                                         ")
        .aisle("                                         ", "                                         ", "                                         ", "                                         ", "                                         ", "                                         ", "                                         ", "                                         ", "                                         ", "               A         A               ", "             AA           AA             ", "            AAA           AAA            ", "           AAA             AAA           ", "          AAA               AAA          ", "          AA                 AA          ", "         A                     A         ", "                                         ", "                                         ", "                                         ", "                                         ", "                                         ", "                                         ", "                                         ", "                                         ", "                                         ", "         A                     A         ", "          AA                 AA          ", "          AAA               AAA          ", "           AAA             AAA           ", "            AAA           AAA            ", "             AA           AA             ", "               A         A               ", "                                         ", "                                         ", "                                         ", "                                         ", "                                         ", "                                         ", "                                         ", "                                         ", "                                         ")
}