package com.gtladd.gtladditions.common.modify.multiblockMachine

import com.gregtechceu.gtceu.api.data.chemical.ChemicalHelper
import com.gregtechceu.gtceu.api.data.tag.TagPrefix
import com.gregtechceu.gtceu.api.machine.MultiblockMachineDefinition
import com.gregtechceu.gtceu.api.machine.multiblock.PartAbility
import com.gregtechceu.gtceu.api.pattern.FactoryBlockPattern
import com.gregtechceu.gtceu.api.pattern.Predicates
import com.gregtechceu.gtceu.common.data.GCyMBlocks
import com.gregtechceu.gtceu.common.data.GTBlocks
import com.gregtechceu.gtceu.common.data.GTMaterials
import com.gtladd.gtladditions.api.machine.GTLAddPartAbility
import org.gtlcore.gtlcore.common.data.GTLBlocks
import org.gtlcore.gtlcore.utils.Registries
import java.util.function.Function

@Suppress("DuplicatedCode")
object CoilMultiRecipeMultiBlocks {

    val MEGA_WIREMILL = Function { definition: MultiblockMachineDefinition ->
        FactoryBlockPattern.start()
            .aisle("  AAA  ", "  AAA  ", "       ", "  BBB  ", "  BBB  ", "  BBB  ", "       ")
            .aisle("  AAA  ", "  AAA  ", "  AAA  ", "  BBB  ", "  BBB  ", "  BBB  ", "       ")
            .aisle("  AAA  ", "       ", "  CCC  ", " CDDDC ", " CDEDC ", " CDDDC ", "  CCC  ")
            .aisle("  AAA  ", "       ", "  CCC  ", " CDDDC ", " CDEDC ", " CDDDC ", "  CCC  ")
            .aisle("AAAAAAA", "       ", "  CCC  ", " CDDDC ", " CDEDC ", " CDDDC ", "  CCC  ")
            .aisle("AAAAAAA", " F   F ", " FGGGF ", " GHHHG ", " GHEHG ", " GHHHG ", "  GGG  ")
            .aisle("AAAAAAA", "       ", "       ", "  HHH  ", "  HEH  ", "  HHH  ", "       ")
            .aisle("AAAAAAA", " F   F ", " FGGGF ", " GHHHG ", " GHEHG ", " GHHHG ", "  GGG  ")
            .aisle("AAAAAAA", "       ", "       ", "  HHH  ", "  HEH  ", "  HHH  ", "       ")
            .aisle("AAAAAAA", " F   F ", " FGGGF ", " GHHHG ", " GHEHG ", " GHHHG ", "  GGG  ")
            .aisle("AAAAAAA", "       ", "       ", "  HHH  ", "  HEH  ", "  HHH  ", "       ")
            .aisle("AAAAAAA", " F   F ", " FGGGF ", " GHHHG ", " GHEHG ", " GHHHG ", "  GGG  ")
            .aisle("AAAAAAA", "       ", "       ", "  HHH  ", "  HEH  ", "  HHH  ", "       ")
            .aisle("AAAAAAA", " F   F ", " FGGGF ", " GHHHG ", " GHEHG ", " GHHHG ", "  GGG  ")
            .aisle("AAAAAAA", "       ", "       ", "  HHH  ", "  HEH  ", "  HHH  ", "       ")
            .aisle("AAAAAAA", " F   F ", " FGGGF ", " GHHHG ", " GHEHG ", " GHHHG ", "  GGG  ")
            .aisle("AAAAAAA", "       ", "       ", "  HHH  ", "  HEH  ", "  HHH  ", "       ")
            .aisle("AAAAAAA", " F   F ", " FGGGF ", " GHHHG ", " GHEHG ", " GHHHG ", "  GGG  ")
            .aisle("AAAAAAA", "       ", "       ", "  HHH  ", "  HEH  ", "  HHH  ", "       ")
            .aisle("AAAAAAA", " F   F ", " FGGGF ", " GHHHG ", " GHEHG ", " GHHHG ", "  GGG  ")
            .aisle("AAAAAAA", "       ", "       ", "  HHH  ", "  HEH  ", "  HHH  ", "       ")
            .aisle("AAAAAAA", " F   F ", " FGGGF ", " GHHHG ", " GHEHG ", " GHHHG ", "  GGG  ")
            .aisle("AAAAAAA", "       ", "       ", "  HHH  ", "  HEH  ", "  HHH  ", "       ")
            .aisle("AAAAAAA", " F   F ", " FGGGF ", " GHHHG ", " GHEHG ", " GHHHG ", "  GGG  ")
            .aisle("AAAAAAA", "       ", "       ", "  HHH  ", "  HEH  ", "  HHH  ", "       ")
            .aisle("  AAA  ", "  AAA  ", "  AAA  ", "  III  ", "  III  ", "  III  ", "       ")
            .aisle("  AAA  ", "  A~A  ", "  AAA  ", "       ", "       ", "       ", "       ")
            .where("~", Predicates.controller(Predicates.blocks(definition.get())))
            .where("A", Predicates.blocks(GTLBlocks.OXIDATION_RESISTANT_HASTELLOY_N_MECHANICAL_CASING.get())
                .or(Predicates.abilities(PartAbility.INPUT_ENERGY).setMaxGlobalLimited(2))
                .or(Predicates.abilities(PartAbility.MAINTENANCE).setExactLimit(1))
                .or(Predicates.abilities(PartAbility.INPUT_LASER).setMaxGlobalLimited(1))
                .or(Predicates.abilities(PartAbility.IMPORT_ITEMS).setPreviewCount(1))
                .or(Predicates.abilities(PartAbility.EXPORT_ITEMS).setPreviewCount(1))
                .or(Predicates.abilities(GTLAddPartAbility.THREAD_MODIFIER).setMaxGlobalLimited(1)))
            .where("B", Predicates.blocks(GTLBlocks.IRIDIUM_CASING.get()))
            .where("C", Predicates.blocks(GTLBlocks.IRIDIUM_CASING.get()))
            .where("D", Predicates.blocks(GTLBlocks.HYPER_MECHANICAL_CASING.get()))
            .where("E", Predicates.blocks(Registries.getBlock("kubejs:hollow_casing")))
            .where("F", Predicates.blocks(ChemicalHelper.getBlock(TagPrefix.frameGt, GTMaterials.Naquadria)))
            .where("G", Predicates.blocks(GTBlocks.CASING_INVAR_HEATPROOF.get()))
            .where("H", Predicates.heatingCoils())
            .where("I", Predicates.blocks(GTBlocks.CASING_INVAR_HEATPROOF.get()))
            .where(" ", Predicates.any())
            .build()
    }

    val MEGA_PRESSER = Function { definition: MultiblockMachineDefinition ->
        FactoryBlockPattern.start()
            .aisle("     AAAAA     ", "   AABBCBBAA   ", "  ABBBBCBBBBA  ", " ABBBBBCBBBBBA ", " ABBBBBCBBBBBA ", "ABBBBBCCCBBBBBA", "ABBBBCCCCCBBBBA", "ACCCCCCCCCCCCCA", "ABBBBCCCCCBBBBA", "ABBBBBCCCBBBBBA", " ABBBBBCBBBBBA ", " ABBBBBCBBBBBA ", "  ABBBBCBBBBA  ", "   AABBCBBAA   ", "     AAAAA     ")
            .aisle("       A       ", "     BBBBB     ", "   BBDDDDDBB   ", "  BDDDDDDDDDB  ", "  BDDD   DDDB  ", " BDDD     DDDB ", " BDD   E   DDB ", "ABDD  EEE  DDBA", " BDD   E   DDB ", " BDDD     DDDB ", "  BDDD   DDDB  ", "  BDDDDDDDDDB  ", "   BBDDDDDBB   ", "     BBBBB     ", "       A       ")
            .aisle("       A       ", "     BBBBB     ", "   BBDDDDDBB   ", "  BDDDDDDDDDB  ", "  BDDD   DDDB  ", " BDDD     DDDB ", " BDD   E   DDB ", "ABDD  EEE  DDBA", " BDD   E   DDB ", " BDDD     DDDB ", "  BDDD   DDDB  ", "  BDDDDDDDDDB  ", "   BBDDDDDBB   ", "     BBBBB     ", "       A       ")
            .aisle("       A       ", "     BBBBB     ", "   BBDDDDDBB   ", "  BDDDDDDDDDB  ", "  BDDD   DDDB  ", " BDDD     DDDB ", " BDD   E   DDB ", "ABDD  EEE  DDBA", " BDD   E   DDB ", " BDDD     DDDB ", "  BDDD   DDDB  ", "  BDDDDDDDDDB  ", "   BBDDDDDBB   ", "     BBBBB     ", "       A       ")
            .aisle("     AAAAA     ", "   AABBBBBAA   ", "  ABB     BBA  ", " AB         BA ", " AB         BA ", "AB           BA", "AB     E     BA", "AB    EEE    BA", "AB     E     BA", "AB           BA", " AB         BA ", " AB         BA ", "  ABB     BBA  ", "   AABBBBBAA   ", "     AAAAA     ")
            .aisle("       A       ", "     FFFFF     ", "   FF     FF   ", "  F         F  ", "  F         F  ", " F           F ", " F     E     F ", "AF    EEE    FA", " F     E     F ", " F           F ", "  F         F  ", "  F         F  ", "   FF     FF   ", "     FFFFF     ", "       A       ")
            .aisle("       A       ", "     FFFFF     ", "   FF     FF   ", "  F         F  ", "  F         F  ", " F           F ", " F     E     F ", "AF    EEE    FA", " F     E     F ", " F           F ", "  F         F  ", "  F         F  ", "   FF     FF   ", "     FFFFF     ", "       A       ")
            .aisle("       A       ", "     FFFFF     ", "   FF     FF   ", "  F         F  ", "  F         F  ", " F           F ", " F     E     F ", "AF    EEE    FA", " F     E     F ", " F           F ", "  F         F  ", "  F         F  ", "   FF     FF   ", "     FFFFF     ", "       A       ")
            .aisle("     AAAAA     ", "   AAFFFFFAA   ", "  AFF     FFA  ", " AF         FA ", " AF   GGG   FA ", "AF   G   G   FA", "AF  G  E  G  FA", "AF  G EEE G  FA", "AF  G  E  G  FA", "AF   G   G   FA", " AF   GGG   FA ", " AF         FA ", "  AFF     FFA  ", "   AAFFFFFAA   ", "     AAAAA     ")
            .aisle("       A       ", "     FFFFF     ", "   FF     FF   ", "  F         F  ", "  F         F  ", " F           F ", " F     E     F ", "AF    EEE    FA", " F     E     F ", " F           F ", "  F         F  ", "  F         F  ", "   FF     FF   ", "     FFFFF     ", "       A       ")
            .aisle("       A       ", "     FFFFF     ", "   FF     FF   ", "  F         F  ", "  F   GGG   F  ", " F   G   G   F ", " F  G BBB G  F ", "AF  G BBB G  FA", " F  G BBB G  F ", " F   G   G   F ", "  F   GGG   F  ", "  F         F  ", "   FF     FF   ", "     FFFFF     ", "       A       ")
            .aisle("       A       ", "     FFFFF     ", "   FF     FF   ", "  F         F  ", "  F         F  ", " F           F ", " F           F ", "AF           FA", " F           F ", " F           F ", "  F         F  ", "  F         F  ", "   FF     FF   ", "     FFFFF     ", "       A       ")
            .aisle("       A       ", "     FFFFF     ", "   FF     FF   ", "  F         F  ", "  F         F  ", " F           F ", " F           F ", "AF           FA", " F           F ", " F           F ", "  F         F  ", "  F         F  ", "   FF     FF   ", "     FFFFF     ", "       A       ")
            .aisle("       A       ", "     FFFFF     ", "   FF     FF   ", "  F         F  ", "  F         F  ", " F           F ", " F           F ", "AF           FA", " F           F ", " F           F ", "  F         F  ", "  F         F  ", "   FF     FF   ", "     FFFFF     ", "       A       ")
            .aisle("       A       ", "     FFFFF     ", "   FF     FF   ", "  F         F  ", "  F   GGG   F  ", " F   G   G   F ", " F  G BBB G  F ", "AF  G BBB G  FA", " F  G BBB G  F ", " F   G   G   F ", "  F   GGG   F  ", "  F         F  ", "   FF     FF   ", "     FFFFF     ", "       A       ")
            .aisle("       A       ", "     FFFFF     ", "   FF     FF   ", "  F         F  ", "  F         F  ", " F           F ", " F     E     F ", "AF    EEE    FA", " F     E     F ", " F           F ", "  F         F  ", "  F         F  ", "   FF     FF   ", "     FFFFF     ", "       A       ")
            .aisle("     AAAAA     ", "   AAFFFFFAA   ", "  AFF     FFA  ", " AF         FA ", " AF   GGG   FA ", "AF   G   G   FA", "AF  G  E  G  FA", "AF  G EEE G  FA", "AF  G  E  G  FA", "AF   G   G   FA", " AF   GGG   FA ", " AF         FA ", "  AFF     FFA  ", "   AAFFFFFAA   ", "     AAAAA     ")
            .aisle("       A       ", "     FFFFF     ", "   FF     FF   ", "  F         F  ", "  F         F  ", " F           F ", " F     E     F ", "AF    EEE    FA", " F     E     F ", " F           F ", "  F         F  ", "  F         F  ", "   FF     FF   ", "     FFFFF     ", "       A       ")
            .aisle("       A       ", "     FFFFF     ", "   FF     FF   ", "  F         F  ", "  F         F  ", " F           F ", " F     E     F ", "AF    EEE    FA", " F     E     F ", " F           F ", "  F         F  ", "  F         F  ", "   FF     FF   ", "     FFFFF     ", "       A       ")
            .aisle("       A       ", "     FFFFF     ", "   FF     FF   ", "  F         F  ", "  F         F  ", " F           F ", " F     E     F ", "AF    EEE    FA", " F     E     F ", " F           F ", "  F         F  ", "  F         F  ", "   FF     FF   ", "     FFFFF     ", "       A       ")
            .aisle("     AAAAA     ", "   AABBBBBAA   ", "  ABB     BBA  ", " AB         BA ", " AB         BA ", "AB           BA", "AB     E     BA", "AB    EEE    BA", "AB     E     BA", "AB           BA", " AB         BA ", " AB         BA ", "  ABB     BBA  ", "   AABBBBBAA   ", "     AAAAA     ")
            .aisle("       A       ", "     BBBBB     ", "   BBDDDDDBB   ", "  BDDDDDDDDDB  ", "  BDDD   DDDB  ", " BDDD     DDDB ", " BDD   E   DDB ", "ABDD  EEE  DDBA", " BDD   E   DDB ", " BDDD     DDDB ", "  BDDD   DDDB  ", "  BDDDDDDDDDB  ", "   BBDDDDDBB   ", "     BBBBB     ", "       A       ")
            .aisle("       A       ", "     BBBBB     ", "   BBDDDDDBB   ", "  BDDDDDDDDDB  ", "  BDDD   DDDB  ", " BDDD     DDDB ", " BDD   E   DDB ", "ABDD  EEE  DDBA", " BDD   E   DDB ", " BDDD     DDDB ", "  BDDD   DDDB  ", "  BDDDDDDDDDB  ", "   BBDDDDDBB   ", "     BBBBB     ", "       A       ")
            .aisle("       A       ", "     BBBBB     ", "   BBDDDDDBB   ", "  BDDDDDDDDDB  ", "  BDDD   DDDB  ", " BDDD     DDDB ", " BDD   E   DDB ", "ABDD  EEE  DDBA", " BDD   E   DDB ", " BDDD     DDDB ", "  BDDD   DDDB  ", "  BDDDDDDDDDB  ", "   BBDDDDDBB   ", "     BBBBB     ", "       A       ")
            .aisle("     AAAAA     ", "   AABBCBBAA   ", "  ABBBBCBBBBA  ", " ABBBBBCBBBBBA ", " ABBBBBCBBBBBA ", "ABBBBBCCCBBBBBA", "ABBBBCCCCCBBBBA", "ACCCCCC~CCCCCCA", "ABBBBCCCCCBBBBA", "ABBBBBCCCBBBBBA", " ABBBBBCBBBBBA ", " ABBBBBCBBBBBA ", "  ABBBBCBBBBA  ", "   AABBCBBAA   ", "     AAAAA     ")
            .where("~", Predicates.controller(Predicates.blocks(definition.get())))
            .where("A", Predicates.blocks(GTLBlocks.MOLECULAR_CASING.get()))
            .where("B", Predicates.blocks(GTLBlocks.IRIDIUM_CASING.get()))
            .where("C", Predicates.blocks(GTLBlocks.MOLECULAR_CASING.get())
                .or(Predicates.abilities(PartAbility.INPUT_ENERGY).setMaxGlobalLimited(2))
                .or(Predicates.abilities(PartAbility.MAINTENANCE).setExactLimit(1))
                .or(Predicates.abilities(PartAbility.INPUT_LASER).setMaxGlobalLimited(1))
                .or(Predicates.abilities(PartAbility.IMPORT_ITEMS).setMaxGlobalLimited(16))
                .or(Predicates.abilities(PartAbility.EXPORT_ITEMS).setMaxGlobalLimited(16))
                .or(Predicates.abilities(GTLAddPartAbility.THREAD_MODIFIER).setMaxGlobalLimited(1)))
            .where("D", Predicates.blocks(GTBlocks.SUPERCONDUCTING_COIL.get()))
            .where("E", Predicates.blocks(GTBlocks.CASING_ASSEMBLY_LINE.get()))
            .where("F", Predicates.blocks(GTBlocks.CASING_TEMPERED_GLASS.get()))
            .where("G", Predicates.heatingCoils())
            .where(" ", Predicates.any())
            .build()
    }

    val MEGA_EXTRACTOR = Function { definition: MultiblockMachineDefinition ->
        FactoryBlockPattern.start()
            .aisle("      AAA      ", "               ", "               ", "               ", "               ", "               ", "               ", "               ", "               ", "               ", "               ", "               ", "               ", "               ", "               ", "               ", "               ", "               ", "               ", "               ")
            .aisle("    AAAAAAA    ", "      AAA      ", "      B B      ", "      B B      ", "      B B      ", "      B B      ", "      B B      ", "      B B      ", "      B B      ", "      B B      ", "      B B      ", "      B B      ", "      B B      ", "      B B      ", "      B B      ", "      B B      ", "      B B      ", "      B B      ", "      B B      ", "      AAA      ")
            .aisle("   AAAAAAAAA   ", "    AAAAAAA    ", "               ", "               ", "               ", "               ", "               ", "               ", "               ", "               ", "               ", "               ", "               ", "               ", "               ", "               ", "               ", "               ", "               ", "      AAA      ")
            .aisle("  AAAAAAAAAAA  ", "   AAAAAAAAA   ", "               ", "               ", "               ", "               ", "               ", "               ", "               ", "               ", "               ", "               ", "               ", "               ", "               ", "               ", "               ", "               ", "               ", "      AAA      ")
            .aisle(" AAAAAAAAAAAAA ", "  AAAAAAAAAAA  ", "               ", "               ", "               ", "               ", "               ", "               ", "               ", "       C       ", "      CCC      ", "       C       ", "               ", "               ", "               ", "               ", "               ", "               ", "               ", "     AAAAA     ")
            .aisle(" AAAAAAAAAAAAA ", "  AAAAAAAAAAA  ", "       D       ", "       D       ", "       D       ", "       D       ", "               ", "               ", "      CCC      ", "     CC CC     ", "     C   C     ", "     CC CC     ", "      CCC      ", "               ", "               ", "       D       ", "       D       ", "       D       ", "       D       ", "    AAAAAAA    ")
            .aisle("AAAAAAAAAAAAAAA", " AAAAAAAAAAAAA ", " B    DED    B ", " B    DED    B ", " B    DED    B ", " B    DED    B ", " B     E     B ", " B     C     B ", " B   CC CC   B ", " B   C   C   B ", " B  C     C  B ", " B   C   C   B ", " B   CC CC   B ", " B     C     B ", " B     E     B ", " B    DED    B ", " B    DED    B ", " B    DED    B ", " B    DED    B ", " AAAAAAAAAAAAA ")
            .aisle("AAAAAAAAAAAAAAA", " AAAAAAAAAAAAA ", "     DEFED     ", "     DEFED     ", "     DEFED     ", "     DEFED     ", "      EFE      ", "      CFC      ", "     C   C     ", "    C     C    ", "    C     C    ", "    C     C    ", "     C   C     ", "      CFC      ", "      EFE      ", "     DEFED     ", "     DEFED     ", "     DEFED     ", "     DEFED     ", " AAAAAAAAAAAAA ")
            .aisle("AAAAAAAAAAAAAAA", " AAAAAAAAAAAAA ", " B    DED    B ", " B    DED    B ", " B    DED    B ", " B    DED    B ", " B     E     B ", " B     C     B ", " B   CC CC   B ", " B   C   C   B ", " B  C     C  B ", " B   C   C   B ", " B   CC CC   B ", " B     C     B ", " B     E     B ", " B    DED    B ", " B    DED    B ", " B    DED    B ", " B    DED    B ", " AAAAAAAAAAAAA ")
            .aisle(" AAAAAAAAAAAAA ", "  AAAAAAAAAAA  ", "       D       ", "       D       ", "       D       ", "       D       ", "               ", "               ", "      CCC      ", "     CC CC     ", "     C   C     ", "     CC CC     ", "      CCC      ", "               ", "               ", "       D       ", "       D       ", "       D       ", "       D       ", "    AAAAAAA    ")
            .aisle(" AAAAAAAAAAAAA ", "  AAAAAAAAAAA  ", "               ", "               ", "               ", "               ", "               ", "               ", "               ", "       C       ", "      CCC      ", "       C       ", "               ", "               ", "               ", "               ", "               ", "               ", "               ", "     AAAAA     ")
            .aisle("  AAAAAAAAAAA  ", "   AAAAAAAAA   ", "               ", "               ", "               ", "               ", "               ", "               ", "               ", "               ", "               ", "               ", "               ", "               ", "               ", "               ", "               ", "               ", "               ", "      AAA      ")
            .aisle("   AAAAAAAAA   ", "    AAAAAAA    ", "               ", "               ", "               ", "               ", "               ", "               ", "               ", "               ", "               ", "               ", "               ", "               ", "               ", "               ", "               ", "               ", "               ", "      AAA      ")
            .aisle("    AAAAAAA    ", "      AAA      ", "      B B      ", "      B B      ", "      B B      ", "      B B      ", "      B B      ", "      B B      ", "      B B      ", "      B B      ", "      B B      ", "      B B      ", "      B B      ", "      B B      ", "      B B      ", "      B B      ", "      B B      ", "      B B      ", "      B B      ", "      AAA      ")
            .aisle("      AAA      ", "      A~A      ", "               ", "               ", "               ", "               ", "               ", "               ", "               ", "               ", "               ", "               ", "               ", "               ", "               ", "               ", "               ", "               ", "               ", "               ")
            .where("~", Predicates.controller(Predicates.blocks(definition.get())))
            .where("A", Predicates.blocks(GTLBlocks.HYPER_MECHANICAL_CASING.get())
                .or(Predicates.autoAbilities(*definition.recipeTypes))
                .or(Predicates.abilities(PartAbility.MAINTENANCE).setExactLimit(1))
                .or(Predicates.abilities(PartAbility.INPUT_LASER).setMaxGlobalLimited(1))
                .or(Predicates.abilities(GTLAddPartAbility.THREAD_MODIFIER).setMaxGlobalLimited(1)))
            .where("B", Predicates.blocks(ChemicalHelper.getBlock(TagPrefix.frameGt, GTMaterials.NaquadahAlloy)))
            .where("C", Predicates.blocks(GTLBlocks.IRIDIUM_CASING.get()))
            .where("D", Predicates.heatingCoils())
            .where("E", Predicates.blocks(GTLBlocks.MOLECULAR_CASING.get()))
            .where("F", Predicates.blocks(GTBlocks.CASING_TUNGSTENSTEEL_PIPE.get()))
            .where(" ", Predicates.any())
            .build()
    }

    val MEGA_FLUID_HEATER = Function { definition: MultiblockMachineDefinition ->
        FactoryBlockPattern.start()
            .aisle("           ", "           ", "           ", "   AAAAA   ", "   BBBBB   ", "   BBBBB   ", "   AAAAA   ", "           ", "           ", "           ", "           ", "           ", "           ", "           ", "           ", "           ", "           ")
            .aisle("           ", "   AAAAA   ", "   AAAAA   ", "  ACCCCCA  ", "  B     B  ", "  B     B  ", "  ACCCCCA  ", "   AAAAA   ", "           ", "           ", "           ", "           ", "           ", "           ", "           ", "           ", "           ")
            .aisle("   AAAAA   ", "  ACCCCCA  ", "  ACCCCCA  ", " ACDDDDDCA ", " B       B ", " B       B ", " AC     CA ", "  ACCCCCA  ", "   AAAAA   ", "           ", "           ", "           ", "           ", "           ", "    EEE    ", "    EEE    ", "           ")
            .aisle("  AAAAAAA  ", " ACCCCCCCA ", " ACDDDDDCA ", "ACD FFF DCA", "B   F F   B", "B   F F   B", "AC  F F  CA", " AC FFF CA ", "  A FFF A  ", "   AAAAA   ", "    ABA    ", "    ABA    ", "    ABA    ", "    EEE    ", "   EGGGE   ", "   EGGGE   ", "    GGG    ")
            .aisle("  AAAAAAA  ", " ACCCCCCCA ", " ACDHHHDCA ", "ACDFHHHFDCA", "B  FHHHF  B", "B  FHHHF  B", "AC FHHHF CA", " ACFHHHFCA ", "  AFHHHFA  ", "   AHHHA   ", "   A   A   ", "   A   A   ", "   A   A   ", "   EGGGE   ", "  EGGGGGE  ", "  EGGGGGE  ", "   GGGGG   ")
            .aisle("  AAAAAAA  ", " ACCCCCCCA ", " ACDH HDCA ", "ACDFH HFDCA", "B   H H   B", "B   H H   B", "AC  H H  CA", " ACFH HFCA ", "  AFH HFA  ", "   AH HA   ", "   B   B   ", "   B   B   ", "   B   B   ", "   EGGGE   ", "  EGGGGGE  ", "  EGGGGGE  ", "   GGGGG   ")
            .aisle("  AAAAAAA  ", " ACCCCCCCA ", " ACDHHHDCA ", "ACDFHHHFDCA", "B  FHHHF  B", "B  FHHHF  B", "AC FHHHF CA", " ACFHHHFCA ", "  AFHHHFA  ", "   AHHHA   ", "   A   A   ", "   A   A   ", "   A   A   ", "   EGGGE   ", "  EGGGGGE  ", "  EGGGGGE  ", "   GGGGG   ")
            .aisle("  AAAAAAA  ", " ACCCCCCCA ", " ACDDDDDCA ", "ACD FFF DCA", "B   F F   B", "B   F F   B", "AC  F F  CA", " AC FFF CA ", "  A FFF A  ", "   AAAAA   ", "    ABA    ", "    ABA    ", "    ABA    ", "    EEE    ", "   EGGGE   ", "   EGGGE   ", "    GGG    ")
            .aisle("   AAAAA   ", "  ACCCCCA  ", "  ACCCCCA  ", " ACDDDDDCA ", " B       B ", " B       B ", " AC     CA ", "  ACCCCCA  ", "   AAAAA   ", "           ", "           ", "           ", "           ", "           ", "    EEE    ", "    EEE    ", "    E~E    ")
            .aisle("           ", "   AAAAA   ", "   AAAAA   ", "  ACCCCCA  ", "  B     B  ", "  B     B  ", "  ACCCCCA  ", "   AAAAA   ", "           ", "           ", "           ", "           ", "           ", "           ", "           ", "           ", "           ")
            .aisle("           ", "           ", "           ", "   AAAAA   ", "   BBBBB   ", "   BBBBB   ", "   AAAAA   ", "           ", "           ", "           ", "           ", "           ", "           ", "           ", "           ", "           ", "           ")
            .where("~", Predicates.controller(Predicates.blocks(definition.get())))
            .where("G", Predicates.blocks(GTBlocks.HIGH_POWER_CASING.get()))
            .where("A", Predicates.blocks(GTLBlocks.MOLECULAR_CASING.get()))
            .where("H", Predicates.heatingCoils())
            .where("D", Predicates.blocks(GTLBlocks.ENHANCE_HYPER_MECHANICAL_CASING.get()))
            .where("B", Predicates.blocks(GTLBlocks.RHENIUM_REINFORCED_ENERGY_GLASS.get()))
            .where("C", Predicates.blocks(GTLBlocks.ANTIFREEZE_HEATPROOF_MACHINE_CASING.get()))
            .where("F", Predicates.blocks(GTBlocks.HERMETIC_CASING_UHV.get()))
            .where("E", Predicates.blocks(GTLBlocks.IRIDIUM_CASING.get())
                .or(Predicates.autoAbilities(*definition.recipeTypes))
                .or(Predicates.abilities(PartAbility.MAINTENANCE).setExactLimit(1))
                .or(Predicates.abilities(PartAbility.INPUT_LASER).setMaxGlobalLimited(1))
                .or(Predicates.abilities(GTLAddPartAbility.THREAD_MODIFIER).setMaxGlobalLimited(1)))
            .where(" ", Predicates.any())
            .build()
    }

    val ADVANCED_MULTI_SMELTER = Function { definition: MultiblockMachineDefinition ->
        FactoryBlockPattern.start()
                    .aisle("XXX", "CCC", "XXX")
                    .aisle("XXX", "C#C", "XMX")
                    .aisle("XSX", "CCC", "XXX")
                    .where('S', Predicates.controller(Predicates.blocks(definition.get())))
                    .where('X', Predicates.blocks(GTBlocks.CASING_INVAR_HEATPROOF.get()).setMinGlobalLimited(9)
                            .or(Predicates.autoAbilities(*definition.recipeTypes))
                            .or(Predicates.abilities(PartAbility.INPUT_LASER))
                            .or(Predicates.autoAbilities(true, false, false))
                            .or(Predicates.abilities(GTLAddPartAbility.THREAD_MODIFIER).setMaxGlobalLimited(1)))
                    .where('M', Predicates.abilities(PartAbility.MUFFLER))
                    .where('C', Predicates.heatingCoils())
                    .where('#', Predicates.air())
                    .build()
    }

    val SUPER_BLAST_SMELTER =  Function { definition: MultiblockMachineDefinition ->
        FactoryBlockPattern.start()
            .aisle("aaaaaaaaaaaaaaaaaaaaaaa", "aaaaaaaaaaaaaaaaaaaaaaa", "                       ", "                       ", "                       ", "                       ", "                       ", "                       ", "                       ", "                       ", "                       ", "                       ", "                       ", "                       ", "                       ", "                       ", "                       ", "                       ", "                       ", "                       ", "                       ", "                       ", "                       ", "                       ", "                       ", "                       ", "                       ", "                       ", "                       ", "                       ", "                       ", "                       ", "                       ", "                       ", "                       ", "                       ", "                       ", "                       ", "                       ", "                       ", "                       ", "                       ")
            .aisle("accccccccccccccccccccca", "aaaaaaaaaaaaaaaaaaaaaaa", "                       ", "                       ", "                       ", "                       ", "                       ", "                       ", "                       ", "                       ", "                       ", "                       ", "                       ", "                       ", "                       ", "                       ", "                       ", "                       ", "                       ", "                       ", "                       ", "                       ", "                       ", "                       ", "                       ", "                       ", "                       ", "                       ", "                       ", "                       ", "                       ", "                       ", "                       ", "                       ", "                       ", "                       ", "                       ", "                       ", "                       ", "                       ", "                       ", "                       ")
            .aisle("accccccccccccccccccccca", "aaaaaaaaaaaaaaaaaaaaaaa", "  d                 d  ", "  d                 d  ", "  d                 d  ", "  ddddddddddddddddddd  ", "  d                 d  ", "  d                 d  ", "  d                 d  ", "  ddddddddddddddddddd  ", "                       ", "                       ", "                       ", "                       ", "                       ", "                       ", "                       ", "                       ", "                       ", "                       ", "                       ", "                       ", "                       ", "                       ", "                       ", "                       ", "                       ", "                       ", "                       ", "                       ", "                       ", "                       ", "                       ", "                       ", "                       ", "                       ", "                       ", "                       ", "                       ", "                       ", "                       ", "                       ")
            .aisle("accccccccccccccccccccca", "aaacccccccccccccccccaaa", "   ceeeeeeeeeeeeeeec   ", "   cfffffffffffffffc   ", "   ceeeeeeeeeeeeeeec   ", "  dcccccccccccccccccd  ", "   g               g   ", "   g               g   ", "   g               g   ", "  dgcccccccccccccccgd  ", "   g               g   ", "   g               g   ", "   g               g   ", "   g               g   ", "   g               g   ", "   g               g   ", "   ggggggggggggggggg   ", "                       ", "                       ", "                       ", "                       ", "                       ", "                       ", "                       ", "                       ", "                       ", "                       ", "                       ", "                       ", "                       ", "                       ", "                       ", "                       ", "                       ", "                       ", "                       ", "                       ", "                       ", "                       ", "                       ", "                       ", "                       ")
            .aisle("accccccccccccccccccccca", "aaacccccccccccccccccaaa", "   ehhhhhhhhhhhhhhhe   ", "   fiiiiiiijiiiiiiif   ", "   ekkkkkkkkkkkkkkke   ", "  dcccccccccccccccccd  ", "    ceeeeeeeeeeeeec    ", "    clllllllllllllc    ", "    ceeeeeeeeeeeeec    ", "  dcccccccccccccccccd  ", "     ccccccccccccc     ", "                       ", "                       ", "                       ", "                       ", "                       ", "   ggcccccccccccccgg   ", "    g             g    ", "    g             g    ", "    g             g    ", "    g             g    ", "    g             g    ", "    g             g    ", "    g             g    ", "    g             g    ", "    g             g    ", "    g             g    ", "    ggggggggggggggg    ", "                       ", "                       ", "                       ", "                       ", "                       ", "                       ", "                       ", "                       ", "                       ", "                       ", "                       ", "                       ", "                       ", "                       ")
            .aisle("accccccccccccccccccccca", "aaacccccccccccccccccaaa", "   ehhhhhhhhhhhhhhhe   ", "   fiiiiiiijiiiiiiif   ", "   ekkkkkkkkkkkkkkke   ", "  dccmmmmmmmmmmmmmccd  ", "    ennnnnnnnnnnnne    ", "    loooooopooooool    ", "    eqqqqqqqqqqqqqe    ", "  dccrrrrrrrrrrrrrccd  ", "    ccccccccccccccc    ", "     csssssssssssc     ", "     csssssssssssc     ", "     ceeeeeeeeeeec     ", "     csssssssssssc     ", "     csssssssssssc     ", "   gcccccccccccccccg   ", "      eeeeeeeeeee      ", "                       ", "                       ", "                       ", "                       ", "                       ", "                       ", "                       ", "                       ", "                       ", "    ggcccccccccccgg    ", "     gg         gg     ", "                       ", "                       ", "                       ", "                       ", "                       ", "                       ", "                       ", "                       ", "                       ", "                       ", "                       ", "                       ", "     ccccccccccccc     ")
            .aisle("accccccccccccccccccccca", "aaacccccccccccccccccaaa", "   ehhhhhhhhhhhhhhhe   ", "   fiiiiiiijiiiiiiif   ", "   ekkkkkkkkkkkkkkke   ", "  dccmmmmmmmmmmmmmccd  ", "    ennnnnnnnnnnnne    ", "    loooooopooooool    ", "    eqqqqqqqqqqqqqe    ", "  dccrrrrrrrrrrrrrccd  ", "    cc           cc    ", "     s           s     ", "     s           s     ", "     e           e     ", "     s           s     ", "     s           s     ", "   gcc           ccg   ", "     eccccccccccce     ", "      csssssssssc      ", "      csssssssssc      ", "      csssssssssc      ", "      csssssssssc      ", "      csssssssssc      ", "      csssssssssc      ", "      csssssssssc      ", "      csssssssssc      ", "      csssssssssc      ", "    gcccccccccccccg    ", "     ggeeeeeeeeegg     ", "      g         g      ", "      g         g      ", "      g         g      ", "      g         g      ", "      g         g      ", "      g         g      ", "      g         g      ", "      g         g      ", "      g         g      ", "      g         g      ", "      g         g      ", "      ggggggggggg      ", "     ccccccccccccc     ")
            .aisle("accccccccccccccccccccca", "aaacccccccccccccccccaaa", "   ehhhhhhhhhhhhhhhe   ", "   fiiiiiiijiiiiiiif   ", "   ekkkkkkkkkkkkkkke   ", "  dccmmmmmmmmmmmmmccd  ", "    ennnnnnnnnnnnne    ", "    loooooopooooool    ", "    eqqqqqqqqqqqqqe    ", "  dccrrrrrrrrrrrrrccd  ", "    cc           cc    ", "     s           s     ", "     s           s     ", "     e           e     ", "     s           s     ", "     s           s     ", "   gcc           ccg   ", "     ec         ce     ", "      s         s      ", "      s         s      ", "      s         s      ", "      s         s      ", "      s         s      ", "      s         s      ", "      s         s      ", "      s         s      ", "      s         s      ", "    gcc         ccg    ", "      eccccccccce      ", "       csssssssc       ", "       csssssssc       ", "       csssssssc       ", "       csssssssc       ", "       csssssssc       ", "       csssssssc       ", "       csssssssc       ", "       csssssssc       ", "       csssssssc       ", "       csssssssc       ", "       ceeeeeeec       ", "      gcccccccccg      ", "     ccccccccccccc     ")
            .aisle("accccccccccccccccccccca", "aaacccccccccccccccccaaa", "   ehhhhhhhhhhhhhhhe   ", "   fiiiiiiijiiiiiiif   ", "   ekkkkkkkkkkkkkkke   ", "  dccmmmmmmmmmmmmmccd  ", "    ennnnnnnnnnnnne    ", "    loooooopooooool    ", "    eqqqqqqqqqqqqqe    ", "  dccrrrrrrrrrrrrrccd  ", "    cc           cc    ", "     s           s     ", "     s           s     ", "     e           e     ", "     s           s     ", "     s           s     ", "   gcc           ccg   ", "     ec         ce     ", "      s         s      ", "      s         s      ", "      s         s      ", "      s         s      ", "      s         s      ", "      s         s      ", "      s         s      ", "      s         s      ", "      s         s      ", "    gcc         ccg    ", "      ec       ce      ", "       s       s       ", "       s       s       ", "       s       s       ", "       s       s       ", "       s       s       ", "       s       s       ", "       s       s       ", "       s       s       ", "       s       s       ", "       s       s       ", "       e       e       ", "      gc       cg      ", "     ccccccccccccc     ")
            .aisle("accccccccccccccccccccca", "aaacccccccccccccccccaaa", "   ehhhhhhhhhhhhhhhe   ", "   fiiiiiiijiiiiiiif   ", "   ekkkkkkkkkkkkkkke   ", "  dccmmmmmmmmmmmmmccd  ", "    ennnnnnnnnnnnne    ", "    loooooopooooool    ", "    eqqqqqqqqqqqqqe    ", "  dccrrrrrrrrrrrrrccd  ", "    cc     r     cc    ", "     s     r     s     ", "     s     r     s     ", "     e     r     e     ", "     s     r     s     ", "     s     r     s     ", "   gcc     r     ccg   ", "     ec    r    ce     ", "      s         s      ", "      s         s      ", "      s         s      ", "      s         s      ", "      s         s      ", "      s         s      ", "      s         s      ", "      s         s      ", "      s         s      ", "    gcc         ccg    ", "      ec       ce      ", "       s       s       ", "       s       s       ", "       s       s       ", "       s       s       ", "       s       s       ", "       s       s       ", "       s       s       ", "       s       s       ", "       s       s       ", "       s       s       ", "       e       e       ", "      gc       cg      ", "     ccccccccccccc     ")
            .aisle("accccccccccccccccccccca", "aaacccccccccccccccccaaa", "   ehhhhhhhhhhhhhhhe   ", "   fiiiiiiijiiiiiiif   ", "   ekkkkkkkkkkkkkkke   ", "  dccmmmmmmmmmmmmmccd  ", "    ennnnnnnnnnnnne    ", "    loooooopooooool    ", "    eqqqqqqqqqqqqqe    ", "  dccrrrrrrrrrrrrrccd  ", "    cc           cc    ", "     s           s     ", "     s           s     ", "     e           e     ", "     s           s     ", "     s           s     ", "   gcc           ccg   ", "     ec    r    ce     ", "      s    r    s      ", "      s    r    s      ", "      s    r    s      ", "      s    r    s      ", "      s    r    s      ", "      s    r    s      ", "      s    r    s      ", "      s    r    s      ", "      s    r    s      ", "    gcc    r    ccg    ", "      ec   r   ce      ", "       s       s       ", "       s       s       ", "       s       s       ", "       s       s       ", "       s       s       ", "       s       s       ", "       s       s       ", "       s       s       ", "       s       s       ", "       s       s       ", "       e       e       ", "      gc   r   cg      ", "     cccccctcccccc     ")
            .aisle("accccccccccccccccccccca", "aaacccccccccccccccccaaa", "   ehhhhhhhhhhhhhhhe   ", "   fjjjjjjjjjjjjjjjf   ", "   ekkkkkkkkkkkkkkke   ", "  dccmmmmmmmmmmmmmccd  ", "    ennnnnnnnnnnnne    ", "    lpppppppppppppl    ", "    eqqqqqqqqqqqqqe    ", "  dccrrrrrrrrrrrrrccd  ", "    cc   r r r   cc    ", "     s   r r r   s     ", "     s   r r r   s     ", "     e   r r r   e     ", "     s   r r r   s     ", "     s   r r r   s     ", "   gcc   r r r   ccg   ", "     ec  rrrrr  ce     ", "      s   r r   s      ", "      s   r r   s      ", "      s   r r   s      ", "      s   r r   s      ", "      s   r r   s      ", "      s   r r   s      ", "      s   r r   s      ", "      s   r r   s      ", "      s   r r   s      ", "    gcc   r r   ccg    ", "      ec  rrr  ce      ", "       s   r   s       ", "       s   r   s       ", "       s   r   s       ", "       s   r   s       ", "       s   r   s       ", "       s   r   s       ", "       s   r   s       ", "       s   r   s       ", "       s   r   s       ", "       s   r   s       ", "       e   r   e       ", "      gc  rrr  cg      ", "     ccccctttccccc     ")
            .aisle("accccccccccccccccccccca", "aaacccccccccccccccccaaa", "   ehhhhhhhhhhhhhhhe   ", "   fiiiiiiijiiiiiiif   ", "   ekkkkkkkkkkkkkkke   ", "  dccmmmmmmmmmmmmmccd  ", "    ennnnnnnnnnnnne    ", "    loooooopooooool    ", "    eqqqqqqqqqqqqqe    ", "  dccrrrrrrrrrrrrrccd  ", "    cc           cc    ", "     s           s     ", "     s           s     ", "     e           e     ", "     s           s     ", "     s           s     ", "   gcc           ccg   ", "     ec    r    ce     ", "      s    r    s      ", "      s    r    s      ", "      s    r    s      ", "      s    r    s      ", "      s    r    s      ", "      s    r    s      ", "      s    r    s      ", "      s    r    s      ", "      s    r    s      ", "    gcc    r    ccg    ", "      ec   r   ce      ", "       s       s       ", "       s       s       ", "       s       s       ", "       s       s       ", "       s       s       ", "       s       s       ", "       s       s       ", "       s       s       ", "       s       s       ", "       s       s       ", "       e       e       ", "      gc   r   cg      ", "     cccccctcccccc     ")
            .aisle("accccccccccccccccccccca", "aaacccccccccccccccccaaa", "   ehhhhhhhhhhhhhhhe   ", "   fiiiiiiijiiiiiiif   ", "   ekkkkkkkkkkkkkkke   ", "  dccmmmmmmmmmmmmmccd  ", "    ennnnnnnnnnnnne    ", "    loooooopooooool    ", "    eqqqqqqqqqqqqqe    ", "  dccrrrrrrrrrrrrrccd  ", "    cc     r     cc    ", "     s     r     s     ", "     s     r     s     ", "     e     r     e     ", "     s     r     s     ", "     s     r     s     ", "   gcc     r     ccg   ", "     ec    r    ce     ", "      s         s      ", "      s         s      ", "      s         s      ", "      s         s      ", "      s         s      ", "      s         s      ", "      s         s      ", "      s         s      ", "      s         s      ", "    gcc         ccg    ", "      ec       ce      ", "       s       s       ", "       s       s       ", "       s       s       ", "       s       s       ", "       s       s       ", "       s       s       ", "       s       s       ", "       s       s       ", "       s       s       ", "       s       s       ", "       e       e       ", "      gc       cg      ", "     ccccccccccccc     ")
            .aisle("accccccccccccccccccccca", "aaacccccccccccccccccaaa", "   ehhhhhhhhhhhhhhhe   ", "   fiiiiiiijiiiiiiif   ", "   ekkkkkkkkkkkkkkke   ", "  dccmmmmmmmmmmmmmccd  ", "    ennnnnnnnnnnnne    ", "    loooooopooooool    ", "    eqqqqqqqqqqqqqe    ", "  dccrrrrrrrrrrrrrccd  ", "    cc           cc    ", "     s           s     ", "     s           s     ", "     e           e     ", "     s           s     ", "     s           s     ", "   gcc           ccg   ", "     ec         ce     ", "      s         s      ", "      s         s      ", "      s         s      ", "      s         s      ", "      s         s      ", "      s         s      ", "      s         s      ", "      s         s      ", "      s         s      ", "    gcc         ccg    ", "      ec       ce      ", "       s       s       ", "       s       s       ", "       s       s       ", "       s       s       ", "       s       s       ", "       s       s       ", "       s       s       ", "       s       s       ", "       s       s       ", "       s       s       ", "       e       e       ", "      gc       cg      ", "     ccccccccccccc     ")
            .aisle("accccccccccccccccccccca", "aaacccccccccccccccccaaa", "   ehhhhhhhhhhhhhhhe   ", "   fiiiiiiijiiiiiiif   ", "   ekkkkkkkkkkkkkkke   ", "  dccmmmmmmmmmmmmmccd  ", "    ennnnnnnnnnnnne    ", "    loooooopooooool    ", "    eqqqqqqqqqqqqqe    ", "  dccrrrrrrrrrrrrrccd  ", "    cc           cc    ", "     s           s     ", "     s           s     ", "     e           e     ", "     s           s     ", "     s           s     ", "   gcc           ccg   ", "     ec         ce     ", "      s         s      ", "      s         s      ", "      s         s      ", "      s         s      ", "      s         s      ", "      s         s      ", "      s         s      ", "      s         s      ", "      s         s      ", "    gcc         ccg    ", "      eccccccccce      ", "       csssssssc       ", "       csssssssc       ", "       csssssssc       ", "       csssssssc       ", "       csssssssc       ", "       csssssssc       ", "       csssssssc       ", "       csssssssc       ", "       csssssssc       ", "       csssssssc       ", "       ceeeeeeec       ", "      gcccccccccg      ", "     ccccccccccccc     ")
            .aisle("accccccccccccccccccccca", "aaacccccccccccccccccaaa", "   ehhhhhhhhhhhhhhhe   ", "   fiiiiiiijiiiiiiif   ", "   ekkkkkkkkkkkkkkke   ", "  dccmmmmmmmmmmmmmccd  ", "    ennnnnnnnnnnnne    ", "    loooooopooooool    ", "    eqqqqqqqqqqqqqe    ", "  dccrrrrrrrrrrrrrccd  ", "    cc           cc    ", "     s           s     ", "     s           s     ", "     e           e     ", "     s           s     ", "     s           s     ", "   gcc           ccg   ", "     eccccccccccce     ", "      csssssssssc      ", "      csssssssssc      ", "      csssssssssc      ", "      csssssssssc      ", "      csssssssssc      ", "      csssssssssc      ", "      csssssssssc      ", "      csssssssssc      ", "      csssssssssc      ", "    gcccccccccccccg    ", "     ggeeeeeeeeegg     ", "      g         g      ", "      g         g      ", "      g         g      ", "      g         g      ", "      g         g      ", "      g         g      ", "      g         g      ", "      g         g      ", "      g         g      ", "      g         g      ", "      g         g      ", "      ggggggggggg      ", "     ccccccccccccc     ")
            .aisle("accccccccccccccccccccca", "aaacccccccccccccccccaaa", "   ehhhhhhhhhhhhhhhe   ", "   fiiiiiiijiiiiiiif   ", "   ekkkkkkkkkkkkkkke   ", "  dccmmmmmmmmmmmmmccd  ", "    ennnnnnnnnnnnne    ", "    loooooopooooool    ", "    eqqqqqqqqqqqqqe    ", "  dccrrrrrrrrrrrrrccd  ", "    ccccccccccccccc    ", "     csssssssssssc     ", "     csssssssssssc     ", "     ceeeeeeeeeeec     ", "     csssssssssssc     ", "     csssssssssssc     ", "   gcccccccccccccccg   ", "      eeeeeeeeeee      ", "                       ", "                       ", "                       ", "                       ", "                       ", "                       ", "                       ", "                       ", "                       ", "    ggcccccccccccgg    ", "     gg         gg     ", "                       ", "                       ", "                       ", "                       ", "                       ", "                       ", "                       ", "                       ", "                       ", "                       ", "                       ", "                       ", "     ccccccccccccc     ")
            .aisle("accccccccccccccccccccca", "aaacccccccccccccccccaaa", "   ehhhhhhhhhhhhhhhe   ", "   fiiiiiiijiiiiiiif   ", "   ekkkkkkkkkkkkkkke   ", "  dcccccccccccccccccd  ", "    ceeeeeeeeeeeeec    ", "    clllllllllllllc    ", "    ceeeeeeeeeeeeec    ", "  dcccccccccccccccccd  ", "     ccccccccccccc     ", "                       ", "                       ", "                       ", "                       ", "                       ", "   ggcccccccccccccgg   ", "    g             g    ", "    g             g    ", "    g             g    ", "    g             g    ", "    g             g    ", "    g             g    ", "    g             g    ", "    g             g    ", "    g             g    ", "    g             g    ", "    ggggggggggggggg    ", "                       ", "                       ", "                       ", "                       ", "                       ", "                       ", "                       ", "                       ", "                       ", "                       ", "                       ", "                       ", "                       ", "                       ")
            .aisle("accccccccccccccccccccca", "aaacccccccccccccccccaaa", "   ceeeeeeeeeeeeeeec   ", "   cfffffffffffffffc   ", "   ceeeeeeeeeeeeeeec   ", "  dcccccccccccccccccd  ", "   g               g   ", "   g               g   ", "   g               g   ", "  dgcccccccccccccccgd  ", "   g               g   ", "   g               g   ", "   g               g   ", "   g               g   ", "   g               g   ", "   g               g   ", "   ggggggggggggggggg   ", "                       ", "                       ", "                       ", "                       ", "                       ", "                       ", "                       ", "                       ", "                       ", "                       ", "                       ", "                       ", "                       ", "                       ", "                       ", "                       ", "                       ", "                       ", "                       ", "                       ", "                       ", "                       ", "                       ", "                       ", "                       ")
            .aisle("accccccccccccccccccccca", "aaaaaaaaaaaaaaaaaaaaaaa", "  d                 d  ", "  d                 d  ", "  d                 d  ", "  ddddddddddddddddddd  ", "  d                 d  ", "  d                 d  ", "  d                 d  ", "  ddddddddddddddddddd  ", "                       ", "                       ", "                       ", "                       ", "                       ", "                       ", "                       ", "                       ", "                       ", "                       ", "                       ", "                       ", "                       ", "                       ", "                       ", "                       ", "                       ", "                       ", "                       ", "                       ", "                       ", "                       ", "                       ", "                       ", "                       ", "                       ", "                       ", "                       ", "                       ", "                       ", "                       ", "                       ")
            .aisle("accccccccccccccccccccca", "aaaaaaaaaaaaaaaaaaaaaaa", "                       ", "                       ", "                       ", "                       ", "                       ", "                       ", "                       ", "                       ", "                       ", "                       ", "                       ", "                       ", "                       ", "                       ", "                       ", "                       ", "                       ", "                       ", "                       ", "                       ", "                       ", "                       ", "                       ", "                       ", "                       ", "                       ", "                       ", "                       ", "                       ", "                       ", "                       ", "                       ", "                       ", "                       ", "                       ", "                       ", "                       ", "                       ", "                       ", "                       ")
            .aisle("aaaaaaaaaaaaaaaaaaaaaaa", "aaaaaaaaaaabaaaaaaaaaaa", "                       ", "                       ", "                       ", "                       ", "                       ", "                       ", "                       ", "                       ", "                       ", "                       ", "                       ", "                       ", "                       ", "                       ", "                       ", "                       ", "                       ", "                       ", "                       ", "                       ", "                       ", "                       ", "                       ", "                       ", "                       ", "                       ", "                       ", "                       ", "                       ", "                       ", "                       ", "                       ", "                       ", "                       ", "                       ", "                       ", "                       ", "                       ", "                       ", "                       ")
            .where("b", Predicates.controller(Predicates.blocks(definition.get())))
            .where("a", Predicates.blocks(GCyMBlocks.CASING_HIGH_TEMPERATURE_SMELTING.get()).setMinGlobalLimited(300)
                .or(Predicates.abilities(PartAbility.PARALLEL_HATCH).setMaxGlobalLimited(1).setPreviewCount(0))
                .or(Predicates.abilities(PartAbility.EXPORT_ITEMS).setPreviewCount(0))
                .or(Predicates.abilities(PartAbility.IMPORT_ITEMS).setPreviewCount(0))
                .or(Predicates.abilities(PartAbility.EXPORT_FLUIDS).setPreviewCount(0))
                .or(Predicates.abilities(PartAbility.IMPORT_FLUIDS).setPreviewCount(0))
                .or(Predicates.abilities(PartAbility.INPUT_ENERGY).setMaxGlobalLimited(2).setPreviewCount(1))
                .or(Predicates.abilities(PartAbility.MAINTENANCE).setExactLimit(1))
                .or(Predicates.abilities(PartAbility.INPUT_LASER).setMaxGlobalLimited(1).setPreviewCount(0))
                .or(Predicates.abilities(GTLAddPartAbility.THREAD_MODIFIER).setMaxGlobalLimited(1)))
            .where("c", Predicates.blocks(GCyMBlocks.CASING_HIGH_TEMPERATURE_SMELTING.get()))
            .where("d", Predicates.blocks(ChemicalHelper.getBlock(TagPrefix.frameGt, GTMaterials.Tungsten)))
            .where("e", Predicates.blocks(GCyMBlocks.HEAT_VENT.get()))
            .where("f", Predicates.blocks(GTBlocks.CASING_ENGINE_INTAKE.get()))
            .where("g", Predicates.blocks(ChemicalHelper.getBlock(TagPrefix.frameGt, GTMaterials.NaquadahAlloy)))
            .where("h", Predicates.blocks(GTBlocks.FIREBOX_BRONZE.get()))
            .where("i", Predicates.blocks(GTBlocks.CASING_BRONZE_PIPE.get()))
            .where("j", Predicates.blocks(GTBlocks.CASING_POLYTETRAFLUOROETHYLENE_PIPE.get()))
            .where("k", Predicates.blocks(GTBlocks.FIREBOX_STEEL.get()))
            .where("l", Predicates.blocks(GTBlocks.CASING_EXTREME_ENGINE_INTAKE.get()))
            .where("m", Predicates.blocks(GTBlocks.CASING_STEEL_PIPE.get()))
            .where("n", Predicates.blocks(GTBlocks.FIREBOX_TITANIUM.get()))
            .where("o", Predicates.blocks(GTBlocks.CASING_TITANIUM_PIPE.get()))
            .where("p", Predicates.blocks(Registries.getBlock("kubejs:neutronium_pipe_casing")))
            .where("q", Predicates.blocks(GTBlocks.FIREBOX_TUNGSTENSTEEL.get()))
            .where("r", Predicates.blocks(GTBlocks.CASING_TUNGSTENSTEEL_PIPE.get()))
            .where("s", Predicates.heatingCoils())
            .where("t", Predicates.abilities(PartAbility.MUFFLER))
            .where(" ", Predicates.any())
            .build()
    }
}