package com.gtladd.gtladditions.common.modify.multiblockMachine

import com.gregtechceu.gtceu.api.data.chemical.ChemicalHelper
import com.gregtechceu.gtceu.api.data.tag.TagPrefix
import com.gregtechceu.gtceu.api.machine.MultiblockMachineDefinition
import com.gregtechceu.gtceu.api.machine.multiblock.PartAbility
import com.gregtechceu.gtceu.api.pattern.FactoryBlockPattern
import com.gregtechceu.gtceu.api.pattern.Predicates
import com.gregtechceu.gtceu.api.pattern.util.RelativeDirection
import com.gregtechceu.gtceu.common.data.GTBlocks
import com.gregtechceu.gtceu.common.data.GTMaterials
import com.gtladd.gtladditions.api.machine.GTLAddPartAbility
import net.minecraft.world.level.block.Blocks
import org.gtlcore.gtlcore.common.data.GTLBlocks
import org.gtlcore.gtlcore.common.data.GTLMaterials
import org.gtlcore.gtlcore.utils.Registries
import java.util.function.Function

@Suppress("DuplicatedCode")
object MutableMultiBlocksB {
    val HUGE_INCUBATOR = Function { definition: MultiblockMachineDefinition ->
        FactoryBlockPattern.start()
            .aisle("   ABBBBBA   CCC   ABBBBBA   ", "   AAAAAAA   CCC   AAAAAAA   ", "   A     A   CDC   A     A   ", "             CDC             ", "             CDC             ", "             CCC             ", "             CCC             ", "                             ", "                             ", "                             ", "                             ", "                             ", "                             ", "                             ", "                             ", "                             ", "                             ", "                             ", "                             ", "                             ", "                             ", "                             ", "                             ", "                             ", "                             ", "                             ")
            .aisle(" EEEEEEEEEEEEEEEEEEEEEEEEEEE ", "  AAAAAAAAAEECCCEEAAAAAAAAA  ", "   A     A EEC CEE A     A   ", "   AAAAAAA   C C   AAAAAAA   ", "   A     A   C C   A     A   ", "             C C             ", "             CFC             ", "                             ", "                             ", "                             ", "                             ", "                             ", "                             ", "                             ", "                             ", "                             ", "                             ", "                             ", "                             ", "                             ", "                             ", "                             ", "                             ", "                             ", "                             ", "                             ")
            .aisle(" EEEEEEEEEEEE E EEEEEEEEEEEE ", " AAAAAAAAAAAECCCEAAAAAAAAAAA ", "  GABBBBBAG EC CE GABBBBBAG  ", "  GAHHHHHAG EC CE GAHHHHHAG  ", "  GA     AG EC CE GA     AG  ", "  GAAAAAAAG  C C  GAAAAAAAG  ", "  G       G  CFC  G       G  ", "  I       I   J   I       I  ", "     HHH      J      HHH     ", "    HHHHH     J     HHHHH    ", "    HHHHH     J     HHHHH    ", "    HHHHH           HHHHH    ", "    HHHHH           HHHHH    ", "    HHHHH           HHHHH    ", "    KKKKK           KKKKK    ", "    HHHHH           HHHHH    ", "    HHHHH           HHHHH    ", "    HHHHH           HHHHH    ", "    HHHHH           HHHHH    ", "    HHHHH           HHHHH    ", "                             ", "                             ", "                             ", "                             ", "                             ", "                             ")
            .aisle("AEEEEEEEEEEEE E EEEEEEEEEEEEA", "AAAAAAAAAAAAECCCEAAAAAAAAAAAA", "AAAA     AAAEC CEAAA     AAAA", " AAAAAAAAAAAEC CEAAAAAAAAAAA ", " AAABBBBBAAAEC CEAAABBBBBAAA ", "  AAA   AAA EC CE AAA   AAA  ", "            ECFCE            ", "     HHH             HHH     ", "    HHHHH           HHHHH    ", "   HH   HH         HH   HH   ", "   HH   HH    J    HH   HH   ", "   HH   HH         HH   HH   ", "   HH   HH         HH   HH   ", "   HH   HH         HH   HH   ", "   KK   KK         KK   KK   ", "   HH   HH         HH   HH   ", "   HH   HH         HH   HH   ", "   HH   HH         HH   HH   ", "   HH   HH         HH   HH   ", "   HHHHHHH         HHHHHHH   ", "    HHHHH           HHHHH    ", "                             ", "                             ", "                             ", "                             ", "                             ")
            .aisle("BEEEEEEEEEEEE E EEEEEEEEEEEEB", "AAAAAAAAAAAAECCCEAAAAAAAAAAAA", "  B       B EC CE B       B  ", " AHA     AHAEC CEAHA     AHA ", "   B     B  EC CE  B     B   ", "  AA     AA EC CE AA     AA  ", "     HHH    ECCCE    HHH     ", "    HHHHH   ECCCE   HHHHH    ", "   H     H  ECCCE  H     H   ", "  HH     HH  CCC  HH     HH  ", "  HH     HH   J   HH     HH  ", "  HH     HH       HH     HH  ", "  HH     HH       HH     HH  ", "  HH     HH       HH     HH  ", "  KK     KK       KK     KK  ", "  HH     HH       HH     HH  ", "  HH     HH       HH     HH  ", "  HH     HH       HH     HH  ", "  HH     HH       HH     HH  ", "  HHH   HHH       HHH   HHH  ", "   HHHHHHH         HHHHHHH   ", "    HHHHH           HHHHH    ", "                             ", "                             ", "                             ", "                             ")
            .aisle("BEEEEEEEEEEEE E EEEEEEEEEEEEB", "AAAAAAAAAAAAECCCEAAAAAAAAAAAA", "  B  L L  B EC CE B  L L  B  ", " AHA L L AHAEC CEAHA L L AHA ", "   B L L B  EC CE  B L L B   ", "  A  HHH  A EC CE A  HHH  A  ", "    HHHHH   EC CE   HHHHH    ", "   HHMMMHH  EC CE  HHMMMHH   ", "  HH     HH EC CE HH     HH  ", "  H       H  CCC  H       H  ", "  H       H   J   H       H  ", "  H       H       H       H  ", "  H       H       H       H  ", "  H       H       H       H  ", "  K       K       K       K  ", "  H       H       H       H  ", "  H       H       H       H  ", "  H       H       H       H  ", "  H       H       H       H  ", "  HH     HH       HH     HH  ", "   HH   HH         HH   HH   ", "    HBBBH           HBBBH    ", "                             ", "                             ", "                             ", "                             ")
            .aisle("BEEEEEEEEEEEEEEEEEEEEEEEEEEEB", "AAAAAAAAAAAAECCCEAAAAAAAAAAAA", "  B   N   B ECFCE B   N   B  ", " AHA  N  AHAECFCEAHA  N  AHA ", "   B  N  B  ECFCE  B  N  B   ", "  A  HHH  A ECFCE A  HHH  A  ", "    HHHHH   ECFCE   HHHHH    ", "   HHMMMHH  ECFCE  HHMMMHH   ", "  HH     HH ECFCE HH     HH  ", "  H       H  CFC  H       H  ", "  H       H   J   H       H  ", "  H       H       H       H  ", "  H       H       H       H  ", "  H       H       H       H  ", "  K       K       K       K  ", "  H       H       H       H  ", "  H       H       H       H  ", "  H       H       H       H  ", "  H       H       H       H  ", "  HH     HH       HH     HH  ", "   HH   HH         HH   HH   ", "    HBFBH           HBFBH    ", "      O               O      ", "      O               O      ", "                             ", "                             ")
            .aisle("BEEEEEEEEEEEE E EEEEEEEEEEEEB", "AAAAAAAAAAAAECCCEAAAAAAAAAAAA", "  B  L L  B ECCCE B  L L  B  ", " AHA L L AHAECCCEAHA L L AHA ", "   B L L B  ECCCE  B L L B   ", "  A  HHH  A ECCCE A  HHH  A  ", "    HHHHH   ECCCE   HHHHH    ", "   HHMMMHH  ECCCE  HHMMMHH   ", "  HH     HH ECCCE HH     HH  ", "  H       H  CCC  H       H  ", "  H       H   J   H       H  ", "  H       H       H       H  ", "  H       H       H       H  ", "  H       H       H       H  ", "  K       K       K       K  ", "  H       H       H       H  ", "  H       H       H       H  ", "  H       H       H       H  ", "  H       H       H       H  ", "  HH     HH       HH     HH  ", "   HH   HH         HH   HH   ", "    HBBBH           HBBBH    ", "                             ", "      O               O      ", "                             ", "                             ")
            .aisle("BEEEEEEEEEEEE E EEEEEEEEEEEEB", "AAAAAAAAAAAAEEEEEAAAAAAAAAAAA", "  B       B EEEEE B       B  ", " AHA     AHAEEEEEAHA     AHA ", "   B     B  EEEEE  B     B   ", "  AA     AA EEEEE AA     AA  ", "     HHH    EEEEE    HHH     ", "    HHHHH   EEEEE   HHHHH    ", "   H     H  EEEEE  H     H   ", "  HH     HH       HH     HH  ", "  HH     HH   J   HH     HH  ", "  HH     HH       HH     HH  ", "  HH     HH       HH     HH  ", "  HH     HH       HH     HH  ", "  KK     KK       KK     KK  ", "  HH     HH       HH     HH  ", "  HH     HH       HH     HH  ", "  HH     HH       HH     HH  ", "  HH     HH       HH     HH  ", "  HHH   HHH       HHH   HHH  ", "   HHHHHHH         HHHHHHH   ", "    HHHHH           HHHHH    ", "                             ", "      O               O      ", "                             ", "                             ")
            .aisle("AEEEEEEEEEEE  E  EEEEEEEEEEEA", "AAAAAAAAAAAA     AAAAAAAAAAAA", "AAAA     AAA     AAA     AAAA", " AAAAAAAAAAA     AAAAAAAAAAA ", " AAABBBBBAAA     AAABBBBBAAA ", "  AAA   AAA       AAA   AAA  ", "                             ", "     HHH             HHH     ", "    HHHHH           HHHHH    ", "   HH   HH         HH   HH   ", "   HH   HH    J    HH   HH   ", "   HH   HH    J    HH   HH   ", "   HH   HH    J    HH   HH   ", "   HH   HH         HH   HH   ", "   KK   KK         KK   KK   ", "   HH   HH         HH   HH   ", "   HH   HH         HH   HH   ", "   HH   HH         HH   HH   ", "   HH   HH         HH   HH   ", "   HHHHHHH         HHHHHHH   ", "    HHHHH           HHHHH    ", "                             ", "                             ", "      O               O      ", "                             ", "                             ")
            .aisle(" EEEEEEEEEEEEEEEEEEEEEEEEEEE ", " AAAAAAAAAAA LLL AAAAAAAAAAA ", "  GABBBBBAG  LLL  GABBBBBAG  ", "  GAHHHHHAG  LLL  GAHHHHHAG  ", "  GA     AG  LLL  GA     AG  ", "  GAAAAAAAG  LLL  GAAAAAAAG  ", "  G       G  LLL  G       G  ", "  I       I  LLL  I       I  ", "     HHH     LLL     HHH     ", "    HHHHH    LLL    HHHHH    ", "    HHHHH    LLL    HHHHH    ", "    HHHHH    LLL    HHHHH    ", "    HHHHH    LLL    HHHHH    ", "    HHHHH    LLL    HHHHH    ", "    KKKKK    LLL    KKKKK    ", "    HHHHH    LLL    HHHHH    ", "    HHHHH    LLL    HHHHH    ", "    HHHHH    LLL    HHHHH    ", "    HHHHH    LLL    HHHHH    ", "    HHHHH           HHHHH    ", "                             ", "                             ", "                             ", "      O               O      ", "                             ", "                             ")
            .aisle(" EEEEEEEEEE   E   EEEEEEEEEE ", "  AAAAAAAAA LLBLL AAAAAAAAAE ", "   A     A  LLFLL  A     A E ", "   AAAAAAA  LLFLL  AAAAAAA   ", "   A     A  LLFLL  A     A   ", "            LLFLL            ", "            LLFLL            ", "            LLFLL            ", "            LLFLL            ", "            LLFLL            ", "            LLFLL            ", "            LLFLL            ", "            LLFLL            ", "            LLFLL            ", "            LLFLL            ", "            LLFLL            ", "            LLFLL            ", "            LLFLL            ", "            LLFLL            ", "             LLL             ", "                             ", "                             ", "                             ", "      O               O      ", "                             ", "                             ")
            .aisle(" EEEEEEEE E   E   E EEEEEEEE ", " EEEEEEEE  LLBBBLL  EEEEEEEE ", " EEEEEEEE  LL   LL  EEEEEEEE ", "  EEEEEEE  LL   LL  EEEEEEE  ", "  EEEEEEE  LL   LL  EEEEEEE  ", "   EEEEEE  LL   LL  EEEEEE   ", "   EEEEEE  LL   LL  EEEEEE   ", "    EEEEE  LL   LL  EEEEE    ", "    EEEEE  LL   LL  EEEEE    ", "           LL   LL           ", "           LL   LL           ", "           LL   LL           ", "           LL   LL           ", "           LL   LL           ", "           LL   LL           ", "           LL   LL           ", "           LL   LL           ", "           LL   LL           ", "           LL F LL           ", "            LLLLL            ", "             KKK             ", "                             ", "                             ", "      O               O      ", "                             ", "                             ")
            .aisle("CE    E   E   E   E   E    EC", "CCCCCCCCE LLBBBBBLL ECCCCCCCC", "CCCCCCCCE LL  N  LL ECCCCCCCC", "CCCCCCCCE LL  N  LL ECCCCCCCC", "CCCCCCCCE LL  N  LL ECCCCCCCC", "CCCCCCCCE LL  N  LL ECCCCCCCC", "CCCCCCCCE LL  I  LL ECCCCCCCC", "    CCCCE LL  I  LL ECCCC    ", "    CCCCE LL  I  LL ECCCC    ", "    CCCC  LL     LL  CCCC    ", "          LL     LL          ", "          LL     LL          ", "          LL     LL          ", "          LL     LL          ", "          LL     LL          ", "          LL     LL          ", "          LL     LL          ", "          LL     LL          ", "          LL  F  LL          ", "           LLKKKLL           ", "            KPPPK            ", "             P P             ", "             P P             ", "      O      P P      O      ", "             KKK             ", "                             ")
            .aisle("CEEEEEEEEEEEEEEEEEEEEEEEEEEEC", "CCCCCCCCE LBBBBBBBL ECCCCCCCC", "D     FCE LF NRN FL ECF     D", "D     FCE LF NRN FL ECF     D", "D     FCE LF NRN FL ECF     D", "C     FCE LF NRN FL ECF     C", "CFFFC FCE LF IRI FL ECF CFFFC", "  J C FCE LF IRI FL ECF C J  ", "  J C FCE LF IRI FL ECF C J  ", "  J CCFC  LF  F  FL  CFCC J  ", "  JJJJJJJJLF  F  FLJJJJJJJJ  ", "         JLF  F  FLJ         ", "         JLF  F  FLJ         ", "          LF  F  FL          ", "          LF  F  FL          ", "          LF  F  FL          ", "          LF  F  FL          ", "          LF  F  FL          ", "          LFFFFFFFL          ", "           LLFFFLL           ", "            KOPOK            ", "             OPO             ", "             OPO             ", "      OOOOOOOOPOOOOOOOO      ", "             KKK             ", "                             ")
            .aisle("CE    E   E   E   E   E    EC", "CCCCCCCCE LLBBBBBLL ECCCCCCCC", "CCCCCCCCE LL  N  LL ECCCCCCCC", "CCCCCCCCE LL  N  LL ECCCCCCCC", "CCCCCCCCE LL  N  LL ECCCCCCCC", "CCCCCCCCE LL  N  LL ECCCCCCCC", "CCCCCCCCE LL  I  LL ECCCCCCCC", "    CCCCE LL  I  LL ECCCC    ", "    CCCCE LL  I  LL ECCCC    ", "    CCCC  LL     LL  CCCC    ", "          LL     LL          ", "          LL     LL          ", "          LL     LL          ", "          LL     LL          ", "          LL     LL          ", "          LL     LL          ", "          LL     LL          ", "          LL     LL          ", "          LL  F  LL          ", "           LLKKKLL           ", "            KPPPK            ", "             P P             ", "             P P             ", "      O      P P      O      ", "             KKK             ", "                             ")
            .aisle(" EEEEEEEE E   E   E EEEEEEEE ", " EEEEEEEE  LLBBBLL  EEEEEEEE ", " EEEEEEEE  LL   LL  EEEEEEEE ", "  EEEEEEE  LL   LL  EEEEEEE  ", "  EEEEEEE  LL   LL  EEEEEEE  ", "   EEEEEE  LL   LL  EEEEEE   ", "   EEEEEE  LL   LL  EEEEEE   ", "    EEEEE  LL   LL  EEEEE    ", "    EEEEE  LL   LL  EEEEE    ", "           LL   LL           ", "           LL   LL           ", "           LL   LL           ", "           LL   LL           ", "           LL   LL           ", "           LL   LL           ", "           LL   LL           ", "           LL   LL           ", "           LL   LL           ", "           LL F LL           ", "            LLLLL            ", "             KKK             ", "                             ", "                             ", "      O               O      ", "                             ", "                             ")
            .aisle(" EEEEEEEEEE   E   EEEEEEEEEE ", " EAAAAAAAAA LLBLL AAAAAAAAA  ", " E A     A  LLFLL  A     A   ", "   AAAAAAA  LLFLL  AAAAAAA   ", "   A     A  LLFLL  A     A   ", "            LLFLL            ", "            LLFLL            ", "            LLFLL            ", "            LLFLL            ", "            LLFLL            ", "            LLFLL            ", "            LLFLL            ", "            LLFLL            ", "            LLFLL            ", "            LLFLL            ", "            LLFLL            ", "            LLFLL            ", "            LLFLL            ", "            LLFLL            ", "             LLL             ", "                             ", "                             ", "                             ", "      O               O      ", "                             ", "                             ")
            .aisle(" EEEEEEEEEEEEEEEEEEEEEEEEEEE ", " AAAAAAAAAAA LLL AAAAAAAAAAA ", "  GABBBBBAG  LLL  GABBBBBAG  ", "  GAHHHHHAG  LLL  GAHHHHHAG  ", "  GA     AG  LLL  GA     AG  ", "  GAAAAAAAG  LLL  GAAAAAAAG  ", "  G       G  LLL  G       G  ", "  I       I  LLL  I       I  ", "     HHH     LLL     HHH     ", "    HHHHH    LLL    HHHHH    ", "    HHHHH    LLL    HHHHH    ", "    HHHHH    LLL    HHHHH    ", "    HHHHH    LLL    HHHHH    ", "    HHHHH    LLL    HHHHH    ", "    KKKKK    LLL    KKKKK    ", "    HHHHH    LLL    HHHHH    ", "    HHHHH    LLL    HHHHH    ", "    HHHHH    LLL    HHHHH    ", "    HHHHH    LLL    HHHHH    ", "    HHHHH           HHHHH    ", "                             ", "                             ", "                             ", "      O               O      ", "                             ", "                             ")
            .aisle("AEEEEEEEEEEE  E  EEEEEEEEEEEA", "AAAAAAAAAAAA     AAAAAAAAAAAA", "AAAA     AAA     AAA     AAAA", " AAAAAAAAAAA     AAAAAAAAAAA ", " AAABBBBBAAA     AAABBBBBAAA ", "  AAA   AAA       AAA   AAA  ", "                             ", "     HHH             HHH     ", "    HHHHH           HHHHH    ", "   HH   HH         HH   HH   ", "   HH   HH    J    HH   HH   ", "   HH   HH    J    HH   HH   ", "   HH   HH    J    HH   HH   ", "   HH   HH         HH   HH   ", "   KK   KK         KK   KK   ", "   HH   HH         HH   HH   ", "   HH   HH         HH   HH   ", "   HH   HH         HH   HH   ", "   HH   HH         HH   HH   ", "   HHHHHHH         HHHHHHH   ", "    HHHHH           HHHHH    ", "                             ", "                             ", "      O               O      ", "                             ", "                             ")
            .aisle("BEEEEEEEEEEEE E EEEEEEEEEEEEB", "AAAAAAAAAAAAEEEEEAAAAAAAAAAAA", "  B       B EEEEE B       B  ", " AHA     AHAEEEEEAHA     AHA ", "   B     B  EEEEE  B     B   ", "  AA     AA EEEEE AA     AA  ", "     HHH    EEEEE    HHH     ", "    HHHHH   EEEEE   HHHHH    ", "   H     H  EEEEE  H     H   ", "  HH     HH       HH     HH  ", "  HH     HH   J   HH     HH  ", "  HH     HH       HH     HH  ", "  HH     HH       HH     HH  ", "  HH     HH       HH     HH  ", "  KK     KK       KK     KK  ", "  HH     HH       HH     HH  ", "  HH     HH       HH     HH  ", "  HH     HH       HH     HH  ", "  HH     HH       HH     HH  ", "  HHH   HHH       HHH   HHH  ", "   HHHHHHH         HHHHHHH   ", "    HHHHH           HHHHH    ", "                             ", "      O               O      ", "                             ", "                             ")
            .aisle("BEEEEEEEEEEEE E EEEEEEEEEEEEB", "AAAAAAAAAAAAECCCEAAAAAAAAAAAA", "  B  L L  B ECCCE B  L L  B  ", " AHA L L AHAECCCEAHA L L AHA ", "   B L L B  ECCCE  B L L B   ", "  A  HHH  A ECCCE A  HHH  A  ", "    HHHHH   ECCCE   HHHHH    ", "   HHMMMHH  ECCCE  HHMMMHH   ", "  HH     HH ECCCE HH     HH  ", "  H       H  CCC  H       H  ", "  H       H   J   H       H  ", "  H       H       H       H  ", "  H       H       H       H  ", "  H       H       H       H  ", "  K       K       K       K  ", "  H       H       H       H  ", "  H       H       H       H  ", "  H       H       H       H  ", "  H       H       H       H  ", "  HH     HH       HH     HH  ", "   HH   HH         HH   HH   ", "    HBBBH           HBBBH    ", "                             ", "      O               O      ", "                             ", "                             ")
            .aisle("BEEEEEEEEEEEEEEEEEEEEEEEEEEEB", "AAAAAAAAAAAAECCCEAAAAAAAAAAAA", "  B   N   B ECFCE B   N   B  ", " AHA  N  AHAECFCEAHA  N  AHA ", "   B  N  B  ECFCE  B  N  B   ", "  A  HHH  A ECFCE A  HHH  A  ", "    HHHHH   ECFCE   HHHHH    ", "   HHMMMHH  ECFCE  HHMMMHH   ", "  HH     HH ECFCE HH     HH  ", "  H       H  CFC  H       H  ", "  H       H   J   H       H  ", "  H       H       H       H  ", "  H       H       H       H  ", "  H       H       H       H  ", "  K       K       K       K  ", "  H       H       H       H  ", "  H       H       H       H  ", "  H       H       H       H  ", "  H       H       H       H  ", "  HH     HH       HH     HH  ", "   HH   HH         HH   HH   ", "    HBFBH           HBFBH    ", "      O               O      ", "      O               O      ", "                             ", "                             ")
            .aisle("BEEEEEEEEEEEE E EEEEEEEEEEEEB", "AAAAAAAAAAAAECCCEAAAAAAAAAAAA", "  B  L L  B EC CE B  L L  B  ", " AHA L L AHAEC CEAHA L L AHA ", "   B L L B  EC CE  B L L B   ", "  A  HHH  A EC CE A  HHH  A  ", "    HHHHH   EC CE   HHHHH    ", "   HHMMMHH  EC CE  HHMMMHH   ", "  HH     HH EC CE HH     HH  ", "  H       H  CCC  H       H  ", "  H       H   J   H       H  ", "  H       H       H       H  ", "  H       H       H       H  ", "  H       H       H       H  ", "  K       K       K       K  ", "  H       H       H       H  ", "  H       H       H       H  ", "  H       H       H       H  ", "  H       H       H       H  ", "  HH     HH       HH     HH  ", "   HH   HH         HH   HH   ", "    HBBBH           HBBBH    ", "                             ", "                             ", "                             ", "                             ")
            .aisle("BEEEEEEEEEEEE E EEEEEEEEEEEEB", "AAAAAAAAAAAAECCCEAAAAAAAAAAAA", "  B       B EC CE B       B  ", " AHA     AHAEC CEAHA     AHA ", "   B     B  EC CE  B     B   ", "  AA     AA EC CE AA     AA  ", "     HHH    ECCCE    HHH     ", "    HHHHH   ECCCE   HHHHH    ", "   H     H  ECCCE  H     H   ", "  HH     HH  CCC  HH     HH  ", "  HH     HH   J   HH     HH  ", "  HH     HH       HH     HH  ", "  HH     HH       HH     HH  ", "  HH     HH       HH     HH  ", "  KK     KK       KK     KK  ", "  HH     HH       HH     HH  ", "  HH     HH       HH     HH  ", "  HH     HH       HH     HH  ", "  HH     HH       HH     HH  ", "  HHH   HHH       HHH   HHH  ", "   HHHHHHH         HHHHHHH   ", "    HHHHH           HHHHH    ", "                             ", "                             ", "                             ", "                             ")
            .aisle("AEEEEEEEEEEEE E EEEEEEEEEEEEA", "AAAAAAAAAAAAECCCEAAAAAAAAAAAA", "AAAA     AAAEC CEAAA     AAAA", " AAAAAAAAAAAEC CEAAAAAAAAAAA ", " AAABBBBBAAAEC CEAAABBBBBAAA ", "  AAA   AAA EC CE AAA   AAA  ", "            ECFCE            ", "     HHH             HHH     ", "    HHHHH           HHHHH    ", "   HH   HH         HH   HH   ", "   HH   HH    J    HH   HH   ", "   HH   HH         HH   HH   ", "   HH   HH         HH   HH   ", "   HH   HH         HH   HH   ", "   KK   KK         KK   KK   ", "   HH   HH         HH   HH   ", "   HH   HH         HH   HH   ", "   HH   HH         HH   HH   ", "   HH   HH         HH   HH   ", "   HHHHHHH         HHHHHHH   ", "    HHHHH           HHHHH    ", "                             ", "                             ", "                             ", "                             ", "                             ")
            .aisle(" EEEEEEEEEEEE E EEEEEEEEEEEE ", " AAAAAAAAAAAECCCEAAAAAAAAAAA ", "  GABBBBBAG EC CE GABBBBBAG  ", "  GAHHHHHAG EC CE GAHHHHHAG  ", "  GA     AG EC CE GA     AG  ", "  GAAAAAAAG  C C  GAAAAAAAG  ", "  G       G  CFC  G       G  ", "  I       I   J   I       I  ", "     HHH      J      HHH     ", "    HHHHH     J     HHHHH    ", "    HHHHH     J     HHHHH    ", "    HHHHH           HHHHH    ", "    HHHHH           HHHHH    ", "    HHHHH           HHHHH    ", "    KKKKK           KKKKK    ", "    HHHHH           HHHHH    ", "    HHHHH           HHHHH    ", "    HHHHH           HHHHH    ", "    HHHHH           HHHHH    ", "    HHHHH           HHHHH    ", "                             ", "                             ", "                             ", "                             ", "                             ", "                             ")
            .aisle(" EEEEEEEEEEEEEEEEEEEEEEEEEEE ", "  AAAAAAAAAEECCCEEAAAAAAAAA  ", "   A     A EEC CEE A     A   ", "   AAAAAAA   C C   AAAAAAA   ", "   A     A   C C   A     A   ", "             C C             ", "             CFC             ", "                             ", "                             ", "                             ", "                             ", "                             ", "                             ", "                             ", "                             ", "                             ", "                             ", "                             ", "                             ", "                             ", "                             ", "                             ", "                             ", "                             ", "                             ", "                             ")
            .aisle("   ABBBBBA   CCC   ABBBBBA   ", "   AAAAAAA   CCC   AAAAAAA   ", "   A     A   CDC   A     A   ", "             CDC             ", "             CDC             ", "             CCC             ", "             CCC             ", "                             ", "                             ", "                             ", "                             ", "                             ", "                             ", "                             ", "                             ", "                             ", "                             ", "                             ", "                             ", "                             ", "                             ", "                             ", "                             ", "                             ", "                             ", "                             ")
            .aisle("             CCC             ", "             C~C             ", "                             ", "                             ", "                             ", "                             ", "                             ", "                             ", "                             ", "                             ", "                             ", "                             ", "                             ", "                             ", "                             ", "                             ", "                             ", "                             ", "                             ", "                             ", "                             ", "                             ", "                             ", "                             ", "                             ", "                             ")
            .where("~", Predicates.controller(Predicates.blocks(definition.get())))
            .where("A", Predicates.blocks(GTLBlocks.IRIDIUM_CASING.get()))
            .where("B", Predicates.blocks(Registries.getBlock("gtceu:sterilizing_filter_casing")))
            .where("C", Predicates.blocks(GTBlocks.CASING_PTFE_INERT.get())
                .or(Predicates.autoAbilities(*definition.recipeTypes))
                .or(Predicates.autoAbilities(true, false, true))
                .or(Predicates.abilities(PartAbility.INPUT_LASER).setMaxGlobalLimited(1))
                .or(Predicates.abilities(GTLAddPartAbility.THREAD_MODIFIER).setMaxGlobalLimited(1)))
            .where("D", Predicates.blocks(GTBlocks.HIGH_POWER_CASING.get()))
            .where("E", Predicates.blocks(GTBlocks.CASING_HSSE_STURDY.get()))
            .where("F", Predicates.blocks(GTBlocks.CASING_POLYTETRAFLUOROETHYLENE_PIPE.get()))
            .where("G", Predicates.blocks(GTLBlocks.MOLECULAR_CASING.get()))
            .where("H", Predicates.blocks(GTBlocks.CLEANROOM_GLASS.get()))
            .where("I", Predicates.blocks(Registries.getBlock("kubejs:containment_field_generator")))
            .where("J", Predicates.blocks(GTBlocks.CASING_STAINLESS_TURBINE.get()))
            .where("K", Predicates.blocks(GTLBlocks.DEGENERATE_RHENIUM_CONSTRAINED_CASING.get()))
            .where("L", Predicates.blocks(GTBlocks.PLASTCRETE.get()))
            .where("M", Predicates.blocks(Blocks.SPONGE))
            .where("N", Predicates.blocks(GTLBlocks.HYPER_CORE.get()))
            .where("O", Predicates.blocks(GTBlocks.CASING_TUNGSTENSTEEL_TURBINE.get()))
            .where("P", Predicates.frames(GTMaterials.Naquadria))
            .where("R", Predicates.blocks(Registries.getBlock("kubejs:containment_field_generator")))
            .where(" ", Predicates.any())
            .build()
    }

    val DIMENSIONALLY_TRANSCENDENT_MIXER = Function { definition: MultiblockMachineDefinition ->
        FactoryBlockPattern.start()
            .aisle("  aaaaa  ", "  aaaaa  ", "  aaaaa  ", "  aaaaa  ", "  aaaaa  ", "  aaaaa  ", "  aaaaa  ", "  aaaaa  ", "  aaaaa  ", "  aaaaa  ", "  aaaaa  ", "  aaaaa  ", "         ")
            .aisle(" aaaaaaa ", " aa c aa ", " aa   aa ", " aa   aa ", " aa   aa ", " aa   aa ", " aa   aa ", " aa   aa ", " aa   aa ", " aa   aa ", " aa   aa ", " aa   aa ", "  aaaaa  ")
            .aisle("aaaaaaaaa", "aac c caa", "aa     aa", "aa  d  aa", "aa     aa", "aa     aa", "aa  d  aa", "aa     aa", "aa     aa", "aa  d  aa", "aa     aa", "aa     aa", " aaaaaaa ")
            .aisle("aaaaaaaaa", "a  ccc  a", "a       a", "a   d   a", "a       a", "a       a", "a   d   a", "a       a", "a       a", "a   d   a", "a       a", "a       a", " aaaaaaa ")
            .aisle("aaaaaaaaa", "accceccca", "a   f   a", "a ddfdd a", "a   f   a", "a   f   a", "a ddfdd a", "a   f   a", "a   f   a", "a ddfdd a", "a   f   a", "a   e   a", " aaaaaaa ")
            .aisle("aaaaaaaaa", "a  ccc  a", "a       a", "a   d   a", "a       a", "a       a", "a   d   a", "a       a", "a       a", "a   d   a", "a       a", "a       a", " aaaaaaa ")
            .aisle("aaaaaaaaa", "aac c caa", "aa     aa", "aa  d  aa", "aa     aa", "aa     aa", "aa  d  aa", "aa     aa", "aa     aa", "aa  d  aa", "aa     aa", "aa     aa", " aaaaaaa ")
            .aisle(" aaaaaaa ", " aa c aa ", " aa   aa ", " aa   aa ", " aa   aa ", " aa   aa ", " aa   aa ", " aa   aa ", " aa   aa ", " aa   aa ", " aa   aa ", " aa   aa ", "  aaaaa  ")
            .aisle("  aaaaa  ", "  aaaaa  ", "  aa~aa  ", "  aaaaa  ", "  aaaaa  ", "  aaaaa  ", "  aaaaa  ", "  aaaaa  ", "  aaaaa  ", "  aaaaa  ", "  aaaaa  ", "  aaaaa  ", "         ")
            .where("~", Predicates.controller(Predicates.blocks(definition.get())))
            .where("a", Predicates.blocks(GTLBlocks.DIMENSIONALLY_TRANSCENDENT_CASING.get())
                .setMinGlobalLimited(440)
                .or(Predicates.autoAbilities(*definition.recipeTypes))
                .or(Predicates.abilities(PartAbility.PARALLEL_HATCH).setMaxGlobalLimited(1))
                .or(Predicates.abilities(PartAbility.INPUT_LASER).setMaxGlobalLimited(1))
                .or(Predicates.abilities(PartAbility.MAINTENANCE).setExactLimit(1))
                .or(Predicates.abilities(GTLAddPartAbility.THREAD_MODIFIER).setMaxGlobalLimited(1)))
            .where("c", Predicates.blocks(GTLBlocks.DIMENSION_INJECTION_CASING.get()))
            .where("d", Predicates.blocks(ChemicalHelper.getBlock(TagPrefix.block, GTLMaterials.HeavyQuarkDegenerateMatter)))
            .where("e", Predicates.blocks(Registries.getBlock("kubejs:neutronium_gearbox")))
            .where("f", Predicates.blocks(Registries.getBlock("kubejs:neutronium_pipe_casing")))
            .where(" ", Predicates.any())
            .build()
    }

    val SUPRACHRONAL_ASSEMBLY_LINE = Function { definition: MultiblockMachineDefinition ->
        FactoryBlockPattern.start(RelativeDirection.UP, RelativeDirection.BACK, RelativeDirection.LEFT)
            .aisle("                                   ", "                                   ", "                                   ", "                                   ", "                                   ", "               IIIII               ", "                                   ", "                                   ", "                                   ", "                                   ", "                                   ", "                                   ", "                                   ", "               IIIII               ", "                                   ", "                                   ", "                                   ", "                                   ", "                                   ", "                                   ", "                                   ", "               IIIII               ", "                                   ", "                                   ", "                                   ", "                                   ", "                                   ", "                                   ", "                                   ", "               IIIII               ", "                                   ", "                                   ", "                                   ", "                                   ", "                                   ", "                                   ", "                                   ", "               IIIII               ", "                                   ", "                                   ", "                                   ", "                                   ", "                                   ", "                                   ", "                                   ", "               IIIII               ", "                                   ", "                                   ", "                                   ", "                                   ", "                                   ", "                                   ", "                                   ", "               IIIII               ", "                                   ", "                                   ", "                                   ", "                                   ", "                                   ", "                                   ", "                                   ", "               IIIII               ", "                                   ", "                                   ", "                                   ", "                                   ", "                                   ", "                                   ", "                                   ", "               IIIII               ", "                                   ", "                                   ", "                                   ", "                                   ", "                                   ", "                                   ", "                                   ", "               IIIII               ", "                                   ", "                                   ", "                                   ", "                                   ", "                                   ", "                                   ", "                                   ", "               IIIII               ", "                                   ", "                                   ", "                                   ", "                                   ", "                                   ", "                                   ", "                                   ", "               IIIII               ", "                                   ", "                                   ", "                                   ", "                                   ", "                                   ", "                                   ", "                                   ", "               IIIII               ", "                                   ", "                                   ", "                                   ", "                                   ", "                                   ", "                                   ", "                                   ", "               IIIII               ", "                                   ", "                                   ", "                                   ", "                                   ", "                                   ", "                                   ", "                                   ", "               IIIII               ", "                                   ", "                                   ", "                                   ", "                                   ", "                                   ", "                                   ", "                                   ", "               IIIII               ", "                                   ", "                                   ", "                                   ", "                                   ", "                                   ")
            .aisle("                                   ", "                                   ", "                                   ", "                                   ", "               IIIII               ", "            IIICCCCCIII            ", "               IIIII               ", "                                   ", "                                   ", "                                   ", "                                   ", "                                   ", "               IIIII               ", "            IIICCCCCIII            ", "               IIIII               ", "                                   ", "                                   ", "                                   ", "                                   ", "                                   ", "               IIIII               ", "            IIICCCCCIII            ", "               IIIII               ", "                                   ", "                                   ", "                                   ", "                                   ", "                                   ", "               IIIII               ", "            IIICCCCCIII            ", "               IIIII               ", "                                   ", "                                   ", "                                   ", "                                   ", "                                   ", "               IIIII               ", "            IIICCCCCIII            ", "               IIIII               ", "                                   ", "                                   ", "                                   ", "                                   ", "                                   ", "               IIIII               ", "            IIICCCCCIII            ", "               IIIII               ", "                                   ", "                                   ", "                                   ", "                                   ", "                                   ", "               IIIII               ", "            IIICCCCCIII            ", "               IIIII               ", "                                   ", "                                   ", "                                   ", "                                   ", "                                   ", "               IIIII               ", "            IIICCCCCIII            ", "               IIIII               ", "                                   ", "                                   ", "                                   ", "                                   ", "                                   ", "               IIIII               ", "            IIICCCCCIII            ", "               IIIII               ", "                                   ", "                                   ", "                                   ", "                                   ", "                                   ", "               IIIII               ", "            IIICCCCCIII            ", "               IIIII               ", "                                   ", "                                   ", "                                   ", "                                   ", "                                   ", "               IIIII               ", "            IIICCCCCIII            ", "               IIIII               ", "                                   ", "                                   ", "                                   ", "                                   ", "                                   ", "               IIIII               ", "            IIICCCCCIII            ", "               IIIII               ", "                                   ", "                                   ", "                                   ", "                                   ", "                                   ", "               IIIII               ", "            IIICCCCCIII            ", "               IIIII               ", "                                   ", "                                   ", "                                   ", "                                   ", "                                   ", "               IIIII               ", "            IIICCCCCIII            ", "               IIIII               ", "                                   ", "                                   ", "                                   ", "                                   ", "                                   ", "               IIIII               ", "            IIICCCCCIII            ", "               IIIII               ", "                                   ", "                                   ", "                                   ", "                                   ", "                                   ", "               IIIII               ", "            IIICCCCCIII            ", "               IIIII               ", "                                   ", "                                   ", "                                   ", "                                   ")
            .aisle("                                   ", "                                   ", "                                   ", "                                   ", "            III   IIIII            ", "          IICCCIIICCCCCII          ", "            III   IIIII            ", "                                   ", "                                   ", "                                   ", "                                   ", "                                   ", "            III   IIIII            ", "          IICCCDDDCCCCCII          ", "            III   IIIII            ", "                                   ", "                                   ", "                                   ", "                                   ", "                                   ", "            III   IIIII            ", "          IICCCIIICCCCCII          ", "            III   IIIII            ", "                                   ", "                                   ", "                                   ", "                                   ", "                                   ", "            III   IIIII            ", "          IICCCDDDCCCCCII          ", "            III   IIIII            ", "                                   ", "                                   ", "                                   ", "                                   ", "                                   ", "            III   IIIII            ", "          IICCCIIICCCCCII          ", "            III   IIIII            ", "                                   ", "                                   ", "                                   ", "                                   ", "                                   ", "            III   IIIII            ", "          IICCCDDDCCCCCII          ", "            III   IIIII            ", "                                   ", "                                   ", "                                   ", "                                   ", "                                   ", "            III   IIIII            ", "          IICCCIIICCCCCII          ", "            III   IIIII            ", "                                   ", "                                   ", "                                   ", "                                   ", "                                   ", "            III   IIIII            ", "          IICCCDDDCCCCCII          ", "            III   IIIII            ", "                                   ", "                                   ", "                                   ", "                                   ", "                                   ", "            III   IIIII            ", "          IICCCIIICCCCCII          ", "            III   IIIII            ", "                                   ", "                                   ", "                                   ", "                                   ", "                                   ", "            III   IIIII            ", "          IICCCDDDCCCCCII          ", "            III   IIIII            ", "                                   ", "                                   ", "                                   ", "                                   ", "                                   ", "            III   IIIII            ", "          IICCCIIICCCCCII          ", "            III   IIIII            ", "                                   ", "                                   ", "                                   ", "                                   ", "                                   ", "            III   IIIII            ", "          IICCCDDDCCCCCII          ", "            III   IIIII            ", "                                   ", "                                   ", "                                   ", "                                   ", "                                   ", "            III   IIIII            ", "          IICCCIIICCCCCII          ", "            III   IIIII            ", "                                   ", "                                   ", "                                   ", "                                   ", "                                   ", "            III   IIIII            ", "          IICCCDDDCCCCCII          ", "            III   IIIII            ", "                                   ", "                                   ", "                                   ", "                                   ", "                                   ", "            III   IIIII            ", "          IICCCIIICCCCCII          ", "            III   IIIII            ", "                                   ", "                                   ", "                                   ", "                                   ", "                                   ", "            III   IIIII            ", "          IICCCDDDCCCCCII          ", "            III   IIIII            ", "                                   ", "                                   ", "                                   ", "                                   ")
            .aisle("                                   ", "                                   ", "                                   ", "                                   ", "          II    II     II          ", "        IICCDDIICCDDDDDCCII        ", "          II    II     II          ", "                                   ", "                                   ", "                                   ", "                                   ", "                                   ", "          II           II          ", "        IICCDDD   DDDDDCCII        ", "          II           II          ", "                                   ", "                                   ", "                                   ", "                                   ", "                                   ", "          II    II     II          ", "        IICCDDIICCDDDDDCCII        ", "          II    II     II          ", "                                   ", "                                   ", "                                   ", "                                   ", "                                   ", "          II           II          ", "        IICCDDD   DDDDDCCII        ", "          II           II          ", "                                   ", "                                   ", "                                   ", "                                   ", "                                   ", "          II    II     II          ", "        IICCDDIICCDDDDDCCII        ", "          II    II     II          ", "                                   ", "                                   ", "                                   ", "                                   ", "                                   ", "          II           II          ", "        IICCDDD   DDDDDCCII        ", "          II           II          ", "                                   ", "                                   ", "                                   ", "                                   ", "                                   ", "          II    II     II          ", "        IICCDDIICCDDDDDCCII        ", "          II    II     II          ", "                                   ", "                                   ", "                                   ", "                                   ", "                                   ", "          II           II          ", "        IICCDDD   DDDDDCCII        ", "          II           II          ", "                                   ", "                                   ", "                                   ", "                                   ", "                                   ", "          II    II     II          ", "        IICCDDIICCDDDDDCCII        ", "          II    II     II          ", "                                   ", "                                   ", "                                   ", "                                   ", "                                   ", "          II           II          ", "        IICCDDD   DDDDDCCII        ", "          II           II          ", "                                   ", "                                   ", "                                   ", "                                   ", "                                   ", "          II    II     II          ", "        IICCDDIICCDDDDDCCII        ", "          II    II     II          ", "                                   ", "                                   ", "                                   ", "                                   ", "                                   ", "          II           II          ", "        IICCDDD   DDDDDCCII        ", "          II           II          ", "                                   ", "                                   ", "                                   ", "                                   ", "                                   ", "          II    II     II          ", "        IICCDDIICCDDDDDCCII        ", "          II    II     II          ", "                                   ", "                                   ", "                                   ", "                                   ", "                                   ", "          II           II          ", "        IICCDDD   DDDDDCCII        ", "          II           II          ", "                                   ", "                                   ", "                                   ", "                                   ", "                                   ", "          II    II     II          ", "        IICCDDIICCDDDDDCCII        ", "          II    II     II          ", "                                   ", "                                   ", "                                   ", "                                   ", "                                   ", "          II           II          ", "        IICCDDD   DDDDDCCII        ", "          II           II          ", "                                   ", "                                   ", "                                   ", "                                   ")
            .aisle("                                   ", "                                   ", "                                   ", "                                   ", "        II    II         II        ", "       ICCDD ICCBB     DDCCI       ", "        II    II         II        ", "                                   ", "                                   ", "                                   ", "                                   ", "                                   ", "        II               II        ", "       ICCDD           DDCCI       ", "        II               II        ", "                                   ", "                                   ", "                                   ", "                                   ", "                                   ", "        II    II         II        ", "       ICCDD ICCBB     DDCCI       ", "        II    II         II        ", "                                   ", "                                   ", "                                   ", "                                   ", "                                   ", "        II               II        ", "       ICCDD           DDCCI       ", "        II               II        ", "                                   ", "                                   ", "                                   ", "                                   ", "                                   ", "        II    II         II        ", "       ICCDD ICCBB     DDCCI       ", "        II    II         II        ", "                                   ", "                                   ", "                                   ", "                                   ", "                                   ", "        II               II        ", "       ICCDD           DDCCI       ", "        II               II        ", "                                   ", "                                   ", "                                   ", "                                   ", "                                   ", "        II    II         II        ", "       ICCDD ICCBB     DDCCI       ", "        II    II         II        ", "                                   ", "                                   ", "                                   ", "                                   ", "                                   ", "        II               II        ", "       ICCDD           DDCCI       ", "        II               II        ", "                                   ", "                                   ", "                                   ", "                                   ", "                                   ", "        II    II         II        ", "       ICCDD ICCBB     DDCCI       ", "        II    II         II        ", "                                   ", "                                   ", "                                   ", "                                   ", "                                   ", "        II               II        ", "       ICCDD           DDCCI       ", "        II               II        ", "                                   ", "                                   ", "                                   ", "                                   ", "                                   ", "        II    II         II        ", "       ICCDD ICCBB     DDCCI       ", "        II    II         II        ", "                                   ", "                                   ", "                                   ", "                                   ", "                                   ", "        II               II        ", "       ICCDD           DDCCI       ", "        II               II        ", "                                   ", "                                   ", "                                   ", "                                   ", "                                   ", "        II    II         II        ", "       ICCDD ICCBB     DDCCI       ", "        II    II         II        ", "                                   ", "                                   ", "                                   ", "                                   ", "                                   ", "        II               II        ", "       ICCDD           DDCCI       ", "        II               II        ", "                                   ", "                                   ", "                                   ", "                                   ", "                                   ", "        II    II         II        ", "       ICCDD ICCBB     DDCCI       ", "        II    II         II        ", "                                   ", "                                   ", "                                   ", "                                   ", "                                   ", "        II               II        ", "       ICCDD           DDCCI       ", "        II               II        ", "                                   ", "                                   ", "                                   ", "                                   ")
            .aisle("                                   ", "                                   ", "                                   ", "                                   ", "       I     I             I       ", "      ICDD  ICBB         DDCI      ", "       I     I             I       ", "                                   ", "                                   ", "                                   ", "                                   ", "                                   ", "       I                   I       ", "      ICDD               DDCI      ", "       I                   I       ", "                                   ", "                                   ", "                                   ", "                                   ", "                                   ", "       I     I             I       ", "      ICDD  ICBB         DDCI      ", "       I     I             I       ", "                                   ", "                                   ", "                                   ", "                                   ", "                                   ", "       I                   I       ", "      ICDD               DDCI      ", "       I                   I       ", "                                   ", "                                   ", "                                   ", "                                   ", "                                   ", "       I     I             I       ", "      ICDD  ICBB         DDCI      ", "       I     I             I       ", "                                   ", "                                   ", "                                   ", "                                   ", "                                   ", "       I                   I       ", "      ICDD               DDCI      ", "       I                   I       ", "                                   ", "                                   ", "                                   ", "                                   ", "                                   ", "       I     I             I       ", "      ICDD  ICBB         DDCI      ", "       I     I             I       ", "                                   ", "                                   ", "                                   ", "                                   ", "                                   ", "       I                   I       ", "      ICDD               DDCI      ", "       I                   I       ", "                                   ", "                                   ", "                                   ", "                                   ", "                                   ", "       I     I             I       ", "      ICDD  ICBB         DDCI      ", "       I     I             I       ", "                                   ", "                                   ", "                                   ", "                                   ", "                                   ", "       I                   I       ", "      ICDD               DDCI      ", "       I                   I       ", "                                   ", "                                   ", "                                   ", "                                   ", "                                   ", "       I     I             I       ", "      ICDD  ICBB         DDCI      ", "       I     I             I       ", "                                   ", "                                   ", "                                   ", "                                   ", "                                   ", "       I                   I       ", "      ICDD               DDCI      ", "       I                   I       ", "                                   ", "                                   ", "                                   ", "                                   ", "                                   ", "       I     I             I       ", "      ICDD  ICBB         DDCI      ", "       I     I             I       ", "                                   ", "                                   ", "                                   ", "                                   ", "                                   ", "       I                   I       ", "      ICDD               DDCI      ", "       I                   I       ", "                                   ", "                                   ", "                                   ", "                                   ", "                                   ", "       I     I             I       ", "      ICDD  ICBB         DDCI      ", "       I     I             I       ", "                                   ", "                                   ", "                                   ", "                                   ", "                                   ", "       I                   I       ", "      ICDD               DDCI      ", "       I                   I       ", "                                   ", "                                   ", "                                   ", "                                   ")
            .aisle("                                   ", "                                   ", "                                   ", "                                   ", "      I     I               I      ", "     ICD   ICB             DCI     ", "      I     I               I      ", "                                   ", "                                   ", "                                   ", "                                   ", "                                   ", "      I                     I      ", "     ICD                   DCI     ", "      I                     I      ", "                                   ", "                                   ", "                                   ", "                                   ", "                                   ", "      I     I               I      ", "     ICD   ICB             DCI     ", "      I     I               I      ", "                                   ", "                                   ", "                                   ", "                                   ", "                                   ", "      I                     I      ", "     ICD                   DCI     ", "      I                     I      ", "                                   ", "                                   ", "                                   ", "                                   ", "                                   ", "      I     I               I      ", "     ICD   ICB             DCI     ", "      I     I               I      ", "                                   ", "                                   ", "                                   ", "                                   ", "                                   ", "      I                     I      ", "     ICD                   DCI     ", "      I                     I      ", "                                   ", "                                   ", "                                   ", "                                   ", "                                   ", "      I     I               I      ", "     ICD   ICB             DCI     ", "      I     I               I      ", "                                   ", "                                   ", "                                   ", "                                   ", "                                   ", "      I                     I      ", "     ICD                   DCI     ", "      I                     I      ", "                                   ", "                                   ", "                                   ", "                                   ", "                                   ", "      I     I               I      ", "     ICD   ICB             DCI     ", "      I     I               I      ", "                                   ", "                                   ", "                                   ", "                                   ", "                                   ", "      I                     I      ", "     ICD                   DCI     ", "      I                     I      ", "                                   ", "                                   ", "                                   ", "                                   ", "                                   ", "      I     I               I      ", "     ICD   ICB             DCI     ", "      I     I               I      ", "                                   ", "                                   ", "                                   ", "                                   ", "                                   ", "      I                     I      ", "     ICD                   DCI     ", "      I                     I      ", "                                   ", "                                   ", "                                   ", "                                   ", "                                   ", "      I     I               I      ", "     ICD   ICB             DCI     ", "      I     I               I      ", "                                   ", "                                   ", "                                   ", "                                   ", "                                   ", "      I                     I      ", "     ICD                   DCI     ", "      I                     I      ", "                                   ", "                                   ", "                                   ", "                                   ", "                                   ", "      I     I               I      ", "     ICD   ICB             DCI     ", "      I     I               I      ", "                                   ", "                                   ", "                                   ", "                                   ", "                                   ", "      I                     I      ", "     ICD                   DCI     ", "      I                     I      ", "                                   ", "                                   ", "                                   ", "                                   ")
            .aisle("                                   ", "                                   ", "                                   ", "                                   ", "     I     I                 I     ", "    ICD   ICB               DCI    ", "     I     I                 I     ", "                                   ", "                                   ", "                                   ", "                                   ", "                                   ", "     I                       I     ", "    ICD           IIII      DCI    ", "     I                       I     ", "                                   ", "                                   ", "                                   ", "                                   ", "                                   ", "     I     I                 I     ", "    ICD   ICB               DCI    ", "     I     I                 I     ", "                                   ", "                                   ", "                                   ", "                                   ", "                                   ", "     I                       I     ", "    ICD           IIII      DCI    ", "     I                       I     ", "                                   ", "                                   ", "                                   ", "                                   ", "                                   ", "     I     I                 I     ", "    ICD   ICB               DCI    ", "     I     I                 I     ", "                                   ", "                                   ", "                                   ", "                                   ", "                                   ", "     I                       I     ", "    ICD           IIII      DCI    ", "     I                       I     ", "                                   ", "                                   ", "                                   ", "                                   ", "                                   ", "     I     I                 I     ", "    ICD   ICB               DCI    ", "     I     I                 I     ", "                                   ", "                                   ", "                                   ", "                                   ", "                                   ", "     I                       I     ", "    ICD           IIII      DCI    ", "     I                       I     ", "                                   ", "                                   ", "                                   ", "                                   ", "                                   ", "     I     I                 I     ", "    ICD   ICB               DCI    ", "     I     I                 I     ", "                                   ", "                                   ", "                                   ", "                                   ", "                                   ", "     I                       I     ", "    ICD           IIII      DCI    ", "     I                       I     ", "                                   ", "                                   ", "                                   ", "                                   ", "                                   ", "     I     I                 I     ", "    ICD   ICB               DCI    ", "     I     I                 I     ", "                                   ", "                                   ", "                                   ", "                                   ", "                                   ", "     I                       I     ", "    ICD           IIII      DCI    ", "     I                       I     ", "                                   ", "                                   ", "                                   ", "                                   ", "                                   ", "     I     I                 I     ", "    ICD   ICB               DCI    ", "     I     I                 I     ", "                                   ", "                                   ", "                                   ", "                                   ", "                                   ", "     I                       I     ", "    ICD           IIII      DCI    ", "     I                       I     ", "                                   ", "                                   ", "                                   ", "                                   ", "                                   ", "     I     I                 I     ", "    ICD   ICB               DCI    ", "     I     I                 I     ", "                                   ", "                                   ", "                                   ", "                                   ", "                                   ", "     I                       I     ", "    ICD           IIII      DCI    ", "     I                       I     ", "                                   ", "                                   ", "                                   ", "                                   ")
            .aisle("                                   ", "               EEEEE               ", "                                   ", "                                   ", "    I     I                   I    ", "   ICD   ICB                 DCI   ", "    I     I                   I    ", "                                   ", "                                   ", "                                   ", "                                   ", "                                   ", "    I             IIII        I    ", "   ICD          IICCCCIII    DCI   ", "    I             IIII        I    ", "                                   ", "                                   ", "                                   ", "                                   ", "                                   ", "    I     I                   I    ", "   ICD   ICB                 DCI   ", "    I     I                   I    ", "                                   ", "                                   ", "                                   ", "                                   ", "                                   ", "    I             IIII        I    ", "   ICD          IICCCCIII    DCI   ", "    I             IIII        I    ", "                                   ", "                                   ", "                                   ", "                                   ", "                                   ", "    I     I                   I    ", "   ICD   ICB                 DCI   ", "    I     I                   I    ", "                                   ", "                                   ", "                                   ", "                                   ", "                                   ", "    I             IIII        I    ", "   ICD          IICCCCIII    DCI   ", "    I             IIII        I    ", "                                   ", "                                   ", "                                   ", "                                   ", "                                   ", "    I     I                   I    ", "   ICD   ICB                 DCI   ", "    I     I                   I    ", "                                   ", "                                   ", "                                   ", "                                   ", "                                   ", "    I             IIII        I    ", "   ICD          IICCCCIII    DCI   ", "    I             IIII        I    ", "                                   ", "                                   ", "                                   ", "                                   ", "                                   ", "    I     I                   I    ", "   ICD   ICB                 DCI   ", "    I     I                   I    ", "                                   ", "                                   ", "                                   ", "                                   ", "                                   ", "    I             IIII        I    ", "   ICD          IICCCCIII    DCI   ", "    I             IIII        I    ", "                                   ", "                                   ", "                                   ", "                                   ", "                                   ", "    I     I                   I    ", "   ICD   ICB                 DCI   ", "    I     I                   I    ", "                                   ", "                                   ", "                                   ", "                                   ", "                                   ", "    I             IIII        I    ", "   ICD          IICCCCIII    DCI   ", "    I             IIII        I    ", "                                   ", "                                   ", "                                   ", "                                   ", "                                   ", "    I     I                   I    ", "   ICD   ICB                 DCI   ", "    I     I                   I    ", "                                   ", "                                   ", "                                   ", "                                   ", "                                   ", "    I             IIII        I    ", "   ICD          IICCCCIII    DCI   ", "    I             IIII        I    ", "                                   ", "                                   ", "                                   ", "                                   ", "                                   ", "    I     I                   I    ", "   ICD   ICB                 DCI   ", "    I     I                   I    ", "                                   ", "                                   ", "                                   ", "                                   ", "                                   ", "    I             IIII        I    ", "   ICD          IICCCCIII    DCI   ", "    I             IIII        I    ", "                                   ", "                                   ", "               EEEEE               ", "                                   ")
            .aisle("               LLLLL               ", "             EEHHHHHEE             ", "               LLLLL               ", "                                   ", "    I     I                   I    ", "   ICD   ICB                 DCI   ", "    I     I                   I    ", "                                   ", "                                   ", "                                   ", "                                   ", "                                   ", "    I           II    III     I    ", "   ICD         ICCBBBBCCCII  DCI   ", "    I           II    III     I    ", "                                   ", "                                   ", "                                   ", "                                   ", "                                   ", "    I     I                   I    ", "   ICD   ICB                 DCI   ", "    I     I                   I    ", "                                   ", "                                   ", "                                   ", "                                   ", "                                   ", "    I           II    III     I    ", "   ICD         ICCBBBBCCCII  DCI   ", "    I           II    III     I    ", "                                   ", "                                   ", "                                   ", "                                   ", "                                   ", "    I     I                   I    ", "   ICD   ICB                 DCI   ", "    I     I                   I    ", "                                   ", "                                   ", "                                   ", "                                   ", "                                   ", "    I           II    III     I    ", "   ICD         ICCBBBBCCCII  DCI   ", "    I           II    III     I    ", "                                   ", "                                   ", "                                   ", "                                   ", "                                   ", "    I     I                   I    ", "   ICD   ICB                 DCI   ", "    I     I                   I    ", "                                   ", "                                   ", "                                   ", "                                   ", "                                   ", "    I           II    III     I    ", "   ICD         ICCBBBBCCCII  DCI   ", "    I           II    III     I    ", "                                   ", "                                   ", "                                   ", "                                   ", "                                   ", "    I     I                   I    ", "   ICD   ICB                 DCI   ", "    I     I                   I    ", "                                   ", "                                   ", "                                   ", "                                   ", "                                   ", "    I           II    III     I    ", "   ICD         ICCBBBBCCCII  DCI   ", "    I           II    III     I    ", "                                   ", "                                   ", "                                   ", "                                   ", "                                   ", "    I     I                   I    ", "   ICD   ICB                 DCI   ", "    I     I                   I    ", "                                   ", "                                   ", "                                   ", "                                   ", "                                   ", "    I           II    III     I    ", "   ICD         ICCBBBBCCCII  DCI   ", "    I           II    III     I    ", "                                   ", "                                   ", "                                   ", "                                   ", "                                   ", "    I     I                   I    ", "   ICD   ICB                 DCI   ", "    I     I                   I    ", "                                   ", "                                   ", "                                   ", "                                   ", "                                   ", "    I           II    III     I    ", "   ICD         ICCBBBBCCCII  DCI   ", "    I           II    III     I    ", "                                   ", "                                   ", "                                   ", "                                   ", "                                   ", "    I     I                   I    ", "   ICD   ICB                 DCI   ", "    I     I                   I    ", "                                   ", "                                   ", "                                   ", "                                   ", "                                   ", "    I           II    III     I    ", "   ICD         ICCBBBBCCCII  DCI   ", "    I           II    III     I    ", "                                   ", "               LLLLL               ", "             EEHHHHHEE             ", "               LLLLL               ")
            .aisle("             LL     LL             ", "            EHHIIIIIHHE            ", "             LL     LL             ", "                                   ", "   I     I                     I   ", "  ICD   ICB     IIII          DCI  ", "   I     I                     I   ", "                                   ", "                                   ", "                                   ", "                                   ", "                                   ", "   I           I         II    I   ", "  ICD         ICBB    BBBCCI  DCI  ", "   I           I         II    I   ", "                                   ", "                                   ", "                                   ", "                                   ", "                                   ", "   I     I                     I   ", "  ICD   ICB     IIII          DCI  ", "   I     I                     I   ", "                                   ", "                                   ", "                                   ", "                                   ", "                                   ", "   I           I         II    I   ", "  ICD         ICBB    BBBCCI  DCI  ", "   I           I         II    I   ", "                                   ", "                                   ", "                                   ", "                                   ", "                                   ", "   I     I                     I   ", "  ICD   ICB     IIII          DCI  ", "   I     I                     I   ", "                                   ", "                                   ", "                                   ", "                                   ", "                                   ", "   I           I         II    I   ", "  ICD         ICBB    BBBCCI  DCI  ", "   I           I         II    I   ", "                                   ", "                                   ", "                                   ", "                                   ", "                                   ", "   I     I                     I   ", "  ICD   ICB     IIII          DCI  ", "   I     I                     I   ", "                                   ", "                                   ", "                                   ", "                                   ", "                                   ", "   I           I         II    I   ", "  ICD         ICBB    BBBCCI  DCI  ", "   I           I         II    I   ", "                                   ", "                                   ", "                                   ", "                                   ", "                                   ", "   I     I                     I   ", "  ICD   ICB     IIII          DCI  ", "   I     I                     I   ", "                                   ", "                                   ", "                                   ", "                                   ", "                                   ", "   I           I         II    I   ", "  ICD         ICBB    BBBCCI  DCI  ", "   I           I         II    I   ", "                                   ", "                                   ", "                                   ", "                                   ", "                                   ", "   I     I                     I   ", "  ICD   ICB     IIII          DCI  ", "   I     I                     I   ", "                                   ", "                                   ", "                                   ", "                                   ", "                                   ", "   I           I         II    I   ", "  ICD         ICBB    BBBCCI  DCI  ", "   I           I         II    I   ", "                                   ", "                                   ", "                                   ", "                                   ", "                                   ", "   I     I                     I   ", "  ICD   ICB     IIII          DCI  ", "   I     I                     I   ", "                                   ", "                                   ", "                                   ", "                                   ", "                                   ", "   I           I         II    I   ", "  ICD         ICBB    BBBCCI  DCI  ", "   I           I         II    I   ", "                                   ", "                                   ", "                                   ", "                                   ", "                                   ", "   I     I                     I   ", "  ICD   ICB     IIII          DCI  ", "   I     I                     I   ", "                                   ", "                                   ", "                                   ", "                                   ", "                                   ", "   I           I         II    I   ", "  ICD         ICBB    BBBCCI  DCI  ", "   I           I         II    I   ", "                                   ", "             LL     LL             ", "            EHHIIIIIHHE            ", "             LL     LL             ")
            .aisle("            L         L            ", "           EHII     IIHE           ", "            L         L            ", "                                   ", "   I     I      IIII           I   ", "  ICD   ICB    ICCCCII        DCI  ", "   I     I      IIII           I   ", "                                   ", "                                   ", "                                   ", "                                   ", "                                   ", "   I          I            I   I   ", "  ICD        ICB         BBCI DCI  ", "   I          I            I   I   ", "                                   ", "                                   ", "                                   ", "                                   ", "                                   ", "   I     I      IIII           I   ", "  ICD   ICB    ICCCCII        DCI  ", "   I     I      IIII           I   ", "                                   ", "                                   ", "                                   ", "                                   ", "                                   ", "   I          I            I   I   ", "  ICD        ICB         BBCI DCI  ", "   I          I            I   I   ", "                                   ", "                                   ", "                                   ", "                                   ", "                                   ", "   I     I      IIII           I   ", "  ICD   ICB    ICCCCII        DCI  ", "   I     I      IIII           I   ", "                                   ", "                                   ", "                                   ", "                                   ", "                                   ", "   I          I            I   I   ", "  ICD        ICB         BBCI DCI  ", "   I          I            I   I   ", "                                   ", "                                   ", "                                   ", "                                   ", "                                   ", "   I     I      IIII           I   ", "  ICD   ICB    ICCCCII        DCI  ", "   I     I      IIII           I   ", "                                   ", "                                   ", "                                   ", "                                   ", "                                   ", "   I          I            I   I   ", "  ICD        ICB         BBCI DCI  ", "   I          I            I   I   ", "                                   ", "                                   ", "                                   ", "                                   ", "                                   ", "   I     I      IIII           I   ", "  ICD   ICB    ICCCCII        DCI  ", "   I     I      IIII           I   ", "                                   ", "                                   ", "                                   ", "                                   ", "                                   ", "   I          I            I   I   ", "  ICD        ICB         BBCI DCI  ", "   I          I            I   I   ", "                                   ", "                                   ", "                                   ", "                                   ", "                                   ", "   I     I      IIII           I   ", "  ICD   ICB    ICCCCII        DCI  ", "   I     I      IIII           I   ", "                                   ", "                                   ", "                                   ", "                                   ", "                                   ", "   I          I            I   I   ", "  ICD        ICB         BBCI DCI  ", "   I          I            I   I   ", "                                   ", "                                   ", "                                   ", "                                   ", "                                   ", "   I     I      IIII           I   ", "  ICD   ICB    ICCCCII        DCI  ", "   I     I      IIII           I   ", "                                   ", "                                   ", "                                   ", "                                   ", "                                   ", "   I          I            I   I   ", "  ICD        ICB         BBCI DCI  ", "   I          I            I   I   ", "                                   ", "                                   ", "                                   ", "                                   ", "                                   ", "   I     I      IIII           I   ", "  ICD   ICB    ICCCCII        DCI  ", "   I     I      IIII           I   ", "                                   ", "                                   ", "                                   ", "                                   ", "                                   ", "   I          I            I   I   ", "  ICD        ICB         BBCI DCI  ", "   I          I            I   I   ", "                                   ", "            L         L            ", "           EHII     IIHE           ", "            L         L            ")
            .aisle("           L           L           ", "          EHI         IHE          ", "           L           L           ", "                JJJ                ", "  I      I     JJJJJII          I  ", " ICD    ICB    JJJJJCCI        DCI ", "  I      I     JJJJJII          I  ", "                JJJ                ", "                                   ", "                                   ", "                                   ", "                                   ", "  I          I              I   I  ", " ICD        ICB            BCI DCI ", "  I          I              I   I  ", "                                   ", "                                   ", "                                   ", "                                   ", "                JJJ                ", "  I      I     JJJJJII          I  ", " ICD    ICB    JJJJJCCI        DCI ", "  I      I     JJJJJII          I  ", "                JJJ                ", "                                   ", "                                   ", "                                   ", "                                   ", "  I          I              I   I  ", " ICD        ICB            BCI DCI ", "  I          I              I   I  ", "                                   ", "                                   ", "                                   ", "                                   ", "                JJJ                ", "  I      I     JJJJJII          I  ", " ICD    ICB    JJJJJCCI        DCI ", "  I      I     JJJJJII          I  ", "                JJJ                ", "                                   ", "                                   ", "                                   ", "                                   ", "  I          I              I   I  ", " ICD        ICB            BCI DCI ", "  I          I              I   I  ", "                                   ", "                                   ", "                                   ", "                                   ", "                JJJ                ", "  I      I     JJJJJII          I  ", " ICD    ICB    JJJJJCCI        DCI ", "  I      I     JJJJJII          I  ", "                JJJ                ", "                                   ", "                                   ", "                                   ", "                                   ", "  I          I              I   I  ", " ICD        ICB            BCI DCI ", "  I          I              I   I  ", "                                   ", "                                   ", "                                   ", "                                   ", "                JJJ                ", "  I      I     JJJJJII          I  ", " ICD    ICB    JJJJJCCI        DCI ", "  I      I     JJJJJII          I  ", "                JJJ                ", "                                   ", "                                   ", "                                   ", "                                   ", "  I          I              I   I  ", " ICD        ICB            BCI DCI ", "  I          I              I   I  ", "                                   ", "                                   ", "                                   ", "                                   ", "                JJJ                ", "  I      I     JJJJJII          I  ", " ICD    ICB    JJJJJCCI        DCI ", "  I      I     JJJJJII          I  ", "                JJJ                ", "                                   ", "                                   ", "                                   ", "                                   ", "  I          I              I   I  ", " ICD        ICB            BCI DCI ", "  I          I              I   I  ", "                                   ", "                                   ", "                                   ", "                                   ", "                JJJ                ", "  I      I     JJJJJII          I  ", " ICD    ICB    JJJJJCCI        DCI ", "  I      I     JJJJJII          I  ", "                JJJ                ", "                                   ", "                                   ", "                                   ", "                                   ", "  I          I              I   I  ", " ICD        ICB            BCI DCI ", "  I          I              I   I  ", "                                   ", "                                   ", "                                   ", "                                   ", "                JJJ                ", "  I      I     JJJJJII          I  ", " ICD    ICB    JJJJJCCI        DCI ", "  I      I     JJJJJII          I  ", "                JJJ                ", "                                   ", "                                   ", "                                   ", "                                   ", "  I          I              I   I  ", " ICD        ICB            BCI DCI ", "  I          I              I   I  ", "                                   ", "           L           L           ", "          EHI         IHE          ", "           L           L           ")
