package com.gtladd.gtladditions.Common.MuiltBlock.Structure;

import com.gregtechceu.gtceu.api.pattern.FactoryBlockPattern;

public class MultiBlockStructure {

    public MultiBlockStructure() {}

    public static final FactoryBlockPattern ARCANIC_ASTROGRAPH_STRUCTURE;
    public static final FactoryBlockPattern FUXI_BAGUA_HEAVEN_FORGING_FURNACE_STRUCTURE;
    public static final FactoryBlockPattern BIOLOGICAL_SIMULATION_LABORATORY_STRUCTURE;
    public static final FactoryBlockPattern TITAN_CRIP_EARTHBORE_STRUCTURE;
    public static final FactoryBlockPattern DRACONIC_COLLAPSE_CORE_STRUCTURE;
    public static final FactoryBlockPattern LUCID_ETCHDREAMER_STRUCTURE;
    public static final FactoryBlockPattern QUANTUM_SYPHON_MATRIX_STRUCTURE;

    static {
        ARCANIC_ASTROGRAPH_STRUCTURE = FactoryBlockPattern.start()
                .aisle("                                 ", "                                 ", "                                 ", "                                 ", "                                 ", "                                 ", "                                 ", "                                 ", "                                 ", "                                 ", "                                 ", "                                 ", "               A A               ", "               A A               ", "               A A               ", "            AAAAAAAAA            ", "               A A               ", "            AAAAAAAAA            ", "               A A               ", "               A A               ", "               A A               ", "                                 ", "                                 ", "                                 ", "                                 ", "                                 ", "                                 ", "                                 ", "                                 ", "                                 ", "                                 ", "                                 ", "                                 ")
                .aisle("                                 ", "                                 ", "                                 ", "                                 ", "                                 ", "                                 ", "                                 ", "                                 ", "                                 ", "               A A               ", "               A A               ", "               A A               ", "               A A               ", "              DDDDD              ", "             DDADADD             ", "         AAAADAADAADAAAA         ", "             DDDDDDD             ", "         AAAADAADAADAAAA         ", "             DDADADD             ", "              DDDDD              ", "               A A               ", "               A A               ", "               A A               ", "               A A               ", "                                 ", "                                 ", "                                 ", "                                 ", "                                 ", "                                 ", "                                 ", "                                 ", "                                 ")
                .aisle("                                 ", "                                 ", "                                 ", "                                 ", "                                 ", "                                 ", "                                 ", "               A A               ", "               A A               ", "               A A               ", "                D                ", "                D                ", "             DDDDDDD             ", "            DD     DD            ", "            D  EEE  D            ", "       AAA  D EFFFE D  AAA       ", "          DDD EFFFE DDD          ", "       AAA  D EFFFE D  AAA       ", "            D  EEE  D            ", "            DD     DD            ", "             DDDDDDD             ", "                D                ", "                D                ", "               A A               ", "               A A               ", "               A A               ", "                                 ", "                                 ", "                                 ", "                                 ", "                                 ", "                                 ", "                                 ")
                .aisle("                                 ", "                                 ", "                                 ", "                                 ", "                                 ", "                                 ", "               A A               ", "               A A               ", "                D                ", "                D                ", "                                 ", "                                 ", "                                 ", "                                 ", "                                 ", "      AA                 AA      ", "        DD             DD        ", "      AA                 AA      ", "                                 ", "                                 ", "                                 ", "                                 ", "                                 ", "                D                ", "                D                ", "               A A               ", "               A A               ", "                                 ", "                                 ", "                                 ", "                                 ", "                                 ", "                                 ")
                .aisle("                                 ", "                                 ", "                                 ", "                                 ", "                                 ", "               A A               ", "              AAAAA              ", "                D                ", "                F                ", "                F                ", "                                 ", "                                 ", "                                 ", "                                 ", "      A                   A      ", "     AA                   AA     ", "      ADFF             FFDA      ", "     AA                   AA     ", "      A                   A      ", "                                 ", "                                 ", "                                 ", "                                 ", "                F                ", "                F                ", "                D                ", "              AAAAA              ", "               A A               ", "                                 ", "                                 ", "                                 ", "                                 ", "                                 ")
                .aisle("                                 ", "                                 ", "                                 ", "                                 ", "               A A               ", "               A A               ", "                D                ", "             GEEFEEG             ", "                                 ", "                                 ", "                                 ", "                                 ", "                                 ", "       G                 G       ", "       E                 E       ", "    AA E                 E AA    ", "      DF                 FD      ", "    AA E                 E AA    ", "       E                 E       ", "       G                 G       ", "                                 ", "                                 ", "                                 ", "                                 ", "                                 ", "             GEEFEEG             ", "                D                ", "               A A               ", "               A A               ", "                                 ", "                                 ", "                                 ", "                                 ")
                .aisle("                                 ", "                                 ", "                                 ", "               A A               ", "              AAAAA              ", "                D                ", "                F                ", "                                 ", "                                 ", "                                 ", "                                 ", "                                 ", "                                 ", "                                 ", "    A                       A    ", "   AA                       AA   ", "    ADF                   FDA    ", "   AA                       AA   ", "    A                       A    ", "                                 ", "                                 ", "                                 ", "                                 ", "                                 ", "                                 ", "                                 ", "                F                ", "                D                ", "              AAAAA              ", "               A A               ", "                                 ", "                                 ", "                                 ")
                .aisle("                                 ", "                                 ", "               A A               ", "               A A               ", "                D                ", "             GEEFEEG             ", "                                 ", "                                 ", "                                 ", "                                 ", "                                 ", "                                 ", "                                 ", "     G                     G     ", "     E                     E     ", "  AA E                     E AA  ", "    DF                     FD    ", "  AA E                     E AA  ", "     E                     E     ", "     G                     G     ", "                                 ", "                                 ", "                                 ", "                                 ", "                                 ", "                                 ", "                                 ", "             GEEFEEG             ", "                D                ", "               A A               ", "               A A               ", "                                 ", "                                 ")
                .aisle("                                 ", "                                 ", "               A A               ", "                D                ", "                F                ", "                                 ", "                                 ", "                                 ", "                                 ", "                                 ", "                                 ", "                                 ", "                                 ", "                                 ", "                                 ", "  A                           A  ", "   DF                       FD   ", "  A                           A  ", "                                 ", "                                 ", "                                 ", "                                 ", "                                 ", "                                 ", "                                 ", "                                 ", "                                 ", "                                 ", "                F                ", "                D                ", "               A A               ", "                                 ", "                                 ")
                .aisle("                                 ", "               A A               ", "               A A               ", "                D                ", "                F                ", "                                 ", "                                 ", "                                 ", "                                 ", "                                 ", "                                 ", "                                 ", "                                 ", "                                 ", "                                 ", " AA                           AA ", "   DF                       FD   ", " AA                           AA ", "                                 ", "                                 ", "                                 ", "                                 ", "                                 ", "                                 ", "                                 ", "                                 ", "                                 ", "                                 ", "                F                ", "                D                ", "               A A               ", "               A A               ", "                                 ")
                .aisle("                                 ", "               A A               ", "                D                ", "                                 ", "                                 ", "                                 ", "                                 ", "                                 ", "                                 ", "                                 ", "                                 ", "                                 ", "                                 ", "                                 ", "                                 ", " A                             A ", "  D                           D  ", " A                             A ", "                                 ", "                                 ", "                                 ", "                                 ", "                                 ", "                                 ", "                                 ", "                                 ", "                                 ", "                                 ", "                                 ", "                                 ", "                D                ", "               A A               ", "                                 ")
                .aisle("                                 ", "               A A               ", "                D                ", "                                 ", "                                 ", "                                 ", "                                 ", "                                 ", "                                 ", "                                 ", "                                 ", "                                 ", "                                 ", "                                 ", "                                 ", " A                             A ", "  D                           D  ", " A                             A ", "                                 ", "                                 ", "                                 ", "                                 ", "                                 ", "                                 ", "                                 ", "                                 ", "                                 ", "                                 ", "                                 ", "                                 ", "                D                ", "               A A               ", "                                 ")
                .aisle("               A A               ", "               A A               ", "             DDDDDDD             ", "                                 ", "                                 ", "                                 ", "                                 ", "                                 ", "                                 ", "                                 ", "                                 ", "                                 ", "                                 ", "  D                           D  ", "  D                           D  ", "AAD                           DAA", "  D                           D  ", "AAD                           DAA", "  D                           D  ", "  D                           D  ", "                                 ", "                                 ", "                                 ", "                                 ", "                                 ", "                                 ", "                                 ", "                                 ", "                                 ", "                                 ", "             DDDDDDD             ", "               A A               ", "               A A               ")
                .aisle("               A A               ", "              DDDDD              ", "            DD     DD            ", "                                 ", "                                 ", "       G                 G       ", "                                 ", "     G                     G     ", "                                 ", "                                 ", "                                 ", "                                 ", "  D                           D  ", "  D                           D  ", " D                             D ", "AD                             DA", " D                             D ", "AD                             DA", " D                             D ", "  D                           D  ", "  D                           D  ", "                                 ", "                                 ", "                                 ", "                                 ", "     G                     G     ", "                                 ", "       G                 G       ", "                                 ", "                                 ", "            DD     DD            ", "              DDDDD              ", "               A A               ")
                .aisle("               A A               ", "             DDADADD             ", "            D  EEE  D            ", "                                 ", "      A                   A      ", "       E                 E       ", "    A                       A    ", "     E                     E     ", "                                 ", "                                 ", "                                 ", "                                 ", "  D                           D  ", " D                             D ", " D                             D ", "AAE                           EAA", " DE                           ED ", "AAE                           EAA", " D                             D ", " D                             D ", "  D                           D  ", "                                 ", "                                 ", "                                 ", "                                 ", "     E                     E     ", "    A                       A    ", "       E                 E       ", "      A                   A      ", "                                 ", "            D  EEE  D            ", "             DDADADD             ", "               A A               ")
                .aisle("            AAAAAAAAA            ", "         AAAADAADAADAAAA         ", "       AAA  D EFFFE D  AAA       ", "      AA                 AA      ", "     AA                   AA     ", "    AA E                 E AA    ", "   AA                       AA   ", "  AA E                     E AA  ", "  A                           A  ", " AA                           AA ", " A                             A ", " A                             A ", "AAD                           DAA", "AD                             DA", "AAE                           EAA", "AAF                           FAA", "ADF                           FDA", "AAF                           FAA", "AAE                           EAA", "AD                             DA", "AAD                           DAA", " A                             A ", " A                             A ", " AA                           AA ", "  A                           A  ", "  AA E                     E AA  ", "   AA                       AA   ", "    AA E                 E AA    ", "     AA                   AA     ", "      AA                 AA      ", "       AAA  D EFFFE D  AAA       ", "         AAAADAADAADAAAA         ", "            AAAAAAAAA            ")
                .aisle("               A A               ", "             DDDDDDD             ", "          DDD EFFFE DDD          ", "        DD             DD        ", "      ADFF             FFDA      ", "      DF                 FD      ", "    ADF                   FDA    ", "    DF                     FD    ", "   DF                       FD   ", "   DF                       FD   ", "  D                           D  ", "  D                           D  ", "  D                           D  ", " D                             D ", " DE                           ED ", "ADF                           FDA", " DF                           FD ", "ADF                           FDA", " DE                           ED ", " D                             D ", "  D                           D  ", "  D                           D  ", "  D                           D  ", "   DF                       FD   ", "   DF                       FD   ", "    DF                     FD    ", "    ADF                   FDA    ", "      DF                 FD      ", "      ADFF             FFDA      ", "        DD             DD        ", "          DDD EFFFE DDD          ", "             DDDDDDD             ", "               A A               ")
                .aisle("            AAAAAAAAA            ", "         AAAADAADAADAAAA         ", "       AAA  D EFFFE D  AAA       ", "      AA                 AA      ", "     AA                   AA     ", "    AA E                 E AA    ", "   AA                       AA   ", "  AA E                     E AA  ", "  A                           A  ", " AA                           AA ", " A                             A ", " A                             A ", "AAD                           DAA", "AD                             DA", "AAE                           EAA", "AAF                           FAA", "ADF                           FDA", "AAF                           FAA", "AAE                           EAA", "AD                             DA", "AAD                           DAA", " A                             A ", " A                             A ", " AA                           AA ", "  A                           A  ", "  AA E                     E AA  ", "   AA                       AA   ", "    AA E                 E AA    ", "     AA                   AA     ", "      AA                 AA      ", "       AAA  D EFFFE D  AAA       ", "         AAAADAADAADAAAA         ", "            AAAAAAAAA            ")
                .aisle("               A A               ", "             DDADADD             ", "            D  EEE  D            ", "                                 ", "      A                   A      ", "       E                 E       ", "    A                       A    ", "     E                     E     ", "                                 ", "                                 ", "                                 ", "                                 ", "  D                           D  ", " D                             D ", " D                             D ", "AAE                           EAA", " DE                           ED ", "AAE                           EAA", " D                             D ", " D                             D ", "  D                           D  ", "                                 ", "                                 ", "                                 ", "                                 ", "     E                     E     ", "    A                       A    ", "       E                 E       ", "      A                   A      ", "                                 ", "            D  EEE  D            ", "             DDADADD             ", "               A A               ")
                .aisle("               A A               ", "              DDDDD              ", "            DD     DD            ", "                                 ", "                                 ", "       G                 G       ", "                                 ", "     G                     G     ", "                                 ", "                                 ", "                                 ", "                                 ", "  D                           D  ", "  D                           D  ", " D                             D ", "AD                             DA", " D                             D ", "AD                             DA", " D                             D ", "  D                           D  ", "  D                           D  ", "                                 ", "                                 ", "                                 ", "                                 ", "     G                     G     ", "                                 ", "       G                 G       ", "                                 ", "                                 ", "            DD     DD            ", "              DDDDD              ", "               A A               ")
                .aisle("               A A               ", "               A A               ", "             DDDDDDD             ", "                                 ", "                                 ", "                                 ", "                                 ", "                                 ", "                                 ", "                                 ", "                                 ", "                                 ", "                                 ", "  D                           D  ", "  D                           D  ", "AAD                           DAA", "  D                           D  ", "AAD                           DAA", "  D                           D  ", "  D                           D  ", "                                 ", "                                 ", "                                 ", "                                 ", "                                 ", "                                 ", "                                 ", "                                 ", "                                 ", "                                 ", "             DDDDDDD             ", "               A A               ", "               A A               ")
                .aisle("                                 ", "               A A               ", "                D                ", "                                 ", "                                 ", "                                 ", "                                 ", "                                 ", "                                 ", "                                 ", "                                 ", "                                 ", "                                 ", "                                 ", "                                 ", " A                             A ", "  D                           D  ", " A                             A ", "                                 ", "                                 ", "                                 ", "                                 ", "                                 ", "                                 ", "                                 ", "                                 ", "                                 ", "                                 ", "                                 ", "                                 ", "                D                ", "               A A               ", "                                 ")
                .aisle("                                 ", "               A A               ", "                D                ", "                                 ", "                                 ", "                                 ", "                                 ", "                                 ", "                                 ", "                                 ", "                                 ", "                                 ", "                                 ", "                                 ", "                                 ", " A                             A ", "  D                           D  ", " A                             A ", "                                 ", "                                 ", "                                 ", "                                 ", "                                 ", "                                 ", "                                 ", "                                 ", "                                 ", "                                 ", "                                 ", "                                 ", "                D                ", "               A A               ", "                                 ")
                .aisle("                                 ", "               A A               ", "               A A               ", "                D                ", "                F                ", "                                 ", "                                 ", "                                 ", "                                 ", "                                 ", "                                 ", "                                 ", "                                 ", "                                 ", "                                 ", " AA                           AA ", "   DF                       FD   ", " AA                           AA ", "                                 ", "                                 ", "                                 ", "                                 ", "                                 ", "                                 ", "                                 ", "                                 ", "                                 ", "                                 ", "                F                ", "                D                ", "               A A               ", "               A A               ", "                                 ")
                .aisle("                                 ", "                                 ", "               A A               ", "                D                ", "                F                ", "                                 ", "                                 ", "                                 ", "                                 ", "                                 ", "                                 ", "                                 ", "                                 ", "                                 ", "                                 ", "  A                           A  ", "   DF                       FD   ", "  A                           A  ", "                                 ", "                                 ", "                                 ", "                                 ", "                                 ", "                                 ", "                                 ", "                                 ", "                                 ", "                                 ", "                F                ", "                D                ", "               A A               ", "                                 ", "                                 ")
                .aisle("                                 ", "                                 ", "               A A               ", "               A A               ", "                D                ", "             GEEFEEG             ", "                                 ", "                                 ", "                                 ", "                                 ", "                                 ", "                                 ", "                                 ", "     G                     G     ", "     E                     E     ", "  AA E                     E AA  ", "    DF                     FD    ", "  AA E                     E AA  ", "     E                     E     ", "     G                     G     ", "                                 ", "                                 ", "                                 ", "                                 ", "                                 ", "                                 ", "                                 ", "             GEEFEEG             ", "                D                ", "               A A               ", "               A A               ", "                                 ", "                                 ")
                .aisle("                                 ", "                                 ", "                                 ", "               A A               ", "              AAAAA              ", "                D                ", "                F                ", "                                 ", "                                 ", "                                 ", "                                 ", "                                 ", "                                 ", "                                 ", "    A                       A    ", "   AA                       AA   ", "    ADF                   FDA    ", "   AA                       AA   ", "    A                       A    ", "                                 ", "                                 ", "                                 ", "                                 ", "                                 ", "                                 ", "                                 ", "                F                ", "                D                ", "              AAAAA              ", "               A A               ", "                                 ", "                                 ", "                                 ")
                .aisle("                                 ", "                                 ", "                                 ", "                                 ", "               A A               ", "               A A               ", "                D                ", "             GEEFEEG             ", "                                 ", "                                 ", "                                 ", "                                 ", "                                 ", "       G                 G       ", "       E                 E       ", "    AA E                 E AA    ", "      DF                 FD      ", "    AA E                 E AA    ", "       E                 E       ", "       G                 G       ", "                                 ", "                                 ", "                                 ", "                                 ", "                                 ", "             GEEFEEG             ", "                D                ", "               A A               ", "               A A               ", "                                 ", "                                 ", "                                 ", "                                 ")
                .aisle("                                 ", "                                 ", "                                 ", "                                 ", "                                 ", "               A A               ", "              AAAAA              ", "                D                ", "                F                ", "                F                ", "                                 ", "                                 ", "                                 ", "                                 ", "      A                   A      ", "     AA                   AA     ", "      ADFF             FFDA      ", "     AA                   AA     ", "      A                   A      ", "                                 ", "                                 ", "                                 ", "                                 ", "                F                ", "                F                ", "                D                ", "              AAAAA              ", "               A A               ", "                                 ", "                                 ", "                                 ", "                                 ", "                                 ")
                .aisle("                                 ", "                                 ", "                                 ", "                                 ", "                                 ", "                                 ", "               A A               ", "               A A               ", "                D                ", "                D                ", "                                 ", "                                 ", "                                 ", "                                 ", "                                 ", "      AA                 AA      ", "        DD             DD        ", "      AA                 AA      ", "                                 ", "                                 ", "                                 ", "                                 ", "                                 ", "                D                ", "                D                ", "               A A               ", "               A A               ", "                                 ", "                                 ", "                                 ", "                                 ", "                                 ", "                                 ")
                .aisle("                                 ", "                                 ", "                                 ", "                                 ", "                                 ", "                                 ", "                                 ", "               A A               ", "               A A               ", "               A A               ", "                D                ", "                D                ", "             DDDDDDD             ", "            DD     DD            ", "            D  EEE  D            ", "       AAA  D EFFFE D  AAA       ", "          DDD EFFFE DDD          ", "       AAA  D EFFFE D  AAA       ", "            D  EEE  D            ", "            DD     DD            ", "             DDDDDDD             ", "                D                ", "                D                ", "               A A               ", "               A A               ", "               A A               ", "                                 ", "                                 ", "                                 ", "                                 ", "                                 ", "                                 ", "                                 ")
                .aisle("                                 ", "                                 ", "                                 ", "                                 ", "                                 ", "                                 ", "                                 ", "                                 ", "                                 ", "               A A               ", "               A A               ", "               A A               ", "               A A               ", "              DDDDD              ", "             DDADADD             ", "         AAAADAADAADAAAA         ", "             DDDDDDD             ", "         AAAADAADAADAAAA         ", "             DDADADD             ", "              DDDDD              ", "               A A               ", "               A A               ", "               A A               ", "               A A               ", "                                 ", "                                 ", "                                 ", "                                 ", "                                 ", "                                 ", "                                 ", "                                 ", "                                 ")
                .aisle("                                 ", "                                 ", "                                 ", "                                 ", "                                 ", "                                 ", "                                 ", "                                 ", "                                 ", "                                 ", "                                 ", "                                 ", "             AAAAAAA             ", "            AABBBBBAA            ", "            ABBBBBBBA            ", "            ABBAAABBA            ", "            ABBA~ABBA            ", "            ABBAAABBA            ", "            ABBBBBBBA            ", "            AABBBBBAA            ", "             AAAAAAA             ", "                                 ", "                                 ", "                                 ", "                                 ", "                                 ", "                                 ", "                                 ", "                                 ", "                                 ", "                                 ", "                                 ", "                                 ");
        FUXI_BAGUA_HEAVEN_FORGING_FURNACE_STRUCTURE = FactoryBlockPattern.start()
                .aisle("                                           ", "                                           ", "                                           ", "                                           ", "                                           ", "                                           ", "                                           ", "                                           ", "                                           ", "                                           ", "                                           ", "                                           ", "                                           ", "                                           ", "                 A                         ", "                AAA                        ", "                AAAA                       ", "                 AAAA                      ", "                  AAAAA                    ", "                   AAAAA                   ", "                    AAAAA                  ", "                      AAAA                 ", "                       AAAA                ", "                        AAA                ", "                         A                 ", "                                           ", "                                           ", "                                           ", "                                           ", "                                           ", "                                           ", "                                           ", "                                           ", "                                           ", "                                           ", "                                           ", "                                           ", "                                           ", "                                           ")
                .aisle("                                           ", "                                           ", "                                           ", "                                           ", "                                           ", "                                           ", "                                           ", "                                           ", "                                           ", "                                           ", "                                           ", "                                           ", "               A                           ", "              AAAA                         ", "              AAAKAA                       ", "               ALLKAA                      ", "               AKLLKAA                     ", "               AAKLLKAA                    ", "                 AKKLKKA                   ", "                  AKKLKKA                  ", "                   AKKLKKA                 ", "                    AAKLLKAA               ", "                     AAKLLKA               ", "                      AAKLLA               ", "                       AAKAAA              ", "                         AAAA              ", "                           A               ", "                                           ", "                                           ", "                                           ", "                                           ", "                                           ", "                                           ", "                                           ", "                                           ", "                                           ", "                                           ", "                                           ", "                                           ")
                .aisle("                                           ", "                                           ", "                                           ", "                                           ", "                                           ", "                                           ", "                                           ", "                                           ", "                                           ", "                                           ", "                                           ", "            AAAA                           ", "           AAAAKA                          ", "            AALKKA                         ", "             AKLLKAA                       ", "             AAKLLKAA                      ", "              AAKLLKAA                     ", "               AAKLLKAA                    ", "                 AKKLKKA                   ", "                  AKKLKKA                  ", "                   AKKLKKA                 ", "                    AAKLLKAA               ", "                     AAKLLKAA              ", "                      AAKLLKAA             ", "                       AAKLLKA             ", "                         AKKLAA            ", "                          AKAAAA           ", "                           AAAA            ", "                                           ", "                                           ", "                                           ", "                                           ", "                                           ", "                                           ", "                                           ", "                                           ", "                                           ", "                                           ", "                                           ")
                .aisle("                                           ", "                                           ", "                                           ", "                                           ", "                                           ", "                                           ", "                                           ", "                                           ", "                                           ", "           A                               ", "          AAAAA                            ", "          AALKKA                           ", "          AKKLKKA                          ", "           AKKLKKA                         ", "            AKKLLKAA                       ", "             AAKLLFAA                      ", "              AAKMMFAA                     ", "               AAFMMFAA                    ", "                 AFFMFFA                   ", "                  AFFMFFA                  ", "                   AFFMFFA                 ", "                    AAFMMFAA               ", "                     AAFMMKAA              ", "                      AAFLLKAA             ", "                       AAKLLKKA            ", "                         AKKLKKA           ", "                          AKKLKKA          ", "                           AKKLAA          ", "                            AAAAA          ", "                               A           ", "                                           ", "                                           ", "                                           ", "                                           ", "                                           ", "                                           ", "                                           ", "                                           ", "                                           ")
                .aisle("                                           ", "                                           ", "                                           ", "                                           ", "                                           ", "                                           ", "                                           ", "                                           ", "           AA                              ", "          AKAA                             ", "         ALLKAA                            ", "         AKKLKKA                           ", "          AKKLKFA                          ", "           AKKMFFA                         ", "            AFFMMFA                        ", "             AAFMMF                        ", "              AAFM                         ", "               AA                          ", "                                           ", "                                           ", "                                           ", "                          AA               ", "                         MFAA              ", "                        FMMFAA             ", "                        AFMMFFA            ", "                         AFFMKKA           ", "                          AFKLKKA          ", "                           AKKLKKA         ", "                            AAKLLA         ", "                             AAKA          ", "                              AA           ", "                                           ", "                                           ", "                                           ", "                                           ", "                                           ", "                                           ", "                                           ", "                                           ")
                .aisle("                                           ", "                                           ", "                                           ", "                                           ", "                                           ", "                                           ", "                                           ", "         A                                 ", "        AAAAA                              ", "       AAALKAA                             ", "        AKLLKAA                            ", "        AAKKLFFA                           ", "          AKFMFF                           ", "           AFFM                            ", "            AFF                            ", "                                           ", "                                           ", "                                           ", "                                           ", "                                           ", "                                           ", "                                           ", "                                           ", "                                           ", "                            FFA            ", "                            MFFA           ", "                           FFMFKA          ", "                           AFFLKKAA        ", "                            AAKLLKA        ", "                             AAKLAAA       ", "                              AAAAA        ", "                                 A         ", "                                           ", "                                           ", "                                           ", "                                           ", "                                           ", "                                           ", "                                           ")
                .aisle("                                           ", "                                           ", "                                           ", "                                           ", "                                           ", "                                           ", "                                           ", "       AAAAA                               ", "       AALKAA                              ", "       AKLLKAA                             ", "        AKLMFAA                            ", "        AAKFMFF                            ", "          AFFM                             ", "           AF                              ", "                                           ", "                        A                  ", "                       A                   ", "                      A                    ", "                      A                    ", "                AAAAAAAAAAA                ", "                    A                      ", "                    A                      ", "                   A                       ", "                  A                        ", "                                           ", "                              FA           ", "                             MFFA          ", "                            FFMFKAA        ", "                            AAFMLKA        ", "                             AAKLLKA       ", "                              AAKLAA       ", "                               AAAAA       ", "                                           ", "                                           ", "                                           ", "                                           ", "                                           ", "                                           ", "                                           ")
                .aisle("                                           ", "                                           ", "                                           ", "                                           ", "                                           ", "                                           ", "       AAA                                 ", "      ALKKAA                               ", "      AKLLKAA                              ", "      AAKLLFA                              ", "       AAKMMF                              ", "        AAFF                               ", "          A              A                 ", "                         A                 ", "                       AA                  ", "                      AALA                 ", "                      ALA                  ", "                     ALAA                  ", "                AAAAAALAAAA                ", "             AAALLLLALALLLLAAA             ", "                AAAALAAAAAA                ", "                  AALA                     ", "                  ALA                      ", "                 ALAA                      ", "                  AA                       ", "                 A                         ", "                 A              A          ", "                               FFAA        ", "                              FMMKAA       ", "                              AFLLKAA      ", "                              AAKLLKA      ", "                               AAKKLA      ", "                                 AAA       ", "                                           ", "                                           ", "                                           ", "                                           ", "                                           ", "                                           ")
                .aisle("                                           ", "                                           ", "                                           ", "                                           ", "                                           ", "       AA                                  ", "      AKKA                                 ", "     AKLKKAA                               ", "      AKLMFAA                              ", "      AAFMMF                               ", "       AAFM                                ", "        AAF              AA                ", "                        ALA                ", "                        ALA                ", "                       ALAA                ", "                      AAMA                 ", "                      AMA                  ", "                     AMAA                  ", "             AAAAAAAAAMAAAAAAA             ", "           AALLLMMMMMMMMMMMLLLAA           ", "             AAAAAAAMAAAAAAAAA             ", "                  AAMA                     ", "                  AMA                      ", "                 AMAA                      ", "                AALA                       ", "                ALA                        ", "                ALA                        ", "                AA              FAA        ", "                                MFAA       ", "                               FMMFAA      ", "                              AAFMLKA      ", "                               AAKKLKA     ", "                                 AKKA      ", "                                  AA       ", "                                           ", "                                           ", "                                           ", "                                           ", "                                           ")
                .aisle("                                           ", "                                           ", "                                           ", "                                           ", "      AA                                   ", "     AAKA                                  ", "     ALKKA                                 ", "    AKKLKFA                                ", "     AAKMMF                                ", "      AAFM                 A               ", "       AA                 AA               ", "                         ALA               ", "                        AMLA               ", "                        AMA                ", "                       AMAA                ", "                        MA                 ", "                                           ", "                                           ", "           AAAAAA         AAAAAA           ", "         AALLMMMM         MMMMLLAA         ", "           AAAAAA         AAAAAA           ", "                                           ", "                                           ", "                 AM                        ", "                AAMA                       ", "                AMA                        ", "               ALMA                        ", "               ALA                         ", "               AA                 AA       ", "               A                 MFAA      ", "                                FMMKAA     ", "                                AFKLKKA    ", "                                 AKKLA     ", "                                  AKAA     ", "                                   AA      ", "                                           ", "                                           ", "                                           ", "                                           ")
                .aisle("                                           ", "                                           ", "                                           ", "                                           ", "     AAA                                   ", "    AAAKA                                  ", "    AALKFA                                 ", "    AKKMFF                                 ", "     AAFM                  AA              ", "      AA                  ALA              ", "                          ALA              ", "                         AMA               ", "                         MMA               ", "                          A                ", "                                           ", "                                           ", "                                           ", "                                           ", "         AAAAA               AAAAA         ", "        ALLMMM               MMMLLA        ", "         AAAAA               AAAAA         ", "                                           ", "                                           ", "                                           ", "                                           ", "                A                          ", "               AMM                         ", "               AMA                         ", "              ALA                          ", "              ALA                  AA      ", "              AA                  MFAA     ", "                                 FFMKKA    ", "                                 AFKLAA    ", "                                  AKAAA    ", "                                   AAA     ", "                                           ", "                                           ", "                                           ", "                                           ")
                .aisle("                                           ", "                                           ", "                                           ", "      A                                    ", "     AKA                                   ", "    ALKKA                                  ", "    AKLFFA                   A             ", "    AKFMF                   AA             ", "     AAF                   ALA             ", "      A                   ALLA             ", "                          AMA              ", "                           A               ", "                                           ", "                                           ", "                                           ", "                                           ", "                                           ", "                                           ", "        AAAA                   AAAA        ", "      AALLMM                   MMLLAA      ", "        AAAA                   AAAA        ", "                                           ", "                                           ", "                                           ", "                                           ", "                                           ", "                                           ", "               A                           ", "              AMA                          ", "             ALLA                   A      ", "             ALA                   FAA     ", "             AA                   FMFKA    ", "                                 AFFLKA    ", "                                  AKKLA    ", "                                   AKA     ", "                                    A      ", "                                           ", "                                           ", "                                           ")
                .aisle("                                           ", "                                           ", "                                           ", "    AAA                                    ", "   AAKKA                                   ", "   AKLKKA                                  ", "   AKKLF                     AA            ", "    AKF                     AA             ", "     AA                    AMA             ", "                          AMMA             ", "                           MA              ", "                                           ", "                                           ", "                                           ", "                                           ", "                                           ", "                                           ", "                                           ", "       AAAA                     AAAA       ", "     AALMMM                     MMMLAA     ", "       AAAA                     AAAA       ", "                                           ", "                                           ", "                                           ", "                                           ", "                                           ", "                                           ", "                                           ", "              AM                           ", "             AMMA                          ", "             AMA                    AA     ", "             AA                     FKA    ", "            AA                     FLKKA   ", "                                  AKKLKA   ", "                                   AKKAA   ", "                                    AAA    ", "                                           ", "                                           ", "                                           ")
                .aisle("                                           ", "                                           ", "   AAA                                     ", "   AKAA                                    ", "  ALLKKA                                   ", "  AKKLKFA                                  ", "  AAKKMF                    AAA            ", "    AFF                     AMA            ", "     AA                     MA             ", "                                           ", "                                           ", "                                           ", "                                           ", "                                           ", "                                           ", "                                           ", "                                           ", "                                           ", "      AAA                         AAA      ", "     ALMM                         MMLA     ", "      AAA                         AAA      ", "                                           ", "                                           ", "                                           ", "                                           ", "                                           ", "                                           ", "                                           ", "                                           ", "                                           ", "             AM                     AA     ", "            AMA                     FFA    ", "            AAA                    FMKKAA  ", "                                  AFKLKKA  ", "                                   AKKLLA  ", "                                    AAKA   ", "                                     AAA   ", "                                           ", "                                           ")
                .aisle("                                           ", "                                           ", "   AAA                                     ", "   AKAA                                    ", "  ALLKFA                                   ", "  AKKMFF                     AA            ", "  AAFFM                     AMLA           ", "    AF                      AMA            ", "                             A             ", "                                           ", "                                           ", "                                           ", "                                           ", "                                           ", "                                           ", "                                           ", "                                           ", "                                           ", "     AAA                           AAA     ", "    ALMM                           MMLA    ", "     AAA                           AAA     ", "                                           ", "                                           ", "                                           ", "                                           ", "                                           ", "                                           ", "                                           ", "                                           ", "                                           ", "             A                             ", "            AMA                      FA    ", "           ALMA                     MFFAA  ", "            AA                     FFMKKA  ", "                                   AFKLLA  ", "                                    AAKA   ", "                                     AAA   ", "                                           ", "                                           ")
                .aisle("                                           ", "                                           ", "  AAAA                                     ", " AALKAA                                    ", " AKLLKF                      AAA           ", "  AKKMF                     AALA           ", "   AFF                      AMLA           ", "    A                         A            ", "                                           ", "                                           ", "                                           ", "                                           ", "                                           ", "                                           ", "                                           ", "                                           ", "                                           ", "                                           ", "    AAA                             AAA    ", "   ALLM                             MLLA   ", "    AAA                             AAA    ", "                                           ", "                                           ", "                                           ", "                                           ", "                                           ", "                                           ", "                                           ", "                                           ", "                                           ", "                                           ", "            A                         A    ", "           ALMA                      FFA   ", "           ALAA                     FMKKA  ", "           AAA                      FKLLKA ", "                                    AAKLAA ", "                                     AAAA  ", "                                           ", "                                           ")
                .aisle("                                           ", "                                           ", "  AAAA                                     ", " AALKAA                                    ", " AKLLFF                      AAA           ", "  AKFMF                     AALA           ", "   AFF                      AMMA           ", "    A                         A            ", "                                           ", "                                           ", "                                           ", "                                           ", "                                           ", "                                           ", "                                           ", "                                           ", "                                           ", "                                           ", "    AAA                             AAA    ", "   ALMM                             MMLA   ", "    AAA                             AAA    ", "                                           ", "                                           ", "                                           ", "                                           ", "                                           ", "                                           ", "                                           ", "                                           ", "                                           ", "                                           ", "            A                         A    ", "           AMMA                      FFA   ", "           ALAA                     FMFKA  ", "           AAA                      FFLLKA ", "                                    AAKLAA ", "                                     AAAA  ", "                                           ", "                                           ")
                .aisle("                                           ", "                                           ", "  AAAA                                     ", " AALKA                        AA           ", " AKLLF                       AALA          ", "  AKF                        AMAA          ", "   A                          MA           ", "                                           ", "                                           ", "                                           ", "                                           ", "                                           ", "                                           ", "                                           ", "                                           ", "                                           ", "                                           ", "                                           ", "   AAA                               AAA   ", "  ALMM                               MMLA  ", "   AAA                               AAA   ", "                                           ", "                                           ", "                                           ", "                                           ", "                                           ", "                                           ", "                                           ", "                                           ", "                                           ", "                                           ", "                                           ", "           AM                          A   ", "          AAMA                        FKA  ", "          ALAA                       FLLKA ", "           AA                        AKLAA ", "                                     AAAA  ", "                                           ", "                                           ")
                .aisle("                                           ", "  AAA                                      ", " ALKAA                                     ", " ALLFA                        AA           ", " AKMMF                       AALA          ", "  AFF                         MAA          ", "   A                                       ", "                                           ", "                                           ", "                                           ", "                                           ", "                                           ", "                                           ", "                                           ", "                                           ", "                                           ", "                                           ", "                                           ", "   AA                                 AA   ", "  ALM                                 MLA  ", "   AA                                 AA   ", "                                           ", "                                           ", "                                           ", "                                           ", "                                           ", "                                           ", "                                           ", "                                           ", "                                           ", "                                           ", "                                           ", "                                       A   ", "          AAM                         FFA  ", "          ALAA                       FMMKA ", "           AA                        AFLLA ", "                                     AAKLA ", "                                      AAA  ", "                                           ")
                .aisle("                                           ", "  AAA                                      ", " ALKAA                         AA          ", " ALLFA                        ALA          ", " AKMM                        AAMA          ", "  AF                          MA           ", "                                           ", "                                           ", "                                           ", "                                           ", "                                           ", "                                           ", "                                           ", "                                           ", "                                           ", "                                           ", "                                           ", "                                           ", "  AAA                                 AAA  ", " ALMM                                 MMLA ", "  AAA                                 AAA  ", "                                           ", "                                           ", "                                           ", "                                           ", "                                           ", "                                           ", "                                           ", "                                           ", "                                           ", "                                           ", "                                           ", "                                           ", "           AM                          FA  ", "          AMAA                        MMKA ", "          ALA                        AFLLA ", "          AA                         AAKLA ", "                                      AAA  ", "                                           ")
                .aisle("                                           ", "  AAA                                      ", " ALKAA                         AA          ", " ALLFA                        ALA          ", " AKMM                          MA          ", "  AF                                       ", "                                           ", "                                           ", "                                           ", "                                           ", "                                           ", "                                           ", "                                           ", "                                           ", "                                           ", "                                           ", "                                           ", "                    NNN                    ", "  AA               NNNNN               AA  ", " ALM               NNNNN               MLA ", "  AA               NNNNN               AA  ", "                    NNN                    ", "                                           ", "                                           ", "                                           ", "                                           ", "                                           ", "                                           ", "                                           ", "                                           ", "                                           ", "                                           ", "                                           ", "                                       FA  ", "          AM                          MMKA ", "          ALA                        AFLLA ", "          AA                         AAKLA ", "                                      AAA  ", "                                           ")
                .aisle("  AA                                       ", " AKAA                                      ", "ALLKAA                         AA          ", "AKLLFA                        ALA          ", "AAKMM                          MA          ", "  AF                                       ", "                                           ", "                                           ", "                                           ", "                                           ", "                                           ", "                                           ", "                                           ", "                                           ", "                                           ", "                   NNNNN                   ", "                  NNNNNNN                  ", "                 NNN   NNN                 ", "  AA             NN     NN             AA  ", " ALM             NN  X  NN             MLA ", "  AA             NN     NN             AA  ", "                 NNN   NNN                 ", "                  NNNNNNN                  ", "                   NNNNN                   ", "                                           ", "                                           ", "                                           ", "                                           ", "                                           ", "                                           ", "                                           ", "                                           ", "                                           ", "                                       FA  ", "          AM                          MMKAA", "          ALA                        AFLLKA", "          AA                         AAKLLA", "                                      AAKA ", "                                       AA  ")
                .aisle("  AA                                       ", " AKAA                           A          ", "ALLKAA                         ALA         ", "AKLMFA                        AMAA         ", "AAFMM                          MA          ", "  AF                                       ", "                                           ", "                                           ", "                                           ", "                                           ", "                                           ", "                                           ", "                                           ", "                                           ", "                   NNNNN                   ", "                  N     N                  ", "                 N       N                 ", "                N         N                ", " AAA            N         N            AAA ", "ALMM            N    X    N            MMLA", " AAA            N         N            AAA ", "                N         N                ", "                 N       N                 ", "                  N     N                  ", "                   NNNNN                   ", "                                           ", "                                           ", "                                           ", "                                           ", "                                           ", "                                           ", "                                           ", "                                           ", "                                       FA  ", "          AM                          MMFAA", "         AAMA                        AFMLKA", "         ALA                         AAKLLA", "          A                           AAKA ", "                                       AA  ")
                .aisle("  AA                                       ", " AKAA                           A          ", "ALLKA                          ALA         ", "AKLM                          AMAA         ", "AAF                             A          ", "  A                                        ", "                                           ", "                                           ", "                                           ", "                                           ", "                                           ", "                                           ", "                                           ", "                   NNNNN                   ", "                  N     N                  ", "                 N       N                 ", "                N         N                ", "               N           N               ", " AA            N           N            AA ", "ALM            N     X     N            MLA", " AA            N           N            AA ", "               N           N               ", "                N         N                ", "                 N       N                 ", "                  N     N                  ", "                   NNNNN                   ", "                                           ", "                                           ", "                                           ", "                                           ", "                                           ", "                                           ", "                                           ", "                                        A  ", "          A                             FAA", "         AAMA                          MLKA", "         ALA                          AKLLA", "          A                           AAKA ", "                                       AA  ")
                .aisle("  AA                                       ", " AKAA                           A          ", "ALLKA                          ALA         ", "AKLM                          AMAA         ", "AAF                             A          ", "  A                                        ", "                                           ", "                                           ", "                                           ", "                                           ", "                                           ", "                                           ", "                                           ", "                  NNNNNNN                  ", "                 N       N                 ", "                N         N                ", "               N           N               ", "               N           N               ", " AA            N           N            AA ", "ALM            N     X     N            MLA", " AA            N           N            AA ", "               N           N               ", "               N           N               ", "                N         N                ", "                 N       N                 ", "                  NNNNNNN                  ", "                                           ", "                                           ", "                                           ", "                                           ", "                                           ", "                                           ", "                                           ", "                                        A  ", "          A                             FAA", "         AAMA                          MLKA", "         ALA                          AKLLA", "          A                           AAKA ", "                                       AA  ")
                .aisle("  AA                                       ", " AKAA                           A          ", "ALLKA                          ALA         ", "AKLM                          AMAA         ", "AAF                             A          ", "  A                                        ", "                                           ", "                                           ", "                                           ", "                                           ", "                                           ", "                                           ", "                    NNN                    ", "                 NNN   NNN                 ", "                N         N                ", "               N           N               ", "               N           N               ", "               N           N               ", " AA           N             N           AA ", "ALM           N      X      N           MLA", " AA           N             N           AA ", "               N           N               ", "               N           N               ", "               N           N               ", "                N         N                ", "                 NNN   NNN                 ", "                    NNN                    ", "                                           ", "                                           ", "                                           ", "                                           ", "                                           ", "                                           ", "                                        A  ", "          A                             FAA", "         AAMA                          MLKA", "         ALA                          AKLLA", "          A                           AAKA ", "                                       AA  ")
                .aisle("  AA                                       ", " AKAA                           A          ", "ALLKA                          ALA         ", "AKLM                          AMAA         ", "AAF                             A          ", "  A                                        ", "                                           ", "                                           ", "                                           ", "                                           ", "                                           ", "                                           ", "                   NNNNN                   ", "                 NN     NN                 ", "                N         N                ", "               N           N               ", "               N           N               ", "              N             N              ", " AA           N     XXX     N           AA ", "ALM           N     XOX     N           MLA", " AA           N     XXX     N           AA ", "              N             N              ", "               N           N               ", "               N           N               ", "                N         N                ", "                 NN     NN                 ", "                   NNNNN                   ", "                                           ", "                                           ", "                                           ", "                                           ", "                                           ", "                                           ", "                                        A  ", "          A                             FAA", "         AAMA                          MLKA", "         ALA                          AKLLA", "          A                           AAKA ", "                                       AA  ")
                .aisle("  AA                                       ", " AKAA                           A          ", "ALLKA                          ALA         ", "AKLM                          AMAA         ", "AAF                             A          ", "  A                                        ", "                                           ", "                                           ", "                                           ", "                                           ", "                                           ", "                                           ", "                   NNNNN                   ", "                 NN  X  NN                 ", "                N    X    N                ", "               N     X     N               ", "               N     X     N               ", "              N      X      N              ", " AA           N     XOX     N           AA ", "ALM           NXXXXXOOOXXXXXN           MLA", " AA           N     XOX     N           AA ", "              N      X      N              ", "               N     X     N               ", "               N     X     N               ", "                N    X    N                ", "                 NN  X  NN                 ", "                   NNNNN                   ", "                                           ", "                                           ", "                                           ", "                                           ", "                                           ", "                                           ", "                                        A  ", "          A                             FAA", "         AAMA                          MLKA", "         ALA                          AKLLA", "          A                           AAKA ", "                                       AA  ")
                .aisle("  AA                                       ", " AKAA                           A          ", "ALLKA                          ALA         ", "AKLM                          AMAA         ", "AAF                             A          ", "  A                                        ", "                                           ", "                                           ", "                                           ", "                                           ", "                                           ", "                                           ", "                   NNNNN                   ", "                 NN     NN                 ", "                N         N                ", "               N           N               ", "               N           N               ", "              N             N              ", " AA           N     XXX     N           AA ", "ALM           N     XOX     N           MLA", " AA           N     XXX     N           AA ", "              N             N              ", "               N           N               ", "               N           N               ", "                N         N                ", "                 NN     NN                 ", "                   NNNNN                   ", "                                           ", "                                           ", "                                           ", "                                           ", "                                           ", "                                           ", "                                        A  ", "          A                             FAA", "         AAMA                          MLKA", "         ALA                          AKLLA", "          A                           AAKA ", "                                       AA  ")
                .aisle("  AA                                       ", " AKAA                           A          ", "ALLKA                          ALA         ", "AKLM                          AMAA         ", "AAF                             A          ", "  A                                        ", "                                           ", "                                           ", "                                           ", "                                           ", "                                           ", "                                           ", "                    NNN                    ", "                 NNN   NNN                 ", "                N         N                ", "               N           N               ", "               N           N               ", "               N           N               ", " AA           N             N           AA ", "ALM           N      X      N           MLA", " AA           N             N           AA ", "               N           N               ", "               N           N               ", "               N           N               ", "                N         N                ", "                 NNN   NNN                 ", "                    NNN                    ", "                                           ", "                                           ", "                                           ", "                                           ", "                                           ", "                                           ", "                                        A  ", "          A                             FAA", "         AAMA                          MLKA", "         ALA                          AKLLA", "          A                           AAKA ", "                                       AA  ")
                .aisle("  AA                                       ", " AKAA                           A          ", "ALLKA                          ALA         ", "AKLM                          AMAA         ", "AAF                             A          ", "  A                                        ", "                                           ", "                                           ", "                                           ", "                                           ", "                                           ", "                                           ", "                                           ", "                  NNNNNNN                  ", "                 N       N                 ", "                N         N                ", "               N           N               ", "               N           N               ", " AA            N           N            AA ", "ALM            N     X     N            MLA", " AA            N           N            AA ", "               N           N               ", "               N           N               ", "                N         N                ", "                 N       N                 ", "                  NNNNNNN                  ", "                                           ", "                                           ", "                                           ", "                                           ", "                                           ", "                                           ", "                                           ", "                                        A  ", "          A                             FAA", "         AAMA                          MLKA", "         ALA                          AKLLA", "          A                           AAKA ", "                                       AA  ")
